Workbook

Sheet B-S calculator
B2: You can copy this calculator and use it in your workings if you wish
B4: Black-Scholes calculator
B5: Parameters
B6: Share price
B7: Strike price
B8: Maturity
B9: Risk-free rate
B10: Volatility
B12: Calculations
B13: Present value of strike | C13: =++C7*EXP(-C9*C8) -> 0
B14: s*t^.5 | C14: =+C10*C8^0.5 -> 0
B15: d1 | C15: =++(LN(C6/C7)+(C9+C10*C10/2)*C8)/(C10*C8^0.5) -> #DIV/0!
B16: d2 | C16: =+C15-C14 -> #DIV/0!
B17: N(d1) | C17: =_xlfn.NORM.DIST(C15,0,1,TRUE) -> #DIV/0!
B18: N(d2) | C18: =_xlfn.NORM.DIST(C16,0,1,TRUE) -> #DIV/0!
B20: Option values
B21: Value of Put option | C21: =(C17-1)*C6-C18*C13+C13 -> #DIV/0!
B22: Value of Call option | C22: =C17*C6-C18*C13 -> #DIV/0!

Sheet Q1 Data
B2: Parameters
B4: U | C4: 200
B5: c | C5: 10
B6: λ | C6: 0.5
B8: α | C8: 250
B9: β | C9: 2.5
B11: Claim numbers | E11: Claim amounts | K11: t(i) = time between (i-1)th and ith claim | Q11: Surplus process
B13: Simulation | C13: N(12) | E13: Simulation | F13: x1 | G13: x2 | H13: x3 | I13: x4 | K13: Simulation | L13: t(1) | M13: t(2) | N13: t(3) | O13: t(4) | Q13: Simulation | R13: U(0) | S13: U(1) | T13: U(2) | U13: U(3) | V13: U(4) | W13: U(5) | X13: U(6) | Y13: U(7) | Z13: U(8) | AA13: U(9) | AB13: U(10) | AC13: U(11) | AD13: U(12)
B14: 1 | C14: 1 | E14: 1 | F14: 106.3 | K14: 1 | L14: 1.2496 | Q14: 1 | R14: Not provided
B15: 2 | C15: 0 | E15: 2 | K15: 2 | Q15: 2
B16: 3 | C16: 2 | E16: 3 | F16: 95.1 | G16: 102.3 | K16: 3 | L16: 0.4032 | M16: 1.089 | Q16: 3
B17: 4 | C17: 3 | E17: 4 | F17: 109 | G17: 95.5 | H17: 96.5 | K17: 4 | L17: 0.5569 | M17: 0.5416 | N17: 5.0276 | Q17: 4
B18: 5 | C18: 1 | E18: 5 | F18: 101.1 | K18: 5 | L18: 3.3945 | Q18: 5
B19: 6 | C19: 0 | E19: 6 | K19: 6 | Q19: 6 | R19: 200 | S19: 210 | T19: 220 | U19: 230 | V19: 240 | W19: 250 | X19: 260 | Y19: 270 | Z19: 280 | AA19: 290 | AB19: 300 | AC19: 310 | AD19: 320
B20: 7 | C20: 0 | E20: 7 | K20: 7 | Q20: 7 | R20: 200 | S20: 210 | T20: 220 | U20: 230 | V20: 240 | W20: 250 | X20: 260 | Y20: 270 | Z20: 280 | AA20: 290 | AB20: 300 | AC20: 310 | AD20: 320
B21: 8 | C21: 1 | E21: 8 | F21: 98.4 | K21: 8 | L21: 0.3442 | Q21: 8 | R21: 200 | S21: 111.61873 | T21: 121.61873 | U21: 131.61873 | V21: 141.61873 | W21: 151.61873 | X21: 161.61873 | Y21: 171.61873 | Z21: 181.61873 | AA21: 191.61873 | AB21: 201.61873 | AC21: 211.61873 | AD21: 221.61873
B22: 9 | C22: 2 | E22: 9 | F22: 99 | G22: 99.3 | K22: 9 | L22: 0.6066 | M22: 1.0251 | Q22: 9 | R22: 200 | S22: 110.99676 | T22: 21.677506 | U22: 31.677506 | V22: 41.677506 | W22: 51.677506 | X22: 61.677506 | Y22: 71.677506 | Z22: 81.677506 | AA22: 91.677506 | AB22: 101.67751 | AC22: 111.67751 | AD22: 121.67751
B23: 10 | C23: 0 | E23: 10 | K23: 10 | Q23: 10 | R23: 200 | S23: 210 | T23: 220 | U23: 230 | V23: 240 | W23: 250 | X23: 260 | Y23: 270 | Z23: 280 | AA23: 290 | AB23: 300 | AC23: 310 | AD23: 320
B24: 11 | C24: 0 | E24: 11 | K24: 11 | Q24: 11 | R24: 200 | S24: 210 | T24: 220 | U24: 230 | V24: 240 | W24: 250 | X24: 260 | Y24: 270 | Z24: 280 | AA24: 290 | AB24: 300 | AC24: 310 | AD24: 320
B25: 12 | C25: 0 | E25: 12 | K25: 12 | Q25: 12 | R25: 200 | S25: 210 | T25: 220 | U25: 230 | V25: 240 | W25: 250 | X25: 260 | Y25: 270 | Z25: 280 | AA25: 290 | AB25: 300 | AC25: 310 | AD25: 320
B26: 13 | C26: 1 | E26: 13 | F26: 93.6 | K26: 13 | L26: 1.3273 | Q26: 13 | R26: 200 | S26: 210 | T26: 126.44721 | U26: 136.44721 | V26: 146.44721 | W26: 156.44721 | X26: 166.44721 | Y26: 176.44721 | Z26: 186.44721 | AA26: 196.44721 | AB26: 206.44721 | AC26: 216.44721 | AD26: 226.44721
B27: 14 | C27: 1 | E27: 14 | F27: 95.4 | K27: 14 | L27: 1.7913 | Q27: 14 | R27: 200 | S27: 210 | T27: 124.56606 | U27: 134.56606 | V27: 144.56606 | W27: 154.56606 | X27: 164.56606 | Y27: 174.56606 | Z27: 184.56606 | AA27: 194.56606 | AB27: 204.56606 | AC27: 214.56606 | AD27: 224.56606
B28: 15 | C28: 0 | E28: 15 | K28: 15 | Q28: 15 | R28: 200 | S28: 210 | T28: 220 | U28: 230 | V28: 240 | W28: 250 | X28: 260 | Y28: 270 | Z28: 280 | AA28: 290 | AB28: 300 | AC28: 310 | AD28: 320
B29: 16 | C29: 0 | E29: 16 | K29: 16 | Q29: 16 | R29: 200 | S29: 210 | T29: 220 | U29: 230 | V29: 240 | W29: 250 | X29: 260 | Y29: 270 | Z29: 280 | AA29: 290 | AB29: 300 | AC29: 310 | AD29: 320
B30: 17 | C30: 0 | E30: 17 | K30: 17 | Q30: 17 | R30: 200 | S30: 210 | T30: 220 | U30: 230 | V30: 240 | W30: 250 | X30: 260 | Y30: 270 | Z30: 280 | AA30: 290 | AB30: 300 | AC30: 310 | AD30: 320
B31: 18 | C31: 1 | E31: 18 | F31: 100.5 | K31: 18 | L31: 4.2149 | Q31: 18 | R31: 200 | S31: 210 | T31: 220 | U31: 230 | V31: 240 | W31: 149.51781 | X31: 159.51781 | Y31: 169.51781 | Z31: 179.51781 | AA31: 189.51781 | AB31: 199.51781 | AC31: 209.51781 | AD31: 219.51781
B32: 19 | C32: 0 | E32: 19 | K32: 19 | Q32: 19 | R32: 200 | S32: 210 | T32: 220 | U32: 230 | V32: 240 | W32: 250 | X32: 260 | Y32: 270 | Z32: 280 | AA32: 290 | AB32: 300 | AC32: 310 | AD32: 320
B33: 20 | C33: 0 | E33: 20 | K33: 20 | Q33: 20 | R33: 200 | S33: 210 | T33: 220 | U33: 230 | V33: 240 | W33: 250 | X33: 260 | Y33: 270 | Z33: 280 | AA33: 290 | AB33: 300 | AC33: 310 | AD33: 320
B34: 21 | C34: 0 | E34: 21 | K34: 21 | Q34: 21 | R34: 200 | S34: 210 | T34: 220 | U34: 230 | V34: 240 | W34: 250 | X34: 260 | Y34: 270 | Z34: 280 | AA34: 290 | AB34: 300 | AC34: 310 | AD34: 320
B35: 22 | C35: 1 | E35: 22 | F35: 106.4 | K35: 22 | L35: 0.8153 | Q35: 22 | R35: 200 | S35: 103.62206 | T35: 113.62206 | U35: 123.62206 | V35: 133.62206 | W35: 143.62206 | X35: 153.62206 | Y35: 163.62206 | Z35: 173.62206 | AA35: 183.62206 | AB35: 193.62206 | AC35: 203.62206 | AD35: 213.62206
B36: 23 | C36: 2 | E36: 23 | F36: 92.7 | G36: 90.9 | K36: 23 | L36: 5.6588 | M36: 5.6237 | Q36: 23 | R36: 200 | S36: 210 | T36: 220 | U36: 230 | V36: 240 | W36: 250 | X36: 167.33485 | Y36: 177.33485 | Z36: 187.33485 | AA36: 197.33485 | AB36: 207.33485 | AC36: 217.33485 | AD36: 136.39238
B37: 24 | C37: 0 | E37: 24 | K37: 24 | Q37: 24 | R37: 200 | S37: 210 | T37: 220 | U37: 230 | V37: 240 | W37: 250 | X37: 260 | Y37: 270 | Z37: 280 | AA37: 290 | AB37: 300 | AC37: 310 | AD37: 320
B38: 25 | C38: 1 | E38: 25 | F38: 111.3 | K38: 25 | L38: 0.5615 | Q38: 25 | R38: 200 | S38: 98.738197 | T38: 108.7382 | U38: 118.7382 | V38: 128.7382 | W38: 138.7382 | X38: 148.7382 | Y38: 158.7382 | Z38: 168.7382 | AA38: 178.7382 | AB38: 188.7382 | AC38: 198.7382 | AD38: 208.7382
B39: 26 | C39: 1 | E39: 26 | F39: 104 | K39: 26 | L39: 1.4694 | Q39: 26 | R39: 200 | S39: 210 | T39: 116.04676 | U39: 126.04676 | V39: 136.04676 | W39: 146.04676 | X39: 156.04676 | Y39: 166.04676 | Z39: 176.04676 | AA39: 186.04676 | AB39: 196.04676 | AC39: 206.04676 | AD39: 216.04676
B40: 27 | C40: 0 | E40: 27 | K40: 27 | Q40: 27 | R40: 200 | S40: 210 | T40: 220 | U40: 230 | V40: 240 | W40: 250 | X40: 260 | Y40: 270 | Z40: 280 | AA40: 290 | AB40: 300 | AC40: 310 | AD40: 320
B41: 28 | C41: 0 | E41: 28 | K41: 28 | Q41: 28 | R41: 200 | S41: 210 | T41: 220 | U41: 230 | V41: 240 | W41: 250 | X41: 260 | Y41: 270 | Z41: 280 | AA41: 290 | AB41: 300 | AC41: 310 | AD41: 320
B42: 29 | C42: 1 | E42: 29 | F42: 110.5 | K42: 29 | L42: 3.6499 | Q42: 29 | R42: 200 | S42: 210 | T42: 220 | U42: 230 | V42: 129.51527 | W42: 139.51527 | X42: 149.51527 | Y42: 159.51527 | Z42: 169.51527 | AA42: 179.51527 | AB42: 189.51527 | AC42: 199.51527 | AD42: 209.51527
B43: 30 | C43: 0 | E43: 30 | K43: 30 | Q43: 30 | R43: 200 | S43: 210 | T43: 220 | U43: 230 | V43: 240 | W43: 250 | X43: 260 | Y43: 270 | Z43: 280 | AA43: 290 | AB43: 300 | AC43: 310 | AD43: 320
B44: 31 | C44: 1 | E44: 31 | F44: 102.5 | K44: 31 | L44: 0.6043 | Q44: 31 | R44: 200 | S44: 107.51699 | T44: 117.51699 | U44: 127.51699 | V44: 137.51699 | W44: 147.51699 | X44: 157.51699 | Y44: 167.51699 | Z44: 177.51699 | AA44: 187.51699 | AB44: 197.51699 | AC44: 207.51699 | AD44: 217.51699
B45: 32 | C45: 1 | E45: 32 | F45: 99.8 | K45: 32 | L45: 2.3877 | Q45: 32 | R45: 200 | S45: 210 | T45: 220 | U45: 130.2081 | V45: 140.2081 | W45: 150.2081 | X45: 160.2081 | Y45: 170.2081 | Z45: 180.2081 | AA45: 190.2081 | AB45: 200.2081 | AC45: 210.2081 | AD45: 220.2081
...

Sheet 1i
B2: λ | C2: ='Q1 Data'!C6 -> 0.5
B4: (a) | C4: Using the poisson pdf:
C6: x | D6: p(x)
C7: 0 | D7: =(EXP(-$C$2)*$C$2^C7)/FACT(C7) -> 0.60653066
C8: 1 | D8: =(EXP(-$C$2)*$C$2^C8)/FACT(C8) -> 0.30326533
C9: 2 | D9: =(EXP(-$C$2)*$C$2^C9)/FACT(C9) -> 0.075816332 | F9: [1]
C11: P(N(t))<=2 | D11: =SUM(D7:D9) -> 0.98561232 | F11: [1]
C13: Note - the question asked for P(N(t))<=2. The answer here is P(N(1))<=2 but credit was awarded for using other values of t or for a general t.
B15: (b) | C15: For a Poisson Process with parameter lambda, inter-event times have an exponential distribution with parameter lambda
C17: P(t(3)>3) = 1-P(t(3)<=3) = exp(-lambda*3) | F17: [1]
C19: P(t(3)>3) | D19: =EXP(-C2*3) -> 0.22313016 | F19: [1]

Sheet 1ii
B2: (a) | C2: Claim numbers | D2: Mean | E2: =AVERAGE('Q1 Data'!$C$14:$C$113) -> 0.51 | F2: [1]
D3: s.d. | E3: =_xlfn.STDEV.P('Q1 Data'!$C$14:$C$113) -> 0.76804948 | F3: [1]
B5: (b) | C5: Claim amounts | D5: Mean | E5: =AVERAGE('Q1 Data'!$F$14:$I$113) -> 99.680392 | F5: [1]
D6: s.d. | E6: =_xlfn.STDEV.P('Q1 Data'!$F$14:$I$113) -> 5.9915633 | F6: [1]

Sheet 1iii
B2: Comments:
B3: The mean/sd for the number/amount are similar for the simulations and the distribution. | C3: [1]
B4: Therefore it is likely the simulations were created using the stated distributions. | C4: [1]
B5: If the simulations were run again the results would be different. | C5: [1]
B6: Increasing the number of simulations would reduce the difference between the simulated mean/sd and the theoretical mean/sd. | C6: [1]
C7: Plus [1] for any other valid comment
C8: [Max 3]

Sheet 1iv
B2: Simulation | C2: N(12) | D2: t(1) | E2: t(2) | F2: t(3) | G2: t(4) | I2: Simulation | J2: x1 | K2: x2 | L2: x3 | M2: x4
B3: ='Q1 Data'!B72 -> 59 | C3: ='Q1 Data'!C72 -> 4 | D3: ='Q1 Data'!L72 -> 3.4938 | E3: ='Q1 Data'!M72 -> 1.1029 | F3: ='Q1 Data'!N72 -> 0.3149 | G3: ='Q1 Data'!O72 -> 0.5633 | I3: ='Q1 Data'!E72 -> 59 | J3: ='Q1 Data'!F72 -> 104.3 | K3: ='Q1 Data'!G72 -> 99.4 | L3: ='Q1 Data'!H72 -> 91.7 | M3: ='Q1 Data'!I72 -> 92.9
B5: U | C5: ='Q1 Data'!C4 -> 200 | E5: [1]
B6: ct | C6: ='Q1 Data'!C5*12 -> 120 | E6: [1]
B7: S(t) | C7: =SUM(J3:M3) -> 388.3 | E7: [1]
B9: U(12) | C9: =C5+C6-C7 -> -68.3 | E9: [1]

Sheet 1v
B2: U | C2: ='Q1 Data'!C4 -> 200
B3: c | C3: ='Q1 Data'!C5 -> 10
B5: Simulation | C5: N(12) | D5: t(1) | E5: t(2) | F5: t(3) | G5: t(4) | I5: Simulation | J5: x1 | K5: x2 | L5: x3 | M5: x4
B6: 1 | C6: 1 | D6: 1.2496 | I6: 1 | J6: 106.3
B7: 2 | C7: 0 | I7: 2
B8: 3 | C8: 2 | D8: 0.4032 | E8: 1.089 | I8: 3 | J8: 95.1 | K8: 102.3
B9: 4 | C9: 3 | D9: 0.5569 | E9: 0.5416 | F9: 5.0276 | I9: 4 | J9: 109 | K9: 95.5 | L9: 96.5
B10: 5 | C10: 1 | D10: 3.3945 | I10: 5 | J10: 101.1
D12: Cumulative time
B13: Simulation | C13: N(12) | D13: 1 | E13: 2 | F13: 3 | G13: 4
B14: 1 | C14: 1 | D14: =SUM($D6:D6) -> 1.2496 | E14: =SUM($D6:E6) -> 1.2496 | F14: =SUM($D6:F6) -> 1.2496 | G14: =SUM($D6:G6) -> 1.2496
B15: 2 | C15: 0 | D15: =SUM($D7:D7) -> 0 | E15: =SUM($D7:E7) -> 0 | F15: =SUM($D7:F7) -> 0 | G15: =SUM($D7:G7) -> 0
B16: 3 | C16: 2 | D16: =SUM($D8:D8) -> 0.4032 | E16: =SUM($D8:E8) -> 1.4922 | F16: =SUM($D8:F8) -> 1.4922 | G16: =SUM($D8:G8) -> 1.4922
B17: 4 | C17: 3 | D17: =SUM($D9:D9) -> 0.5569 | E17: =SUM($D9:E9) -> 1.0985 | F17: =SUM($D9:F9) -> 6.1261 | G17: =SUM($D9:G9) -> 6.1261
B18: 5 | C18: 1 | D18: =SUM($D10:D10) -> 3.3945 | E18: =SUM($D10:E10) -> 3.3945 | F18: =SUM($D10:F10) -> 3.3945 | G18: =SUM($D10:G10) -> 3.3945
B21: Aggregate claims for t=0 to 12
C22: 0 | D22: 1 | E22: 2 | F22: 3 | G22: 4 | H22: 5 | I22: 6 | J22: 7 | K22: 8 | L22: 9 | M22: 10 | N22: 11 | O22: 12
B23: Simulation | C23: S(0) | D23: S(1) | E23: S(2) | F23: S(3) | G23: S(4) | H23: S(5) | I23: S(6) | J23: S(7) | K23: S(8) | L23: S(9) | M23: S(10) | N23: S(11) | O23: S(12)
B24: 1 | C24: 0 | D24: =IF(ISERROR(MATCH(D$22,$D14:$G14)),0,SUMIF($D14:$G14,"<"&D$22,$J6:$M6)) -> 0 | E24: =IF(ISERROR(MATCH(E$22,$D14:$G14)),0,SUMIF($D14:$G14,"<"&E$22,$J6:$M6)) -> 106.3 | F24: =IF(ISERROR(MATCH(F$22,$D14:$G14)),0,SUMIF($D14:$G14,"<"&F$22,$J6:$M6)) -> 106.3 | G24: =IF(ISERROR(MATCH(G$22,$D14:$G14)),0,SUMIF($D14:$G14,"<"&G$22,$J6:$M6)) -> 106.3 | H24: =IF(ISERROR(MATCH(H$22,$D14:$G14)),0,SUMIF($D14:$G14,"<"&H$22,$J6:$M6)) -> 106.3 | I24: =IF(ISERROR(MATCH(I$22,$D14:$G14)),0,SUMIF($D14:$G14,"<"&I$22,$J6:$M6)) -> 106.3 | J24: =IF(ISERROR(MATCH(J$22,$D14:$G14)),0,SUMIF($D14:$G14,"<"&J$22,$J6:$M6)) -> 106.3 | K24: =IF(ISERROR(MATCH(K$22,$D14:$G14)),0,SUMIF($D14:$G14,"<"&K$22,$J6:$M6)) -> 106.3 | ... O24: =IF(ISERROR(MATCH(O$22,$D14:$G14)),0,SUMIF($D14:$G14,"<"&O$22,$J6:$M6)) -> 106.3 | Q24: [1] | R24: for correct number of claims in each simulation
B25: 2 | C25: 0 | D25: =IF(ISERROR(MATCH(D$22,$D15:$G15)),0,SUMIF($D15:$G15,"<"&D$22,$J7:$M7)) -> 0 | E25: =IF(ISERROR(MATCH(E$22,$D15:$G15)),0,SUMIF($D15:$G15,"<"&E$22,$J7:$M7)) -> 0 | F25: =IF(ISERROR(MATCH(F$22,$D15:$G15)),0,SUMIF($D15:$G15,"<"&F$22,$J7:$M7)) -> 0 | G25: =IF(ISERROR(MATCH(G$22,$D15:$G15)),0,SUMIF($D15:$G15,"<"&G$22,$J7:$M7)) -> 0 | H25: =IF(ISERROR(MATCH(H$22,$D15:$G15)),0,SUMIF($D15:$G15,"<"&H$22,$J7:$M7)) -> 0 | I25: =IF(ISERROR(MATCH(I$22,$D15:$G15)),0,SUMIF($D15:$G15,"<"&I$22,$J7:$M7)) -> 0 | J25: =IF(ISERROR(MATCH(J$22,$D15:$G15)),0,SUMIF($D15:$G15,"<"&J$22,$J7:$M7)) -> 0 | K25: =IF(ISERROR(MATCH(K$22,$D15:$G15)),0,SUMIF($D15:$G15,"<"&K$22,$J7:$M7)) -> 0 | ... O25: =IF(ISERROR(MATCH(O$22,$D15:$G15)),0,SUMIF($D15:$G15,"<"&O$22,$J7:$M7)) -> 0 | Q25: [1] | R25: for correct total claim amounts in each simulation
B26: 3 | C26: 0 | D26: =IF(ISERROR(MATCH(D$22,$D16:$G16)),0,SUMIF($D16:$G16,"<"&D$22,$J8:$M8)) -> 95.1 | E26: =IF(ISERROR(MATCH(E$22,$D16:$G16)),0,SUMIF($D16:$G16,"<"&E$22,$J8:$M8)) -> 197.4 | F26: =IF(ISERROR(MATCH(F$22,$D16:$G16)),0,SUMIF($D16:$G16,"<"&F$22,$J8:$M8)) -> 197.4 | G26: =IF(ISERROR(MATCH(G$22,$D16:$G16)),0,SUMIF($D16:$G16,"<"&G$22,$J8:$M8)) -> 197.4 | H26: =IF(ISERROR(MATCH(H$22,$D16:$G16)),0,SUMIF($D16:$G16,"<"&H$22,$J8:$M8)) -> 197.4 | I26: =IF(ISERROR(MATCH(I$22,$D16:$G16)),0,SUMIF($D16:$G16,"<"&I$22,$J8:$M8)) -> 197.4 | J26: =IF(ISERROR(MATCH(J$22,$D16:$G16)),0,SUMIF($D16:$G16,"<"&J$22,$J8:$M8)) -> 197.4 | K26: =IF(ISERROR(MATCH(K$22,$D16:$G16)),0,SUMIF($D16:$G16,"<"&K$22,$J8:$M8)) -> 197.4 | ... O26: =IF(ISERROR(MATCH(O$22,$D16:$G16)),0,SUMIF($D16:$G16,"<"&O$22,$J8:$M8)) -> 197.4 | Q26: [2] | R26: for correct timing of claims
B27: 4 | C27: 0 | D27: =IF(ISERROR(MATCH(D$22,$D17:$G17)),0,SUMIF($D17:$G17,"<"&D$22,$J9:$M9)) -> 109 | E27: =IF(ISERROR(MATCH(E$22,$D17:$G17)),0,SUMIF($D17:$G17,"<"&E$22,$J9:$M9)) -> 204.5 | F27: =IF(ISERROR(MATCH(F$22,$D17:$G17)),0,SUMIF($D17:$G17,"<"&F$22,$J9:$M9)) -> 204.5 | G27: =IF(ISERROR(MATCH(G$22,$D17:$G17)),0,SUMIF($D17:$G17,"<"&G$22,$J9:$M9)) -> 204.5 | H27: =IF(ISERROR(MATCH(H$22,$D17:$G17)),0,SUMIF($D17:$G17,"<"&H$22,$J9:$M9)) -> 204.5 | I27: =IF(ISERROR(MATCH(I$22,$D17:$G17)),0,SUMIF($D17:$G17,"<"&I$22,$J9:$M9)) -> 204.5 | J27: =IF(ISERROR(MATCH(J$22,$D17:$G17)),0,SUMIF($D17:$G17,"<"&J$22,$J9:$M9)) -> 301 | K27: =IF(ISERROR(MATCH(K$22,$D17:$G17)),0,SUMIF($D17:$G17,"<"&K$22,$J9:$M9)) -> 301 | ... O27: =IF(ISERROR(MATCH(O$22,$D17:$G17)),0,SUMIF($D17:$G17,"<"&O$22,$J9:$M9)) -> 301
B28: 5 | C28: 0 | D28: =IF(ISERROR(MATCH(D$22,$D18:$G18)),0,SUMIF($D18:$G18,"<"&D$22,$J10:$M10)) -> 0 | E28: =IF(ISERROR(MATCH(E$22,$D18:$G18)),0,SUMIF($D18:$G18,"<"&E$22,$J10:$M10)) -> 0 | F28: =IF(ISERROR(MATCH(F$22,$D18:$G18)),0,SUMIF($D18:$G18,"<"&F$22,$J10:$M10)) -> 0 | G28: =IF(ISERROR(MATCH(G$22,$D18:$G18)),0,SUMIF($D18:$G18,"<"&G$22,$J10:$M10)) -> 101.1 | H28: =IF(ISERROR(MATCH(H$22,$D18:$G18)),0,SUMIF($D18:$G18,"<"&H$22,$J10:$M10)) -> 101.1 | I28: =IF(ISERROR(MATCH(I$22,$D18:$G18)),0,SUMIF($D18:$G18,"<"&I$22,$J10:$M10)) -> 101.1 | J28: =IF(ISERROR(MATCH(J$22,$D18:$G18)),0,SUMIF($D18:$G18,"<"&J$22,$J10:$M10)) -> 101.1 | K28: =IF(ISERROR(MATCH(K$22,$D18:$G18)),0,SUMIF($D18:$G18,"<"&K$22,$J10:$M10)) -> 101.1 | ... O28: =IF(ISERROR(MATCH(O$22,$D18:$G18)),0,SUMIF($D18:$G18,"<"&O$22,$J10:$M10)) -> 101.1
B30: Surplus process for t=0 to 12
C31: 0 | D31: 1 | E31: 2 | F31: 3 | G31: 4 | H31: 5 | I31: 6 | J31: 7 | K31: 8 | L31: 9 | M31: 10 | N31: 11 | O31: 12
B32: Simulation | C32: U(0) | D32: U(1) | E32: U(2) | F32: U(3) | G32: U(4) | H32: U(5) | I32: U(6) | J32: U(7) | K32: U(8) | L32: U(9) | M32: U(10) | N32: U(11) | O32: U(12)
B33: 1 | C33: =$C$2 -> 200 | D33: =C33+$C$3-(D24-C24) -> 210 | E33: =D33+$C$3-(E24-D24) -> 113.7 | F33: =E33+$C$3-(F24-E24) -> 123.7 | G33: =F33+$C$3-(G24-F24) -> 133.7 | H33: =G33+$C$3-(H24-G24) -> 143.7 | I33: =H33+$C$3-(I24-H24) -> 153.7 | J33: =I33+$C$3-(J24-I24) -> 163.7 | K33: =J33+$C$3-(K24-J24) -> 173.7 | ... O33: =N33+$C$3-(O24-N24) -> 213.7 | Q33: [1] | R33: for U(0) = 200
B34: 2 | C34: =$C$2 -> 200 | D34: =C34+$C$3-(D25-C25) -> 210 | E34: =D34+$C$3-(E25-D25) -> 220 | F34: =E34+$C$3-(F25-E25) -> 230 | G34: =F34+$C$3-(G25-F25) -> 240 | H34: =G34+$C$3-(H25-G25) -> 250 | I34: =H34+$C$3-(I25-H25) -> 260 | J34: =I34+$C$3-(J25-I25) -> 270 | K34: =J34+$C$3-(K25-J25) -> 280 | ... O34: =N34+$C$3-(O25-N25) -> 320 | Q34: [2] | R34: for correct allowance for premium income
B35: 3 | C35: =$C$2 -> 200 | D35: =C35+$C$3-(D26-C26) -> 114.9 | E35: =D35+$C$3-(E26-D26) -> 22.6 | F35: =E35+$C$3-(F26-E26) -> 32.6 | G35: =F35+$C$3-(G26-F26) -> 42.6 | H35: =G35+$C$3-(H26-G26) -> 52.6 | I35: =H35+$C$3-(I26-H26) -> 62.6 | J35: =I35+$C$3-(J26-I26) -> 72.6 | K35: =J35+$C$3-(K26-J26) -> 82.6 | ... O35: =N35+$C$3-(O26-N26) -> 122.6 | Q35: [2] | R35: for correct surplus process
B36: 4 | C36: =$C$2 -> 200 | D36: =C36+$C$3-(D27-C27) -> 101 | E36: =D36+$C$3-(E27-D27) -> 15.5 | F36: =E36+$C$3-(F27-E27) -> 25.5 | G36: =F36+$C$3-(G27-F27) -> 35.5 | H36: =G36+$C$3-(H27-G27) -> 45.5 | I36: =H36+$C$3-(I27-H27) -> 55.5 | J36: =I36+$C$3-(J27-I27) -> -31 | K36: =J36+$C$3-(K27-J27) -> -21 | ... O36: =N36+$C$3-(O27-N27) -> 19
B37: 5 | C37: =$C$2 -> 200 | D37: =C37+$C$3-(D28-C28) -> 210 | E37: =D37+$C$3-(E28-D28) -> 220 | F37: =E37+$C$3-(F28-E28) -> 230 | G37: =F37+$C$3-(G28-F28) -> 138.9 | H37: =G37+$C$3-(H28-G28) -> 148.9 | I37: =H37+$C$3-(I28-H28) -> 158.9 | J37: =I37+$C$3-(J28-I28) -> 168.9 | K37: =J37+$C$3-(K28-J28) -> 178.9 | ... O37: =N37+$C$3-(O28-N28) -> 218.9

Sheet 1vi
B2: Simulation | C2: Does ruin occur?
B3: 1 | C3: =IF(MIN('1v'!C33:O33)<=0,"Yes","No") -> No | E3: Simulations where ruin occurs | F3: =COUNTIF($C$3:$C$102,"Yes") -> 2 | G3: [1]
B4: 2 | C4: =IF(MIN('1v'!C34:O34)<=0,"Yes","No") -> No | E4: Probability of ruin | F4: =F3/100 -> 0.02 | G4: [1]
B5: 3 | C5: =IF(MIN('1v'!C35:O35)<=0,"Yes","No") -> No
B6: 4 | C6: =IF(MIN('1v'!C36:O36)<=0,"Yes","No") -> Yes
B7: 5 | C7: =IF(MIN('1v'!C37:O37)<=0,"Yes","No") -> No
B8: 6 | C8: =IF(MIN('Q1 Data'!R19:AD19)<=0,"Yes","No") -> No
B9: 7 | C9: =IF(MIN('Q1 Data'!R20:AD20)<=0,"Yes","No") -> No
B10: 8 | C10: =IF(MIN('Q1 Data'!R21:AD21)<=0,"Yes","No") -> No
B11: 9 | C11: =IF(MIN('Q1 Data'!R22:AD22)<=0,"Yes","No") -> No
B12: 10 | C12: =IF(MIN('Q1 Data'!R23:AD23)<=0,"Yes","No") -> No
B13: 11 | C13: =IF(MIN('Q1 Data'!R24:AD24)<=0,"Yes","No") -> No
B14: 12 | C14: =IF(MIN('Q1 Data'!R25:AD25)<=0,"Yes","No") -> No
B15: 13 | C15: =IF(MIN('Q1 Data'!R26:AD26)<=0,"Yes","No") -> No
B16: 14 | C16: =IF(MIN('Q1 Data'!R27:AD27)<=0,"Yes","No") -> No
B17: 15 | C17: =IF(MIN('Q1 Data'!R28:AD28)<=0,"Yes","No") -> No
B18: 16 | C18: =IF(MIN('Q1 Data'!R29:AD29)<=0,"Yes","No") -> No
B19: 17 | C19: =IF(MIN('Q1 Data'!R30:AD30)<=0,"Yes","No") -> No
... B102: 100 | C102: =IF(MIN('Q1 Data'!R113:AD113)<=0,"Yes","No") -> No

Sheet 1vii
B2: (a) | C2: The mean of the claim amounts distribution would increase | D2: [1]
C3: The s.d. of the claim amounts distribution would increase | D3: [1]
C4: This would be likely to increase the probability of ruin | D4: [1]
C5: Any other sensible comment | D5: [1]
D6: [Max 2]
B8: (b) | C8: This is an increase in the rate of premium income | D8: [1]
C9: This would be likely to reduce the probability of ruin | D9: [1]
C11: Any other sensible comment | D11: [1]
D12: [Max 2]
B14: (c) | C14: This would increase the number of claims. | D14: [1]
C15: This would be likely to increase the probability of ruin | D15: [1]
C17: Any other sensible comment | D17: [1]
D18: [Max 2]

Sheet Q2 Data
B2: Monthly share prices | H2: Standard deviation of error term εi
B4: Month, j | C4: Company A | D4: Company B | E4: Company C | F4: Whole market | H4: Company A | I4: Company B | J4: Company C
B5: 1 | C5: 67 | D5: 32 | E5: 30 | F5: 2037 | H5: 0.081 | I5: 0.218 | J5: 0.122
B6: 2 | C6: 70.734998 | D6: 35.02196 | E6: 28.841151 | F6: 2039.2304
B7: 3 | C7: 72.213459 | D7: 36.761815 | E7: 30.477617 | F7: 2140.7106
B8: 4 | C8: 74.072456 | D8: 39.248157 | E8: 31.274431 | F8: 2181.8792
B9: 5 | C9: 77.746053 | D9: 39.323628 | E9: 33.632747 | F9: 2286.4774
B10: 6 | C10: 82.419715 | D10: 44.584871 | E10: 34.867531 | F10: 2453.8918
B11: 7 | C11: 87.80717 | D11: 50.394073 | E11: 38.562684 | F11: 2841.7443
B12: 8 | C12: 89.66157 | D12: 51.38933 | E12: 40.632918 | F12: 2933.5234
B13: 9 | C13: 96.998012 | D13: 54.876198 | E13: 41.977704 | F13: 3103.7515
B14: 10 | C14: 101.44252 | D14: 59.181446 | E14: 40.56407 | F14: 3207.2924
B15: 11 | C15: 98.746496 | D15: 60.171437 | E15: 40.617486 | F15: 3176.1733
B16: 12 | C16: 96.450263 | D16: 56.809343 | E16: 40.659313 | F16: 3005.3482
B17: 13 | C17: 98.995081 | D17: 55.500467 | E17: 40.420524 | F17: 3104.9849
... B52: 48 | C52: 172.46143 | D52: 171.98783 | E52: 100.07056 | F52: 7653.28

Sheet 2i
C2: [1] | D2: [1] | E2: [1] | F2: [1]
B3: Month, j | C3: Company A | D3: Company B | E3: Company C | F3: Whole market
B4: 1 | C4: ='Q2 Data'!C6/'Q2 Data'!C5-1 -> 0.055746241 | D4: ='Q2 Data'!D6/'Q2 Data'!D5-1 -> 0.094436253 | E4: ='Q2 Data'!E6/'Q2 Data'!E5-1 -> -0.0386283 | F4: ='Q2 Data'!F6/'Q2 Data'!F5-1 -> 0.0010949564
B5: 2 | C5: ='Q2 Data'!C7/'Q2 Data'!C6-1 -> 0.020901406 | D5: ='Q2 Data'!D7/'Q2 Data'!D6-1 -> 0.049678984 | E5: ='Q2 Data'!E7/'Q2 Data'!E6-1 -> 0.056740656 | F5: ='Q2 Data'!F7/'Q2 Data'!F6-1 -> 0.049763962
B6: 3 | C6: ='Q2 Data'!C8/'Q2 Data'!C7-1 -> 0.025743079 | D6: ='Q2 Data'!D8/'Q2 Data'!D7-1 -> 0.067633813 | E6: ='Q2 Data'!E8/'Q2 Data'!E7-1 -> 0.026144228 | F6: ='Q2 Data'!F8/'Q2 Data'!F7-1 -> 0.01923128
B7: 4 | C7: ='Q2 Data'!C9/'Q2 Data'!C8-1 -> 0.049594651 | D7: ='Q2 Data'!D9/'Q2 Data'!D8-1 -> 0.0019229244 | E7: ='Q2 Data'!E9/'Q2 Data'!E8-1 -> 0.07540717 | F7: ='Q2 Data'!F9/'Q2 Data'!F8-1 -> 0.047939503
B8: 5 | C8: ='Q2 Data'!C10/'Q2 Data'!C9-1 -> 0.060114454 | D8: ='Q2 Data'!D10/'Q2 Data'!D9-1 -> 0.13379342 | E8: ='Q2 Data'!E10/'Q2 Data'!E9-1 -> 0.036713735 | F8: ='Q2 Data'!F10/'Q2 Data'!F9-1 -> 0.073219367
B9: 6 | C9: ='Q2 Data'!C11/'Q2 Data'!C10-1 -> 0.065366094 | D9: ='Q2 Data'!D11/'Q2 Data'!D10-1 -> 0.13029536 | E9: ='Q2 Data'!E11/'Q2 Data'!E10-1 -> 0.10597691 | F9: ='Q2 Data'!F11/'Q2 Data'!F10-1 -> 0.15805603
B10: 7 | C10: ='Q2 Data'!C12/'Q2 Data'!C11-1 -> 0.021119004 | D10: ='Q2 Data'!D12/'Q2 Data'!D11-1 -> 0.019749493 | E10: ='Q2 Data'!E12/'Q2 Data'!E11-1 -> 0.053684915 | F10: ='Q2 Data'!F12/'Q2 Data'!F11-1 -> 0.032296759
B11: 8 | C11: ='Q2 Data'!C13/'Q2 Data'!C12-1 -> 0.081823713 | D11: ='Q2 Data'!D13/'Q2 Data'!D12-1 -> 0.067851986 | E11: ='Q2 Data'!E13/'Q2 Data'!E12-1 -> 0.033095979 | F11: ='Q2 Data'!F13/'Q2 Data'!F12-1 -> 0.058028556
B12: 9 | C12: ='Q2 Data'!C14/'Q2 Data'!C13-1 -> 0.045820607 | D12: ='Q2 Data'!D14/'Q2 Data'!D13-1 -> 0.078453828 | E12: ='Q2 Data'!E14/'Q2 Data'!E13-1 -> -0.033675829 | F12: ='Q2 Data'!F14/'Q2 Data'!F13-1 -> 0.033359904
B13: 10 | C13: ='Q2 Data'!C15/'Q2 Data'!C14-1 -> -0.026576866 | D13: ='Q2 Data'!D15/'Q2 Data'!D14-1 -> 0.016728063 | E13: ='Q2 Data'!E15/'Q2 Data'!E14-1 -> 0.0013168115 | F13: ='Q2 Data'!F15/'Q2 Data'!F14-1 -> -0.0097025972
B14: 11 | C14: ='Q2 Data'!C16/'Q2 Data'!C15-1 -> -0.023253816 | D14: ='Q2 Data'!D16/'Q2 Data'!D15-1 -> -0.055875256 | E14: ='Q2 Data'!E16/'Q2 Data'!E15-1 -> 0.0010297784 | F14: ='Q2 Data'!F16/'Q2 Data'!F15-1 -> -0.053783318
B15: 12 | C15: ='Q2 Data'!C17/'Q2 Data'!C16-1 -> 0.026384766 | D15: ='Q2 Data'!D17/'Q2 Data'!D16-1 -> -0.023039798 | E15: ='Q2 Data'!E17/'Q2 Data'!E16-1 -> -0.0058729108 | F15: ='Q2 Data'!F17/'Q2 Data'!F16-1 -> 0.033153159
... B50: 47 | C50: ='Q2 Data'!C52/'Q2 Data'!C51-1 -> 0.060553461 | D50: ='Q2 Data'!D52/'Q2 Data'!D51-1 -> 0.022105669 | E50: ='Q2 Data'!E52/'Q2 Data'!E51-1 -> 0.046667516 | F50: ='Q2 Data'!F52/'Q2 Data'!F51-1 -> 0.081093334

Sheet 2ii
B2: (a) | C2: Return on market | D2: =AVERAGE('2i'!F4:F50) -> 0.029536194 | E2: [1]
B4: (b) | C4: Variance of market | D4: =_xlfn.VAR.P('2i'!$F$4:$F$50) -> 0.0019990682 | E4: [1]

Sheet 2iii
B2: (a) | D2: Company A | E2: Company B | F2: Company C
C3: Covariance with market | D3: =_xlfn.COVARIANCE.P('2i'!C4:C50,'2i'!$F$4:$F$50) -> 0.0010432098 | E3: =_xlfn.COVARIANCE.P('2i'!D4:D50,'2i'!$F$4:$F$50) -> 0.0015227396 | F3: =_xlfn.COVARIANCE.P('2i'!E4:E50,'2i'!$F$4:$F$50) -> 0.0010963706 | G3: [2]
C5: Beta | D5: =D3/'2ii'!$D$4 -> 0.52184804 | E5: =E3/'2ii'!$D$4 -> 0.76172468 | F5: =F3/'2ii'!$D$4 -> 0.54844082 | G5: [4]
B7: (b) | D7: Company A | E7: Company B | F7: Company C
C8: Alpha | D8: =AVERAGE(D10:D56) -> 0.0054183946 | E8: =AVERAGE(E10:E56) -> 0.015278566 | F8: =AVERAGE(F10:F56) -> 0.010678449 | G8: [2]
C10: Ri - Beta * Rm | D10: ='2i'!C4-'2i'!$F4*D$5 -> 0.055174841 | E10: ='2i'!D4-'2i'!$F4*E$5 -> 0.093602197 | F10: ='2i'!E4-'2i'!$F4*F$5 -> -0.039228819 | G10: [4]
D11: ='2i'!C5-'2i'!$F5*D$5 -> -0.0050678205 | E11: ='2i'!D5-'2i'!$F5*E$5 -> 0.011772547 | F11: ='2i'!E5-'2i'!$F5*F$5 -> 0.029448068
D12: ='2i'!C6-'2i'!$F6*D$5 -> 0.015707274 | E12: ='2i'!D6-'2i'!$F6*E$5 -> 0.052984872 | F12: ='2i'!E6-'2i'!$F6*F$5 -> 0.015597009
D13: ='2i'!C7-'2i'!$F7*D$5 -> 0.024577516 | E13: ='2i'!D7-'2i'!$F7*E$5 -> -0.034593778 | F13: ='2i'!E7-'2i'!$F7*F$5 -> 0.04911519
D14: ='2i'!C8-'2i'!$F8*D$5 -> 0.021905071 | E14: ='2i'!D8-'2i'!$F8*E$5 -> 0.078020418 | F14: ='2i'!E8-'2i'!$F8*F$5 -> -0.0034427541
D15: ='2i'!C9-'2i'!$F9*D$5 -> -0.017115135 | E15: ='2i'!D9-'2i'!$F9*E$5 -> 0.0099001803 | F15: ='2i'!E9-'2i'!$F9*F$5 -> 0.019292531
D16: ='2i'!C10-'2i'!$F10*D$5 -> 0.0042650034 | E16: ='2i'!D10-'2i'!$F10*E$5 -> -0.0048517456 | F16: ='2i'!E10-'2i'!$F10*F$5 -> 0.035972054
D17: ='2i'!C11-'2i'!$F11*D$5 -> 0.051541625 | E17: ='2i'!D11-'2i'!$F11*E$5 -> 0.023650203 | F17: ='2i'!E11-'2i'!$F11*F$5 -> 0.0012707504
D18: ='2i'!C12-'2i'!$F12*D$5 -> 0.028411806 | E18: ='2i'!D12-'2i'!$F12*E$5 -> 0.053042765 | F18: ='2i'!E12-'2i'!$F12*F$5 -> -0.051971763
D19: ='2i'!C13-'2i'!$F13*D$5 -> -0.021513585 | E19: ='2i'!D13-'2i'!$F13*E$5 -> 0.02411877 | F19: ='2i'!E13-'2i'!$F13*F$5 -> 0.0066381118
D20: ='2i'!C14-'2i'!$F14*D$5 -> 0.0048129026 | E20: ='2i'!D14-'2i'!$F14*E$5 -> -0.014907175 | F20: ='2i'!E14-'2i'!$F14*F$5 -> 0.030526745
D21: ='2i'!C15-'2i'!$F15*D$5 -> 0.0090838546 | E21: ='2i'!D15-'2i'!$F15*E$5 -> -0.048293377 | F21: ='2i'!E15-'2i'!$F15*F$5 -> -0.024055456
D22: ='2i'!C16-'2i'!$F16*D$5 -> -0.014961251 | E22: ='2i'!D16-'2i'!$F16*E$5 -> 0.04401651 | F22: ='2i'!E16-'2i'!$F16*F$5 -> -0.00033572429
... D56: ='2i'!C50-'2i'!$F50*D$5 -> 0.018235064 | E56: ='2i'!D50-'2i'!$F50*E$5 -> -0.039665124 | F56: ='2i'!E50-'2i'!$F50*F$5 -> 0.0021926212

Sheet 2iv
B2: (a) | D2: Company A | E2: Company B | F2: Company C
C3: Beta | D3: ='2iii'!D5 -> 0.52184804 | E3: ='2iii'!E5 -> 0.76172468 | F3: ='2iii'!F5 -> 0.54844082
C4: Systematic risk | D4: =D3^2*'2ii'!$D$4 -> 0.000544397 | E4: =E3^2*'2ii'!$D$4 -> 0.0011599083 | F4: =F3^2*'2ii'!$D$4 -> 0.00060129439 | G4: [3]
B7: (b) | D7: Company A | E7: Company B | F7: Company C
C8: Specific risk | D8: ='Q2 Data'!H5^2 -> 0.006561 | E8: ='Q2 Data'!I5^2 -> 0.047524 | F8: ='Q2 Data'!J5^2 -> 0.014884 | G8: [3]
B11: (c) | D11: Company A | E11: Company B | F11: Company C
C12: Total risk | D12: =D4+D8 -> 0.007105397 | E12: =E4+E8 -> 0.048683908 | F12: =F4+F8 -> 0.015485294 | G12: [1]
B14: (d) | D14: Company A | E14: Company B | F14: Company C
C15: Expected return | D15: ='2iii'!D8+'2iii'!D5*'2ii'!$D$2 -> 0.020831799 | E15: ='2iii'!E8+'2iii'!E5*'2ii'!$D$2 -> 0.037777013 | F15: ='2iii'!F8+'2iii'!F5*'2ii'!$D$2 -> 0.026877303 | G15: [3]

Sheet 2v
B2: Comments:
B3: Company A has the lowest risk using any of the three measures | M3: [1]
B4: But it also has the lowest expected return | M4: [1]
B5: Company B would give a much higher expected return but with more risk | M5: [1]
B6: Company C would give a higher expected return with only slightly more market correlation | M6: [1]
B7: A portfolio of more than one company's shares might give a higher expected return and lower risk… | M7: [1]
B8: …due to the benefits of diversification | M8: [1]
B9: The CEO might also want to consider any specific risk measures relating to their own situation | M9: [1]
M12: [Max 6]

Sheet 2vi
C2: EM | D2: ='2ii'!D2 -> 0.029536194
C3: VM | D3: ='2ii'!D4 -> 0.0019990682
C4: Target return | D4: 0.025
D6: Company A | E6: Company B | F6: Company C
C7: Alpha | D7: ='2iii'!D8 -> 0.0054183946 | E7: ='2iii'!E8 -> 0.015278566 | F7: ='2iii'!F8 -> 0.010678449
C8: Beta | D8: ='2iii'!D5 -> 0.52184804 | E8: ='2iii'!E5 -> 0.76172468 | F8: ='2iii'!F5 -> 0.54844082
C9: Vεi | D9: ='Q2 Data'!H5^2 -> 0.006561 | E9: ='Q2 Data'!I5^2 -> 0.047524 | F9: ='Q2 Data'!J5^2 -> 0.014884
C10: Expected return | D10: ='2iv'!D15 -> 0.020831799 | E10: ='2iv'!E15 -> 0.037777013 | F10: ='2iv'!F15 -> 0.026877303
C11: Variance | D11: =D8^2*$D$3+D9 -> 0.007105397 | E11: =E8^2*$D$3+E9 -> 0.048683908 | F11: =F8^2*$D$3+F9 -> 0.015485294 | G11: [2] | H11: [1] each for A and C
C12: Weight | D12: =(F10-D4)/(F10-D10) -> 0.31052882 | E12: 0 | F12: =100%-D12 -> 0.68947118
C14: CA,C | D14: =D8*F8*D3 -> 0.00057213885 | E14: [1]
C15: EP | D15: =SUMPRODUCT(D10:F10,D12:F12) -> 0.025
C16: VP | D16: =D12^2*D11+F12^2*F11+2*D12*F12*D14 -> 0.0082914032
B18: (a) | C18: Amounts to invest:
D19: $m
C20: Company A | D20: =D22*D12 -> 31.052882 | E20: [1]
C21: Company C | D21: =D22*F12 -> 68.947118 | E21: [1]
D22: 100
B24: (b) | C24: VP | D24: =D16 -> 0.0082914032 | E24: [3]

Sheet 2vii
B2: Comments:
B3: The portfolio has a lower expected return than the market portfolio… | M3: [1]
B4: …and a higher variance | M4: [1]
B5: This is because the CEO prevented us from holding any of Asset B | M5: [1]
B6: Asset B has less than 100% correlation with the market and with the other the assets | M6: [1]
B7: So holding some of Asset B would give a diversification benefit | M7: [1]
M9: [Max 4]

Sheet Q3 Data
B2: Parameters
B4: λ | C4: 1.145
B5: Claim per visit | C5: 50
B7: Poisson distribution
B9: Number of visits | C9: Probability
B10: 0 | C10: =_xlfn.POISSON.DIST(B10,$C$4,FALSE) -> 0.31822392
B11: =B10+1 -> 1 | C11: =_xlfn.POISSON.DIST(B11,$C$4,FALSE) -> 0.36436639
B12: =B11+1 -> 2 | C12: =_xlfn.POISSON.DIST(B12,$C$4,FALSE) -> 0.20859976
B13: =B12+1 -> 3 | C13: =_xlfn.POISSON.DIST(B13,$C$4,FALSE) -> 0.079615574
B14: =B13+1 -> 4 | C14: =_xlfn.POISSON.DIST(B14,$C$4,FALSE) -> 0.022789958
B15: =B14+1 -> 5 | C15: =_xlfn.POISSON.DIST(B15,$C$4,FALSE) -> 0.0052189004
B16: =B15+1 -> 6 | C16: =_xlfn.POISSON.DIST(B16,$C$4,FALSE) -> 0.00099594015
B17: =B16+1 -> 7 | C17: =_xlfn.POISSON.DIST(B17,$C$4,FALSE) -> 0.00016290735
B18: =B17+1 -> 8 | C18: =_xlfn.POISSON.DIST(B18,$C$4,FALSE) -> 2.3316115e-05
B19: =B18+1 -> 9 | C19: =_xlfn.POISSON.DIST(B19,$C$4,FALSE) -> 2.966328e-06
B20: =B19+1 -> 10 | C20: =_xlfn.POISSON.DIST(B20,$C$4,FALSE) -> 3.3964455e-07

Sheet 3i
B2: Initial wealth
B3: Insurer | C3: 16000
B4: Policy holder | C4: 1000
B6: Parameters
B7: λ | C7: 1.145
B8: Claim per visit | C8: 50
D10: [1] | E10: [1]
B11: Number of visits | C11: Probability | D11: Claims | E11: Expected claims cost
B12: ='Q3 Data'!B10 -> 0 | C12: ='Q3 Data'!C10 -> 0.31822392 | D12: =$C$8*B12 -> 0 | E12: =D12*C12 -> 0
B13: ='Q3 Data'!B11 -> 1 | C13: ='Q3 Data'!C11 -> 0.36436639 | D13: =$C$8*B13 -> 50 | E13: =D13*C13 -> 18.218319
B14: ='Q3 Data'!B12 -> 2 | C14: ='Q3 Data'!C12 -> 0.20859976 | D14: =$C$8*B14 -> 100 | E14: =D14*C14 -> 20.859976
B15: ='Q3 Data'!B13 -> 3 | C15: ='Q3 Data'!C13 -> 0.079615574 | D15: =$C$8*B15 -> 150 | E15: =D15*C15 -> 11.942336
B16: ='Q3 Data'!B14 -> 4 | C16: ='Q3 Data'!C14 -> 0.022789958 | D16: =$C$8*B16 -> 200 | E16: =D16*C16 -> 4.5579916
B17: ='Q3 Data'!B15 -> 5 | C17: ='Q3 Data'!C15 -> 0.0052189004 | D17: =$C$8*B17 -> 250 | E17: =D17*C17 -> 1.3047251
B18: ='Q3 Data'!B16 -> 6 | C18: ='Q3 Data'!C16 -> 0.00099594015 | D18: =$C$8*B18 -> 300 | E18: =D18*C18 -> 0.29878205
B19: ='Q3 Data'!B17 -> 7 | C19: ='Q3 Data'!C17 -> 0.00016290735 | D19: =$C$8*B19 -> 350 | E19: =D19*C19 -> 0.057017574
B20: ='Q3 Data'!B18 -> 8 | C20: ='Q3 Data'!C18 -> 2.3316115e-05 | D20: =$C$8*B20 -> 400 | E20: =D20*C20 -> 0.009326446
B21: ='Q3 Data'!B19 -> 9 | C21: ='Q3 Data'!C19 -> 2.966328e-06 | D21: =$C$8*B21 -> 450 | E21: =D21*C21 -> 0.0013348476
B22: ='Q3 Data'!B20 -> 10 | C22: ='Q3 Data'!C20 -> 3.3964455e-07 | D22: =$C$8*B22 -> 500 | E22: =D22*C22 -> 0.00016982228
A24: a) | B24: Expected claims cost | C24: =SUM(E12:E22) -> 57.249978 | D24: [1]
A26: b) | B26: Comments:
B27: Insurer will always aim to charge premium that is higher than expected claim cost. | H27: [1]
B28: Hence, the minimum premium should be above $57.25 | H28: [1]
B29: And will need to be higher to allow for expenses and profit | H29: [1]
H31: [Max 2]

Sheet 3ii
B2: Initial wealth
B3: Insurer | C3: 16000
B4: Policy holder | C4: 1000
B6: Parameters
B7: λ | C7: 1.145
B8: Claim per visit | C8: 50 | G8: [1] | H8: [1] | I8: [1]
A9: a) | F9: Without insurance
F10: Wealth | H10: Utility
B11: Number of visits | C11: Probability | D11: claims | E11: Expected claims cost | F11: Insurer | G11: Policy holder | H11: Insurer | I11: Policy holder
B12: ='3i'!B12 -> 0 | C12: ='3i'!C12 -> 0.31822392 | D12: ='3i'!D12 -> 0 | E12: ='3i'!E12 -> 0 | F12: =$C$3 -> 16000 | G12: =$C$4-D12 -> 1000 | H12: =SQRT(F12) -> 126.49111 | I12: =G12-0.0001*(G12)^2 -> 900
B13: ='3i'!B13 -> 1 | C13: ='3i'!C13 -> 0.36436639 | D13: ='3i'!D13 -> 50 | E13: ='3i'!E13 -> 18.218319 | F13: =$C$3 -> 16000 | G13: =$C$4-D13 -> 950 | H13: =SQRT(F13) -> 126.49111 | I13: =G13-0.0001*(G13)^2 -> 859.75
B14: ='3i'!B14 -> 2 | C14: ='3i'!C14 -> 0.20859976 | D14: ='3i'!D14 -> 100 | E14: ='3i'!E14 -> 20.859976 | F14: =$C$3 -> 16000 | G14: =$C$4-D14 -> 900 | H14: =SQRT(F14) -> 126.49111 | I14: =G14-0.0001*(G14)^2 -> 819
B15: ='3i'!B15 -> 3 | C15: ='3i'!C15 -> 0.079615574 | D15: ='3i'!D15 -> 150 | E15: ='3i'!E15 -> 11.942336 | F15: =$C$3 -> 16000 | G15: =$C$4-D15 -> 850 | H15: =SQRT(F15) -> 126.49111 | I15: =G15-0.0001*(G15)^2 -> 777.75
B16: ='3i'!B16 -> 4 | C16: ='3i'!C16 -> 0.022789958 | D16: ='3i'!D16 -> 200 | E16: ='3i'!E16 -> 4.5579916 | F16: =$C$3 -> 16000 | G16: =$C$4-D16 -> 800 | H16: =SQRT(F16) -> 126.49111 | I16: =G16-0.0001*(G16)^2 -> 736
B17: ='3i'!B17 -> 5 | C17: ='3i'!C17 -> 0.0052189004 | D17: ='3i'!D17 -> 250 | E17: ='3i'!E17 -> 1.3047251 | F17: =$C$3 -> 16000 | G17: =$C$4-D17 -> 750 | H17: =SQRT(F17) -> 126.49111 | I17: =G17-0.0001*(G17)^2 -> 693.75
B18: ='3i'!B18 -> 6 | C18: ='3i'!C18 -> 0.00099594015 | D18: ='3i'!D18 -> 300 | E18: ='3i'!E18 -> 0.29878205 | F18: =$C$3 -> 16000 | G18: =$C$4-D18 -> 700 | H18: =SQRT(F18) -> 126.49111 | I18: =G18-0.0001*(G18)^2 -> 651
B19: ='3i'!B19 -> 7 | C19: ='3i'!C19 -> 0.00016290735 | D19: ='3i'!D19 -> 350 | E19: ='3i'!E19 -> 0.057017574 | F19: =$C$3 -> 16000 | G19: =$C$4-D19 -> 650 | H19: =SQRT(F19) -> 126.49111 | I19: =G19-0.0001*(G19)^2 -> 607.75
B20: ='3i'!B20 -> 8 | C20: ='3i'!C20 -> 2.3316115e-05 | D20: ='3i'!D20 -> 400 | E20: ='3i'!E20 -> 0.009326446 | F20: =$C$3 -> 16000 | G20: =$C$4-D20 -> 600 | H20: =SQRT(F20) -> 126.49111 | I20: =G20-0.0001*(G20)^2 -> 564
B21: ='3i'!B21 -> 9 | C21: ='3i'!C21 -> 2.966328e-06 | D21: ='3i'!D21 -> 450 | E21: ='3i'!E21 -> 0.0013348476 | F21: =$C$3 -> 16000 | G21: =$C$4-D21 -> 550 | H21: =SQRT(F21) -> 126.49111 | I21: =G21-0.0001*(G21)^2 -> 519.75
B22: ='3i'!B22 -> 10 | C22: ='3i'!C22 -> 3.3964455e-07 | D22: ='3i'!D22 -> 500 | E22: ='3i'!E22 -> 0.00016982228 | F22: =$C$3 -> 16000 | G22: =$C$4-D22 -> 500 | H22: =SQRT(F22) -> 126.49111 | I22: =G22-0.0001*(G22)^2 -> 475
E23: =SUM(E12:E22) -> 57.249978
C25: Insurer | D25: Policy holder
A26: b) | B26: Expected utility without insurance | C26: =SUMPRODUCT($C$12:$C$22,H12:H22) -> 126.4911 | D26: =SUMPRODUCT($C$12:$C$22,I12:I22) -> 853.58598
C27: [1] | D27: [1]

Sheet 3iii
B2: Initial wealth
B3: Insurer | C3: 16000
B4: Policy holder | C4: 1000
B6: Parameters
B7: λ | C7: 1.145
B8: Claim per visit | C8: 50
F9: [1] | G9: [1] | H9: [1] | I9: [1]
F10: Wealth | H10: Utility
B11: Number of visits | C11: Probability | D11: claims | E11: Expected claims cost | F11: Insurer | G11: Policy holder | H11: Insurer | I11: Policy holder
B12: ='3i'!B12 -> 0 | C12: ='3i'!C12 -> 0.31822392 | D12: ='3i'!D12 -> 0 | E12: ='3i'!E12 -> 0 | F12: =$C$3-D12+$C$30 -> 16057.25 | G12: =$C$4-$C$33 -> 942.397 | H12: =SQRT(F12) -> 126.7172 | I12: =G12-0.0001*(G12)^2 -> 853.58579
B13: ='3i'!B13 -> 1 | C13: ='3i'!C13 -> 0.36436639 | D13: ='3i'!D13 -> 50 | E13: ='3i'!E13 -> 18.218319 | F13: =$C$3-D13+$C$30 -> 16007.25 | G13: =$C$4-$C$33 -> 942.397 | H13: =SQRT($C$3-D13+$C$30) -> 126.51976 | I13: =G13-0.0001*(G13)^2 -> 853.58579
B14: ='3i'!B14 -> 2 | C14: ='3i'!C14 -> 0.20859976 | D14: ='3i'!D14 -> 100 | E14: ='3i'!E14 -> 20.859976 | F14: =$C$3-D14+$C$30 -> 15957.25 | G14: =$C$4-$C$33 -> 942.397 | H14: =SQRT($C$3-D14+$C$30) -> 126.32201 | I14: =G14-0.0001*(G14)^2 -> 853.58579
B15: ='3i'!B15 -> 3 | C15: ='3i'!C15 -> 0.079615574 | D15: ='3i'!D15 -> 150 | E15: ='3i'!E15 -> 11.942336 | F15: =$C$3-D15+$C$30 -> 15907.25 | G15: =$C$4-$C$33 -> 942.397 | H15: =SQRT($C$3-D15+$C$30) -> 126.12395 | I15: =G15-0.0001*(G15)^2 -> 853.58579
B16: ='3i'!B16 -> 4 | C16: ='3i'!C16 -> 0.022789958 | D16: ='3i'!D16 -> 200 | E16: ='3i'!E16 -> 4.5579916 | F16: =$C$3-D16+$C$30 -> 15857.25 | G16: =$C$4-$C$33 -> 942.397 | H16: =SQRT($C$3-D16+$C$30) -> 125.92557 | I16: =G16-0.0001*(G16)^2 -> 853.58579
B17: ='3i'!B17 -> 5 | C17: ='3i'!C17 -> 0.0052189004 | D17: ='3i'!D17 -> 250 | E17: ='3i'!E17 -> 1.3047251 | F17: =$C$3-D17+$C$30 -> 15807.25 | G17: =$C$4-$C$33 -> 942.397 | H17: =SQRT($C$3-D17+$C$30) -> 125.72689 | I17: =G17-0.0001*(G17)^2 -> 853.58579
B18: ='3i'!B18 -> 6 | C18: ='3i'!C18 -> 0.00099594015 | D18: ='3i'!D18 -> 300 | E18: ='3i'!E18 -> 0.29878205 | F18: =$C$3-D18+$C$30 -> 15757.25 | G18: =$C$4-$C$33 -> 942.397 | H18: =SQRT($C$3-D18+$C$30) -> 125.52789 | I18: =G18-0.0001*(G18)^2 -> 853.58579
B19: ='3i'!B19 -> 7 | C19: ='3i'!C19 -> 0.00016290735 | D19: ='3i'!D19 -> 350 | E19: ='3i'!E19 -> 0.057017574 | F19: =$C$3-D19+$C$30 -> 15707.25 | G19: =$C$4-$C$33 -> 942.397 | H19: =SQRT($C$3-D19+$C$30) -> 125.32857 | I19: =G19-0.0001*(G19)^2 -> 853.58579
B20: ='3i'!B20 -> 8 | C20: ='3i'!C20 -> 2.3316115e-05 | D20: ='3i'!D20 -> 400 | E20: ='3i'!E20 -> 0.009326446 | F20: =$C$3-D20+$C$30 -> 15657.25 | G20: =$C$4-$C$33 -> 942.397 | H20: =SQRT($C$3-D20+$C$30) -> 125.12893 | I20: =G20-0.0001*(G20)^2 -> 853.58579
B21: ='3i'!B21 -> 9 | C21: ='3i'!C21 -> 2.966328e-06 | D21: ='3i'!D21 -> 450 | E21: ='3i'!E21 -> 0.0013348476 | F21: =$C$3-D21+$C$30 -> 15607.25 | G21: =$C$4-$C$33 -> 942.397 | H21: =SQRT($C$3-D21+$C$30) -> 124.92898 | I21: =G21-0.0001*(G21)^2 -> 853.58579
B22: ='3i'!B22 -> 10 | C22: ='3i'!C22 -> 3.3964455e-07 | D22: ='3i'!D22 -> 500 | E22: ='3i'!E22 -> 0.00016982228 | F22: =$C$3-D22+$C$30 -> 15557.25 | G22: =$C$4-$C$33 -> 942.397 | H22: =SQRT($C$3-D22+$C$30) -> 124.72871 | I22: =G22-0.0001*(G22)^2 -> 853.58579
E23: =SUM(E13:E22) -> 57.249978
C25: Insurer | D25: Policy holder
B26: Expected utility without insurance | C26: ='3ii'!C26 -> 126.4911 | D26: ='3ii'!D26 -> 853.58598
B27: Expected utility with insurance | C27: =SUMPRODUCT($C$12:$C$22,H12:H22) -> 126.49092 | D27: =SUMPRODUCT($C$12:$C$22,I12:I22) -> 853.58576 | E27: [2]
B28: Difference | C28: =C26-C27 -> 0.00017699845 | D28: =D26-D27 -> 0.00022104739
B30: Minimum premium insurer will accept | C30: 57.25 | D30: [2] | E30: (by goal seek)
B33: Maximum premium policyholder will pay | C33: 57.603 | D33: [2] | E33: (by goal seek)

Sheet 3iv
B2: Min premium insurer will accept
B3: ='3iii'!C30 -> 57.25
B5: Max premium policyholder will pay
B6: ='3iii'!C33 -> 57.603
B8: Comments:
B9: The policyholder is willing to pay a higher premium than required by the insurer. | O9: [1]
B10: The premium should be between $57.25 and $57.60 | O10: [1]
B11: e.g. a premium of $57.50 would be acceptable for both insurer and policyholder | O11: [1]
O13: [Max 2]
