Workbook

Sheet Raw data (base scenario)
A1: Raw Data
B5: Status | C5: Status
A6: Lives | B6: Start of Year | C6: End of Year
A7: 1 | B7: I | C7: S
A8: 2 | B8: S | C8: H
A9: 3 | B9: D | C9: D
A10: 4 | B10: H | C10: H
A11: 5 | B11: I | C11: I
A12: 6 | B12: I | C12: D
A13: 7 | B13: H | C13: H
A14: 8 | B14: D | C14: D
A15: 9 | B15: H | C15: H
A16: 10 | B16: S | C16: H
A17: 11 | B17: I | C17: I
A18: 12 | B18: H | C18: H
... A12009: 12003 | B12009: D | C12009: D

Sheet Raw data (alternative scenario)
A1: Raw Data
B3: Transition probabilities in the alternative scenario is:
C4: original transition probabilities + (t - 1) * transition improvements
B5: where t = 1 to 30
B7: Transition improvements
D8: End of year
D9: H | E9: S | F9: I | G9: D
B10: Start of year | C10: H | D10: 0.0018 | E10: -0.0012 | F10: -0.00055 | G10: -5e-05
C11: S | D11: 0.00065 | E11: 0.0005 | F11: -0.00083 | G11: -0.00032
C12: I | D12: 0.0005 | E12: 0.001 | F12: 0.0005 | G12: -0.002
C13: D | D13: 0 | E13: 0 | F13: 0 | G13: 0

Sheet Data_checks
A1: Data checking
A3: Permissible statuses
A4: H | B4: Healthy
A5: S | B5: Sick
A6: I | B6: Very sick
A7: D | B7: Dead
K9: WARNING: This data is hardcoded
K11: Same data but with corrupted data removed
A12: Checks | B12: Check no missing lives | C12: Check no missing status | D12: Check no missing status | E12: Number of errors | F12: Number of errors | G12: Number of errors | J12: Checks | K12: Check no missing lives | L12: Check no missing status | M12: Check no missing status | N12: Number of errors | O12: Number of errors | P12: Number of errors
A13: Count: | B13: =COUNT(B15:B12017) -> 12003 | C13: =IF(COUNT(C15:C12017)=0,"No missing statuses","check") -> No missing statuses | D13: =IF(COUNT(D15:D12017)=0,"No missing statuses","check") -> No missing statuses | E13: =COUNTIF(E15:E12017,FALSE) -> 2 | F13: =COUNTIF(F15:F12017,FALSE) -> 1 | G13: =COUNTIF(G15:G12017,FALSE) -> 1 | J13: Count: | K13: =COUNT(K15:K12014) -> 12000 | L13: =IF(COUNT(L15:L12017)=0,"No missing statuses","check") -> No missing statuses | M13: =IF(COUNT(M15:M12017)=0,"No missing statuses","check") -> No missing statuses | N13: =COUNTIF(N15:N12014,FALSE) -> 0 | O13: =COUNTIF(O15:O12014,FALSE) -> 0 | P13: =COUNTIF(P15:P12014,FALSE) -> 0
B14: Lives | C14: Start of Year | D14: End of Year | E14: Check status only contains H, S, I, D | F14: Check status only contains H, S, I, D | G14: Check no resurrection | H14: Note | K14: Lives | L14: Start of Year | M14: End of Year | N14: Check status only contains H, S, I, D | O14: Check status only contains H, S, I, D | P14: Check no resurrection
B15: ='Raw data (base scenario)'!A7 -> 1 | C15: ='Raw data (base scenario)'!B7 -> I | D15: ='Raw data (base scenario)'!C7 -> S | E15: =OR(C15=$A$4,C15=$A$5,C15=$A$6,C15=$A$7) -> TRUE | F15: =OR(D15=$A$4,D15=$A$5,D15=$A$6,D15=$A$7) -> TRUE | G15: =IF(C15="D",D15="D","N/A") -> N/A | K15: 1 | L15: I | M15: S | N15: =OR(L15=$A$4,L15=$A$5,L15=$A$6,L15=$A$7) -> TRUE | O15: =OR(M15=$A$4,M15=$A$5,M15=$A$6,M15=$A$7) -> TRUE | P15: =IF(L15="D",M15="D","N/A") -> N/A
B16: ='Raw data (base scenario)'!A8 -> 2 | C16: ='Raw data (base scenario)'!B8 -> S | D16: ='Raw data (base scenario)'!C8 -> H | E16: =OR(C16=$A$4,C16=$A$5,C16=$A$6,C16=$A$7) -> TRUE | F16: =OR(D16=$A$4,D16=$A$5,D16=$A$6,D16=$A$7) -> TRUE | G16: =IF(C16="D",D16="D","N/A") -> N/A | K16: 2 | L16: S | M16: H | N16: =OR(L16=$A$4,L16=$A$5,L16=$A$6,L16=$A$7) -> TRUE | O16: =OR(M16=$A$4,M16=$A$5,M16=$A$6,M16=$A$7) -> TRUE | P16: =IF(L16="D",M16="D","N/A") -> N/A
B17: ='Raw data (base scenario)'!A9 -> 3 | C17: ='Raw data (base scenario)'!B9 -> D | D17: ='Raw data (base scenario)'!C9 -> D | E17: =OR(C17=$A$4,C17=$A$5,C17=$A$6,C17=$A$7) -> TRUE | F17: =OR(D17=$A$4,D17=$A$5,D17=$A$6,D17=$A$7) -> TRUE | G17: =IF(C17="D",D17="D","N/A") -> TRUE | K17: 3 | L17: D | M17: D | N17: =OR(L17=$A$4,L17=$A$5,L17=$A$6,L17=$A$7) -> TRUE | O17: =OR(M17=$A$4,M17=$A$5,M17=$A$6,M17=$A$7) -> TRUE | P17: =IF(L17="D",M17="D","N/A") -> TRUE
B18: ='Raw data (base scenario)'!A10 -> 4 | C18: ='Raw data (base scenario)'!B10 -> H | D18: ='Raw data (base scenario)'!C10 -> H | E18: =OR(C18=$A$4,C18=$A$5,C18=$A$6,C18=$A$7) -> TRUE | F18: =OR(D18=$A$4,D18=$A$5,D18=$A$6,D18=$A$7) -> TRUE | G18: =IF(C18="D",D18="D","N/A") -> N/A | K18: 4 | L18: H | M18: H | N18: =OR(L18=$A$4,L18=$A$5,L18=$A$6,L18=$A$7) -> TRUE | O18: =OR(M18=$A$4,M18=$A$5,M18=$A$6,M18=$A$7) -> TRUE | P18: =IF(L18="D",M18="D","N/A") -> N/A
B19: ='Raw data (base scenario)'!A11 -> 5 | C19: ='Raw data (base scenario)'!B11 -> I | D19: ='Raw data (base scenario)'!C11 -> I | E19: =OR(C19=$A$4,C19=$A$5,C19=$A$6,C19=$A$7) -> TRUE | F19: =OR(D19=$A$4,D19=$A$5,D19=$A$6,D19=$A$7) -> TRUE | G19: =IF(C19="D",D19="D","N/A") -> N/A | K19: 5 | L19: I | M19: I | N19: =OR(L19=$A$4,L19=$A$5,L19=$A$6,L19=$A$7) -> TRUE | O19: =OR(M19=$A$4,M19=$A$5,M19=$A$6,M19=$A$7) -> TRUE | P19: =IF(L19="D",M19="D","N/A") -> N/A
B20: ='Raw data (base scenario)'!A12 -> 6 | C20: ='Raw data (base scenario)'!B12 -> I | D20: ='Raw data (base scenario)'!C12 -> D | E20: =OR(C20=$A$4,C20=$A$5,C20=$A$6,C20=$A$7) -> TRUE | F20: =OR(D20=$A$4,D20=$A$5,D20=$A$6,D20=$A$7) -> TRUE | G20: =IF(C20="D",D20="D","N/A") -> N/A | K20: 6 | L20: I | M20: D | N20: =OR(L20=$A$4,L20=$A$5,L20=$A$6,L20=$A$7) -> TRUE | O20: =OR(M20=$A$4,M20=$A$5,M20=$A$6,M20=$A$7) -> TRUE | P20: =IF(L20="D",M20="D","N/A") -> N/A
B21: ='Raw data (base scenario)'!A13 -> 7 | C21: ='Raw data (base scenario)'!B13 -> H | D21: ='Raw data (base scenario)'!C13 -> H | E21: =OR(C21=$A$4,C21=$A$5,C21=$A$6,C21=$A$7) -> TRUE | F21: =OR(D21=$A$4,D21=$A$5,D21=$A$6,D21=$A$7) -> TRUE | G21: =IF(C21="D",D21="D","N/A") -> N/A | K21: 7 | L21: H | M21: H | N21: =OR(L21=$A$4,L21=$A$5,L21=$A$6,L21=$A$7) -> TRUE | O21: =OR(M21=$A$4,M21=$A$5,M21=$A$6,M21=$A$7) -> TRUE | P21: =IF(L21="D",M21="D","N/A") -> N/A
B22: ='Raw data (base scenario)'!A14 -> 8 | C22: ='Raw data (base scenario)'!B14 -> D | D22: ='Raw data (base scenario)'!C14 -> D | E22: =OR(C22=$A$4,C22=$A$5,C22=$A$6,C22=$A$7) -> TRUE | F22: =OR(D22=$A$4,D22=$A$5,D22=$A$6,D22=$A$7) -> TRUE | G22: =IF(C22="D",D22="D","N/A") -> TRUE | K22: 8 | L22: D | M22: D | N22: =OR(L22=$A$4,L22=$A$5,L22=$A$6,L22=$A$7) -> TRUE | O22: =OR(M22=$A$4,M22=$A$5,M22=$A$6,M22=$A$7) -> TRUE | P22: =IF(L22="D",M22="D","N/A") -> TRUE
B23: ='Raw data (base scenario)'!A15 -> 9 | C23: ='Raw data (base scenario)'!B15 -> H | D23: ='Raw data (base scenario)'!C15 -> H | E23: =OR(C23=$A$4,C23=$A$5,C23=$A$6,C23=$A$7) -> TRUE | F23: =OR(D23=$A$4,D23=$A$5,D23=$A$6,D23=$A$7) -> TRUE | G23: =IF(C23="D",D23="D","N/A") -> N/A | K23: 9 | L23: H | M23: H | N23: =OR(L23=$A$4,L23=$A$5,L23=$A$6,L23=$A$7) -> TRUE | O23: =OR(M23=$A$4,M23=$A$5,M23=$A$6,M23=$A$7) -> TRUE | P23: =IF(L23="D",M23="D","N/A") -> N/A
B24: ='Raw data (base scenario)'!A16 -> 10 | C24: ='Raw data (base scenario)'!B16 -> S | D24: ='Raw data (base scenario)'!C16 -> H | E24: =OR(C24=$A$4,C24=$A$5,C24=$A$6,C24=$A$7) -> TRUE | F24: =OR(D24=$A$4,D24=$A$5,D24=$A$6,D24=$A$7) -> TRUE | G24: =IF(C24="D",D24="D","N/A") -> N/A | K24: 10 | L24: S | M24: H | N24: =OR(L24=$A$4,L24=$A$5,L24=$A$6,L24=$A$7) -> TRUE | O24: =OR(M24=$A$4,M24=$A$5,M24=$A$6,M24=$A$7) -> TRUE | P24: =IF(L24="D",M24="D","N/A") -> N/A
B25: ='Raw data (base scenario)'!A17 -> 11 | C25: ='Raw data (base scenario)'!B17 -> I | D25: ='Raw data (base scenario)'!C17 -> I | E25: =OR(C25=$A$4,C25=$A$5,C25=$A$6,C25=$A$7) -> TRUE | F25: =OR(D25=$A$4,D25=$A$5,D25=$A$6,D25=$A$7) -> TRUE | G25: =IF(C25="D",D25="D","N/A") -> N/A | K25: 11 | L25: I | M25: I | N25: =OR(L25=$A$4,L25=$A$5,L25=$A$6,L25=$A$7) -> TRUE | O25: =OR(M25=$A$4,M25=$A$5,M25=$A$6,M25=$A$7) -> TRUE | P25: =IF(L25="D",M25="D","N/A") -> N/A
B26: ='Raw data (base scenario)'!A18 -> 12 | C26: ='Raw data (base scenario)'!B18 -> H | D26: ='Raw data (base scenario)'!C18 -> H | E26: =OR(C26=$A$4,C26=$A$5,C26=$A$6,C26=$A$7) -> TRUE | F26: =OR(D26=$A$4,D26=$A$5,D26=$A$6,D26=$A$7) -> TRUE | G26: =IF(C26="D",D26="D","N/A") -> N/A | K26: 12 | L26: H | M26: H | N26: =OR(L26=$A$4,L26=$A$5,L26=$A$6,L26=$A$7) -> TRUE | O26: =OR(M26=$A$4,M26=$A$5,M26=$A$6,M26=$A$7) -> TRUE | P26: =IF(L26="D",M26="D","N/A") -> N/A
... B4466: ='Raw data (base scenario)'!A4458 -> 4452 | C4466: ='Raw data (base scenario)'!B4458 -> D | D4466: ='Raw data (base scenario)'!C4458 -> D | E4466: =OR(C4466=$A$4,C4466=$A$5,C4466=$A$6,C4466=$A$7) -> TRUE | F4466: =OR(D4466=$A$4,D4466=$A$5,D4466=$A$6,D4466=$A$7) -> TRUE | G4466: =IF(C4466="D",D4466="D","N/A") -> TRUE | K4466: 4452 | L4466: D | M4466: D | N4466: =OR(L4466=$A$4,L4466=$A$5,L4466=$A$6,L4466=$A$7) -> TRUE | O4466: =OR(M4466=$A$4,M4466=$A$5,M4466=$A$6,M4466=$A$7) -> TRUE | P4466: =IF(L4466="D",M4466="D","N/A") -> TRUE
B4467: ='Raw data (base scenario)'!A4459 -> 4453 | C4467: ='Raw data (base scenario)'!B4459 -> D | D4467: ='Raw data (base scenario)'!C4459 -> H | E4467: =OR(C4467=$A$4,C4467=$A$5,C4467=$A$6,C4467=$A$7) -> TRUE | F4467: =OR(D4467=$A$4,D4467=$A$5,D4467=$A$6,D4467=$A$7) -> TRUE | G4467: =IF(C4467="D",D4467="D","N/A") -> FALSE | H4467: Corrupted data - remove | K4467: 4453 | L4467: D | M4467: D | N4467: =OR(L4467=$A$4,L4467=$A$5,L4467=$A$6,L4467=$A$7) -> TRUE | O4467: =OR(M4467=$A$4,M4467=$A$5,M4467=$A$6,M4467=$A$7) -> TRUE | P4467: =IF(L4467="D",M4467="D","N/A") -> TRUE
B4468: ='Raw data (base scenario)'!A4460 -> 4454 | C4468: ='Raw data (base scenario)'!B4460 -> D | D4468: ='Raw data (base scenario)'!C4460 -> D | E4468: =OR(C4468=$A$4,C4468=$A$5,C4468=$A$6,C4468=$A$7) -> TRUE | F4468: =OR(D4468=$A$4,D4468=$A$5,D4468=$A$6,D4468=$A$7) -> TRUE | G4468: =IF(C4468="D",D4468="D","N/A") -> TRUE | K4468: 4454 | L4468: H | M4468: H | N4468: =OR(L4468=$A$4,L4468=$A$5,L4468=$A$6,L4468=$A$7) -> TRUE | O4468: =OR(M4468=$A$4,M4468=$A$5,M4468=$A$6,M4468=$A$7) -> TRUE | P4468: =IF(L4468="D",M4468="D","N/A") -> N/A
B4469: ='Raw data (base scenario)'!A4461 -> 4455 | C4469: ='Raw data (base scenario)'!B4461 -> H | D4469: ='Raw data (base scenario)'!C4461 -> H | E4469: =OR(C4469=$A$4,C4469=$A$5,C4469=$A$6,C4469=$A$7) -> TRUE | F4469: =OR(D4469=$A$4,D4469=$A$5,D4469=$A$6,D4469=$A$7) -> TRUE | G4469: =IF(C4469="D",D4469="D","N/A") -> N/A | K4469: 4455 | L4469: H | M4469: H | N4469: =OR(L4469=$A$4,L4469=$A$5,L4469=$A$6,L4469=$A$7) -> TRUE | O4469: =OR(M4469=$A$4,M4469=$A$5,M4469=$A$6,M4469=$A$7) -> TRUE | P4469: =IF(L4469="D",M4469="D","N/A") -> N/A
B4470: ='Raw data (base scenario)'!A4462 -> 4456 | C4470: ='Raw data (base scenario)'!B4462 -> H | D4470: ='Raw data (base scenario)'!C4462 -> H | E4470: =OR(C4470=$A$4,C4470=$A$5,C4470=$A$6,C4470=$A$7) -> TRUE | F4470: =OR(D4470=$A$4,D4470=$A$5,D4470=$A$6,D4470=$A$7) -> TRUE | G4470: =IF(C4470="D",D4470="D","N/A") -> N/A | K4470: 4456 | L4470: I | M4470: H | N4470: =OR(L4470=$A$4,L4470=$A$5,L4470=$A$6,L4470=$A$7) -> TRUE | O4470: =OR(M4470=$A$4,M4470=$A$5,M4470=$A$6,M4470=$A$7) -> TRUE | P4470: =IF(L4470="D",M4470="D","N/A") -> N/A
B4471: ='Raw data (base scenario)'!A4463 -> 4457 | C4471: ='Raw data (base scenario)'!B4463 -> I | D4471: ='Raw data (base scenario)'!C4463 -> H | E4471: =OR(C4471=$A$4,C4471=$A$5,C4471=$A$6,C4471=$A$7) -> TRUE | F4471: =OR(D4471=$A$4,D4471=$A$5,D4471=$A$6,D4471=$A$7) -> TRUE | G4471: =IF(C4471="D",D4471="D","N/A") -> N/A | K4471: 4457 | L4471: S | M4471: I | N4471: =OR(L4471=$A$4,L4471=$A$5,L4471=$A$6,L4471=$A$7) -> TRUE | O4471: =OR(M4471=$A$4,M4471=$A$5,M4471=$A$6,M4471=$A$7) -> TRUE | P4471: =IF(L4471="D",M4471="D","N/A") -> N/A
B4472: ='Raw data (base scenario)'!A4464 -> 4458 | C4472: ='Raw data (base scenario)'!B4464 -> S | D4472: ='Raw data (base scenario)'!C4464 -> I | E4472: =OR(C4472=$A$4,C4472=$A$5,C4472=$A$6,C4472=$A$7) -> TRUE | F4472: =OR(D4472=$A$4,D4472=$A$5,D4472=$A$6,D4472=$A$7) -> TRUE | G4472: =IF(C4472="D",D4472="D","N/A") -> N/A | K4472: 4458 | L4472: S | M4472: H | N4472: =OR(L4472=$A$4,L4472=$A$5,L4472=$A$6,L4472=$A$7) -> TRUE | O4472: =OR(M4472=$A$4,M4472=$A$5,M4472=$A$6,M4472=$A$7) -> TRUE | P4472: =IF(L4472="D",M4472="D","N/A") -> N/A
B4473: ='Raw data (base scenario)'!A4465 -> 4459 | C4473: ='Raw data (base scenario)'!B4465 -> S | D4473: ='Raw data (base scenario)'!C4465 -> H | E4473: =OR(C4473=$A$4,C4473=$A$5,C4473=$A$6,C4473=$A$7) -> TRUE | F4473: =OR(D4473=$A$4,D4473=$A$5,D4473=$A$6,D4473=$A$7) -> TRUE | G4473: =IF(C4473="D",D4473="D","N/A") -> N/A | K4473: 4459 | L4473: S | M4473: H | N4473: =OR(L4473=$A$4,L4473=$A$5,L4473=$A$6,L4473=$A$7) -> TRUE | O4473: =OR(M4473=$A$4,M4473=$A$5,M4473=$A$6,M4473=$A$7) -> TRUE | P4473: =IF(L4473="D",M4473="D","N/A") -> N/A
B4474: ='Raw data (base scenario)'!A4466 -> 4460 | C4474: ='Raw data (base scenario)'!B4466 -> S | D4474: ='Raw data (base scenario)'!C4466 -> H | E4474: =OR(C4474=$A$4,C4474=$A$5,C4474=$A$6,C4474=$A$7) -> TRUE | F4474: =OR(D4474=$A$4,D4474=$A$5,D4474=$A$6,D4474=$A$7) -> TRUE | G4474: =IF(C4474="D",D4474="D","N/A") -> N/A | K4474: 4460 | L4474: D | M4474: D | N4474: =OR(L4474=$A$4,L4474=$A$5,L4474=$A$6,L4474=$A$7) -> TRUE | O4474: =OR(M4474=$A$4,M4474=$A$5,M4474=$A$6,M4474=$A$7) -> TRUE | P4474: =IF(L4474="D",M4474="D","N/A") -> TRUE
B4475: ='Raw data (base scenario)'!A4467 -> 4461 | C4475: ='Raw data (base scenario)'!B4467 -> D | D4475: ='Raw data (base scenario)'!C4467 -> D | E4475: =OR(C4475=$A$4,C4475=$A$5,C4475=$A$6,C4475=$A$7) -> TRUE | F4475: =OR(D4475=$A$4,D4475=$A$5,D4475=$A$6,D4475=$A$7) -> TRUE | G4475: =IF(C4475="D",D4475="D","N/A") -> TRUE | K4475: 4461 | L4475: D | M4475: D | N4475: =OR(L4475=$A$4,L4475=$A$5,L4475=$A$6,L4475=$A$7) -> TRUE | O4475: =OR(M4475=$A$4,M4475=$A$5,M4475=$A$6,M4475=$A$7) -> TRUE | P4475: =IF(L4475="D",M4475="D","N/A") -> TRUE
B4476: ='Raw data (base scenario)'!A4468 -> 4462 | C4476: ='Raw data (base scenario)'!B4468 -> D | D4476: ='Raw data (base scenario)'!C4468 -> D | E4476: =OR(C4476=$A$4,C4476=$A$5,C4476=$A$6,C4476=$A$7) -> TRUE | F4476: =OR(D4476=$A$4,D4476=$A$5,D4476=$A$6,D4476=$A$7) -> TRUE | G4476: =IF(C4476="D",D4476="D","N/A") -> TRUE | K4476: 4462 | L4476: I | M4476: D | N4476: =OR(L4476=$A$4,L4476=$A$5,L4476=$A$6,L4476=$A$7) -> TRUE | O4476: =OR(M4476=$A$4,M4476=$A$5,M4476=$A$6,M4476=$A$7) -> TRUE | P4476: =IF(L4476="D",M4476="D","N/A") -> N/A
B4477: ='Raw data (base scenario)'!A4469 -> 4463 | C4477: ='Raw data (base scenario)'!B4469 -> I | D4477: ='Raw data (base scenario)'!C4469 -> D | E4477: =OR(C4477=$A$4,C4477=$A$5,C4477=$A$6,C4477=$A$7) -> TRUE | F4477: =OR(D4477=$A$4,D4477=$A$5,D4477=$A$6,D4477=$A$7) -> TRUE | G4477: =IF(C4477="D",D4477="D","N/A") -> N/A | K4477: 4463 | L4477: S | M4477: H | N4477: =OR(L4477=$A$4,L4477=$A$5,L4477=$A$6,L4477=$A$7) -> TRUE | O4477: =OR(M4477=$A$4,M4477=$A$5,M4477=$A$6,M4477=$A$7) -> TRUE | P4477: =IF(L4477="D",M4477="D","N/A") -> N/A
B4478: ='Raw data (base scenario)'!A4470 -> 4464 | C4478: ='Raw data (base scenario)'!B4470 -> S | D4478: ='Raw data (base scenario)'!C4470 -> H | E4478: =OR(C4478=$A$4,C4478=$A$5,C4478=$A$6,C4478=$A$7) -> TRUE | F4478: =OR(D4478=$A$4,D4478=$A$5,D4478=$A$6,D4478=$A$7) -> TRUE | G4478: =IF(C4478="D",D4478="D","N/A") -> N/A | K4478: 4464 | L4478: H | M4478: H | N4478: =OR(L4478=$A$4,L4478=$A$5,L4478=$A$6,L4478=$A$7) -> TRUE | O4478: =OR(M4478=$A$4,M4478=$A$5,M4478=$A$6,M4478=$A$7) -> TRUE | P4478: =IF(L4478="D",M4478="D","N/A") -> N/A
B4479: ='Raw data (base scenario)'!A4471 -> 4465 | C4479: ='Raw data (base scenario)'!B4471 -> H | D4479: ='Raw data (base scenario)'!C4471 -> H | E4479: =OR(C4479=$A$4,C4479=$A$5,C4479=$A$6,C4479=$A$7) -> TRUE | F4479: =OR(D4479=$A$4,D4479=$A$5,D4479=$A$6,D4479=$A$7) -> TRUE | G4479: =IF(C4479="D",D4479="D","N/A") -> N/A | K4479: 4465 | L4479: S | M4479: H | N4479: =OR(L4479=$A$4,L4479=$A$5,L4479=$A$6,L4479=$A$7) -> TRUE | O4479: =OR(M4479=$A$4,M4479=$A$5,M4479=$A$6,M4479=$A$7) -> TRUE | P4479: =IF(L4479="D",M4479="D","N/A") -> N/A
... B7120: ='Raw data (base scenario)'!A7112 -> 7106 | C7120: ='Raw data (base scenario)'!B7112 -> S | D7120: ='Raw data (base scenario)'!C7112 -> D | E7120: =OR(C7120=$A$4,C7120=$A$5,C7120=$A$6,C7120=$A$7) -> TRUE | F7120: =OR(D7120=$A$4,D7120=$A$5,D7120=$A$6,D7120=$A$7) -> TRUE | G7120: =IF(C7120="D",D7120="D","N/A") -> N/A | K7120: 7106 | L7120: S | M7120: H | N7120: =OR(L7120=$A$4,L7120=$A$5,L7120=$A$6,L7120=$A$7) -> TRUE | O7120: =OR(M7120=$A$4,M7120=$A$5,M7120=$A$6,M7120=$A$7) -> TRUE | P7120: =IF(L7120="D",M7120="D","N/A") -> N/A
B7121: ='Raw data (base scenario)'!A7113 -> 7107 | C7121: ='Raw data (base scenario)'!B7113 -> U | D7121: ='Raw data (base scenario)'!C7113 -> Q | E7121: =OR(C7121=$A$4,C7121=$A$5,C7121=$A$6,C7121=$A$7) -> FALSE | F7121: =OR(D7121=$A$4,D7121=$A$5,D7121=$A$6,D7121=$A$7) -> FALSE | G7121: =IF(C7121="D",D7121="D","N/A") -> N/A | H7121: Corrupted data - remove | K7121: 7107 | L7121: I | M7121: D | N7121: =OR(L7121=$A$4,L7121=$A$5,L7121=$A$6,L7121=$A$7) -> TRUE | O7121: =OR(M7121=$A$4,M7121=$A$5,M7121=$A$6,M7121=$A$7) -> TRUE | P7121: =IF(L7121="D",M7121="D","N/A") -> N/A
B7122: ='Raw data (base scenario)'!A7114 -> 7108 | C7122: ='Raw data (base scenario)'!B7114 -> S | D7122: ='Raw data (base scenario)'!C7114 -> H | E7122: =OR(C7122=$A$4,C7122=$A$5,C7122=$A$6,C7122=$A$7) -> TRUE | F7122: =OR(D7122=$A$4,D7122=$A$5,D7122=$A$6,D7122=$A$7) -> TRUE | G7122: =IF(C7122="D",D7122="D","N/A") -> N/A | K7122: 7108 | L7122: H | M7122: S | N7122: =OR(L7122=$A$4,L7122=$A$5,L7122=$A$6,L7122=$A$7) -> TRUE | O7122: =OR(M7122=$A$4,M7122=$A$5,M7122=$A$6,M7122=$A$7) -> TRUE | P7122: =IF(L7122="D",M7122="D","N/A") -> N/A
...

Sheet Clean_data
A1: Clean data
B6: Status | C6: Status
A7: Lives | B7: Start of Year | C7: End of Year
A8: =Data_checks!K15 -> 1 | B8: =Data_checks!L15 -> I | C8: =Data_checks!M15 -> S | G8: End of Year
A9: =Data_checks!K16 -> 2 | B9: =Data_checks!L16 -> S | C9: =Data_checks!M16 -> H | G9: Healthy | H9: Sick | I9: Very sick | J9: Dead | P9: Reassonableness checks
A10: =Data_checks!K17 -> 3 | B10: =Data_checks!L17 -> D | C10: =Data_checks!M17 -> D | E10: Start of Year | G10: H | H10: S | I10: I | J10: D | K10: Total | P10: Dead stays dead (absorbing state)
A11: =Data_checks!K18 -> 4 | B11: =Data_checks!L18 -> H | C11: =Data_checks!M18 -> H | E11: Healthy | F11: H | G11: =COUNTIFS($B$8:$B$12007,$F11,$C$8:$C$12007,G$10) -> 2400 | H11: =COUNTIFS($B$8:$B$12007,$F11,$C$8:$C$12007,H$10) -> 480 | I11: =COUNTIFS($B$8:$B$12007,$F11,$C$8:$C$12007,I$10) -> 90 | J11: =COUNTIFS($B$8:$B$12007,$F11,$C$8:$C$12007,J$10) -> 30 | K11: =SUM(G11:J11) -> 3000
A12: =Data_checks!K19 -> 5 | B12: =Data_checks!L19 -> I | C12: =Data_checks!M19 -> I | E12: Sick | F12: S | G12: =COUNTIFS($B$8:$B$12007,$F12,$C$8:$C$12007,G$10) -> 2250 | H12: =COUNTIFS($B$8:$B$12007,$F12,$C$8:$C$12007,H$10) -> 300 | I12: =COUNTIFS($B$8:$B$12007,$F12,$C$8:$C$12007,I$10) -> 300 | J12: =COUNTIFS($B$8:$B$12007,$F12,$C$8:$C$12007,J$10) -> 150 | K12: =SUM(G12:J12) -> 3000
A13: =Data_checks!K20 -> 6 | B13: =Data_checks!L20 -> I | C13: =Data_checks!M20 -> D | E13: Very sick | F13: I | G13: =COUNTIFS($B$8:$B$12007,$F13,$C$8:$C$12007,G$10) -> 450 | H13: =COUNTIFS($B$8:$B$12007,$F13,$C$8:$C$12007,H$10) -> 750 | I13: =COUNTIFS($B$8:$B$12007,$F13,$C$8:$C$12007,I$10) -> 900 | J13: =COUNTIFS($B$8:$B$12007,$F13,$C$8:$C$12007,J$10) -> 900 | K13: =SUM(G13:J13) -> 3000
A14: =Data_checks!K21 -> 7 | B14: =Data_checks!L21 -> H | C14: =Data_checks!M21 -> H | E14: Dead | F14: D | G14: =COUNTIFS($B$8:$B$12007,$F14,$C$8:$C$12007,G$10) -> 0 | H14: =COUNTIFS($B$8:$B$12007,$F14,$C$8:$C$12007,H$10) -> 0 | I14: =COUNTIFS($B$8:$B$12007,$F14,$C$8:$C$12007,I$10) -> 0 | J14: =COUNTIFS($B$8:$B$12007,$F14,$C$8:$C$12007,J$10) -> 3000 | K14: =SUM(G14:J14) -> 3000
A15: =Data_checks!K22 -> 8 | B15: =Data_checks!L22 -> D | C15: =Data_checks!M22 -> D | F15: Total | G15: =SUM(G11:G14) -> 5100 | H15: =SUM(H11:H14) -> 1530 | I15: =SUM(I11:I14) -> 1290 | J15: =SUM(J11:J14) -> 4080 | K15: =SUM(K11:K14)=SUM(G15:J15) -> TRUE
A16: =Data_checks!K23 -> 9 | B16: =Data_checks!L23 -> H | C16: =Data_checks!M23 -> H
A17: =Data_checks!K24 -> 10 | B17: =Data_checks!L24 -> S | C17: =Data_checks!M24 -> H
A18: =Data_checks!K25 -> 11 | B18: =Data_checks!L25 -> I | C18: =Data_checks!M25 -> I
A19: =Data_checks!K26 -> 12 | B19: =Data_checks!L26 -> H | C19: =Data_checks!M26 -> H
A20: =Data_checks!K27 -> 13 | B20: =Data_checks!L27 -> H | C20: =Data_checks!M27 -> H
A21: =Data_checks!K28 -> 14 | B21: =Data_checks!L28 -> S | C21: =Data_checks!M28 -> H
A22: =Data_checks!K29 -> 15 | B22: =Data_checks!L29 -> H | C22: =Data_checks!M29 -> H
A23: =Data_checks!K30 -> 16 | B23: =Data_checks!L30 -> H | C23: =Data_checks!M30 -> H
A24: =Data_checks!K31 -> 17 | B24: =Data_checks!L31 -> H | C24: =Data_checks!M31 -> H
A25: =Data_checks!K32 -> 18 | B25: =Data_checks!L32 -> D | C25: =Data_checks!M32 -> D
A26: =Data_checks!K33 -> 19 | B26: =Data_checks!L33 -> D | C26: =Data_checks!M33 -> D
A27: =Data_checks!K34 -> 20 | B27: =Data_checks!L34 -> I | C27: =Data_checks!M34 -> S
... A12007: =Data_checks!K12014 -> 12000 | B12007: =Data_checks!L12014 -> D | C12007: =Data_checks!M12014 -> D

Sheet Parameters
A1: Parameters: Derived from raw data or provided in background information
A3: Transition probabilities
C4: End of year
C5: H | D5: S | E5: I | F5: D | G5: Check sum to 1?
A6: Start of year | B6: H | C6: =Clean_data!G11/Clean_data!$K11 -> 0.8 | D6: =Clean_data!H11/Clean_data!$K11 -> 0.16 | E6: =Clean_data!I11/Clean_data!$K11 -> 0.03 | F6: =Clean_data!J11/Clean_data!$K11 -> 0.01 | G6: =SUM(C6:F6)=1 -> TRUE
B7: S | C7: =Clean_data!G12/Clean_data!$K12 -> 0.75 | D7: =Clean_data!H12/Clean_data!$K12 -> 0.1 | E7: =Clean_data!I12/Clean_data!$K12 -> 0.1 | F7: =Clean_data!J12/Clean_data!$K12 -> 0.05 | G7: =SUM(C7:F7)=1 -> TRUE
B8: I | C8: =Clean_data!G13/Clean_data!$K13 -> 0.15 | D8: =Clean_data!H13/Clean_data!$K13 -> 0.25 | E8: =Clean_data!I13/Clean_data!$K13 -> 0.3 | F8: =Clean_data!J13/Clean_data!$K13 -> 0.3 | G8: =SUM(C8:F8)=1 -> TRUE
B9: D | C9: =Clean_data!G14/Clean_data!$K14 -> 0 | D9: =Clean_data!H14/Clean_data!$K14 -> 0 | E9: =Clean_data!I14/Clean_data!$K14 -> 0 | F9: =Clean_data!J14/Clean_data!$K14 -> 1 | G9: =SUM(C9:F9)=1 -> TRUE
A11: Number of lives | B11: H | C11: S | D11: I | E11: D
A12: Initial state | B12: 1000000 | C12: 0 | D12: 0 | E12: 0
A14: Overheads at each health state
A15: Healthy | B15: 50
A16: Sick | B16: 200
A17: Very sick | B17: 3000
A18: Dead | B18: 250
A20: Drug cost
A21: Sick | B21: 150
A22: Very sick | B22: 4000
A24: General inflation (overheads) | B24: 0.02
A25: Drug inflation | B25: 0.05
A26: Discount rate | B26: 0.04
A28: Alternative transition
A29: Transition improvements
C30: End of year
C31: H | D31: S | E31: I | F31: D | G31: Check sum to 0?
A32: Start of year | B32: H | C32: 0.0018 | D32: -0.0012 | E32: -0.00055 | F32: -5e-05 | G32: =SUM(C32:F32)=0 -> TRUE
B33: S | C33: 0.00065 | D33: 0.0005 | E33: -0.00083 | F33: -0.00032 | G33: =SUM(C33:F33)=0 -> TRUE
B34: I | C34: 0.0005 | D34: 0.001 | E34: 0.0005 | F34: -0.002 | G34: =SUM(C34:F34)=0 -> TRUE
B35: D | C35: 0 | D35: 0 | E35: 0 | F35: 0 | G35: =SUM(C35:F35)=0 -> TRUE
A36: New drug cost
A37: Sick | B37: 250
A38: Very sick | B38: 6000
A40: Negotiated drug cost
A41: Sick | B41: 236.97678
A42: Very sick | B42: =B41*20 -> 4739.5356
A44: Negotiated drug cost (if using SoY status)
A45: Sick | B45: 176.55465
A46: Very sick | B46: =B45*20 -> 3531.0929

Sheet Base Scenario
A1: Initial position
A3: * This is an example approach to determining the solution. An reasonable attempt is awarded credit.
C5: Different formulae - do not drag
Y8: Total PV
G9: Total | Y9: =SUM(Y13:Y43) -> 8.8497636e+09
G10: =SUM(G14:G43) -> 19110751
I11: Overheads | M11: Drug | O11: Combined cost | S11: Cost per state x population | W11: Total cost | X11: v | Y11: PV of cost | Z11: Real cost per life alive
B12: Year | C12: Healthy | D12: Sick | E12: Very sick | F12: Dead | G12: Lives alive | H12: Excess deaths | I12: H | J12: S | K12: I | L12: D | M12: S | N12: I | O12: H | P12: S | Q12: I | R12: D | S12: H | T12: S | U12: I | V12: D
B13: 0 | C13: =Parameters!B12 -> 1000000 | D13: =Parameters!C12 -> 0 | E13: =Parameters!D12 -> 0 | F13: =Parameters!E12 -> 0 | G13: =SUM(C13:E13) -> 1000000 | H13: =F13 -> 0 | W13: =C13*O13+D13*P13+E13*Q13+H13*R13 -> 0 | X13: 1 | Y13: =W13*X13 -> 0
B14: 1 | C14: {=SUMPRODUCT($C13:$F13,TRANSPOSE(Parameters!C$6:C$9))} -> 800000 | D14: {=SUMPRODUCT($C13:$F13,TRANSPOSE(Parameters!D$6:D$9))} -> 160000 | E14: {=SUMPRODUCT($C13:$F13,TRANSPOSE(Parameters!E$6:E$9))} -> 30000 | F14: {=SUMPRODUCT($C13:$F13,TRANSPOSE(Parameters!F$6:F$9))} -> 10000 | G14: =SUM(C14:E14) -> 990000 | H14: =F14-F13 -> 10000 | I14: =Parameters!B15 -> 50 | J14: =Parameters!B16 -> 200 | K14: =Parameters!B17 -> 3000 | L14: =Parameters!B18 -> 250 | M14: =Parameters!B21 -> 150 | N14: =Parameters!B22 -> 4000 | O14: =I14 -> 50 | P14: =J14+M14 -> 350 | Q14: =K14+N14 -> 7000 | R14: =L14 -> 250 | S14: =C13*Parameters!$C$6*O14+D13*Parameters!$C$7*(O14+P14)/2+E13*Parameters!$C$8*(O14+Q14)/2 -> 40000000 | T14: =C13*Parameters!$D$6*(O14+P14)/2+D13*Parameters!$D$7*P14+E13*Parameters!$D$8*(P14+Q14)/2 -> 32000000 | U14: =C13*Parameters!$E$6*(O14+Q14)/2+D13*Parameters!$E$7*(P14+Q14)/2+E13*Parameters!$E$8*Q14 -> 105750000 | V14: =C13*Parameters!$F$6*(O14/2+R14)+D13*Parameters!$F$7*(P14/2+R14)+E13*Parameters!$F$8*(Q14/2+R14) -> 2750000 | W14: =S14+T14+U14+V14 -> 180500000 | X14: =1/(1+Parameters!$B$26) -> 0.96153846 | Y14: =W14*X14 -> 1.7355769e+08 | Z14: =Y14/G13 -> 173.55769
B15: 2 | C15: {=SUMPRODUCT($C14:$F14,TRANSPOSE(Parameters!C$6:C$9))} -> 764500 | D15: {=SUMPRODUCT($C14:$F14,TRANSPOSE(Parameters!D$6:D$9))} -> 151500 | E15: {=SUMPRODUCT($C14:$F14,TRANSPOSE(Parameters!E$6:E$9))} -> 49000 | F15: {=SUMPRODUCT($C14:$F14,TRANSPOSE(Parameters!F$6:F$9))} -> 35000 | G15: =SUM(C15:E15) -> 965000 | H15: =F15-F14 -> 25000 | I15: =I14*(1+Parameters!$B$24) -> 51 | J15: =J14*(1+Parameters!$B$24) -> 204 | K15: =K14*(1+Parameters!$B$24) -> 3060 | L15: =L14*(1+Parameters!$B$24) -> 255 | M15: =M14*(1+Parameters!$B$25) -> 157.5 | N15: =N14*(1+Parameters!$B$25) -> 4200 | O15: =I15 -> 51 | P15: =J15+M15 -> 361.5 | Q15: =K15+N15 -> 7260 | R15: =L15 -> 255 | S15: =C14*Parameters!$C$6*O15+D14*Parameters!$C$7*(O15+P15)/2+E14*Parameters!$C$8*(O15+Q15)/2 -> 73839750 | T15: =C14*Parameters!$D$6*(O15+P15)/2+D14*Parameters!$D$7*P15+E14*Parameters!$D$8*(P15+Q15)/2 -> 60764625 | U15: =C14*Parameters!$E$6*(O15+Q15)/2+D14*Parameters!$E$7*(P15+Q15)/2+E14*Parameters!$E$8*Q15 -> 214044000 | V15: =C14*Parameters!$F$6*(O15/2+R15)+D14*Parameters!$F$7*(P15/2+R15)+E14*Parameters!$F$8*(Q15/2+R15) -> 40695000 | W15: =S15+T15+U15+V15 -> 389343375 | X15: =X14/(1+Parameters!$B$26) -> 0.92455621 | Y15: =W15*X15 -> 3.5996984e+08 | Z15: =Y15/G14 -> 363.6059
B16: 3 | C16: {=SUMPRODUCT($C15:$F15,TRANSPOSE(Parameters!C$6:C$9))} -> 732575 | D16: {=SUMPRODUCT($C15:$F15,TRANSPOSE(Parameters!D$6:D$9))} -> 149720 | E16: {=SUMPRODUCT($C15:$F15,TRANSPOSE(Parameters!E$6:E$9))} -> 52785 | F16: {=SUMPRODUCT($C15:$F15,TRANSPOSE(Parameters!F$6:F$9))} -> 64920 | G16: =SUM(C16:E16) -> 935080 | H16: =F16-F15 -> 29920 | I16: =I15*(1+Parameters!$B$24) -> 52.02 | J16: =J15*(1+Parameters!$B$24) -> 208.08 | K16: =K15*(1+Parameters!$B$24) -> 3121.2 | L16: =L15*(1+Parameters!$B$24) -> 260.1 | M16: =M15*(1+Parameters!$B$25) -> 165.375 | N16: =N15*(1+Parameters!$B$25) -> 4410 | O16: =I16 -> 52.02 | P16: =J16+M16 -> 373.455 | Q16: =K16+N16 -> 7531.2 | R16: =L16 -> 260.1 | S16: =C15*Parameters!$C$6*O16+D15*Parameters!$C$7*(O16+P16)/2+E15*Parameters!$C$8*(O16+Q16)/2 -> 83856064 | T16: =C15*Parameters!$D$6*(O16+P16)/2+D15*Parameters!$D$7*P16+E15*Parameters!$D$8*(P16+Q16)/2 -> 80095906 | U16: =C15*Parameters!$E$6*(O16+Q16)/2+D15*Parameters!$E$7*(P16+Q16)/2+E15*Parameters!$E$8*Q16 -> 2.5754698e+08 | V16: =C15*Parameters!$F$6*(O16/2+R16)+D15*Parameters!$F$7*(P16/2+R16)+E15*Parameters!$F$8*(Q16/2+R16) -> 64749819 | W16: =S16+T16+U16+V16 -> 4.8624877e+08 | X16: =X15/(1+Parameters!$B$26) -> 0.88899636 | Y16: =W16*X16 -> 4.3227338e+08 | Z16: =Y16/G15 -> 447.95169
B17: 4 | C17: {=SUMPRODUCT($C16:$F16,TRANSPOSE(Parameters!C$6:C$9))} -> 706267.75 | D17: {=SUMPRODUCT($C16:$F16,TRANSPOSE(Parameters!D$6:D$9))} -> 145380.25 | E17: {=SUMPRODUCT($C16:$F16,TRANSPOSE(Parameters!E$6:E$9))} -> 52784.75 | F17: {=SUMPRODUCT($C16:$F16,TRANSPOSE(Parameters!F$6:F$9))} -> 95567.25 | G17: =SUM(C17:E17) -> 904432.75 | H17: =F17-F16 -> 30647.25 | I17: =I16*(1+Parameters!$B$24) -> 53.0604 | J17: =J16*(1+Parameters!$B$24) -> 212.2416 | K17: =K16*(1+Parameters!$B$24) -> 3183.624 | L17: =L16*(1+Parameters!$B$24) -> 265.302 | M17: =M16*(1+Parameters!$B$25) -> 173.64375 | N17: =N16*(1+Parameters!$B$25) -> 4630.5 | O17: =I17 -> 53.0604 | P17: =J17+M17 -> 385.88535 | Q17: =K17+N17 -> 7814.124 | R17: =L17 -> 265.302 | S17: =C16*Parameters!$C$6*O17+D16*Parameters!$C$7*(O17+P17)/2+E16*Parameters!$C$8*(O17+Q17)/2 -> 86886387 | T17: =C16*Parameters!$D$6*(O17+P17)/2+D16*Parameters!$D$7*P17+E16*Parameters!$D$8*(P17+Q17)/2 -> 85607017 | U17: =C16*Parameters!$E$6*(O17+Q17)/2+D16*Parameters!$E$7*(P17+Q17)/2+E16*Parameters!$E$8*Q17 -> 2.7157537e+08 | V17: =C16*Parameters!$F$6*(O17/2+R17)+D16*Parameters!$F$7*(P17/2+R17)+E16*Parameters!$F$8*(Q17/2+R17) -> 71639779 | W17: =S17+T17+U17+V17 -> 5.1570855e+08 | X17: =X16/(1+Parameters!$B$26) -> 0.85480419 | Y17: =W17*X17 -> 4.4082983e+08 | Z17: =Y17/G16 -> 471.43542
B18: 5 | C18: {=SUMPRODUCT($C17:$F17,TRANSPOSE(Parameters!C$6:C$9))} -> 681967.1 | D18: {=SUMPRODUCT($C17:$F17,TRANSPOSE(Parameters!D$6:D$9))} -> 140737.05 | E18: {=SUMPRODUCT($C17:$F17,TRANSPOSE(Parameters!E$6:E$9))} -> 51561.482 | F18: {=SUMPRODUCT($C17:$F17,TRANSPOSE(Parameters!F$6:F$9))} -> 125734.36 | G18: =SUM(C18:E18) -> 874265.64 | H18: =F18-F17 -> 30167.115 | I18: =I17*(1+Parameters!$B$24) -> 54.121608 | J18: =J17*(1+Parameters!$B$24) -> 216.48643 | K18: =K17*(1+Parameters!$B$24) -> 3247.2965 | L18: =L17*(1+Parameters!$B$24) -> 270.60804 | M18: =M17*(1+Parameters!$B$25) -> 182.32594 | N18: =N17*(1+Parameters!$B$25) -> 4862.025 | O18: =I18 -> 54.121608 | P18: =J18+M18 -> 398.81237 | Q18: =K18+N18 -> 8109.3215 | R18: =L18 -> 270.60804 | S18: =C17*Parameters!$C$6*O18+D17*Parameters!$C$7*(O18+P18)/2+E17*Parameters!$C$8*(O18+Q18)/2 -> 87590245 | T18: =C17*Parameters!$D$6*(O18+P18)/2+D17*Parameters!$D$7*P18+E17*Parameters!$D$8*(P18+Q18)/2 -> 87526822 | U18: =C17*Parameters!$E$6*(O18+Q18)/2+D17*Parameters!$E$7*(P18+Q18)/2+E17*Parameters!$E$8*Q18 -> 2.7674393e+08 | V18: =C17*Parameters!$F$6*(O18/2+R18)+D17*Parameters!$F$7*(P18/2+R18)+E17*Parameters!$F$8*(Q18/2+R18) -> 74011348 | W18: =S18+T18+U18+V18 -> 5.2587235e+08 | X18: =X17/(1+Parameters!$B$26) -> 0.82192711 | Y18: =W18*X18 -> 4.3222874e+08 | Z18: =Y18/G17 -> 477.90036
B19: 6 | C19: {=SUMPRODUCT($C18:$F18,TRANSPOSE(Parameters!C$6:C$9))} -> 658860.69 | D19: {=SUMPRODUCT($C18:$F18,TRANSPOSE(Parameters!D$6:D$9))} -> 136078.81 | E19: {=SUMPRODUCT($C18:$F18,TRANSPOSE(Parameters!E$6:E$9))} -> 50001.163 | F19: {=SUMPRODUCT($C18:$F18,TRANSPOSE(Parameters!F$6:F$9))} -> 155059.33 | G19: =SUM(C19:E19) -> 844940.67 | H19: =F19-F18 -> 29324.968 | I19: =I18*(1+Parameters!$B$24) -> 55.20404 | J19: =J18*(1+Parameters!$B$24) -> 220.81616 | K19: =K18*(1+Parameters!$B$24) -> 3312.2424 | L19: =L18*(1+Parameters!$B$24) -> 276.0202 | M19: =M18*(1+Parameters!$B$25) -> 191.44223 | N19: =N18*(1+Parameters!$B$25) -> 5105.1263 | O19: =I19 -> 55.20404 | P19: =J19+M19 -> 412.2584 | Q19: =K19+N19 -> 8417.3687 | R19: =L19 -> 276.0202 | S19: =C18*Parameters!$C$6*O19+D18*Parameters!$C$7*(O19+P19)/2+E18*Parameters!$C$8*(O19+Q19)/2 -> 87553234 | T19: =C18*Parameters!$D$6*(O19+P19)/2+D18*Parameters!$D$7*P19+E18*Parameters!$D$8*(P19+Q19)/2 -> 88214106 | U19: =C18*Parameters!$E$6*(O19+Q19)/2+D18*Parameters!$E$7*(P19+Q19)/2+E18*Parameters!$E$8*Q19 -> 2.7900662e+08 | V19: =C18*Parameters!$F$6*(O19/2+R19)+D18*Parameters!$F$7*(P19/2+R19)+E18*Parameters!$F$8*(Q19/2+R19) -> 74834822 | W19: =S19+T19+U19+V19 -> 5.2960879e+08 | X19: =X18/(1+Parameters!$B$26) -> 0.79031453 | Y19: =W19*X19 -> 4.1855752e+08 | Z19: =Y19/G18 -> 478.75325
B20: 7 | C20: {=SUMPRODUCT($C19:$F19,TRANSPOSE(Parameters!C$6:C$9))} -> 636647.84 | D20: {=SUMPRODUCT($C19:$F19,TRANSPOSE(Parameters!D$6:D$9))} -> 131525.88 | E20: {=SUMPRODUCT($C19:$F19,TRANSPOSE(Parameters!E$6:E$9))} -> 48374.051 | F20: {=SUMPRODUCT($C19:$F19,TRANSPOSE(Parameters!F$6:F$9))} -> 183452.23 | G20: =SUM(C20:E20) -> 816547.77 | H20: =F20-F19 -> 28392.896 | I20: =I19*(1+Parameters!$B$24) -> 56.308121 | J20: =J19*(1+Parameters!$B$24) -> 225.23248 | K20: =K19*(1+Parameters!$B$24) -> 3378.4873 | L20: =L19*(1+Parameters!$B$24) -> 281.5406 | M20: =M19*(1+Parameters!$B$25) -> 201.01435 | N20: =N19*(1+Parameters!$B$25) -> 5360.3826 | O20: =I20 -> 56.308121 | P20: =J20+M20 -> 426.24683 | Q20: =K20+N20 -> 8738.8698 | R20: =L20 -> 281.5406 | S20: =C19*Parameters!$C$6*O20+D19*Parameters!$C$7*(O20+P20)/2+E19*Parameters!$C$8*(O20+Q20)/2 -> 87286615 | T20: =C19*Parameters!$D$6*(O20+P20)/2+D19*Parameters!$D$7*P20+E19*Parameters!$D$8*(P20+Q20)/2 -> 88518547 | U20: =C19*Parameters!$E$6*(O20+Q20)/2+D19*Parameters!$E$7*(P20+Q20)/2+E19*Parameters!$E$8*Q20 -> 2.8036696e+08 | V20: =C19*Parameters!$F$6*(O20/2+R20)+D19*Parameters!$F$7*(P20/2+R20)+E19*Parameters!$F$8*(Q20/2+R20) -> 75172376 | W20: =S20+T20+U20+V20 -> 5.313445e+08 | X20: =X19/(1+Parameters!$B$26) -> 0.75991781 | Y20: =W20*X20 -> 4.0377815e+08 | Z20: =Y20/G19 -> 477.87752
B21: 8 | C21: {=SUMPRODUCT($C20:$F20,TRANSPOSE(Parameters!C$6:C$9))} -> 615218.79 | D21: {=SUMPRODUCT($C20:$F20,TRANSPOSE(Parameters!D$6:D$9))} -> 127109.75 | E21: {=SUMPRODUCT($C20:$F20,TRANSPOSE(Parameters!E$6:E$9))} -> 46764.239 | F21: {=SUMPRODUCT($C20:$F20,TRANSPOSE(Parameters!F$6:F$9))} -> 210907.22 | G21: =SUM(C21:E21) -> 789092.78 | H21: =F21-F20 -> 27454.988 | I21: =I20*(1+Parameters!$B$24) -> 57.434283 | J21: =J20*(1+Parameters!$B$24) -> 229.73713 | K21: =K20*(1+Parameters!$B$24) -> 3446.057 | L21: =L20*(1+Parameters!$B$24) -> 287.17142 | M21: =M20*(1+Parameters!$B$25) -> 211.06506 | N21: =N20*(1+Parameters!$B$25) -> 5628.4017 | O21: =I21 -> 57.434283 | P21: =J21+M21 -> 440.8022 | Q21: =K21+N21 -> 9074.4587 | R21: =L21 -> 287.17142 | S21: =C20*Parameters!$C$6*O21+D20*Parameters!$C$7*(O21+P21)/2+E20*Parameters!$C$8*(O21+Q21)/2 -> 86957451 | T21: =C20*Parameters!$D$6*(O21+P21)/2+D20*Parameters!$D$7*P21+E20*Parameters!$D$8*(P21+Q21)/2 -> 88710248 | U21: =C20*Parameters!$E$6*(O21+Q21)/2+D20*Parameters!$E$7*(P21+Q21)/2+E20*Parameters!$E$8*Q21 -> 2.8147265e+08 | V21: =C20*Parameters!$F$6*(O21/2+R21)+D20*Parameters!$F$7*(P21/2+R21)+E20*Parameters!$F$8*(Q21/2+R21) -> 75361786 | W21: =S21+T21+U21+V21 -> 5.3250214e+08 | X21: =X20/(1+Parameters!$B$26) -> 0.73069021 | Y21: =W21*X21 -> 3.890941e+08 | Z21: =Y21/G20 -> 476.51112
B22: 9 | C22: {=SUMPRODUCT($C21:$F21,TRANSPOSE(Parameters!C$6:C$9))} -> 594521.98 | D22: {=SUMPRODUCT($C21:$F21,TRANSPOSE(Parameters!D$6:D$9))} -> 122837.04 | E22: {=SUMPRODUCT($C21:$F21,TRANSPOSE(Parameters!E$6:E$9))} -> 45196.811 | F22: {=SUMPRODUCT($C21:$F21,TRANSPOSE(Parameters!F$6:F$9))} -> 237444.16 | G22: =SUM(C22:E22) -> 762555.84 | H22: =F22-F21 -> 26536.947 | I22: =I21*(1+Parameters!$B$24) -> 58.582969 | J22: =J21*(1+Parameters!$B$24) -> 234.33188 | K22: =K21*(1+Parameters!$B$24) -> 3514.9781 | L22: =L21*(1+Parameters!$B$24) -> 292.91485 | M22: =M21*(1+Parameters!$B$25) -> 221.61832 | N22: =N21*(1+Parameters!$B$25) -> 5909.8218 | O22: =I22 -> 58.582969 | P22: =J22+M22 -> 455.95019 | Q22: =K22+N22 -> 9424.7999 | R22: =L22 -> 292.91485 | S22: =C21*Parameters!$C$6*O22+D21*Parameters!$C$7*(O22+P22)/2+E21*Parameters!$C$8*(O22+Q22)/2 -> 86620132 | T22: =C21*Parameters!$D$6*(O22+P22)/2+D21*Parameters!$D$7*P22+E21*Parameters!$D$8*(P22+Q22)/2 -> 88877829 | U22: =C21*Parameters!$E$6*(O22+Q22)/2+D21*Parameters!$E$7*(P22+Q22)/2+E21*Parameters!$E$8*Q22 -> 2.8253539e+08 | V22: =C21*Parameters!$F$6*(O22/2+R22)+D21*Parameters!$F$7*(P22/2+R22)+E21*Parameters!$F$8*(Q22/2+R22) -> 75513704 | W22: =S22+T22+U22+V22 -> 5.3354706e+08 | X22: =X21/(1+Parameters!$B$26) -> 0.70258674 | Y22: =W22*X22 -> 3.7486309e+08 | Z22: =Y22/G21 -> 475.05578
B23: 10 | C23: {=SUMPRODUCT($C22:$F22,TRANSPOSE(Parameters!C$6:C$9))} -> 574524.89 | D23: {=SUMPRODUCT($C22:$F22,TRANSPOSE(Parameters!D$6:D$9))} -> 118706.42 | E23: {=SUMPRODUCT($C22:$F22,TRANSPOSE(Parameters!E$6:E$9))} -> 43678.407 | F23: {=SUMPRODUCT($C22:$F22,TRANSPOSE(Parameters!F$6:F$9))} -> 263090.28 | G23: =SUM(C23:E23) -> 736909.72 | H23: =F23-F22 -> 25646.115 | I23: =I22*(1+Parameters!$B$24) -> 59.754628 | J23: =J22*(1+Parameters!$B$24) -> 239.01851 | K23: =K22*(1+Parameters!$B$24) -> 3585.2777 | L23: =L22*(1+Parameters!$B$24) -> 298.77314 | M23: =M22*(1+Parameters!$B$25) -> 232.69923 | N23: =N22*(1+Parameters!$B$25) -> 6205.3129 | O23: =I23 -> 59.754628 | P23: =J23+M23 -> 471.71775 | Q23: =K23+N23 -> 9790.5906 | R23: =L23 -> 298.77314 | S23: =C22*Parameters!$C$6*O23+D22*Parameters!$C$7*(O23+P23)/2+E22*Parameters!$C$8*(O23+Q23)/2 -> 86292352 | T23: =C22*Parameters!$D$6*(O23+P23)/2+D22*Parameters!$D$7*P23+E22*Parameters!$D$8*(P23+Q23)/2 -> 89050153 | U23: =C22*Parameters!$E$6*(O23+Q23)/2+D22*Parameters!$E$7*(P23+Q23)/2+E22*Parameters!$E$8*Q23 -> 2.8362432e+08 | V23: =C22*Parameters!$F$6*(O23/2+R23)+D22*Parameters!$F$7*(P23/2+R23)+E22*Parameters!$F$8*(Q23/2+R23) -> 75664128 | W23: =S23+T23+U23+V23 -> 5.3463095e+08 | X23: =X22/(1+Parameters!$B$26) -> 0.67556417 | Y23: =W23*X23 -> 3.6117752e+08 | Z23: =Y23/G22 -> 473.64075
B24: 11 | C24: {=SUMPRODUCT($C23:$F23,TRANSPOSE(Parameters!C$6:C$9))} -> 555201.49 | D24: {=SUMPRODUCT($C23:$F23,TRANSPOSE(Parameters!D$6:D$9))} -> 114714.23 | E24: {=SUMPRODUCT($C23:$F23,TRANSPOSE(Parameters!E$6:E$9))} -> 42209.911 | F24: {=SUMPRODUCT($C23:$F23,TRANSPOSE(Parameters!F$6:F$9))} -> 287874.37 | G24: =SUM(C24:E24) -> 712125.63 | H24: =F24-F23 -> 24784.092 | I24: =I23*(1+Parameters!$B$24) -> 60.949721 | J24: =J23*(1+Parameters!$B$24) -> 243.79888 | K24: =K23*(1+Parameters!$B$24) -> 3656.9833 | L24: =L23*(1+Parameters!$B$24) -> 304.7486 | M24: =M23*(1+Parameters!$B$25) -> 244.33419 | N24: =N23*(1+Parameters!$B$25) -> 6515.5785 | O24: =I24 -> 60.949721 | P24: =J24+M24 -> 488.13308 | Q24: =K24+N24 -> 10172.562 | R24: =L24 -> 304.7486 | S24: =C23*Parameters!$C$6*O24+D23*Parameters!$C$7*(O24+P24)/2+E23*Parameters!$C$8*(O24+Q24)/2 -> 85979837 | T24: =C23*Parameters!$D$6*(O24+P24)/2+D23*Parameters!$D$7*P24+E23*Parameters!$D$8*(P24+Q24)/2 -> 89236663 | U24: =C23*Parameters!$E$6*(O24+Q24)/2+D23*Parameters!$E$7*(P24+Q24)/2+E23*Parameters!$E$8*Q24 -> 2.8476214e+08 | V24: =C23*Parameters!$F$6*(O24/2+R24)+D23*Parameters!$F$7*(P24/2+R24)+E23*Parameters!$F$8*(Q24/2+R24) -> 75824810 | W24: =S24+T24+U24+V24 -> 5.3580345e+08 | X24: =X23/(1+Parameters!$B$26) -> 0.64958093 | Y24: =W24*X24 -> 3.4804771e+08 | Z24: =Y24/G23 -> 472.30712
B25: 12 | C25: {=SUMPRODUCT($C24:$F24,TRANSPOSE(Parameters!C$6:C$9))} -> 536528.35 | D25: {=SUMPRODUCT($C24:$F24,TRANSPOSE(Parameters!D$6:D$9))} -> 110856.14 | E25: {=SUMPRODUCT($C24:$F24,TRANSPOSE(Parameters!E$6:E$9))} -> 40790.441 | F25: {=SUMPRODUCT($C24:$F24,TRANSPOSE(Parameters!F$6:F$9))} -> 311825.07 | G25: =SUM(C25:E25) -> 688174.93 | H25: =F25-F24 -> 23950.7 | I25: =I24*(1+Parameters!$B$24) -> 62.168715 | J25: =J24*(1+Parameters!$B$24) -> 248.67486 | K25: =K24*(1+Parameters!$B$24) -> 3730.1229 | L25: =L24*(1+Parameters!$B$24) -> 310.84358 | M25: =M24*(1+Parameters!$B$25) -> 256.5509 | N25: =N24*(1+Parameters!$B$25) -> 6841.3574 | O25: =I25 -> 62.168715 | P25: =J25+M25 -> 505.22577 | Q25: =K25+N25 -> 10571.48 | R25: =L25 -> 310.84358 | S25: =C24*Parameters!$C$6*O25+D24*Parameters!$C$7*(O25+P25)/2+E24*Parameters!$C$8*(O25+Q25)/2 -> 85684417 | T25: =C24*Parameters!$D$6*(O25+P25)/2+D24*Parameters!$D$7*P25+E24*Parameters!$D$8*(P25+Q25)/2 -> 89440467 | U25: =C24*Parameters!$E$6*(O25+Q25)/2+D24*Parameters!$E$7*(P25+Q25)/2+E24*Parameters!$E$8*Q25 -> 2.8595643e+08 | V25: =C24*Parameters!$F$6*(O25/2+R25)+D24*Parameters!$F$7*(P25/2+R25)+E24*Parameters!$F$8*(Q25/2+R25) -> 75999603 | W25: =S25+T25+U25+V25 -> 5.3708092e+08 | X25: =X24/(1+Parameters!$B$26) -> 0.62459705 | Y25: =W25*X25 -> 3.3545916e+08 | Z25: =Y25/G24 -> 471.06738
B26: 13 | C26: {=SUMPRODUCT($C25:$F25,TRANSPOSE(Parameters!C$6:C$9))} -> 518483.35 | D26: {=SUMPRODUCT($C25:$F25,TRANSPOSE(Parameters!D$6:D$9))} -> 107127.76 | E26: {=SUMPRODUCT($C25:$F25,TRANSPOSE(Parameters!E$6:E$9))} -> 39418.597 | F26: {=SUMPRODUCT($C25:$F25,TRANSPOSE(Parameters!F$6:F$9))} -> 334970.29 | G26: =SUM(C26:E26) -> 665029.71 | H26: =F26-F25 -> 23145.223 | I26: =I25*(1+Parameters!$B$24) -> 63.41209 | J26: =J25*(1+Parameters!$B$24) -> 253.64836 | K26: =K25*(1+Parameters!$B$24) -> 3804.7254 | L26: =L25*(1+Parameters!$B$24) -> 317.06045 | M26: =M25*(1+Parameters!$B$25) -> 269.37845 | N26: =N25*(1+Parameters!$B$25) -> 7183.4253 | O26: =I26 -> 63.41209 | P26: =J26+M26 -> 523.02681 | Q26: =K26+N26 -> 10988.151 | R26: =L26 -> 317.06045 | S26: =C25*Parameters!$C$6*O26+D25*Parameters!$C$7*(O26+P26)/2+E25*Parameters!$C$8*(O26+Q26)/2 -> 85406648 | T26: =C25*Parameters!$D$6*(O26+P26)/2+D25*Parameters!$D$7*P26+E25*Parameters!$D$8*(P26+Q26)/2 -> 89662611 | U26: =C25*Parameters!$E$6*(O26+Q26)/2+D25*Parameters!$E$7*(P26+Q26)/2+E25*Parameters!$E$8*Q26 -> 2.8720984e+08 | V26: =C25*Parameters!$F$6*(O26/2+R26)+D25*Parameters!$F$7*(P26/2+R26)+E25*Parameters!$F$8*(Q26/2+R26) -> 76189791 | W26: =S26+T26+U26+V26 -> 5.3846889e+08 | X26: =X25/(1+Parameters!$B$26) -> 0.60057409 | Y26: =W26*X26 -> 3.2339046e+08 | Z26: =Y26/G25 -> 469.92479
... B43: 30 | C43: {=SUMPRODUCT($C42:$F42,TRANSPOSE(Parameters!C$6:C$9))} -> 289835.72 | D43: {=SUMPRODUCT($C42:$F42,TRANSPOSE(Parameters!D$6:D$9))} -> 59885.155 | E43: {=SUMPRODUCT($C42:$F42,TRANSPOSE(Parameters!E$6:E$9))} -> 22035.279 | F43: {=SUMPRODUCT($C42:$F42,TRANSPOSE(Parameters!F$6:F$9))} -> 628243.85 | G43: =SUM(C43:E43) -> 371756.15 | H43: =F43-F42 -> 12938.351 | I43: =I42*(1+Parameters!$B$24) -> 88.792235 | J43: =J42*(1+Parameters!$B$24) -> 355.16894 | K43: =K42*(1+Parameters!$B$24) -> 5327.5341 | L43: =L42*(1+Parameters!$B$24) -> 443.96117 | M43: =M42*(1+Parameters!$B$25) -> 617.42034 | N43: =N42*(1+Parameters!$B$25) -> 16464.542 | O43: =I43 -> 88.792235 | P43: =J43+M43 -> 972.58928 | Q43: =K43+N43 -> 21792.076 | R43: =L43 -> 443.96117 | S43: =C42*Parameters!$C$6*O43+D42*Parameters!$C$7*(O43+P43)/2+E42*Parameters!$C$8*(O43+Q43)/2 -> 83389451 | T43: =C42*Parameters!$D$6*(O43+P43)/2+D42*Parameters!$D$7*P43+E42*Parameters!$D$8*(P43+Q43)/2 -> 96379188 | U43: =C42*Parameters!$E$6*(O43+Q43)/2+D42*Parameters!$E$7*(P43+Q43)/2+E42*Parameters!$E$8*Q43 -> 3.1804626e+08 | V43: =C42*Parameters!$F$6*(O43/2+R43)+D42*Parameters!$F$7*(P43/2+R43)+E42*Parameters!$F$8*(Q43/2+R43) -> 81920075 | W43: =S43+T43+U43+V43 -> 5.7973498e+08 | X43: =X42/(1+Parameters!$B$26) -> 0.30831867 | Y43: =W43*X43 -> 1.7874312e+08 | Z43: =Y43/G42 -> 464.63652

Sheet Alt Scenario_1
A1: Alternative position - allowing for alternative drugs
C5: Different formulae - do not drag
Y8: Total PV
G9: Total | Y9: =SUM(Y13:Y43) -> 1.01543e+10
G10: =SUM(G14:G43) -> 20149312
I11: Overheads | M11: Drug | O11: Combined cost | S11: Cost per state x population | W11: Total cost | X11: v | Y11: PV of cost | Z11: Real cost per life alive
B12: Year | C12: Healthy | D12: Sick | E12: Very sick | F12: Dead | G12: Lives alive | H12: Excess deaths | I12: H | J12: S | K12: I | L12: D | M12: S | N12: I | O12: H | P12: S | Q12: I | R12: D | S12: H | T12: S | U12: I | V12: D
B13: 0 | C13: =Parameters!B12 -> 1000000 | D13: =Parameters!C12 -> 0 | E13: =Parameters!D12 -> 0 | F13: =Parameters!E12 -> 0 | G13: =SUM(C13:E13) -> 1000000 | H13: =F13 -> 0 | W13: =C13*O13+D13*P13+E13*Q13+H13*R13 -> 0 | X13: 1 | Y13: =W13*X13 -> 0
B14: 1 | C14: {=SUMPRODUCT($C13:$F13,TRANSPOSE(Parameters!C$6:C$9))+($B14-1)*SUMPRODUCT($C13:$F13,TRANSPOSE(Parameters!C$32:C$35))} -> 800000 | D14: {=SUMPRODUCT($C13:$F13,TRANSPOSE(Parameters!D$6:D$9))+($B14-1)*SUMPRODUCT($C13:$F13,TRANSPOSE(Parameters!D$32:D$35))} -> 160000 | E14: {=SUMPRODUCT($C13:$F13,TRANSPOSE(Parameters!E$6:E$9))+($B14-1)*SUMPRODUCT($C13:$F13,TRANSPOSE(Parameters!E$32:E$35))} -> 30000 | F14: {=SUMPRODUCT($C13:$F13,TRANSPOSE(Parameters!F$6:F$9))+($B14-1)*SUMPRODUCT($C13:$F13,TRANSPOSE(Parameters!F$32:F$35))} -> 10000 | G14: =SUM(C14:E14) -> 990000 | H14: =F14-F13 -> 10000 | I14: =Parameters!B15 -> 50 | J14: =Parameters!B16 -> 200 | K14: =Parameters!B17 -> 3000 | L14: =Parameters!B18 -> 250 | M14: =Parameters!B37 -> 250 | N14: =Parameters!B38 -> 6000 | O14: =I14 -> 50 | P14: =J14+M14 -> 450 | Q14: =K14+N14 -> 9000 | R14: =L14 -> 250 | S14: =C13*(Parameters!$C$6+($B14-1)*Parameters!$C$32)*O14+D13*(Parameters!$C$7+($B14-1)*Parameters!$C$33)*(O14+P14)/2+E13*(Parameters!$C$8+($B14-1)*Parameters!$C$34)*(O14+Q14)/2 -> 40000000 | T14: =C13*(Parameters!$D$6+($B14-1)*Parameters!$D$32)*(O14+P14)/2+D13*(Parameters!$D$7+($B14-1)*Parameters!$D$33)*P14+E13*(Parameters!$D$8+($B14-1)*Parameters!$D$34)*(P14+Q14)/2 -> 40000000 | U14: =C13*(Parameters!$E$6+($B14-1)*Parameters!$E$32)*(O14+Q14)/2+D13*(Parameters!$E$7+($B14-1)*Parameters!$E$33)*(P14+Q14)/2+E13*(Parameters!$E$8+($B14-1)*Parameters!$E$34)*Q14 -> 135750000 | V14: =C13*(Parameters!$F$6+($B14-1)*Parameters!$F$32)*(O14/2+R14)+D13*(Parameters!$F$7+($B14-1)*Parameters!$F$33)*(P14/2+R14)+E13*(Parameters!$F$8+($B14-1)*Parameters!$F$34)*(Q14/2+R14) -> 2750000 | W14: =S14+T14+U14+V14 -> 218500000 | X14: =1/(1+Parameters!$B$26) -> 0.96153846 | Y14: =W14*X14 -> 2.1009615e+08 | Z14: =Y14/G13 -> 210.09615
B15: 2 | C15: {=SUMPRODUCT($C14:$F14,TRANSPOSE(Parameters!C$6:C$9))+($B15-1)*SUMPRODUCT($C14:$F14,TRANSPOSE(Parameters!C$32:C$35))} -> 766059 | D15: {=SUMPRODUCT($C14:$F14,TRANSPOSE(Parameters!D$6:D$9))+($B15-1)*SUMPRODUCT($C14:$F14,TRANSPOSE(Parameters!D$32:D$35))} -> 150650 | E15: {=SUMPRODUCT($C14:$F14,TRANSPOSE(Parameters!E$6:E$9))+($B15-1)*SUMPRODUCT($C14:$F14,TRANSPOSE(Parameters!E$32:E$35))} -> 48442.2 | F15: {=SUMPRODUCT($C14:$F14,TRANSPOSE(Parameters!F$6:F$9))+($B15-1)*SUMPRODUCT($C14:$F14,TRANSPOSE(Parameters!F$32:F$35))} -> 34848.8 | G15: =SUM(C15:E15) -> 965151.2 | H15: =F15-F14 -> 24848.8 | I15: =I14*(1+Parameters!$B$24) -> 51 | J15: =J14*(1+Parameters!$B$24) -> 204 | K15: =K14*(1+Parameters!$B$24) -> 3060 | L15: =L14*(1+Parameters!$B$24) -> 255 | M15: =M14*(1+Parameters!$B$25) -> 262.5 | N15: =N14*(1+Parameters!$B$25) -> 6300 | O15: =I15 -> 51 | P15: =J15+M15 -> 466.5 | Q15: =K15+N15 -> 9360 | R15: =L15 -> 255 | S15: =C14*(Parameters!$C$6+($B15-1)*Parameters!$C$32)*O15+D14*(Parameters!$C$7+($B15-1)*Parameters!$C$33)*(O15+P15)/2+E14*(Parameters!$C$8+($B15-1)*Parameters!$C$34)*(O15+Q15)/2 -> 85035682 | T15: =C14*(Parameters!$D$6+($B15-1)*Parameters!$D$32)*(O15+P15)/2+D14*(Parameters!$D$7+($B15-1)*Parameters!$D$33)*P15+E14*(Parameters!$D$8+($B15-1)*Parameters!$D$34)*(P15+Q15)/2 -> 77369692 | U15: =C14*(Parameters!$E$6+($B15-1)*Parameters!$E$32)*(O15+Q15)/2+D14*(Parameters!$E$7+($B15-1)*Parameters!$E$33)*(P15+Q15)/2+E14*(Parameters!$E$8+($B15-1)*Parameters!$E$34)*Q15 -> 2.732015e+08 | V15: =C14*(Parameters!$F$6+($B15-1)*Parameters!$F$32)*(O15/2+R15)+D14*(Parameters!$F$7+($B15-1)*Parameters!$F$33)*(P15/2+R15)+E14*(Parameters!$F$8+($B15-1)*Parameters!$F$34)*(Q15/2+R15) -> 50232682 | W15: =S15+T15+U15+V15 -> 485839557 | X15: =X14/(1+Parameters!$B$26) -> 0.92455621 | Y15: =W15*X15 -> 4.4918598e+08 | Z15: =Y15/G14 -> 453.72321
B16: 3 | C16: {=SUMPRODUCT($C15:$F15,TRANSPOSE(Parameters!C$6:C$9))+($B16-1)*SUMPRODUCT($C15:$F15,TRANSPOSE(Parameters!C$32:C$35))} -> 736103.13 | D16: {=SUMPRODUCT($C15:$F15,TRANSPOSE(Parameters!D$6:D$9))+($B16-1)*SUMPRODUCT($C15:$F15,TRANSPOSE(Parameters!D$32:D$35))} -> 148153.98 | E16: {=SUMPRODUCT($C15:$F15,TRANSPOSE(Parameters!E$6:E$9))+($B16-1)*SUMPRODUCT($C15:$F15,TRANSPOSE(Parameters!E$32:E$35))} -> 51535.128 | F16: {=SUMPRODUCT($C15:$F15,TRANSPOSE(Parameters!F$6:F$9))+($B16-1)*SUMPRODUCT($C15:$F15,TRANSPOSE(Parameters!F$32:F$35))} -> 64207.759 | G16: =SUM(C16:E16) -> 935792.24 | H16: =F16-F15 -> 29358.959 | I16: =I15*(1+Parameters!$B$24) -> 52.02 | J16: =J15*(1+Parameters!$B$24) -> 208.08 | K16: =K15*(1+Parameters!$B$24) -> 3121.2 | L16: =L15*(1+Parameters!$B$24) -> 260.1 | M16: =M15*(1+Parameters!$B$25) -> 275.625 | N16: =N15*(1+Parameters!$B$25) -> 6615 | O16: =I16 -> 52.02 | P16: =J16+M16 -> 483.705 | Q16: =K16+N16 -> 9736.2 | R16: =L16 -> 260.1 | S16: =C15*(Parameters!$C$6+($B16-1)*Parameters!$C$32)*O16+D15*(Parameters!$C$7+($B16-1)*Parameters!$C$33)*(O16+P16)/2+E15*(Parameters!$C$8+($B16-1)*Parameters!$C$34)*(O16+Q16)/2 -> 98140646 | T16: =C15*(Parameters!$D$6+($B16-1)*Parameters!$D$32)*(O16+P16)/2+D15*(Parameters!$D$7+($B16-1)*Parameters!$D$33)*P16+E15*(Parameters!$D$8+($B16-1)*Parameters!$D$34)*(P16+Q16)/2 -> 1.0207858e+08 | U16: =C15*(Parameters!$E$6+($B16-1)*Parameters!$E$32)*(O16+Q16)/2+D15*(Parameters!$E$7+($B16-1)*Parameters!$E$33)*(P16+Q16)/2+E15*(Parameters!$E$8+($B16-1)*Parameters!$E$34)*Q16 -> 3.2601929e+08 | V16: =C15*(Parameters!$F$6+($B16-1)*Parameters!$F$32)*(O16/2+R16)+D15*(Parameters!$F$7+($B16-1)*Parameters!$F$33)*(P16/2+R16)+E15*(Parameters!$F$8+($B16-1)*Parameters!$F$34)*(Q16/2+R16) -> 79435116 | W16: =S16+T16+U16+V16 -> 6.0567362e+08 | X16: =X15/(1+Parameters!$B$26) -> 0.88899636 | Y16: =W16*X16 -> 5.3844165e+08 | Z16: =Y16/G15 -> 557.88321
B17: 4 | C17: {=SUMPRODUCT($C16:$F16,TRANSPOSE(Parameters!C$6:C$9))+($B17-1)*SUMPRODUCT($C16:$F16,TRANSPOSE(Parameters!C$32:C$35))} -> 712069.42 | D17: {=SUMPRODUCT($C16:$F16,TRANSPOSE(Parameters!D$6:D$9))+($B17-1)*SUMPRODUCT($C16:$F16,TRANSPOSE(Parameters!D$32:D$35))} -> 143202.55 | E17: {=SUMPRODUCT($C16:$F16,TRANSPOSE(Parameters!E$6:E$9))+($B17-1)*SUMPRODUCT($C16:$F16,TRANSPOSE(Parameters!E$32:E$35))} -> 50852.86 | F17: {=SUMPRODUCT($C16:$F16,TRANSPOSE(Parameters!F$6:F$9))+($B17-1)*SUMPRODUCT($C16:$F16,TRANSPOSE(Parameters!F$32:F$35))} -> 93875.174 | G17: =SUM(C17:E17) -> 906124.83 | H17: =F17-F16 -> 29667.415 | I17: =I16*(1+Parameters!$B$24) -> 53.0604 | J17: =J16*(1+Parameters!$B$24) -> 212.2416 | K17: =K16*(1+Parameters!$B$24) -> 3183.624 | L17: =L16*(1+Parameters!$B$24) -> 265.302 | M17: =M16*(1+Parameters!$B$25) -> 289.40625 | N17: =N16*(1+Parameters!$B$25) -> 6945.75 | O17: =I17 -> 53.0604 | P17: =J17+M17 -> 501.64785 | Q17: =K17+N17 -> 10129.374 | R17: =L17 -> 265.302 | S17: =C16*(Parameters!$C$6+($B17-1)*Parameters!$C$32)*O17+D16*(Parameters!$C$7+($B17-1)*Parameters!$C$33)*(O17+P17)/2+E16*(Parameters!$C$8+($B17-1)*Parameters!$C$34)*(O17+Q17)/2 -> 1.0210576e+08 | T17: =C16*(Parameters!$D$6+($B17-1)*Parameters!$D$32)*(O17+P17)/2+D16*(Parameters!$D$7+($B17-1)*Parameters!$D$33)*P17+E16*(Parameters!$D$8+($B17-1)*Parameters!$D$34)*(P17+Q17)/2 -> 1.087801e+08 | U17: =C16*(Parameters!$E$6+($B17-1)*Parameters!$E$32)*(O17+Q17)/2+D16*(Parameters!$E$7+($B17-1)*Parameters!$E$33)*(P17+Q17)/2+E16*(Parameters!$E$8+($B17-1)*Parameters!$E$34)*Q17 -> 3.4042529e+08 | V17: =C16*(Parameters!$F$6+($B17-1)*Parameters!$F$32)*(O17/2+R17)+D16*(Parameters!$F$7+($B17-1)*Parameters!$F$33)*(P17/2+R17)+E16*(Parameters!$F$8+($B17-1)*Parameters!$F$34)*(Q17/2+R17) -> 86622271 | W17: =S17+T17+U17+V17 -> 6.3793343e+08 | X17: =X16/(1+Parameters!$B$26) -> 0.85480419 | Y17: =W17*X17 -> 5.4530817e+08 | Z17: =Y17/G16 -> 582.72354
B18: 5 | C18: {=SUMPRODUCT($C17:$F17,TRANSPOSE(Parameters!C$6:C$9))+($B18-1)*SUMPRODUCT($C17:$F17,TRANSPOSE(Parameters!C$32:C$35))} -> 690286.31 | D18: {=SUMPRODUCT($C17:$F17,TRANSPOSE(Parameters!D$6:D$9))+($B18-1)*SUMPRODUCT($C17:$F17,TRANSPOSE(Parameters!D$32:D$35))} -> 138036.46 | E18: {=SUMPRODUCT($C17:$F17,TRANSPOSE(Parameters!E$6:E$9))+($B18-1)*SUMPRODUCT($C17:$F17,TRANSPOSE(Parameters!E$32:E$35))} -> 48997.916 | F18: {=SUMPRODUCT($C17:$F17,TRANSPOSE(Parameters!F$6:F$9))+($B18-1)*SUMPRODUCT($C17:$F17,TRANSPOSE(Parameters!F$32:F$35))} -> 122679.32 | G18: =SUM(C18:E18) -> 877320.68 | H18: =F18-F17 -> 28804.143 | I18: =I17*(1+Parameters!$B$24) -> 54.121608 | J18: =J17*(1+Parameters!$B$24) -> 216.48643 | K18: =K17*(1+Parameters!$B$24) -> 3247.2965 | L18: =L17*(1+Parameters!$B$24) -> 270.60804 | M18: =M17*(1+Parameters!$B$25) -> 303.87656 | N18: =N17*(1+Parameters!$B$25) -> 7293.0375 | O18: =I18 -> 54.121608 | P18: =J18+M18 -> 520.36299 | Q18: =K18+N18 -> 10540.334 | R18: =L18 -> 270.60804 | S18: =C17*(Parameters!$C$6+($B18-1)*Parameters!$C$32)*O18+D17*(Parameters!$C$7+($B18-1)*Parameters!$C$33)*(O18+P18)/2+E17*(Parameters!$C$8+($B18-1)*Parameters!$C$34)*(O18+Q18)/2 -> 1.0301111e+08 | T18: =C17*(Parameters!$D$6+($B18-1)*Parameters!$D$32)*(O18+P18)/2+D17*(Parameters!$D$7+($B18-1)*Parameters!$D$33)*P18+E17*(Parameters!$D$8+($B18-1)*Parameters!$D$34)*(P18+Q18)/2 -> 1.1077827e+08 | U18: =C17*(Parameters!$E$6+($B18-1)*Parameters!$E$32)*(O18+Q18)/2+D17*(Parameters!$E$7+($B18-1)*Parameters!$E$33)*(P18+Q18)/2+E17*(Parameters!$E$8+($B18-1)*Parameters!$E$34)*Q18 -> 3.4330197e+08 | V18: =C17*(Parameters!$F$6+($B18-1)*Parameters!$F$32)*(O18/2+R18)+D17*(Parameters!$F$7+($B18-1)*Parameters!$F$33)*(P18/2+R18)+E17*(Parameters!$F$8+($B18-1)*Parameters!$F$34)*(Q18/2+R18) -> 88055607 | W18: =S18+T18+U18+V18 -> 6.4514695e+08 | X18: =X17/(1+Parameters!$B$26) -> 0.82192711 | Y18: =W18*X18 -> 5.3026377e+08 | Z18: =Y18/G17 -> 585.19947
B19: 6 | C19: {=SUMPRODUCT($C18:$F18,TRANSPOSE(Parameters!C$6:C$9))+($B19-1)*SUMPRODUCT($C18:$F18,TRANSPOSE(Parameters!C$32:C$35))} -> 669889.77 | D19: {=SUMPRODUCT($C18:$F18,TRANSPOSE(Parameters!D$6:D$9))+($B19-1)*SUMPRODUCT($C18:$F18,TRANSPOSE(Parameters!D$32:D$35))} -> 132947.3 | E19: {=SUMPRODUCT($C18:$F18,TRANSPOSE(Parameters!E$6:E$9))+($B19-1)*SUMPRODUCT($C18:$F18,TRANSPOSE(Parameters!E$32:E$35))} -> 46862.966 | F19: {=SUMPRODUCT($C18:$F18,TRANSPOSE(Parameters!F$6:F$9))+($B19-1)*SUMPRODUCT($C18:$F18,TRANSPOSE(Parameters!F$32:F$35))} -> 150299.97 | G19: =SUM(C19:E19) -> 849700.03 | H19: =F19-F18 -> 27620.652 | I19: =I18*(1+Parameters!$B$24) -> 55.20404 | J19: =J18*(1+Parameters!$B$24) -> 220.81616 | K19: =K18*(1+Parameters!$B$24) -> 3312.2424 | L19: =L18*(1+Parameters!$B$24) -> 276.0202 | M19: =M18*(1+Parameters!$B$25) -> 319.07039 | N19: =N18*(1+Parameters!$B$25) -> 7657.6894 | O19: =I19 -> 55.20404 | P19: =J19+M19 -> 539.88655 | Q19: =K19+N19 -> 10969.932 | R19: =L19 -> 276.0202 | S19: =C18*(Parameters!$C$6+($B19-1)*Parameters!$C$32)*O19+D18*(Parameters!$C$7+($B19-1)*Parameters!$C$33)*(O19+P19)/2+E18*(Parameters!$C$8+($B19-1)*Parameters!$C$34)*(O19+Q19)/2 -> 1.029567e+08 | T19: =C18*(Parameters!$D$6+($B19-1)*Parameters!$D$32)*(O19+P19)/2+D18*(Parameters!$D$7+($B19-1)*Parameters!$D$33)*P19+E18*(Parameters!$D$8+($B19-1)*Parameters!$D$34)*(P19+Q19)/2 -> 1.1117353e+08 | U19: =C18*(Parameters!$E$6+($B19-1)*Parameters!$E$32)*(O19+Q19)/2+D18*(Parameters!$E$7+($B19-1)*Parameters!$E$33)*(P19+Q19)/2+E18*(Parameters!$E$8+($B19-1)*Parameters!$E$34)*Q19 -> 3.4242999e+08 | V19: =C18*(Parameters!$F$6+($B19-1)*Parameters!$F$32)*(O19/2+R19)+D18*(Parameters!$F$7+($B19-1)*Parameters!$F$33)*(P19/2+R19)+E18*(Parameters!$F$8+($B19-1)*Parameters!$F$34)*(Q19/2+R19) -> 87551159 | W19: =S19+T19+U19+V19 -> 6.4411137e+08 | X19: =X18/(1+Parameters!$B$26) -> 0.79031453 | Y19: =W19*X19 -> 5.0905058e+08 | Z19: =Y19/G18 -> 580.23319
B20: 7 | C20: {=SUMPRODUCT($C19:$F19,TRANSPOSE(Parameters!C$6:C$9))+($B20-1)*SUMPRODUCT($C19:$F19,TRANSPOSE(Parameters!C$32:C$35))} -> 650545.62 | D20: {=SUMPRODUCT($C19:$F19,TRANSPOSE(Parameters!D$6:D$9))+($B20-1)*SUMPRODUCT($C19:$F19,TRANSPOSE(Parameters!D$32:D$35))} -> 128049.65 | E20: {=SUMPRODUCT($C19:$F19,TRANSPOSE(Parameters!E$6:E$9))+($B20-1)*SUMPRODUCT($C19:$F19,TRANSPOSE(Parameters!E$32:E$35))} -> 44718.188 | F20: {=SUMPRODUCT($C19:$F19,TRANSPOSE(Parameters!F$6:F$9))+($B20-1)*SUMPRODUCT($C19:$F19,TRANSPOSE(Parameters!F$32:F$35))} -> 176686.54 | G20: =SUM(C20:E20) -> 823313.46 | H20: =F20-F19 -> 26386.571 | I20: =I19*(1+Parameters!$B$24) -> 56.308121 | J20: =J19*(1+Parameters!$B$24) -> 225.23248 | K20: =K19*(1+Parameters!$B$24) -> 3378.4873 | L20: =L19*(1+Parameters!$B$24) -> 281.5406 | M20: =M19*(1+Parameters!$B$25) -> 335.02391 | N20: =N19*(1+Parameters!$B$25) -> 8040.5738 | O20: =I20 -> 56.308121 | P20: =J20+M20 -> 560.25639 | Q20: =K20+N20 -> 11419.061 | R20: =L20 -> 281.5406 | S20: =C19*(Parameters!$C$6+($B20-1)*Parameters!$C$32)*O20+D19*(Parameters!$C$7+($B20-1)*Parameters!$C$33)*(O20+P20)/2+E19*(Parameters!$C$8+($B20-1)*Parameters!$C$34)*(O20+Q20)/2 -> 1.0262177e+08 | T20: =C19*(Parameters!$D$6+($B20-1)*Parameters!$D$32)*(O20+P20)/2+D19*(Parameters!$D$7+($B20-1)*Parameters!$D$33)*P20+E19*(Parameters!$D$8+($B20-1)*Parameters!$D$34)*(P20+Q20)/2 -> 1.1108488e+08 | U20: =C19*(Parameters!$E$6+($B20-1)*Parameters!$E$32)*(O20+Q20)/2+D19*(Parameters!$E$7+($B20-1)*Parameters!$E$33)*(P20+Q20)/2+E19*(Parameters!$E$8+($B20-1)*Parameters!$E$34)*Q20 -> 3.4043454e+08 | V20: =C19*(Parameters!$F$6+($B20-1)*Parameters!$F$32)*(O20/2+R20)+D19*(Parameters!$F$7+($B20-1)*Parameters!$F$33)*(P20/2+R20)+E19*(Parameters!$F$8+($B20-1)*Parameters!$F$34)*(Q20/2+R20) -> 86461318 | W20: =S20+T20+U20+V20 -> 6.4060251e+08 | X20: =X19/(1+Parameters!$B$26) -> 0.75991781 | Y20: =W20*X20 -> 4.8680526e+08 | Z20: =Y20/G19 -> 572.91425
B21: 8 | C21: {=SUMPRODUCT($C20:$F20,TRANSPOSE(Parameters!C$6:C$9))+($B21-1)*SUMPRODUCT($C20:$F20,TRANSPOSE(Parameters!C$32:C$35))} -> 632117.48 | D21: {=SUMPRODUCT($C20:$F20,TRANSPOSE(Parameters!D$6:D$9))+($B21-1)*SUMPRODUCT($C20:$F20,TRANSPOSE(Parameters!D$32:D$35))} -> 123368.43 | E21: {=SUMPRODUCT($C20:$F20,TRANSPOSE(Parameters!E$6:E$9))+($B21-1)*SUMPRODUCT($C20:$F20,TRANSPOSE(Parameters!E$32:E$35))} -> 42644.734 | F21: {=SUMPRODUCT($C20:$F20,TRANSPOSE(Parameters!F$6:F$9))+($B21-1)*SUMPRODUCT($C20:$F20,TRANSPOSE(Parameters!F$32:F$35))} -> 201869.36 | G21: =SUM(C21:E21) -> 798130.64 | H21: =F21-F20 -> 25182.818 | I21: =I20*(1+Parameters!$B$24) -> 57.434283 | J21: =J20*(1+Parameters!$B$24) -> 229.73713 | K21: =K20*(1+Parameters!$B$24) -> 3446.057 | L21: =L20*(1+Parameters!$B$24) -> 287.17142 | M21: =M20*(1+Parameters!$B$25) -> 351.77511 | N21: =N20*(1+Parameters!$B$25) -> 8442.6025 | O21: =I21 -> 57.434283 | P21: =J21+M21 -> 581.51224 | Q21: =K21+N21 -> 11888.66 | R21: =L21 -> 287.17142 | S21: =C20*(Parameters!$C$6+($B21-1)*Parameters!$C$32)*O21+D20*(Parameters!$C$7+($B21-1)*Parameters!$C$33)*(O21+P21)/2+E20*(Parameters!$C$8+($B21-1)*Parameters!$C$34)*(O21+Q21)/2 -> 1.0222958e+08 | T21: =C20*(Parameters!$D$6+($B21-1)*Parameters!$D$32)*(O21+P21)/2+D20*(Parameters!$D$7+($B21-1)*Parameters!$D$33)*P21+E20*(Parameters!$D$8+($B21-1)*Parameters!$D$34)*(P21+Q21)/2 -> 1.1087137e+08 | U21: =C20*(Parameters!$E$6+($B21-1)*Parameters!$E$32)*(O21+Q21)/2+D20*(Parameters!$E$7+($B21-1)*Parameters!$E$33)*(P21+Q21)/2+E20*(Parameters!$E$8+($B21-1)*Parameters!$E$34)*Q21 -> 3.3816597e+08 | V21: =C20*(Parameters!$F$6+($B21-1)*Parameters!$F$32)*(O21/2+R21)+D20*(Parameters!$F$7+($B21-1)*Parameters!$F$33)*(P21/2+R21)+E20*(Parameters!$F$8+($B21-1)*Parameters!$F$34)*(Q21/2+R21) -> 85214649 | W21: =S21+T21+U21+V21 -> 6.3648157e+08 | X21: =X20/(1+Parameters!$B$26) -> 0.73069021 | Y21: =W21*X21 -> 4.6507085e+08 | Z21: =Y21/G20 -> 564.87701
