Workbook

Sheet Prices
A1: Date | B1: Tech | C1: Banking | D1: Mining | E1: Energy | F1: Insurance
A2: 43891 | B2: 1671.73 | C2: 40.610001 | D2: 58.360001 | E2: 62.32 | F2: 432
A3: 43894 | B3: 1696.17 | C3: 40.68 | D3: 58.66 | E3: 62.290001 | F3: 434.5
A4: 43895 | B4: 1692.4301 | C4: 41 | D4: 58.919998 | E4: 62.380001 | F4: 438.79999
A5: 43896 | B5: 1668.95 | C5: 40.970001 | D5: 59.189999 | E5: 62.389999 | F5: 433.29999
A6: 43897 | B6: 1625.95 | C6: 40.869999 | D6: 54.740002 | E6: 61.57 | F6: 419
A7: 43898 | B7: 1620.8 | C7: 40.869999 | D7: 54.66 | E7: 60.799999 | F7: 414.89999
A8: 43901 | B8: 1670.62 | C8: 41.009998 | D8: 55.279999 | E8: 61.23 | F8: 421.70001
A9: 43902 | B9: 1673.1 | C9: 41.07 | D9: 55.32 | E9: 61.34 | F9: 420
A10: 43903 | B10: 1690.8101 | C10: 41.119999 | D10: 56.029999 | E10: 62.990002 | F10: 419.79999
A11: 43904 | B11: 1686.22 | C11: 41.139999 | D11: 56 | E11: 63.049999 | F11: 425.60001
A12: 43905 | B12: 1712.36 | C12: 41.41 | D12: 55.98 | E12: 63.290001 | F12: 433.89999
A13: 43908 | B13: 1742.15 | C13: 41.529999 | D13: 56.990002 | E13: 64.089996 | F13: 436
... A465: 44560 | B465: 3285.8501 | C465: 25.940001 | D465: 75.989998 | E465: 36.029999 | F465: 328

Sheet Data Checks
A1: Data Checks
G2: Index at 100 | L2: Daily Change
A3: Date | B3: Tech | C3: Banking | D3: Mining | E3: Energy | F3: Insurance | G3: Tech | H3: Banking | I3: Mining | J3: Energy | K3: Insurance | L3: Tech | M3: Banking | N3: Mining | O3: Energy | P3: Insurance
A4: =Prices!A2 -> 43891 | B4: =Prices!B2 -> 1671.73 | C4: =Prices!C2 -> 40.610001 | D4: =Prices!D2 -> 58.360001 | E4: =Prices!E2 -> 62.32 | F4: =Prices!F2 -> 432 | G4: 100 | H4: 100 | I4: 100 | J4: 100 | K4: 100 | L4: 0 | M4: 0 | N4: 0 | O4: 0 | P4: 0 | U4: Statistics (all data)
A5: =Prices!A3 -> 43894 | B5: =Prices!B3 -> 1696.17 | C5: =Prices!C3 -> 40.68 | D5: =Prices!D3 -> 58.66 | E5: =Prices!E3 -> 62.290001 | F5: =Prices!F3 -> 434.5 | G5: =G4*B5/B4 -> 101.46196 | H5: =H4*C5/C4 -> 100.17237 | I5: =I4*D5/D4 -> 100.51405 | J5: =J4*E5/E4 -> 99.951863 | K5: =K4*F5/F4 -> 100.5787 | L5: =B5/B4-1 -> 0.014619624 | M5: =C5/C4-1 -> 0.0017236887 | N5: =D5/D4-1 -> 0.00514049 | O5: =E5/E4-1 -> -0.00048137035 | P5: =F5/F4-1 -> 0.005787037 | V5: Tech | W5: Banking | X5: Mining | Y5: Energy | Z5: Insurance | AA5: All
A6: =Prices!A4 -> 43895 | B6: =Prices!B4 -> 1692.4301 | C6: =Prices!C4 -> 41 | D6: =Prices!D4 -> 58.919998 | E6: =Prices!E4 -> 62.380001 | F6: =Prices!F4 -> 438.79999 | G6: =G5*B6/B5 -> 101.23824 | H6: =H5*C6/C5 -> 100.96035 | I6: =I5*D6/D5 -> 100.95956 | J6: =J5*E6/E5 -> 100.09628 | K6: =K5*F6/F5 -> 101.57407 | L6: =B6/B5-1 -> -0.0022049617 | M6: =C6/C5-1 -> 0.0078662734 | N6: =D6/D5-1 -> 0.0044322878 | O6: =E6/E5-1 -> 0.0014448547 | P6: =F6/F5-1 -> 0.0098964051 | U6: Average | V6: =AVERAGE(L5:L467) -> 0.0016576435 | W6: =AVERAGE(M5:M467) -> -0.00076085988 | X6: =AVERAGE(N5:N467) -> 0.00083631482 | Y6: =AVERAGE(O5:O467) -> -0.00071286181 | Z6: =AVERAGE(P5:P467) -> -0.00030738652 | AA6: =AVERAGE(L5:P467) -> 0.00014257002
A7: =Prices!A5 -> 43896 | B7: =Prices!B5 -> 1668.95 | C7: =Prices!C5 -> 40.970001 | D7: =Prices!D5 -> 59.189999 | E7: =Prices!E5 -> 62.389999 | F7: =Prices!F5 -> 433.29999 | G7: =G6*B7/B6 -> 99.833703 | H7: =H6*C7/C6 -> 100.88648 | I7: =I6*D7/D6 -> 101.4222 | J7: =J6*E7/E6 -> 100.11232 | K7: =K6*F7/F6 -> 100.30092 | L7: =B7/B6-1 -> -0.013873603 | M7: =C7/C6-1 -> -0.00073168293 | N7: =D7/D6-1 -> 0.0045825019 | O7: =E7/E6-1 -> 0.00016027573 | P7: =F7/F6-1 -> -0.012534184 | U7: Standard Deviation | V7: =STDEV(L5:L467) -> 0.019898026 | W7: =STDEV(M5:M467) -> 0.020348004 | X7: =STDEV(N5:N467) -> 0.02315619 | Y7: =STDEV(O5:O467) -> 0.030467019 | Z7: =STDEV(P5:P467) -> 0.023978764 | AA7: =STDEV(L5:P467) -> 0.023870508
A8: =Prices!A6 -> 43897 | B8: =Prices!B6 -> 1625.95 | C8: =Prices!C6 -> 40.869999 | D8: =Prices!D6 -> 54.740002 | E8: =Prices!E6 -> 61.57 | F8: =Prices!F6 -> 419 | G8: =G7*B8/B7 -> 97.261518 | H8: =H7*C8/C7 -> 100.64023 | I8: =I7*D8/D7 -> 93.797123 | J8: =J7*E8/E7 -> 98.796534 | K8: =K7*F8/F7 -> 96.990741 | L8: =B8/B7-1 -> -0.025764703 | M8: =C8/C7-1 -> -0.0024408591 | N8: =D8/D7-1 -> -0.075181569 | O8: =E8/E7-1 -> -0.013143116 | P8: =F8/F7-1 -> -0.033002512 | U8: Max | V8: =MAX(L5:L467) -> 0.079295239 | W8: =MAX(M5:M467) -> 0.10368038 | X8: =MAX(N5:N467) -> 0.15788029 | Y8: =MAX(O5:O467) -> 0.19679467 | Z8: =MAX(P5:P467) -> 0.14976306 | AA8: =MAX(L5:P467) -> 0.19679467
A9: =Prices!A7 -> 43898 | B9: =Prices!B7 -> 1620.8 | C9: =Prices!C7 -> 40.869999 | D9: =Prices!D7 -> 54.66 | E9: =Prices!E7 -> 60.799999 | F9: =Prices!F7 -> 414.89999 | G9: =G8*B9/B8 -> 96.953459 | H9: =H8*C9/C8 -> 100.64023 | I9: =I8*D9/D8 -> 93.66004 | J9: =J8*E9/E8 -> 97.560974 | K9: =K8*F9/F8 -> 96.041665 | L9: =B9/B8-1 -> -0.0031673189 | M9: =C9/C8-1 -> 0 | N9: =D9/D8-1 -> -0.0014614906 | O9: =E9/E8-1 -> -0.012506107 | P9: =F9/F8-1 -> -0.0097852172 | U9: Min | V9: =MIN(L5:L467) -> -0.079220808 | W9: =MIN(M5:M467) -> -0.10246344 | X9: =MIN(N5:N467) -> -0.094237413 | Y9: =MIN(O5:O467) -> -0.17172198 | Z9: =MIN(P5:P467) -> -0.12540193 | AA9: =MIN(L5:P467) -> -0.17172198
A10: =Prices!A8 -> 43901 | B10: =Prices!B8 -> 1670.62 | C10: =Prices!C8 -> 41.009998 | D10: =Prices!D8 -> 55.279999 | E10: =Prices!E8 -> 61.23 | F10: =Prices!F8 -> 421.70001 | G10: =G9*B10/B9 -> 99.933603 | H10: =H9*C10/C9 -> 100.98497 | I10: =I9*D10/D9 -> 94.722409 | J10: =J9*E10/E9 -> 98.250963 | K10: =K9*F10/F9 -> 97.615744 | L10: =B10/B9-1 -> 0.030737873 | M10: =C10/C9-1 -> 0.0034254711 | N10: =D10/D9-1 -> 0.011342828 | O10: =E10/E9-1 -> 0.007072385 | P10: =F10/F9-1 -> 0.016389535 | U10: Count | V10: =COUNT(L$5:L$467) -> 463 | W10: =COUNT(M$5:M$467) -> 463 | X10: =COUNT(N$5:N$467) -> 463 | Y10: =COUNT(O$5:O$467) -> 463 | Z10: =COUNT(P$5:P$467) -> 463 | AA10: =COUNT(L$5:P$467) -> 2315
A11: =Prices!A9 -> 43902 | B11: =Prices!B9 -> 1673.1 | C11: =Prices!C9 -> 41.07 | D11: =Prices!D9 -> 55.32 | E11: =Prices!E9 -> 61.34 | F11: =Prices!F9 -> 420 | G11: =G10*B11/B10 -> 100.08195 | H11: =H10*C11/C10 -> 101.13272 | I11: =I10*D11/D10 -> 94.790951 | J11: =J10*E11/E10 -> 98.427471 | K11: =K10*F11/F10 -> 97.222222 | L11: =B11/B10-1 -> 0.0014844674 | M11: =C11/C10-1 -> 0.0014631066 | N11: =D11/D10-1 -> 0.0007236071 | O11: =E11/E10-1 -> 0.001796505 | P11: =F11/F10-1 -> -0.0040313302
A12: =Prices!A10 -> 43903 | B12: =Prices!B10 -> 1690.8101 | C12: =Prices!C10 -> 41.119999 | D12: =Prices!D10 -> 56.029999 | E12: =Prices!E10 -> 62.990002 | F12: =Prices!F10 -> 419.79999 | G12: =G11*B12/B11 -> 101.14134 | H12: =H11*C12/C11 -> 101.25584 | I12: =I11*D12/D11 -> 96.007536 | J12: =J11*E12/E11 -> 101.0751 | K12: =K11*F12/F11 -> 97.175923 | L12: =B12/B11-1 -> 0.010585191 | M12: =C12/C11-1 -> 0.0012174093 | N12: =D12/D11-1 -> 0.0128344 | O12: =E12/E11-1 -> 0.026899283 | P12: =F12/F11-1 -> -0.00047621905 | U12: Statistics (2021 only)
A13: =Prices!A11 -> 43904 | B13: =Prices!B11 -> 1686.22 | C13: =Prices!C11 -> 41.139999 | D13: =Prices!D11 -> 56 | E13: =Prices!E11 -> 63.049999 | F13: =Prices!F11 -> 425.60001 | G13: =G12*B13/B12 -> 100.86677 | H13: =H12*C13/C12 -> 101.30509 | I13: =I12*D13/D12 -> 95.956133 | J13: =J12*E13/E12 -> 101.17137 | K13: =K12*F13/F12 -> 98.51852 | L13: =B13/B12-1 -> -0.0027147272 | M13: =C13/C12-1 -> 0.00048638133 | N13: =D13/D12-1 -> -0.00053540961 | O13: =E13/E12-1 -> 0.00095248449 | P13: =F13/F12-1 -> 0.013816146 | U13: Average | V13: =AVERAGE(L216:L467) -> 0.0025799798 | W13: =AVERAGE(M216:M467) -> -0.0012838777 | X13: =AVERAGE(N216:N467) -> 0.0013699428 | Y13: =AVERAGE(O216:O467) -> -0.0011383666 | Z13: =AVERAGE(P216:P467) -> -0.00056497856 | AA13: =AVERAGE(L216:P467) -> 0.00019253997
A14: =Prices!A12 -> 43905 | B14: =Prices!B12 -> 1712.36 | C14: =Prices!C12 -> 41.41 | D14: =Prices!D12 -> 55.98 | E14: =Prices!E12 -> 63.290001 | F14: =Prices!F12 -> 433.89999 | G14: =G13*B14/B13 -> 102.43042 | H14: =H13*C14/C13 -> 101.96996 | I14: =I13*D14/D13 -> 95.921863 | J14: =J13*E14/E13 -> 101.55648 | K14: =K13*F14/F13 -> 100.43981 | L14: =B14/B13-1 -> 0.015502138 | M14: =C14/C13-1 -> 0.0065629802 | N14: =D14/D13-1 -> -0.00035714286 | O14: =E14/E13-1 -> 0.0038065346 | P14: =F14/F13-1 -> 0.019501851 | U14: Standard Deviation | V14: =_xlfn.STDEV.P(L216:L467) -> 0.024250709 | W14: =_xlfn.STDEV.P(M216:M467) -> 0.026153321 | X14: =_xlfn.STDEV.P(N216:N467) -> 0.028036105 | Y14: =_xlfn.STDEV.P(O216:O467) -> 0.040100514 | Z14: =_xlfn.STDEV.P(P216:P467) -> 0.029959572 | AA14: =STDEV(L216:P467) -> 0.03026215
A15: =Prices!A13 -> 43908 | B15: =Prices!B13 -> 1742.15 | C15: =Prices!C13 -> 41.529999 | D15: =Prices!D13 -> 56.990002 | E15: =Prices!E13 -> 64.089996 | F15: =Prices!F13 -> 436 | G15: =G14*B15/B14 -> 104.21241 | H15: =H14*C15/C14 -> 102.26545 | I15: =I14*D15/D14 -> 97.652503 | J15: =J14*E15/E14 -> 102.84017 | K15: =K14*F15/F14 -> 100.92593 | L15: =B15/B14-1 -> 0.017397066 | M15: =C15/C14-1 -> 0.0028978266 | N15: =D15/D14-1 -> 0.018042194 | O15: =E15/E14-1 -> 0.012640148 | P15: =F15/F14-1 -> 0.0048398387 | U15: Max | V15: =MAX(L216:L467) -> 0.079295239 | W15: =MAX(M216:M467) -> 0.10368038 | X15: =MAX(N216:N467) -> 0.15788029 | Y15: =MAX(O216:O467) -> 0.19679467 | Z15: =MAX(P216:P467) -> 0.14976306 | AA15: =MAX(L216:P467) -> 0.19679467
A16: =Prices!A14 -> 43909 | B16: =Prices!B14 -> 1761.85 | C16: =Prices!C14 -> 41.380001 | D16: =Prices!D14 -> 56.52 | E16: =Prices!E14 -> 63.950001 | F16: =Prices!F14 -> 434.29999 | G16: =G15*B16/B15 -> 105.39082 | H16: =H15*C16/C15 -> 101.89608 | I16: =I15*D16/D15 -> 96.847154 | J16: =J15*E16/E15 -> 102.61553 | K16: =K15*F16/F15 -> 100.5324 | L16: =B16/B15-1 -> 0.011307839 | M16: =C16/C15-1 -> -0.0036117988 | N16: =D16/D15-1 -> -0.0082470957 | O16: =E16/E15-1 -> -0.0021843503 | P16: =F16/F15-1 -> -0.0038991101 | U16: Min | V16: =MIN(L216:L467) -> -0.079220808 | W16: =MIN(M216:M467) -> -0.10246344 | X16: =MIN(N216:N467) -> -0.094237413 | Y16: =MIN(O216:O467) -> -0.17172198 | Z16: =MIN(P216:P467) -> -0.12540193 | AA16: =MIN(L216:P467) -> -0.17172198
A17: =Prices!A15 -> 43910 | B17: =Prices!B15 -> 1797.27 | C17: =Prices!C15 -> 41.209999 | D17: =Prices!D15 -> 56.650002 | E17: =Prices!E15 -> 64.480003 | F17: =Prices!F15 -> 427.60001 | G17: =G16*B17/B16 -> 107.50959 | H17: =H16*C17/C16 -> 101.47746 | I17: =I16*D17/D16 -> 97.069913 | J17: =J16*E17/E16 -> 103.46599 | K17: =K16*F17/F16 -> 98.981483 | L17: =B17/B16-1 -> 0.020103893 | M17: =C17/C16-1 -> -0.0041083131 | N17: =D17/D16-1 -> 0.0023001062 | O17: =E17/E16-1 -> 0.0082877559 | P17: =F17/F16-1 -> -0.015427083 | U17: Count | V17: =COUNT(L$216:L$467) -> 252 | W17: =COUNT(M$216:M$467) -> 252 | X17: =COUNT(N$216:N$467) -> 252 | Y17: =COUNT(O$216:O$467) -> 252 | Z17: =COUNT(P$216:P$467) -> 252 | AA17: =COUNT(L$216:P$467) -> 1260
A18: =Prices!A16 -> 43911 | B18: =Prices!B16 -> 1819.26 | C18: =Prices!C16 -> 41.07 | D18: =Prices!D16 -> 56.830002 | E18: =Prices!E16 -> 64.080002 | F18: =Prices!F16 -> 424.5 | G18: =G17*B18/B17 -> 108.82499 | H18: =H17*C18/C17 -> 101.13272 | I18: =I17*D18/D17 -> 97.378343 | J18: =J17*E18/E17 -> 102.82414 | K18: =K17*F18/F17 -> 98.263889 | L18: =B18/B17-1 -> 0.012235218 | M18: =C18/C17-1 -> -0.0033972095 | N18: =D18/D17-1 -> 0.003177405 | O18: =E18/E17-1 -> -0.0062034892 | P18: =F18/F17-1 -> -0.0072497801
A19: =Prices!A17 -> 43912 | B19: =Prices!B17 -> 1764.77 | C19: =Prices!C17 -> 40.419998 | D19: =Prices!D17 -> 56.139999 | E19: =Prices!E17 -> 62.880001 | F19: =Prices!F17 -> 409.89999 | G19: =G18*B19/B18 -> 105.56549 | H19: =H18*C19/C18 -> 99.532128 | I19: =I18*D19/D18 -> 96.196021 | J19: =J18*E19/E18 -> 100.89859 | K19: =K18*F19/F18 -> 94.884258 | L19: =B19/B18-1 -> -0.029951733 | M19: =C19/C18-1 -> -0.015826686 | N19: =D19/D18-1 -> -0.012141527 | O19: =E19/E18-1 -> -0.018726607 | P19: =F19/F18-1 -> -0.034393418 | U19: Check average return vs final index value: | AC19: Looks roughly normally distributed
A20: =Prices!A18 -> 43915 | B20: =Prices!B18 -> 1774.26 | C20: =Prices!C18 -> 40.43 | D20: =Prices!D18 -> 56.950001 | E20: =Prices!E18 -> 62.790001 | F20: =Prices!F18 -> 409 | G20: =G19*B20/B19 -> 106.13317 | H20: =H19*C20/C19 -> 99.556757 | I20: =I19*D20/D19 -> 97.583962 | J20: =J19*E20/E19 -> 100.75417 | K20: =K19*F20/F19 -> 94.675926 | L20: =B20/B19-1 -> 0.0053774656 | M20: =C20/C19-1 -> 0.00024745177 | N20: =D20/D19-1 -> 0.014428251 | O20: =E20/E19-1 -> -0.0014312977 | P20: =F20/F19-1 -> -0.0021956429 | U20: Ave>0 => index > 100 | V20: =IF(V6>0,IF(G467>100,"OK","Not OK"),IF(G467<100,"OK","Not OK")) -> OK | W20: =IF(W6>0,IF(H467>100,"OK","Not OK"),IF(H467<100,"OK","Not OK")) -> OK | X20: =IF(X6>0,IF(I467>100,"OK","Not OK"),IF(I467<100,"OK","Not OK")) -> OK | Y20: =IF(Y6>0,IF(J467>100,"OK","Not OK"),IF(J467<100,"OK","Not OK")) -> OK | Z20: =IF(Z6>0,IF(K467>100,"OK","Not OK"),IF(K467<100,"OK","Not OK")) -> OK | AC20: But quite a few outliers, and perhaps a little high in the middle.
A21: =Prices!A19 -> 43916 | B21: =Prices!B19 -> 1783.76 | C21: =Prices!C19 -> 40.580002 | D21: =Prices!D19 -> 57.790001 | E21: =Prices!E19 -> 63.200001 | F21: =Prices!F19 -> 405 | G21: =G20*B21/B20 -> 106.70144 | H21: =H20*C21/C20 -> 99.926129 | I21: =I20*D21/D20 -> 99.023304 | J21: =J20*E21/E20 -> 101.41207 | K21: =K20*F21/F20 -> 93.75 | L21: =B21/B20-1 -> 0.0053543449 | M21: =C21/C20-1 -> 0.0037101657 | N21: =D21/D20-1 -> 0.01474978 | O21: =E21/E20-1 -> 0.0065297021 | P21: =F21/F20-1 -> -0.0097799511 | U21: (reverse is also checked)
A22: =Prices!A20 -> 43917 | B22: =Prices!B20 -> 1765.7 | C22: =Prices!C20 -> 40.650002 | D22: =Prices!D20 -> 57.66 | E22: =Prices!E20 -> 62.580002 | F22: =Prices!F20 -> 410.89999 | G22: =G21*B22/B21 -> 105.62112 | H22: =H21*C22/C21 -> 100.0985 | I22: =I21*D22/D21 -> 98.800547 | J22: =J21*E22/E21 -> 100.4172 | K22: =K21*F22/F21 -> 95.115739 | L22: =B22/B21-1 -> -0.010124713 | M22: =C22/C21-1 -> 0.0017249876 | N22: =D22/D21-1 -> -0.0022495414 | O22: =E22/E21-1 -> -0.0098101106 | P22: =F22/F21-1 -> 0.014567886
A23: =Prices!A21 -> 43918 | B23: =Prices!B21 -> 1773.42 | C23: =Prices!C21 -> 40.509998 | D23: =Prices!D21 -> 58.02 | E23: =Prices!E21 -> 62.639999 | F23: =Prices!F21 -> 407.10001 | G23: =G22*B23/B22 -> 106.08292 | H23: =H22*C23/C22 -> 99.753748 | I23: =I22*D23/D22 -> 99.417407 | J23: =J22*E23/E22 -> 100.51348 | K23: =K22*F23/F22 -> 94.236113 | L23: =B23/B22-1 -> 0.0043722565 | M23: =C23/C22-1 -> -0.0034441327 | N23: =D23/D22-1 -> 0.0062434964 | O23: =E23/E22-1 -> 0.0009587248 | P23: =F23/F22-1 -> -0.0092479631 | AB23: Chi-Squared test:
A24: =Prices!A22 -> 43919 | B24: =Prices!B22 -> 1780.75 | C24: =Prices!C22 -> 40.580002 | D24: =Prices!D22 -> 58.849998 | E24: =Prices!E22 -> 62.59 | F24: =Prices!F22 -> 412.39999 | G24: =G23*B24/B23 -> 106.52139 | H24: =H23*C24/C23 -> 99.926129 | I24: =I23*D24/D23 -> 100.83961 | J24: =J23*E24/E23 -> 100.43325 | K24: =K23*F24/F23 -> 95.462962 | L24: =B24/B23-1 -> 0.0041332317 | M24: =C24/C23-1 -> 0.0017280672 | N24: =D24/D23-1 -> 0.014305377 | O24: =E24/E23-1 -> -0.00079819605 | P24: =F24/F23-1 -> 0.013018885
A25: =Prices!A23 -> 43922 | B25: =Prices!B23 -> 1814.1899 | C25: =Prices!C23 -> 41.759998 | D25: =Prices!D23 -> 59.849998 | E25: =Prices!E23 -> 63.279999 | F25: =Prices!F23 -> 416.39999 | G25: =G24*B25/B24 -> 108.52171 | H25: =H24*C25/C24 -> 102.83181 | I25: =I24*D25/D24 -> 102.55311 | J25: =J24*E25/E24 -> 101.54043 | K25: =K24*F25/F24 -> 96.388888 | L25: =B25/B24-1 -> 0.018778571 | M25: =C25/C24-1 -> 0.029078264 | N25: =D25/D24-1 -> 0.016992354 | O25: =E25/E24-1 -> 0.011024109 | P25: =F25/F24-1 -> 0.0096993212 | AB25: First method - using equally spaced probability bands
A26: =Prices!A24 -> 43923 | B26: =Prices!B24 -> 1813.98 | C26: =Prices!C24 -> 42.150002 | D26: =Prices!D24 -> 60.98 | E26: =Prices!E24 -> 63.509998 | F26: =Prices!F24 -> 422.39999 | G26: =G25*B26/B25 -> 108.50915 | H26: =H25*C26/C25 -> 103.79217 | I26: =I25*D26/D25 -> 104.48937 | J26: =J25*E26/E25 -> 101.9095 | K26: =K25*F26/F25 -> 97.777776 | L26: =B26/B25-1 -> -0.00011573264 | M26: =C26/C25-1 -> 0.0093391767 | N26: =D26/D25-1 -> 0.018880569 | O26: =E26/E25-1 -> 0.003634624 | P26: =F26/F25-1 -> 0.014409222
A27: =Prices!A25 -> 43924 | B27: =Prices!B25 -> 1820.7 | C27: =Prices!C25 -> 42.549999 | D27: =Prices!D25 -> 61.02 | E27: =Prices!E25 -> 63.82 | F27: =Prices!F25 -> 428.60001 | G27: =G26*B27/B26 -> 108.91113 | H27: =H26*C27/C26 -> 104.77714 | I27: =I26*D27/D26 -> 104.55791 | J27: =J26*E27/E26 -> 102.40693 | K27: =K26*F27/F26 -> 99.212964 | L27: =B27/B26-1 -> 0.0037045453 | M27: =C27/C26-1 -> 0.0094898453 | N27: =D27/D26-1 -> 0.00065595277 | O27: =E27/E26-1 -> 0.0048811527 | P27: =F27/F26-1 -> 0.014678059 | AB27: Band | AC27: From | AD27: To | AE27: Actual | AF27: Expected
A28: =Prices!A26 -> 43925 | B28: =Prices!B26 -> 1818.86 | C28: =Prices!C26 -> 42.299999 | D28: =Prices!D26 -> 61.040001 | E28: =Prices!E26 -> 63.970001 | F28: =Prices!F26 -> 429.10001 | G28: =G27*B28/B27 -> 108.80106 | H28: =H27*C28/C27 -> 104.16153 | I28: =I27*D28/D27 -> 104.59219 | J28: =J27*E28/E27 -> 102.64763 | K28: =K27*F28/F27 -> 99.328705 | L28: =B28/B27-1 -> -0.0010105817 | M28: =C28/C27-1 -> -0.0058754408 | N28: =D28/D27-1 -> 0.00032777778 | O28: =E28/E27-1 -> 0.0023503761 | P28: =F28/F27-1 -> 0.0011665889 | AB28: 1 | AC28: =PERCENTILE($L$5:$P$467,(AB28-1)/10) -> -0.17172198 | AD28: =PERCENTILE($L$5:$P$467,AB28/10) -> -0.023126486 | AE28: =COUNTIFS($L$5:$P$467,">="&AC28,$L$5:$P$467,"<"&AD28) -> 232 | AF28: =$AA$10*_xlfn.NORM.DIST(AD28,$AA$6,$AA$7,TRUE) -> 381.5788
A29: =Prices!A27 -> 43926 | B29: =Prices!B27 -> 1837.28 | C29: =Prices!C27 -> 42.48 | D29: =Prices!D27 -> 61.07 | E29: =Prices!E27 -> 64.519997 | F29: =Prices!F27 -> 430.5 | G29: =G28*B29/B28 -> 109.90292 | H29: =H28*C29/C28 -> 104.60477 | I29: =I28*D29/D28 -> 104.64359 | J29: =J28*E29/E28 -> 103.53016 | K29: =K28*F29/F28 -> 99.652778 | L29: =B29/B28-1 -> 0.010127247 | M29: =C29/C28-1 -> 0.0042553429 | N29: =D29/D28-1 -> 0.00049146461 | O29: =E29/E28-1 -> 0.0085977175 | P29: =F29/F28-1 -> 0.0032626287 | AB29: 2 | AC29: =PERCENTILE($L$5:$P$467,(AB29-1)/10) -> -0.023126486 | AD29: =PERCENTILE($L$5:$P$467,AB29/10) -> -0.012695051 | AE29: =COUNTIFS($L$5:$P$467,">="&AC29,$L$5:$P$467,"<"&AD29) -> 231 | AF29: =$AA$10*_xlfn.NORM.DIST(AD29,$AA$6,$AA$7,TRUE)-SUM($AF$28:AF28) -> 302.17191
A30: =Prices!A28 -> 43929 | B30: =Prices!B28 -> 1849.86 | C30: =Prices!C28 -> 42.560001 | D30: =Prices!D28 -> 62.360001 | E30: =Prices!E28 -> 65.300003 | F30: =Prices!F28 -> 429.60001 | G30: =G29*B30/B29 -> 110.65543 | H30: =H29*C30/C29 -> 104.80177 | I30: =I29*D30/D29 -> 106.85401 | J30: =J29*E30/E29 -> 104.78178 | K30: =K29*F30/F29 -> 99.444446 | L30: =B30/B29-1 -> 0.0068470542 | M30: =C30/C29-1 -> 0.0018832627 | N30: =D30/D29-1 -> 0.021123318 | O30: =E30/E29-1 -> 0.012089368 | P30: =F30/F29-1 -> -0.0020905784 | AB30: 3 | AC30: =PERCENTILE($L$5:$P$467,(AB30-1)/10) -> -0.012695051 | AD30: =PERCENTILE($L$5:$P$467,AB30/10) -> -0.0066225425 | AE30: =COUNTIFS($L$5:$P$467,">="&AC30,$L$5:$P$467,"<"&AD30) -> 232 | AF30: =$AA$10*_xlfn.NORM.DIST(AD30,$AA$6,$AA$7,TRUE)-SUM($AF$28:AF29) -> 215.46876
A31: =Prices!A29 -> 43930 | B31: =Prices!B29 -> 1835.84 | C31: =Prices!C29 -> 42.630001 | D31: =Prices!D29 -> 61.889999 | E31: =Prices!E29 -> 64.57 | F31: =Prices!F29 -> 431.70001 | G31: =G30*B31/B30 -> 109.81678 | H31: =H30*C31/C30 -> 104.97414 | I31: =I30*D31/D30 -> 106.04866 | J31: =J30*E31/E30 -> 103.6104 | K31: =K30*F31/F30 -> 99.930558 | L31: =B31/B30-1 -> -0.0075789623 | M31: =C31/C30-1 -> 0.0016447368 | N31: =D31/D30-1 -> -0.0075369146 | O31: =E31/E30-1 -> -0.011179218 | P31: =F31/F30-1 -> 0.0048882821 | AB31: 4 | AC31: =PERCENTILE($L$5:$P$467,(AB31-1)/10) -> -0.0066225425 | AD31: =PERCENTILE($L$5:$P$467,AB31/10) -> -0.0028187969 | AE31: =COUNTIFS($L$5:$P$467,">="&AC31,$L$5:$P$467,"<"&AD31) -> 231 | AF31: =$AA$10*_xlfn.NORM.DIST(AD31,$AA$6,$AA$7,TRUE)-SUM($AF$28:AF30) -> 143.9983
A32: =Prices!A30 -> 43931 | B32: =Prices!B30 -> 1847.33 | C32: =Prices!C30 -> 42.540001 | D32: =Prices!D30 -> 62.400002 | E32: =Prices!E30 -> 65.010002 | F32: =Prices!F30 -> 429.89999 | G32: =G31*B32/B31 -> 110.50409 | H32: =H31*C32/C31 -> 104.75252 | I32: =I31*D32/D31 -> 106.92255 | J32: =J31*E32/E31 -> 104.31643 | K32: =K31*F32/F31 -> 99.513888 | L32: =B32/B31-1 -> 0.00625871 | M32: =C32/C31-1 -> -0.0021111893 | N32: =D32/D31-1 -> 0.0082404752 | O32: =E32/E31-1 -> 0.006814341 | P32: =F32/F31-1 -> -0.0041696038 | AB32: 5 | AC32: =PERCENTILE($L$5:$P$467,(AB32-1)/10) -> -0.0028187969 | AD32: =PERCENTILE($L$5:$P$467,AB32/10) -> 0.0003170233 | AE32: =COUNTIFS($L$5:$P$467,">="&AC32,$L$5:$P$467,"<"&AD32) -> 231 | AF32: =$AA$10*_xlfn.NORM.DIST(AD32,$AA$6,$AA$7,TRUE)-SUM($AF$28:AF31) -> 121.03179
A33: =Prices!A31 -> 43932 | B33: =Prices!B31 -> 1844.0699 | C33: =Prices!C31 -> 42.59 | D33: =Prices!D31 -> 62.060001 | E33: =Prices!E31 -> 64.919998 | F33: =Prices!F31 -> 416.5 | G33: =G32*B33/B32 -> 110.30908 | H33: =H32*C33/C32 -> 104.87564 | I33: =I32*D33/D32 -> 106.33996 | J33: =J32*E33/E32 -> 104.17201 | K33: =K32*F33/F32 -> 96.412037 | L33: =B33/B32-1 -> -0.0017647145 | M33: =C33/C32-1 -> 0.0011753408 | N33: =D33/D32-1 -> -0.0054487338 | O33: =E33/E32-1 -> -0.0013844639 | P33: =F33/F32-1 -> -0.031170026 | AB33: 6 | AC33: =PERCENTILE($L$5:$P$467,(AB33-1)/10) -> 0.0003170233 | AD33: =PERCENTILE($L$5:$P$467,AB33/10) -> 0.003636134 | AE33: =COUNTIFS($L$5:$P$467,">="&AC33,$L$5:$P$467,"<"&AD33) -> 232 | AF33: =$AA$10*_xlfn.NORM.DIST(AD33,$AA$6,$AA$7,TRUE)-SUM($AF$28:AF32) -> 127.93566
A34: =Prices!A32 -> 43933 | B34: =Prices!B32 -> 1843.0601 | C34: =Prices!C32 -> 43.040001 | D34: =Prices!D32 -> 62.779999 | E34: =Prices!E32 -> 64.5 | F34: =Prices!F32 -> 418 | G34: =G33*B34/B33 -> 110.24867 | H34: =H33*C34/C33 -> 105.98375 | I34: =I33*D34/D33 -> 107.57368 | J34: =J33*E34/E33 -> 103.49807 | K34: =K33*F34/F33 -> 96.759259 | L34: =B34/B33-1 -> -0.00054764029 | M34: =C34/C33-1 -> 0.010565884 | N34: =D34/D33-1 -> 0.011601643 | O34: =E34/E33-1 -> -0.0064694703 | P34: =F34/F33-1 -> 0.0036014406 | AB34: 7 | AC34: =PERCENTILE($L$5:$P$467,(AB34-1)/10) -> 0.003636134 | AD34: =PERCENTILE($L$5:$P$467,AB34/10) -> 0.007619471 | AE34: =COUNTIFS($L$5:$P$467,">="&AC34,$L$5:$P$467,"<"&AD34) -> 231 | AF34: =$AA$10*_xlfn.NORM.DIST(AD34,$AA$6,$AA$7,TRUE)-SUM($AF$28:AF33) -> 149.93503
A35: =Prices!A33 -> 43936 | B35: =Prices!B33 -> 1844.87 | C35: =Prices!C33 -> 42.889999 | D35: =Prices!D33 -> 62.459999 | E35: =Prices!E33 -> 64.580002 | F35: =Prices!F33 -> 418.70001 | G35: =G34*B35/B34 -> 110.35694 | H35: =H34*C35/C34 -> 105.61438 | I35: =I34*D35/D34 -> 107.02536 | J35: =J34*E35/E34 -> 103.62645 | K35: =K34*F35/F34 -> 96.921299 | L35: =B35/B34-1 -> 0.00098202768 | M35: =C35/C34-1 -> -0.0034851765 | N35: =D35/D34-1 -> -0.0050971648 | O35: =E35/E34-1 -> 0.0012403411 | P35: =F35/F34-1 -> 0.0016746699 | AB35: 8 | AC35: =PERCENTILE($L$5:$P$467,(AB35-1)/10) -> 0.007619471 | AD35: =PERCENTILE($L$5:$P$467,AB35/10) -> 0.012699513 | AE35: =COUNTIFS($L$5:$P$467,">="&AC35,$L$5:$P$467,"<"&AD35) -> 232 | AF35: =$AA$10*_xlfn.NORM.DIST(AD35,$AA$6,$AA$7,TRUE)-SUM($AF$28:AF34) -> 179.70221
A36: =Prices!A34 -> 43937 | B36: =Prices!B34 -> 1863.04 | C36: =Prices!C34 -> 43.330002 | D36: =Prices!D34 -> 60.34 | E36: =Prices!E34 -> 64.300003 | F36: =Prices!F34 -> 426.29999 | G36: =G35*B36/B35 -> 111.44384 | H36: =H35*C36/C35 -> 106.69786 | I36: =I35*D36/D35 -> 103.39273 | J36: =J35*E36/E35 -> 103.17716 | K36: =K35*F36/F35 -> 98.680553 | L36: =B36/B35-1 -> 0.0098489563 | M36: =C36/C35-1 -> 0.010258872 | N36: =D36/D35-1 -> -0.033941707 | O36: =E36/E35-1 -> -0.004335692 | P36: =F36/F35-1 -> 0.018151363 | AB36: 9 | AC36: =PERCENTILE($L$5:$P$467,(AB36-1)/10) -> 0.012699513 | AD36: =PERCENTILE($L$5:$P$467,AB36/10) -> 0.022913873 | AE36: =COUNTIFS($L$5:$P$467,">="&AC36,$L$5:$P$467,"<"&AD36) -> 231 | AF36: =$AA$10*_xlfn.NORM.DIST(AD36,$AA$6,$AA$7,TRUE)-SUM($AF$28:AF35) -> 299.5022
A37: =Prices!A35 -> 43938 | B37: =Prices!B35 -> 1864.8199 | C37: =Prices!C35 -> 43.459999 | D37: =Prices!D35 -> 60.459999 | E37: =Prices!E35 -> 64.589996 | F37: =Prices!F35 -> 435 | G37: =G36*B37/B36 -> 111.55031 | H37: =H36*C37/C36 -> 107.01797 | I37: =I36*D37/D36 -> 103.59835 | J37: =J36*E37/E36 -> 103.64248 | K37: =K36*F37/F36 -> 100.69444 | L37: =B37/B36-1 -> 0.00095537775 | M37: =C37/C36-1 -> 0.0030001614 | N37: =D37/D36-1 -> 0.001988714 | O37: =E37/E36-1 -> 0.0045099998 | P37: =F37/F36-1 -> 0.020408192 | AB37: 10 | AC37: =PERCENTILE($L$5:$P$467,(AB37-1)/10) -> 0.022913873 | AD37: =PERCENTILE($L$5:$P$467,AB37/10) -> 0.19679467 | AE37: =COUNTIFS($L$5:$P$467,">="&AC37,$L$5:$P$467,"<="&AD37) -> 232 | AF37: =$AA$10*_xlfn.NORM.DIST(AD37,$AA$6,$AA$7,TRUE)-SUM($AF$28:AF36) -> 393.67534
A38: =Prices!A36 -> 43939 | B38: =Prices!B36 -> 1861.6899 | C38: =Prices!C36 -> 43.25 | D38: =Prices!D36 -> 60.77 | E38: =Prices!E36 -> 64.199997 | F38: =Prices!F36 -> 431.60001 | G38: =G37*B38/B37 -> 111.36308 | H38: =H37*C38/C37 -> 106.50086 | I38: =I37*D38/D37 -> 104.12954 | J38: =J37*E38/E37 -> 103.01668 | K38: =K37*F38/F37 -> 99.907409 | L38: =B38/B37-1 -> -0.0016784489 | M38: =C38/C37-1 -> -0.0048320066 | N38: =D38/D37-1 -> 0.0051273736 | O38: =E38/E37-1 -> -0.0060380713 | P38: =F38/F37-1 -> -0.0078160782
A39: =Prices!A37 -> 43943 | B39: =Prices!B37 -> 1887.3101 | C39: =Prices!C37 -> 43.220001 | D39: =Prices!D37 -> 60.869999 | E39: =Prices!E37 -> 65.239998 | F39: =Prices!F37 -> 425.60001 | G39: =G38*B39/B38 -> 112.89563 | H39: =H38*C39/C38 -> 106.42699 | I39: =I38*D39/D38 -> 104.30089 | J39: =J38*E39/E38 -> 104.68549 | K39: =K38*F39/F38 -> 98.51852 | L39: =B39/B38-1 -> 0.013761753 | M39: =C39/C38-1 -> -0.0006936185 | N39: =D39/D38-1 -> 0.0016455323 | O39: =E39/E38-1 -> 0.016199393 | P39: =F39/F38-1 -> -0.013901761 | AC39: Chi squared: | AE39: =_xlfn.CHISQ.TEST(AE28:AE37,AF28:AF37) -> 2.5583455e-92
A40: =Prices!A38 -> 43944 | B40: =Prices!B38 -> 1923.77 | C40: =Prices!C38 -> 43.150002 | D40: =Prices!D38 -> 60.599998 | E40: =Prices!E38 -> 65 | F40: =Prices!F38 -> 422.79999 | G40: =G39*B40/B39 -> 115.0766 | H40: =H39*C40/C39 -> 106.25462 | I40: =I39*D40/D39 -> 103.83824 | J40: =J39*E40/E39 -> 104.30039 | K40: =K39*F40/F39 -> 97.870368 | L40: =B40/B39-1 -> 0.01931848 | M40: =C40/C39-1 -> -0.0016195974 | N40: =D40/D39-1 -> -0.0044356991 | O40: =E40/E39-1 -> -0.0036786942 | P40: =F40/F39-1 -> -0.0065789896 | AC40: Very unlikely to be normal.
...

Sheet Parameters
A1: Parameters
A3: Total notional investment | B3: 1000
A4: Number of stocks | B4: 5
A5: Invesment per stock | B5: =B3/B4 -> 200

Sheet Moving Ave
A1: Moving averages calculations
G2: 50-day rolling average | L2: 200-day rolling average
A3: Date | B3: Tech | C3: Banking | D3: Mining | E3: Energy | F3: Insurance | G3: =B3 -> Tech | H3: =C3 -> Banking | I3: =D3 -> Mining | J3: =E3 -> Energy | K3: =F3 -> Insurance | L3: =G3 -> Tech | M3: =H3 -> Banking | N3: =I3 -> Mining | ... P3: =K3 -> Insurance
A4: =Prices!A2 -> 43891 | B4: =Prices!B2 -> 1671.73 | C4: =Prices!C2 -> 40.610001 | D4: =Prices!D2 -> 58.360001 | E4: =Prices!E2 -> 62.32 | F4: =Prices!F2 -> 432 | H4: Formulas start on 02/01/2021
A5: =Prices!A3 -> 43894 | B5: =Prices!B3 -> 1696.17 | C5: =Prices!C3 -> 40.68 | D5: =Prices!D3 -> 58.66 | E5: =Prices!E3 -> 62.290001 | F5: =Prices!F3 -> 434.5
A6: =Prices!A4 -> 43895 | B6: =Prices!B4 -> 1692.4301 | C6: =Prices!C4 -> 41 | D6: =Prices!D4 -> 58.919998 | E6: =Prices!E4 -> 62.380001 | F6: =Prices!F4 -> 438.79999
A7: =Prices!A5 -> 43896 | B7: =Prices!B5 -> 1668.95 | C7: =Prices!C5 -> 40.970001 | D7: =Prices!D5 -> 59.189999 | E7: =Prices!E5 -> 62.389999 | F7: =Prices!F5 -> 433.29999
A8: =Prices!A6 -> 43897 | B8: =Prices!B6 -> 1625.95 | C8: =Prices!C6 -> 40.869999 | D8: =Prices!D6 -> 54.740002 | E8: =Prices!E6 -> 61.57 | F8: =Prices!F6 -> 419
A9: =Prices!A7 -> 43898 | B9: =Prices!B7 -> 1620.8 | C9: =Prices!C7 -> 40.869999 | D9: =Prices!D7 -> 54.66 | E9: =Prices!E7 -> 60.799999 | F9: =Prices!F7 -> 414.89999
A10: =Prices!A8 -> 43901 | B10: =Prices!B8 -> 1670.62 | C10: =Prices!C8 -> 41.009998 | D10: =Prices!D8 -> 55.279999 | E10: =Prices!E8 -> 61.23 | F10: =Prices!F8 -> 421.70001
A11: =Prices!A9 -> 43902 | B11: =Prices!B9 -> 1673.1 | C11: =Prices!C9 -> 41.07 | D11: =Prices!D9 -> 55.32 | E11: =Prices!E9 -> 61.34 | F11: =Prices!F9 -> 420
A12: =Prices!A10 -> 43903 | B12: =Prices!B10 -> 1690.8101 | C12: =Prices!C10 -> 41.119999 | D12: =Prices!D10 -> 56.029999 | E12: =Prices!E10 -> 62.990002 | F12: =Prices!F10 -> 419.79999
A13: =Prices!A11 -> 43904 | B13: =Prices!B11 -> 1686.22 | C13: =Prices!C11 -> 41.139999 | D13: =Prices!D11 -> 56 | E13: =Prices!E11 -> 63.049999 | F13: =Prices!F11 -> 425.60001
A14: =Prices!A12 -> 43905 | B14: =Prices!B12 -> 1712.36 | C14: =Prices!C12 -> 41.41 | D14: =Prices!D12 -> 55.98 | E14: =Prices!E12 -> 63.290001 | F14: =Prices!F12 -> 433.89999
A15: =Prices!A13 -> 43908 | B15: =Prices!B13 -> 1742.15 | C15: =Prices!C13 -> 41.529999 | D15: =Prices!D13 -> 56.990002 | E15: =Prices!E13 -> 64.089996 | F15: =Prices!F13 -> 436
A16: =Prices!A14 -> 43909 | B16: =Prices!B14 -> 1761.85 | C16: =Prices!C14 -> 41.380001 | D16: =Prices!D14 -> 56.52 | E16: =Prices!E14 -> 63.950001 | F16: =Prices!F14 -> 434.29999
... A215: =Prices!A213 -> 44196 | B215: =Prices!B213 -> 1847.84 | C215: =Prices!C213 -> 39.09 | D215: =Prices!D213 -> 59.360001 | E215: =Prices!E213 -> 58.98 | F215: =Prices!F213 -> 423.60001
A216: =Prices!A214 -> 44198 | B216: =Prices!B214 -> 1898.01 | C216: =Prices!C214 -> 39.369999 | D216: =Prices!D214 -> 59.889999 | E216: =Prices!E214 -> 59.740002 | F216: =Prices!F214 -> 419.39999 | G216: =AVERAGE(B166:B215) -> 1778.7844 | H216: =AVERAGE(C166:C215) -> 37.972 | I216: =AVERAGE(D166:D215) -> 55.2592 | J216: =AVERAGE(E166:E215) -> 58.6786 | K216: =AVERAGE(F166:F215) -> 416.09 | L216: =AVERAGE(B16:B215) -> 1826.8595 | M216: =AVERAGE(C16:C215) -> 39.64655 | N216: =AVERAGE(D16:D215) -> 56.17445 | O216: =AVERAGE(E16:E215) -> 60.66765 | P216: =AVERAGE(F16:F215) -> 407.4455
A217: =Prices!A215 -> 44199 | B217: =Prices!B215 -> 1874.97 | C217: =Prices!C215 -> 38.759998 | D217: =Prices!D215 -> 58.84 | E217: =Prices!E215 -> 60.209999 | F217: =Prices!F215 -> 414 | G217: =AVERAGE(B167:B216) -> 1781.0314 | H217: =AVERAGE(C167:C216) -> 37.9764 | I217: =AVERAGE(D167:D216) -> 55.4194 | J217: =AVERAGE(E167:E216) -> 58.7078 | K217: =AVERAGE(F167:F216) -> 416.106 | L217: =AVERAGE(B17:B216) -> 1827.5403 | M217: =AVERAGE(C17:C216) -> 39.6365 | N217: =AVERAGE(D17:D216) -> 56.1913 | O217: =AVERAGE(E17:E216) -> 60.6466 | P217: =AVERAGE(F17:F216) -> 407.371
A218: =Prices!A216 -> 44202 | B218: =Prices!B216 -> 1902.88 | C218: =Prices!C216 -> 38.630001 | D218: =Prices!D216 -> 58.450001 | E218: =Prices!E216 -> 60.959999 | F218: =Prices!F216 -> 417.39999 | G218: =AVERAGE(B168:B217) -> 1783.2162 | H218: =AVERAGE(C168:C217) -> 37.9674 | I218: =AVERAGE(D168:D217) -> 55.5522 | J218: =AVERAGE(E168:E217) -> 58.7332 | K218: =AVERAGE(F168:F217) -> 415.956 | L218: =AVERAGE(B18:B217) -> 1827.9288 | M218: =AVERAGE(C18:C217) -> 39.62425 | N218: =AVERAGE(D18:D217) -> 56.20225 | O218: =AVERAGE(E18:E217) -> 60.62525 | P218: =AVERAGE(F18:F217) -> 407.303
A219: =Prices!A217 -> 44203 | B219: =Prices!B217 -> 1906.86 | C219: =Prices!C217 -> 38.34 | D219: =Prices!D217 -> 58.389999 | E219: =Prices!E217 -> 60.400002 | F219: =Prices!F217 -> 416.10001 | G219: =AVERAGE(B169:B218) -> 1786.0304 | H219: =AVERAGE(C169:C218) -> 37.9528 | I219: =AVERAGE(D169:D218) -> 55.6786 | J219: =AVERAGE(E169:E218) -> 58.7602 | K219: =AVERAGE(F169:F218) -> 415.818 | L219: =AVERAGE(B19:B218) -> 1828.3469 | M219: =AVERAGE(C19:C218) -> 39.61205 | N219: =AVERAGE(D19:D218) -> 56.21035 | O219: =AVERAGE(E19:E218) -> 60.60965 | P219: =AVERAGE(F19:F218) -> 407.2675
A220: =Prices!A218 -> 44204 | B220: =Prices!B218 -> 1891.97 | C220: =Prices!C218 -> 38.25 | D220: =Prices!D218 -> 58.900002 | E220: =Prices!E218 -> 59.689999 | F220: =Prices!F218 -> 417.70001 | G220: =AVERAGE(B170:B219) -> 1788.552 | H220: =AVERAGE(C170:C219) -> 37.9304 | I220: =AVERAGE(D170:D219) -> 55.806 | J220: =AVERAGE(E170:E219) -> 58.7768 | K220: =AVERAGE(F170:F219) -> 415.722 | L220: =AVERAGE(B20:B219) -> 1829.0573 | M220: =AVERAGE(C20:C219) -> 39.60165 | N220: =AVERAGE(D20:D219) -> 56.2216 | O220: =AVERAGE(E20:E219) -> 60.59725 | P220: =AVERAGE(F20:F219) -> 407.2985
A221: =Prices!A219 -> 44205 | B221: =Prices!B219 -> 1901.05 | C221: =Prices!C219 -> 38.5 | D221: =Prices!D219 -> 58.290001 | E221: =Prices!E219 -> 59.68 | F221: =Prices!F219 -> 412.79999 | G221: =AVERAGE(B171:B220) -> 1791.1648 | H221: =AVERAGE(C171:C220) -> 37.905 | I221: =AVERAGE(D171:D220) -> 55.9328 | J221: =AVERAGE(E171:E220) -> 58.776 | K221: =AVERAGE(F171:F220) -> 415.592 | L221: =AVERAGE(B21:B220) -> 1829.6459 | M221: =AVERAGE(C21:C220) -> 39.59075 | N221: =AVERAGE(D21:D220) -> 56.23135 | O221: =AVERAGE(E21:E220) -> 60.58175 | P221: =AVERAGE(F21:F220) -> 407.342
A222: =Prices!A220 -> 44206 | B222: =Prices!B220 -> 1883.16 | C222: =Prices!C220 -> 38.139999 | D222: =Prices!D220 -> 58.450001 | E222: =Prices!E220 -> 59.009998 | F222: =Prices!F220 -> 411.60001 | G222: =AVERAGE(B172:B221) -> 1793.6442 | H222: =AVERAGE(C172:C221) -> 37.9132 | I222: =AVERAGE(D172:D221) -> 56.0318 | J222: =AVERAGE(E172:E221) -> 58.7712 | K222: =AVERAGE(F172:F221) -> 415.376 | L222: =AVERAGE(B22:B221) -> 1830.2323 | M222: =AVERAGE(C22:C221) -> 39.58035 | N222: =AVERAGE(D22:D221) -> 56.23385 | O222: =AVERAGE(E22:E221) -> 60.56415 | P222: =AVERAGE(F22:F221) -> 407.381
A223: =Prices!A221 -> 44209 | B223: =Prices!B221 -> 1891.3 | C223: =Prices!C221 -> 38.52 | D223: =Prices!D221 -> 59.130001 | E223: =Prices!E221 -> 58.959999 | F223: =Prices!F221 -> 411 | G223: =AVERAGE(B173:B222) -> 1796.0532 | H223: =AVERAGE(C173:C222) -> 37.9166 | I223: =AVERAGE(D173:D222) -> 56.1334 | J223: =AVERAGE(E173:E222) -> 58.7528 | K223: =AVERAGE(F173:F222) -> 415.28 | L223: =AVERAGE(B23:B222) -> 1830.8196 | M223: =AVERAGE(C23:C222) -> 39.5678 | N223: =AVERAGE(D23:D222) -> 56.2378 | O223: =AVERAGE(E23:E222) -> 60.5463 | P223: =AVERAGE(F23:F222) -> 407.3845
A224: =Prices!A222 -> 44210 | B224: =Prices!B222 -> 1869.4399 | C224: =Prices!C222 -> 38.380001 | D224: =Prices!D222 -> 59.23 | E224: =Prices!E222 -> 58.919998 | F224: =Prices!F222 -> 408.5 | G224: =AVERAGE(B174:B223) -> 1798.2794 | H224: =AVERAGE(C174:C223) -> 37.9284 | I224: =AVERAGE(D174:D223) -> 56.2654 | J224: =AVERAGE(E174:E223) -> 58.731 | K224: =AVERAGE(F174:F223) -> 415.196 | L224: =AVERAGE(B24:B223) -> 1831.409 | M224: =AVERAGE(C24:C223) -> 39.55785 | N224: =AVERAGE(D24:D223) -> 56.24335 | O224: =AVERAGE(E24:E223) -> 60.5279 | P224: =AVERAGE(F24:F223) -> 407.404
A225: =Prices!A223 -> 44211 | B225: =Prices!B223 -> 1862.02 | C225: =Prices!C223 -> 38.349998 | D225: =Prices!D223 -> 58.990002 | E225: =Prices!E223 -> 58.82 | F225: =Prices!F223 -> 406.89999 | G225: =AVERAGE(B175:B224) -> 1800.135 | H225: =AVERAGE(C175:C224) -> 37.9402 | I225: =AVERAGE(D175:D224) -> 56.4098 | J225: =AVERAGE(E175:E224) -> 58.75 | K225: =AVERAGE(F175:F224) -> 414.972 | L225: =AVERAGE(B25:B224) -> 1831.8525 | M225: =AVERAGE(C25:C224) -> 39.54685 | N225: =AVERAGE(D25:D224) -> 56.24525 | O225: =AVERAGE(E25:E224) -> 60.50955 | P225: =AVERAGE(F25:F224) -> 407.3845
A226: =Prices!A224 -> 44212 | B226: =Prices!B224 -> 1877.9399 | C226: =Prices!C224 -> 38.619999 | D226: =Prices!D224 -> 59.150002 | E226: =Prices!E224 -> 58.77 | F226: =Prices!F224 -> 407.70001 | G226: =AVERAGE(B176:B225) -> 1801.5466 | H226: =AVERAGE(C176:C225) -> 37.9458 | I226: =AVERAGE(D176:D225) -> 56.51 | J226: =AVERAGE(E176:E225) -> 58.7536 | K226: =AVERAGE(F176:F225) -> 414.67 | L226: =AVERAGE(B26:B225) -> 1832.0916 | M226: =AVERAGE(C26:C225) -> 39.5298 | N226: =AVERAGE(D26:D225) -> 56.24095 | O226: =AVERAGE(E26:E225) -> 60.48725 | P226: =AVERAGE(F26:F225) -> 407.337
A227: =Prices!A225 -> 44213 | B227: =Prices!B225 -> 1864.72 | C227: =Prices!C225 -> 38.77 | D227: =Prices!D225 -> 60.669998 | E227: =Prices!E225 -> 58.540001 | F227: =Prices!F225 -> 408.79999 | G227: =AVERAGE(B177:B226) -> 1803.0122 | H227: =AVERAGE(C177:C226) -> 37.9478 | I227: =AVERAGE(D177:D226) -> 56.5884 | J227: =AVERAGE(E177:E226) -> 58.7402 | K227: =AVERAGE(F177:F226) -> 414.188 | L227: =AVERAGE(B27:B226) -> 1832.4114 | M227: =AVERAGE(C27:C226) -> 39.51215 | N227: =AVERAGE(D27:D226) -> 56.2318 | O227: =AVERAGE(E27:E226) -> 60.46355 | P227: =AVERAGE(F27:F226) -> 407.2635
... A467: =Prices!A465 -> 44560 | B467: =Prices!B465 -> 3285.8501 | C467: =Prices!C465 -> 25.940001 | D467: =Prices!D465 -> 75.989998 | E467: =Prices!E465 -> 36.029999 | F467: =Prices!F465 -> 328 | G467: =AVERAGE(B417:B466) -> 3170.743 | H467: =AVERAGE(C417:C466) -> 24.6066 | I467: =AVERAGE(D417:D466) -> 66.4186 | J467: =AVERAGE(E417:E466) -> 32.396 | K467: =AVERAGE(F417:F466) -> 307.45 | L467: =AVERAGE(B267:B466) -> 2862.7965 | M467: =AVERAGE(C267:C466) -> 23.7792 | N467: =AVERAGE(D267:D466) -> 58.1215 | O467: =AVERAGE(E267:E466) -> 31.7446 | P467: =AVERAGE(F267:F466) -> 279.997

Sheet Modelling
A1: Modelling
B3: Strategy A: Hold | J3: Strategy B: Profit Taking | W3: Strategy C: Following Trend | AJ3: Strategy D: Moving Average
B4: Value | J4: Instruction | O4: Value | W4: Instruction | AB4: Value | AJ4: Instruction | AO4: Value
A5: Date | B5: Tech | C5: Banking | D5: Mining | E5: Energy | F5: Insurance | G5: Total | H5: Daily Return | J5: Tech | K5: Banking | L5: Mining | M5: Energy | N5: Insurance | O5: =J5 -> Tech | P5: =K5 -> Banking | Q5: =L5 -> Mining | R5: =M5 -> Energy | S5: =N5 -> Insurance | T5: Total | U5: Daily Return | W5: Tech | X5: Banking | Y5: Mining | Z5: Energy | AA5: Insurance | AB5: =W5 -> Tech | AC5: =X5 -> Banking | AD5: =Y5 -> Mining | AE5: =Z5 -> Energy | AF5: =AA5 -> Insurance | AG5: Total | AH5: Daily Return | AJ5: Tech | AK5: Banking | AL5: Mining | AM5: Energy | AN5: Insurance | AO5: =AJ5 -> Tech | AP5: =AK5 -> Banking | AQ5: =AL5 -> Mining | AR5: =AM5 -> Energy | AS5: =AN5 -> Insurance | AT5: Total | AU5: Daily Return
A6: =Prices!A214 -> 44198 | B6: =Parameters!$B$5 -> 200 | C6: =Parameters!$B$5 -> 200 | D6: =Parameters!$B$5 -> 200 | E6: =Parameters!$B$5 -> 200 | F6: =Parameters!$B$5 -> 200 | G6: =SUM(B6:F6) -> 1000 | H6: 0 | J6: =IF(AND('Data Checks'!B216>'Data Checks'!B215,'Data Checks'!B215>'Data Checks'!B214,'Data Checks'!B214>'Data Checks'!B213),"SELL",IF(AND('Data Checks'!B216<'Data Checks'!B215,'Data Checks'!B215<'Data Checks'!B214,'Data Checks'!B214<'Data Checks'!B213),"BUY","")) | K6: =IF(AND('Data Checks'!C216>'Data Checks'!C215,'Data Checks'!C215>'Data Checks'!C214,'Data Checks'!C214>'Data Checks'!C213),"SELL",IF(AND('Data Checks'!C216<'Data Checks'!C215,'Data Checks'!C215<'Data Checks'!C214,'Data Checks'!C214<'Data Checks'!C213),"BUY","")) | L6: =IF(AND('Data Checks'!D216>'Data Checks'!D215,'Data Checks'!D215>'Data Checks'!D214,'Data Checks'!D214>'Data Checks'!D213),"SELL",IF(AND('Data Checks'!D216<'Data Checks'!D215,'Data Checks'!D215<'Data Checks'!D214,'Data Checks'!D214<'Data Checks'!D213),"BUY","")) | M6: =IF(AND('Data Checks'!E216>'Data Checks'!E215,'Data Checks'!E215>'Data Checks'!E214,'Data Checks'!E214>'Data Checks'!E213),"SELL",IF(AND('Data Checks'!E216<'Data Checks'!E215,'Data Checks'!E215<'Data Checks'!E214,'Data Checks'!E214<'Data Checks'!E213),"BUY","")) | N6: =IF(AND('Data Checks'!F216>'Data Checks'!F215,'Data Checks'!F215>'Data Checks'!F214,'Data Checks'!F214>'Data Checks'!F213),"SELL",IF(AND('Data Checks'!F216<'Data Checks'!F215,'Data Checks'!F215<'Data Checks'!F214,'Data Checks'!F214<'Data Checks'!F213),"BUY","")) | O6: =Parameters!$B$5 -> 200 | P6: =Parameters!$B$5 -> 200 | Q6: =Parameters!$B$5 -> 200 | R6: =Parameters!$B$5 -> 200 | S6: =Parameters!$B$5 -> 200 | T6: =SUM(O6:S6) -> 1000 | U6: 0 | W6: =IF(AND('Data Checks'!B216>'Data Checks'!B215,'Data Checks'!B215>'Data Checks'!B214,'Data Checks'!B214>'Data Checks'!B213),"BUY",IF(AND('Data Checks'!B216<'Data Checks'!B215,'Data Checks'!B215<'Data Checks'!B214,'Data Checks'!B214<'Data Checks'!B213),"SELL","")) | X6: =IF(AND('Data Checks'!C216>'Data Checks'!C215,'Data Checks'!C215>'Data Checks'!C214,'Data Checks'!C214>'Data Checks'!C213),"BUY",IF(AND('Data Checks'!C216<'Data Checks'!C215,'Data Checks'!C215<'Data Checks'!C214,'Data Checks'!C214<'Data Checks'!C213),"SELL","")) | Y6: =IF(AND('Data Checks'!D216>'Data Checks'!D215,'Data Checks'!D215>'Data Checks'!D214,'Data Checks'!D214>'Data Checks'!D213),"BUY",IF(AND('Data Checks'!D216<'Data Checks'!D215,'Data Checks'!D215<'Data Checks'!D214,'Data Checks'!D214<'Data Checks'!D213),"SELL","")) | Z6: =IF(AND('Data Checks'!E216>'Data Checks'!E215,'Data Checks'!E215>'Data Checks'!E214,'Data Checks'!E214>'Data Checks'!E213),"BUY",IF(AND('Data Checks'!E216<'Data Checks'!E215,'Data Checks'!E215<'Data Checks'!E214,'Data Checks'!E214<'Data Checks'!E213),"SELL","")) | AA6: =IF(AND('Data Checks'!F216>'Data Checks'!F215,'Data Checks'!F215>'Data Checks'!F214,'Data Checks'!F214>'Data Checks'!F213),"BUY",IF(AND('Data Checks'!F216<'Data Checks'!F215,'Data Checks'!F215<'Data Checks'!F214,'Data Checks'!F214<'Data Checks'!F213),"SELL","")) | AB6: =Parameters!$B$5 -> 200 | AC6: =Parameters!$B$5 -> 200 | AD6: =Parameters!$B$5 -> 200 | AE6: =Parameters!$B$5 -> 200 | AF6: =Parameters!$B$5 -> 200 | AG6: =SUM(AB6:AF6) -> 1000 | AH6: 0 | AJ6: =IF('Moving Ave'!G216>'Moving Ave'!L216,"SELL","BUY") -> BUY | AK6: =IF('Moving Ave'!H216>'Moving Ave'!M216,"SELL","BUY") -> BUY | AL6: =IF('Moving Ave'!I216>'Moving Ave'!N216,"SELL","BUY") -> BUY | AM6: =IF('Moving Ave'!J216>'Moving Ave'!O216,"SELL","BUY") -> BUY | AN6: =IF('Moving Ave'!K216>'Moving Ave'!P216,"SELL","BUY") -> SELL | AO6: =Parameters!$B$5 -> 200 | AP6: =Parameters!$B$5 -> 200 | AQ6: =Parameters!$B$5 -> 200 | AR6: =Parameters!$B$5 -> 200 | AS6: =Parameters!$B$5 -> 200 | AT6: =SUM(AO6:AS6) -> 1000 | AU6: 0
A7: =Prices!A215 -> 44199 | B7: =B6*('Data Checks'!B217/'Data Checks'!B216) -> 197.57219 | C7: =C6*('Data Checks'!C217/'Data Checks'!C216) -> 196.90119 | D7: =D6*('Data Checks'!D217/'Data Checks'!D216) -> 196.49357 | E7: =E6*('Data Checks'!E217/'Data Checks'!E216) -> 201.57348 | F7: =F6*('Data Checks'!F217/'Data Checks'!F216) -> 197.4249 | G7: =SUM(B7:F7) -> 989.96532 | H7: =G7/G6-1 -> -0.010034676 | J7: =IF(AND('Data Checks'!B217>'Data Checks'!B216,'Data Checks'!B216>'Data Checks'!B215,'Data Checks'!B215>'Data Checks'!B214),"SELL",IF(AND('Data Checks'!B217<'Data Checks'!B216,'Data Checks'!B216<'Data Checks'!B215,'Data Checks'!B215<'Data Checks'!B214),"BUY","")) | K7: =IF(AND('Data Checks'!C217>'Data Checks'!C216,'Data Checks'!C216>'Data Checks'!C215,'Data Checks'!C215>'Data Checks'!C214),"SELL",IF(AND('Data Checks'!C217<'Data Checks'!C216,'Data Checks'!C216<'Data Checks'!C215,'Data Checks'!C215<'Data Checks'!C214),"BUY","")) | L7: =IF(AND('Data Checks'!D217>'Data Checks'!D216,'Data Checks'!D216>'Data Checks'!D215,'Data Checks'!D215>'Data Checks'!D214),"SELL",IF(AND('Data Checks'!D217<'Data Checks'!D216,'Data Checks'!D216<'Data Checks'!D215,'Data Checks'!D215<'Data Checks'!D214),"BUY","")) | M7: =IF(AND('Data Checks'!E217>'Data Checks'!E216,'Data Checks'!E216>'Data Checks'!E215,'Data Checks'!E215>'Data Checks'!E214),"SELL",IF(AND('Data Checks'!E217<'Data Checks'!E216,'Data Checks'!E216<'Data Checks'!E215,'Data Checks'!E215<'Data Checks'!E214),"BUY","")) -> SELL | N7: =IF(AND('Data Checks'!F217>'Data Checks'!F216,'Data Checks'!F216>'Data Checks'!F215,'Data Checks'!F215>'Data Checks'!F214),"SELL",IF(AND('Data Checks'!F217<'Data Checks'!F216,'Data Checks'!F216<'Data Checks'!F215,'Data Checks'!F215<'Data Checks'!F214),"BUY","")) | O7: =IF(J6="BUY",O6*('Data Checks'!B217/'Data Checks'!B216),IF(J6="SELL",O6*('Data Checks'!B216/'Data Checks'!B217),O6)) -> 200 | P7: =IF(K6="BUY",P6*('Data Checks'!C217/'Data Checks'!C216),IF(K6="SELL",P6*('Data Checks'!C216/'Data Checks'!C217),P6)) -> 200 | Q7: =IF(L6="BUY",Q6*('Data Checks'!D217/'Data Checks'!D216),IF(L6="SELL",Q6*('Data Checks'!D216/'Data Checks'!D217),Q6)) -> 200 | R7: =IF(M6="BUY",R6*('Data Checks'!E217/'Data Checks'!E216),IF(M6="SELL",R6*('Data Checks'!E216/'Data Checks'!E217),R6)) -> 200 | S7: =IF(N6="BUY",S6*('Data Checks'!F217/'Data Checks'!F216),IF(N6="SELL",S6*('Data Checks'!F216/'Data Checks'!F217),S6)) -> 200 | T7: =SUM(O7:S7) -> 1000 | U7: =T7/T6-1 -> 0 | W7: =IF(AND('Data Checks'!B217>'Data Checks'!B216,'Data Checks'!B216>'Data Checks'!B215,'Data Checks'!B215>'Data Checks'!B214),"BUY",IF(AND('Data Checks'!B217<'Data Checks'!B216,'Data Checks'!B216<'Data Checks'!B215,'Data Checks'!B215<'Data Checks'!B214),"SELL","")) | X7: =IF(AND('Data Checks'!C217>'Data Checks'!C216,'Data Checks'!C216>'Data Checks'!C215,'Data Checks'!C215>'Data Checks'!C214),"BUY",IF(AND('Data Checks'!C217<'Data Checks'!C216,'Data Checks'!C216<'Data Checks'!C215,'Data Checks'!C215<'Data Checks'!C214),"SELL","")) | Y7: =IF(AND('Data Checks'!D217>'Data Checks'!D216,'Data Checks'!D216>'Data Checks'!D215,'Data Checks'!D215>'Data Checks'!D214),"BUY",IF(AND('Data Checks'!D217<'Data Checks'!D216,'Data Checks'!D216<'Data Checks'!D215,'Data Checks'!D215<'Data Checks'!D214),"SELL","")) | Z7: =IF(AND('Data Checks'!E217>'Data Checks'!E216,'Data Checks'!E216>'Data Checks'!E215,'Data Checks'!E215>'Data Checks'!E214),"BUY",IF(AND('Data Checks'!E217<'Data Checks'!E216,'Data Checks'!E216<'Data Checks'!E215,'Data Checks'!E215<'Data Checks'!E214),"SELL","")) -> BUY | AA7: =IF(AND('Data Checks'!F217>'Data Checks'!F216,'Data Checks'!F216>'Data Checks'!F215,'Data Checks'!F215>'Data Checks'!F214),"BUY",IF(AND('Data Checks'!F217<'Data Checks'!F216,'Data Checks'!F216<'Data Checks'!F215,'Data Checks'!F215<'Data Checks'!F214),"SELL","")) | AB7: =IF(W6="BUY",AB6*('Data Checks'!B217/'Data Checks'!B216),IF(W6="SELL",AB6*('Data Checks'!B216/'Data Checks'!B217),AB6)) -> 200 | AC7: =IF(X6="BUY",AC6*('Data Checks'!C217/'Data Checks'!C216),IF(X6="SELL",AC6*('Data Checks'!C216/'Data Checks'!C217),AC6)) -> 200 | AD7: =IF(Y6="BUY",AD6*('Data Checks'!D217/'Data Checks'!D216),IF(Y6="SELL",AD6*('Data Checks'!D216/'Data Checks'!D217),AD6)) -> 200 | AE7: =IF(Z6="BUY",AE6*('Data Checks'!E217/'Data Checks'!E216),IF(Z6="SELL",AE6*('Data Checks'!E216/'Data Checks'!E217),AE6)) -> 200 | AF7: =IF(AA6="BUY",AF6*('Data Checks'!F217/'Data Checks'!F216),IF(AA6="SELL",AF6*('Data Checks'!F216/'Data Checks'!F217),AF6)) -> 200 | AG7: =SUM(AB7:AF7) -> 1000 | AH7: =AG7/AG6-1 -> 0 | AJ7: =IF('Moving Ave'!G217>'Moving Ave'!L217,"SELL","BUY") -> BUY | AK7: =IF('Moving Ave'!H217>'Moving Ave'!M217,"SELL","BUY") -> BUY | AL7: =IF('Moving Ave'!I217>'Moving Ave'!N217,"SELL","BUY") -> BUY | AM7: =IF('Moving Ave'!J217>'Moving Ave'!O217,"SELL","BUY") -> BUY | AN7: =IF('Moving Ave'!K217>'Moving Ave'!P217,"SELL","BUY") -> SELL | AO7: =IF(AJ6="BUY",AO6*('Data Checks'!B217/'Data Checks'!B216),AO6*('Data Checks'!B216/'Data Checks'!B217)) -> 197.57219 | AP7: =IF(AK6="BUY",AP6*('Data Checks'!C217/'Data Checks'!C216),AP6*('Data Checks'!C216/'Data Checks'!C217)) -> 196.90119 | AQ7: =IF(AL6="BUY",AQ6*('Data Checks'!D217/'Data Checks'!D216),AQ6*('Data Checks'!D216/'Data Checks'!D217)) -> 196.49357 | AR7: =IF(AM6="BUY",AR6*('Data Checks'!E217/'Data Checks'!E216),AR6*('Data Checks'!E216/'Data Checks'!E217)) -> 201.57348 | AS7: =IF(AN6="BUY",AS6*('Data Checks'!F217/'Data Checks'!F216),AS6*('Data Checks'!F216/'Data Checks'!F217)) -> 202.60869 | AT7: =SUM(AO7:AS7) -> 995.14912 | AU7: =AT7/AT6-1 -> -0.0048508788
A8: =Prices!A216 -> 44202 | B8: =B7*('Data Checks'!B218/'Data Checks'!B217) -> 200.51317 | C8: =C7*('Data Checks'!C218/'Data Checks'!C217) -> 196.2408 | D8: =D7*('Data Checks'!D218/'Data Checks'!D217) -> 195.19119 | E8: =E7*('Data Checks'!E218/'Data Checks'!E217) -> 204.08436 | F8: =F7*('Data Checks'!F218/'Data Checks'!F217) -> 199.04626 | G8: =SUM(B8:F8) -> 995.07577 | H8: =G8/G7-1 -> 0.005162251 | J8: =IF(AND('Data Checks'!B218>'Data Checks'!B217,'Data Checks'!B217>'Data Checks'!B216,'Data Checks'!B216>'Data Checks'!B215),"SELL",IF(AND('Data Checks'!B218<'Data Checks'!B217,'Data Checks'!B217<'Data Checks'!B216,'Data Checks'!B216<'Data Checks'!B215),"BUY","")) | K8: =IF(AND('Data Checks'!C218>'Data Checks'!C217,'Data Checks'!C217>'Data Checks'!C216,'Data Checks'!C216>'Data Checks'!C215),"SELL",IF(AND('Data Checks'!C218<'Data Checks'!C217,'Data Checks'!C217<'Data Checks'!C216,'Data Checks'!C216<'Data Checks'!C215),"BUY","")) | L8: =IF(AND('Data Checks'!D218>'Data Checks'!D217,'Data Checks'!D217>'Data Checks'!D216,'Data Checks'!D216>'Data Checks'!D215),"SELL",IF(AND('Data Checks'!D218<'Data Checks'!D217,'Data Checks'!D217<'Data Checks'!D216,'Data Checks'!D216<'Data Checks'!D215),"BUY","")) | M8: =IF(AND('Data Checks'!E218>'Data Checks'!E217,'Data Checks'!E217>'Data Checks'!E216,'Data Checks'!E216>'Data Checks'!E215),"SELL",IF(AND('Data Checks'!E218<'Data Checks'!E217,'Data Checks'!E217<'Data Checks'!E216,'Data Checks'!E216<'Data Checks'!E215),"BUY","")) -> SELL | N8: =IF(AND('Data Checks'!F218>'Data Checks'!F217,'Data Checks'!F217>'Data Checks'!F216,'Data Checks'!F216>'Data Checks'!F215),"SELL",IF(AND('Data Checks'!F218<'Data Checks'!F217,'Data Checks'!F217<'Data Checks'!F216,'Data Checks'!F216<'Data Checks'!F215),"BUY","")) | O8: =IF(J7="BUY",O7*('Data Checks'!B218/'Data Checks'!B217),IF(J7="SELL",O7*('Data Checks'!B217/'Data Checks'!B218),O7)) -> 200 | P8: =IF(K7="BUY",P7*('Data Checks'!C218/'Data Checks'!C217),IF(K7="SELL",P7*('Data Checks'!C217/'Data Checks'!C218),P7)) -> 200 | Q8: =IF(L7="BUY",Q7*('Data Checks'!D218/'Data Checks'!D217),IF(L7="SELL",Q7*('Data Checks'!D217/'Data Checks'!D218),Q7)) -> 200 | R8: =IF(M7="BUY",R7*('Data Checks'!E218/'Data Checks'!E217),IF(M7="SELL",R7*('Data Checks'!E217/'Data Checks'!E218),R7)) -> 197.53937 | S8: =IF(N7="BUY",S7*('Data Checks'!F218/'Data Checks'!F217),IF(N7="SELL",S7*('Data Checks'!F217/'Data Checks'!F218),S7)) -> 200 | T8: =SUM(O8:S8) -> 997.53937 | U8: =T8/T7-1 -> -0.00246063 | W8: =IF(AND('Data Checks'!B218>'Data Checks'!B217,'Data Checks'!B217>'Data Checks'!B216,'Data Checks'!B216>'Data Checks'!B215),"BUY",IF(AND('Data Checks'!B218<'Data Checks'!B217,'Data Checks'!B217<'Data Checks'!B216,'Data Checks'!B216<'Data Checks'!B215),"SELL","")) | X8: =IF(AND('Data Checks'!C218>'Data Checks'!C217,'Data Checks'!C217>'Data Checks'!C216,'Data Checks'!C216>'Data Checks'!C215),"BUY",IF(AND('Data Checks'!C218<'Data Checks'!C217,'Data Checks'!C217<'Data Checks'!C216,'Data Checks'!C216<'Data Checks'!C215),"SELL","")) | Y8: =IF(AND('Data Checks'!D218>'Data Checks'!D217,'Data Checks'!D217>'Data Checks'!D216,'Data Checks'!D216>'Data Checks'!D215),"BUY",IF(AND('Data Checks'!D218<'Data Checks'!D217,'Data Checks'!D217<'Data Checks'!D216,'Data Checks'!D216<'Data Checks'!D215),"SELL","")) | Z8: =IF(AND('Data Checks'!E218>'Data Checks'!E217,'Data Checks'!E217>'Data Checks'!E216,'Data Checks'!E216>'Data Checks'!E215),"BUY",IF(AND('Data Checks'!E218<'Data Checks'!E217,'Data Checks'!E217<'Data Checks'!E216,'Data Checks'!E216<'Data Checks'!E215),"SELL","")) -> BUY | AA8: =IF(AND('Data Checks'!F218>'Data Checks'!F217,'Data Checks'!F217>'Data Checks'!F216,'Data Checks'!F216>'Data Checks'!F215),"BUY",IF(AND('Data Checks'!F218<'Data Checks'!F217,'Data Checks'!F217<'Data Checks'!F216,'Data Checks'!F216<'Data Checks'!F215),"SELL","")) | AB8: =IF(W7="BUY",AB7*('Data Checks'!B218/'Data Checks'!B217),IF(W7="SELL",AB7*('Data Checks'!B217/'Data Checks'!B218),AB7)) -> 200 | AC8: =IF(X7="BUY",AC7*('Data Checks'!C218/'Data Checks'!C217),IF(X7="SELL",AC7*('Data Checks'!C217/'Data Checks'!C218),AC7)) -> 200 | AD8: =IF(Y7="BUY",AD7*('Data Checks'!D218/'Data Checks'!D217),IF(Y7="SELL",AD7*('Data Checks'!D217/'Data Checks'!D218),AD7)) -> 200 | AE8: =IF(Z7="BUY",AE7*('Data Checks'!E218/'Data Checks'!E217),IF(Z7="SELL",AE7*('Data Checks'!E217/'Data Checks'!E218),AE7)) -> 202.49128 | AF8: =IF(AA7="BUY",AF7*('Data Checks'!F218/'Data Checks'!F217),IF(AA7="SELL",AF7*('Data Checks'!F217/'Data Checks'!F218),AF7)) -> 200 | AG8: =SUM(AB8:AF8) -> 1002.4913 | AH8: =AG8/AG7-1 -> 0.0024912806 | AJ8: =IF('Moving Ave'!G218>'Moving Ave'!L218,"SELL","BUY") -> BUY | AK8: =IF('Moving Ave'!H218>'Moving Ave'!M218,"SELL","BUY") -> BUY | AL8: =IF('Moving Ave'!I218>'Moving Ave'!N218,"SELL","BUY") -> BUY | AM8: =IF('Moving Ave'!J218>'Moving Ave'!O218,"SELL","BUY") -> BUY | AN8: =IF('Moving Ave'!K218>'Moving Ave'!P218,"SELL","BUY") -> SELL | AO8: =IF(AJ7="BUY",AO7*('Data Checks'!B218/'Data Checks'!B217),AO7*('Data Checks'!B217/'Data Checks'!B218)) -> 200.51317 | AP8: =IF(AK7="BUY",AP7*('Data Checks'!C218/'Data Checks'!C217),AP7*('Data Checks'!C217/'Data Checks'!C218)) -> 196.2408 | AQ8: =IF(AL7="BUY",AQ7*('Data Checks'!D218/'Data Checks'!D217),AQ7*('Data Checks'!D217/'Data Checks'!D218)) -> 195.19119 | AR8: =IF(AM7="BUY",AR7*('Data Checks'!E218/'Data Checks'!E217),AR7*('Data Checks'!E217/'Data Checks'!E218)) -> 204.08436 | AS8: =IF(AN7="BUY",AS7*('Data Checks'!F218/'Data Checks'!F217),AS7*('Data Checks'!F217/'Data Checks'!F218)) -> 200.95831 | AT8: =SUM(AO8:AS8) -> 996.98783 | AU8: =AT8/AT7-1 -> 0.001847672
A9: =Prices!A217 -> 44203 | B9: =B8*('Data Checks'!B219/'Data Checks'!B218) -> 200.93255 | C9: =C8*('Data Checks'!C219/'Data Checks'!C218) -> 194.76759 | D9: =D8*('Data Checks'!D219/'Data Checks'!D218) -> 194.99082 | E9: =E8*('Data Checks'!E219/'Data Checks'!E218) -> 202.20957 | F9: =F8*('Data Checks'!F219/'Data Checks'!F218) -> 198.42633 | G9: =SUM(B9:F9) -> 991.32687 | H9: =G9/G8-1 -> -0.0037674576 | J9: =IF(AND('Data Checks'!B219>'Data Checks'!B218,'Data Checks'!B218>'Data Checks'!B217,'Data Checks'!B217>'Data Checks'!B216),"SELL",IF(AND('Data Checks'!B219<'Data Checks'!B218,'Data Checks'!B218<'Data Checks'!B217,'Data Checks'!B217<'Data Checks'!B216),"BUY","")) | K9: =IF(AND('Data Checks'!C219>'Data Checks'!C218,'Data Checks'!C218>'Data Checks'!C217,'Data Checks'!C217>'Data Checks'!C216),"SELL",IF(AND('Data Checks'!C219<'Data Checks'!C218,'Data Checks'!C218<'Data Checks'!C217,'Data Checks'!C217<'Data Checks'!C216),"BUY","")) -> BUY | L9: =IF(AND('Data Checks'!D219>'Data Checks'!D218,'Data Checks'!D218>'Data Checks'!D217,'Data Checks'!D217>'Data Checks'!D216),"SELL",IF(AND('Data Checks'!D219<'Data Checks'!D218,'Data Checks'!D218<'Data Checks'!D217,'Data Checks'!D217<'Data Checks'!D216),"BUY","")) -> BUY | M9: =IF(AND('Data Checks'!E219>'Data Checks'!E218,'Data Checks'!E218>'Data Checks'!E217,'Data Checks'!E217>'Data Checks'!E216),"SELL",IF(AND('Data Checks'!E219<'Data Checks'!E218,'Data Checks'!E218<'Data Checks'!E217,'Data Checks'!E217<'Data Checks'!E216),"BUY","")) | N9: =IF(AND('Data Checks'!F219>'Data Checks'!F218,'Data Checks'!F218>'Data Checks'!F217,'Data Checks'!F217>'Data Checks'!F216),"SELL",IF(AND('Data Checks'!F219<'Data Checks'!F218,'Data Checks'!F218<'Data Checks'!F217,'Data Checks'!F217<'Data Checks'!F216),"BUY","")) | O9: =IF(J8="BUY",O8*('Data Checks'!B219/'Data Checks'!B218),IF(J8="SELL",O8*('Data Checks'!B218/'Data Checks'!B219),O8)) -> 200 | P9: =IF(K8="BUY",P8*('Data Checks'!C219/'Data Checks'!C218),IF(K8="SELL",P8*('Data Checks'!C218/'Data Checks'!C219),P8)) -> 200 | Q9: =IF(L8="BUY",Q8*('Data Checks'!D219/'Data Checks'!D218),IF(L8="SELL",Q8*('Data Checks'!D218/'Data Checks'!D219),Q8)) -> 200 | R9: =IF(M8="BUY",R8*('Data Checks'!E219/'Data Checks'!E218),IF(M8="SELL",R8*('Data Checks'!E218/'Data Checks'!E219),R8)) -> 199.37085 | S9: =IF(N8="BUY",S8*('Data Checks'!F219/'Data Checks'!F218),IF(N8="SELL",S8*('Data Checks'!F218/'Data Checks'!F219),S8)) -> 200 | T9: =SUM(O9:S9) -> 999.37085 | U9: =T9/T8-1 -> 0.0018359987 | W9: =IF(AND('Data Checks'!B219>'Data Checks'!B218,'Data Checks'!B218>'Data Checks'!B217,'Data Checks'!B217>'Data Checks'!B216),"BUY",IF(AND('Data Checks'!B219<'Data Checks'!B218,'Data Checks'!B218<'Data Checks'!B217,'Data Checks'!B217<'Data Checks'!B216),"SELL","")) | X9: =IF(AND('Data Checks'!C219>'Data Checks'!C218,'Data Checks'!C218>'Data Checks'!C217,'Data Checks'!C217>'Data Checks'!C216),"BUY",IF(AND('Data Checks'!C219<'Data Checks'!C218,'Data Checks'!C218<'Data Checks'!C217,'Data Checks'!C217<'Data Checks'!C216),"SELL","")) -> SELL | Y9: =IF(AND('Data Checks'!D219>'Data Checks'!D218,'Data Checks'!D218>'Data Checks'!D217,'Data Checks'!D217>'Data Checks'!D216),"BUY",IF(AND('Data Checks'!D219<'Data Checks'!D218,'Data Checks'!D218<'Data Checks'!D217,'Data Checks'!D217<'Data Checks'!D216),"SELL","")) -> SELL | Z9: =IF(AND('Data Checks'!E219>'Data Checks'!E218,'Data Checks'!E218>'Data Checks'!E217,'Data Checks'!E217>'Data Checks'!E216),"BUY",IF(AND('Data Checks'!E219<'Data Checks'!E218,'Data Checks'!E218<'Data Checks'!E217,'Data Checks'!E217<'Data Checks'!E216),"SELL","")) | AA9: =IF(AND('Data Checks'!F219>'Data Checks'!F218,'Data Checks'!F218>'Data Checks'!F217,'Data Checks'!F217>'Data Checks'!F216),"BUY",IF(AND('Data Checks'!F219<'Data Checks'!F218,'Data Checks'!F218<'Data Checks'!F217,'Data Checks'!F217<'Data Checks'!F216),"SELL","")) | AB9: =IF(W8="BUY",AB8*('Data Checks'!B219/'Data Checks'!B218),IF(W8="SELL",AB8*('Data Checks'!B218/'Data Checks'!B219),AB8)) -> 200 | AC9: =IF(X8="BUY",AC8*('Data Checks'!C219/'Data Checks'!C218),IF(X8="SELL",AC8*('Data Checks'!C218/'Data Checks'!C219),AC8)) -> 200 | AD9: =IF(Y8="BUY",AD8*('Data Checks'!D219/'Data Checks'!D218),IF(Y8="SELL",AD8*('Data Checks'!D218/'Data Checks'!D219),AD8)) -> 200 | AE9: =IF(Z8="BUY",AE8*('Data Checks'!E219/'Data Checks'!E218),IF(Z8="SELL",AE8*('Data Checks'!E218/'Data Checks'!E219),AE8)) -> 200.63113 | AF9: =IF(AA8="BUY",AF8*('Data Checks'!F219/'Data Checks'!F218),IF(AA8="SELL",AF8*('Data Checks'!F218/'Data Checks'!F219),AF8)) -> 200 | AG9: =SUM(AB9:AF9) -> 1000.6311 | AH9: =AG9/AG8-1 -> -0.0018555236 | AJ9: =IF('Moving Ave'!G219>'Moving Ave'!L219,"SELL","BUY") -> BUY | AK9: =IF('Moving Ave'!H219>'Moving Ave'!M219,"SELL","BUY") -> BUY | AL9: =IF('Moving Ave'!I219>'Moving Ave'!N219,"SELL","BUY") -> BUY | AM9: =IF('Moving Ave'!J219>'Moving Ave'!O219,"SELL","BUY") -> BUY | AN9: =IF('Moving Ave'!K219>'Moving Ave'!P219,"SELL","BUY") -> SELL | AO9: =IF(AJ8="BUY",AO8*('Data Checks'!B219/'Data Checks'!B218),AO8*('Data Checks'!B218/'Data Checks'!B219)) -> 200.93255 | AP9: =IF(AK8="BUY",AP8*('Data Checks'!C219/'Data Checks'!C218),AP8*('Data Checks'!C218/'Data Checks'!C219)) -> 194.76759 | AQ9: =IF(AL8="BUY",AQ8*('Data Checks'!D219/'Data Checks'!D218),AQ8*('Data Checks'!D218/'Data Checks'!D219)) -> 194.99082 | AR9: =IF(AM8="BUY",AR8*('Data Checks'!E219/'Data Checks'!E218),AR8*('Data Checks'!E218/'Data Checks'!E219)) -> 202.20957 | AS9: =IF(AN8="BUY",AS8*('Data Checks'!F219/'Data Checks'!F218),AS8*('Data Checks'!F218/'Data Checks'!F219)) -> 201.58615 | AT9: =SUM(AO9:AS9) -> 994.48669 | AU9: =AT9/AT8-1 -> -0.0025086968
