Workbook
Name admin_cost: Parameters!$C$49
Name advert_cost: Parameters!$C$50
Name avg_petrol_consump_pa: Parameters!$C$60
Name budget: Parameters!$C$5
Name disc_rate: Parameters!$C$6
Name energy_req_fullrecharge_per_car: Parameters!$C$37
Name energy_supply_per_station_pa: Parameters!$C$38
Name expense_inflation: Parameters!$C$51
Name inflation_petrol: Parameters!$C$57
Name no_of_recharges_per_car_pa: Parameters!$C$36
Name petrol_cost_per_litre: Parameters!$C$56
Name projection_period: Parameters!$C$4
Name station_build_cost: Parameters!$C$40
Name station_build_cost_inflation: Parameters!$C$41
Name subsidy: Parameters!$C$7
Name tax_rate_petrol: Parameters!$C$59
Name VAL_DATE: Parameters!$C$3

Sheet Raw_data_old
I3: values pasted with removed duplicates
A4: No. | B4: Year | C4: Month | D4: Petrol car sales | F4: Quarter | K4: =SUM(K5:K84)=SUM(D5:D244) -> #REF!
A5: 1 | B5: 1 | C5: 45658 | D5: =#REF! -> #REF! | F5: ="Q"&ROUNDUP(MONTH(C5)/3,0) -> Q1 | G5: ="Q"&ROUNDUP(MONTH(C5)/3,0)&"_"&YEAR(C5) -> Q1_2025 | H5: 1 | I5: Q1 | J5: Q1_2025 | K5: =SUMIFS($D$5:$D$244,$G$5:$G$244,J5) -> #REF!
A6: 2 | B6: 2 | C6: 45689 | D6: =#REF! -> #REF! | F6: ="Q"&ROUNDUP(MONTH(C6)/3,0) -> Q1 | G6: ="Q"&ROUNDUP(MONTH(C6)/3,0)&"_"&YEAR(C6) -> Q1_2025 | H6: =H5+1 -> 2 | I6: Q2 | J6: Q2_2025 | K6: =SUMIFS($D$5:$D$244,$G$5:$G$244,J6) -> #REF!
A7: 3 | B7: 3 | C7: 45717 | D7: =#REF! -> #REF! | F7: ="Q"&ROUNDUP(MONTH(C7)/3,0) -> Q1 | G7: ="Q"&ROUNDUP(MONTH(C7)/3,0)&"_"&YEAR(C7) -> Q1_2025 | H7: =H6+1 -> 3 | I7: Q3 | J7: Q3_2025 | K7: =SUMIFS($D$5:$D$244,$G$5:$G$244,J7) -> #REF!
A8: 4 | B8: 4 | C8: 45748 | D8: =#REF! -> #REF! | F8: ="Q"&ROUNDUP(MONTH(C8)/3,0) -> Q2 | G8: ="Q"&ROUNDUP(MONTH(C8)/3,0)&"_"&YEAR(C8) -> Q2_2025 | H8: =H7+1 -> 4 | I8: Q4 | J8: Q4_2025 | K8: =SUMIFS($D$5:$D$244,$G$5:$G$244,J8) -> #REF!
A9: 5 | B9: 5 | C9: 45778 | D9: =#REF! -> #REF! | F9: ="Q"&ROUNDUP(MONTH(C9)/3,0) -> Q2 | G9: ="Q"&ROUNDUP(MONTH(C9)/3,0)&"_"&YEAR(C9) -> Q2_2025 | H9: =H8+1 -> 5 | I9: Q1 | J9: Q1_2026 | K9: =SUMIFS($D$5:$D$244,$G$5:$G$244,J9) -> #REF!
A10: 6 | B10: 6 | C10: 45809 | D10: =#REF! -> #REF! | F10: ="Q"&ROUNDUP(MONTH(C10)/3,0) -> Q2 | G10: ="Q"&ROUNDUP(MONTH(C10)/3,0)&"_"&YEAR(C10) -> Q2_2025 | H10: =H9+1 -> 6 | I10: Q2 | J10: Q2_2026 | K10: =SUMIFS($D$5:$D$244,$G$5:$G$244,J10) -> #REF!
A11: 7 | B11: 7 | C11: 45839 | D11: =#REF! -> #REF! | F11: ="Q"&ROUNDUP(MONTH(C11)/3,0) -> Q3 | G11: ="Q"&ROUNDUP(MONTH(C11)/3,0)&"_"&YEAR(C11) -> Q3_2025 | H11: =H10+1 -> 7 | I11: Q3 | J11: Q3_2026 | K11: =SUMIFS($D$5:$D$244,$G$5:$G$244,J11) -> #REF!
A12: 8 | B12: 8 | C12: 45870 | D12: =#REF! -> #REF! | F12: ="Q"&ROUNDUP(MONTH(C12)/3,0) -> Q3 | G12: ="Q"&ROUNDUP(MONTH(C12)/3,0)&"_"&YEAR(C12) -> Q3_2025 | H12: =H11+1 -> 8 | I12: Q4 | J12: Q4_2026 | K12: =SUMIFS($D$5:$D$244,$G$5:$G$244,J12) -> #REF!
A13: 9 | B13: 9 | C13: 45901 | D13: =#REF! -> #REF! | F13: ="Q"&ROUNDUP(MONTH(C13)/3,0) -> Q3 | G13: ="Q"&ROUNDUP(MONTH(C13)/3,0)&"_"&YEAR(C13) -> Q3_2025 | H13: =H12+1 -> 9 | I13: Q1 | J13: Q1_2027 | K13: =SUMIFS($D$5:$D$244,$G$5:$G$244,J13) -> #REF!
A14: 10 | B14: 10 | C14: 45931 | D14: =#REF! -> #REF! | F14: ="Q"&ROUNDUP(MONTH(C14)/3,0) -> Q4 | G14: ="Q"&ROUNDUP(MONTH(C14)/3,0)&"_"&YEAR(C14) -> Q4_2025 | H14: =H13+1 -> 10 | I14: Q2 | J14: Q2_2027 | K14: =SUMIFS($D$5:$D$244,$G$5:$G$244,J14) -> #REF!
A15: 11 | B15: 11 | C15: 45962 | D15: =#REF! -> #REF! | F15: ="Q"&ROUNDUP(MONTH(C15)/3,0) -> Q4 | G15: ="Q"&ROUNDUP(MONTH(C15)/3,0)&"_"&YEAR(C15) -> Q4_2025 | H15: =H14+1 -> 11 | I15: Q3 | J15: Q3_2027 | K15: =SUMIFS($D$5:$D$244,$G$5:$G$244,J15) -> #REF!
A16: 12 | B16: 12 | C16: 45992 | D16: =#REF! -> #REF! | F16: ="Q"&ROUNDUP(MONTH(C16)/3,0) -> Q4 | G16: ="Q"&ROUNDUP(MONTH(C16)/3,0)&"_"&YEAR(C16) -> Q4_2025 | H16: =H15+1 -> 12 | I16: Q4 | J16: Q4_2027 | K16: =SUMIFS($D$5:$D$244,$G$5:$G$244,J16) -> #REF!
A17: 13 | B17: 13 | C17: 46023 | D17: =#REF! -> #REF! | F17: ="Q"&ROUNDUP(MONTH(C17)/3,0) -> Q1 | G17: ="Q"&ROUNDUP(MONTH(C17)/3,0)&"_"&YEAR(C17) -> Q1_2026 | H17: =H16+1 -> 13 | I17: Q1 | J17: Q1_2028 | K17: =SUMIFS($D$5:$D$244,$G$5:$G$244,J17) -> #REF!
... A84: 80 | B84: 80 | C84: 48061 | D84: =#REF! -> #REF! | F84: ="Q"&ROUNDUP(MONTH(C84)/3,0) -> Q3 | G84: ="Q"&ROUNDUP(MONTH(C84)/3,0)&"_"&YEAR(C84) -> Q3_2031 | H84: =H83+1 -> 80 | I84: Q4 | J84: Q4_2044 | K84: =SUMIFS($D$5:$D$244,$G$5:$G$244,J84) -> #REF!
A85: 81 | B85: 81 | C85: 48092 | D85: =#REF! -> #REF! | F85: ="Q"&ROUNDUP(MONTH(C85)/3,0) -> Q3 | G85: ="Q"&ROUNDUP(MONTH(C85)/3,0)&"_"&YEAR(C85) -> Q3_2031
A86: 82 | B86: 82 | C86: 48122 | D86: =#REF! -> #REF! | F86: ="Q"&ROUNDUP(MONTH(C86)/3,0) -> Q4 | G86: ="Q"&ROUNDUP(MONTH(C86)/3,0)&"_"&YEAR(C86) -> Q4_2031
A87: 83 | B87: 83 | C87: 48153 | D87: =#REF! -> #REF! | F87: ="Q"&ROUNDUP(MONTH(C87)/3,0) -> Q4 | G87: ="Q"&ROUNDUP(MONTH(C87)/3,0)&"_"&YEAR(C87) -> Q4_2031
A88: 84 | B88: 84 | C88: 48183 | D88: =#REF! -> #REF! | F88: ="Q"&ROUNDUP(MONTH(C88)/3,0) -> Q4 | G88: ="Q"&ROUNDUP(MONTH(C88)/3,0)&"_"&YEAR(C88) -> Q4_2031
A89: 85 | B89: 85 | C89: 48214 | D89: =#REF! -> #REF! | F89: ="Q"&ROUNDUP(MONTH(C89)/3,0) -> Q1 | G89: ="Q"&ROUNDUP(MONTH(C89)/3,0)&"_"&YEAR(C89) -> Q1_2032
A90: 86 | B90: 86 | C90: 48245 | D90: =#REF! -> #REF! | F90: ="Q"&ROUNDUP(MONTH(C90)/3,0) -> Q1 | G90: ="Q"&ROUNDUP(MONTH(C90)/3,0)&"_"&YEAR(C90) -> Q1_2032
A91: 87 | B91: 87 | C91: 48274 | D91: =#REF! -> #REF! | F91: ="Q"&ROUNDUP(MONTH(C91)/3,0) -> Q1 | G91: ="Q"&ROUNDUP(MONTH(C91)/3,0)&"_"&YEAR(C91) -> Q1_2032
A92: 88 | B92: 88 | C92: 48305 | D92: =#REF! -> #REF! | F92: ="Q"&ROUNDUP(MONTH(C92)/3,0) -> Q2 | G92: ="Q"&ROUNDUP(MONTH(C92)/3,0)&"_"&YEAR(C92) -> Q2_2032
A93: 89 | B93: 89 | C93: 48335 | D93: =#REF! -> #REF! | F93: ="Q"&ROUNDUP(MONTH(C93)/3,0) -> Q2 | G93: ="Q"&ROUNDUP(MONTH(C93)/3,0)&"_"&YEAR(C93) -> Q2_2032
A94: 90 | B94: 90 | C94: 48366 | D94: =#REF! -> #REF! | F94: ="Q"&ROUNDUP(MONTH(C94)/3,0) -> Q2 | G94: ="Q"&ROUNDUP(MONTH(C94)/3,0)&"_"&YEAR(C94) -> Q2_2032
A95: 91 | B95: 91 | C95: 48396 | D95: =#REF! -> #REF! | F95: ="Q"&ROUNDUP(MONTH(C95)/3,0) -> Q3 | G95: ="Q"&ROUNDUP(MONTH(C95)/3,0)&"_"&YEAR(C95) -> Q3_2032
A96: 92 | B96: 92 | C96: 48427 | D96: =#REF! -> #REF! | F96: ="Q"&ROUNDUP(MONTH(C96)/3,0) -> Q3 | G96: ="Q"&ROUNDUP(MONTH(C96)/3,0)&"_"&YEAR(C96) -> Q3_2032
... A124: 120 | B124: 120 | C124: 49279 | D124: =#REF! -> #REF! | F124: ="Q"&ROUNDUP(MONTH(C124)/3,0) -> Q4 | G124: ="Q"&ROUNDUP(MONTH(C124)/3,0)&"_"&YEAR(C124) -> Q4_2034
B125: 121 | C125: 49310 | D125: =#REF! -> #REF! | F125: ="Q"&ROUNDUP(MONTH(C125)/3,0) -> Q1 | G125: ="Q"&ROUNDUP(MONTH(C125)/3,0)&"_"&YEAR(C125) -> Q1_2035
B126: 122 | C126: 49341 | D126: =#REF! -> #REF! | F126: ="Q"&ROUNDUP(MONTH(C126)/3,0) -> Q1 | G126: ="Q"&ROUNDUP(MONTH(C126)/3,0)&"_"&YEAR(C126) -> Q1_2035
B127: 123 | C127: 49369 | D127: =#REF! -> #REF! | F127: ="Q"&ROUNDUP(MONTH(C127)/3,0) -> Q1 | G127: ="Q"&ROUNDUP(MONTH(C127)/3,0)&"_"&YEAR(C127) -> Q1_2035
B128: 124 | C128: 49400 | D128: =#REF! -> #REF! | F128: ="Q"&ROUNDUP(MONTH(C128)/3,0) -> Q2 | G128: ="Q"&ROUNDUP(MONTH(C128)/3,0)&"_"&YEAR(C128) -> Q2_2035
B129: 125 | C129: 49430 | D129: =#REF! -> #REF! | F129: ="Q"&ROUNDUP(MONTH(C129)/3,0) -> Q2 | G129: ="Q"&ROUNDUP(MONTH(C129)/3,0)&"_"&YEAR(C129) -> Q2_2035
B130: 126 | C130: 49461 | D130: =#REF! -> #REF! | F130: ="Q"&ROUNDUP(MONTH(C130)/3,0) -> Q2 | G130: ="Q"&ROUNDUP(MONTH(C130)/3,0)&"_"&YEAR(C130) -> Q2_2035
B131: 127 | C131: 49491 | D131: =#REF! -> #REF! | F131: ="Q"&ROUNDUP(MONTH(C131)/3,0) -> Q3 | G131: ="Q"&ROUNDUP(MONTH(C131)/3,0)&"_"&YEAR(C131) -> Q3_2035
B132: 128 | C132: 49522 | D132: =#REF! -> #REF! | F132: ="Q"&ROUNDUP(MONTH(C132)/3,0) -> Q3 | G132: ="Q"&ROUNDUP(MONTH(C132)/3,0)&"_"&YEAR(C132) -> Q3_2035
B133: 129 | C133: 49553 | D133: =#REF! -> #REF! | F133: ="Q"&ROUNDUP(MONTH(C133)/3,0) -> Q3 | G133: ="Q"&ROUNDUP(MONTH(C133)/3,0)&"_"&YEAR(C133) -> Q3_2035
B134: 130 | C134: 49583 | D134: =#REF! -> #REF! | F134: ="Q"&ROUNDUP(MONTH(C134)/3,0) -> Q4 | G134: ="Q"&ROUNDUP(MONTH(C134)/3,0)&"_"&YEAR(C134) -> Q4_2035
B135: 131 | C135: 49614 | D135: =#REF! -> #REF! | F135: ="Q"&ROUNDUP(MONTH(C135)/3,0) -> Q4 | G135: ="Q"&ROUNDUP(MONTH(C135)/3,0)&"_"&YEAR(C135) -> Q4_2035
...

Sheet Raw_data
A2: Source: Government Transport Department
B4: Month | C4: Petrol car sales
B5: 46023 | C5: 16755
B6: 46054 | C6: 18135
B7: 46082 | C7: 19675
B8: 46113 | C8: 21170
B9: 46143 | C9: 21300
B10: 46174 | C10: 21630
B11: 46204 | C11: 23100
B12: 46235 | C12: 24800
B13: 46266 | C13: 26430
B14: 46296 | C14: 28335
B15: 46327 | C15: 25925
B16: 46357 | C16: 27470
... B244: 53297 | C244: 183254

Sheet Parameters
B1: Parameters | E1: LEGEND:
E2: model inputs
B3: Valuation date | C3: 46023 | E3: checks
B4: Projection period | C4: 20 | D4: years | E4: corrected data and key results
B5: CT program budget | C5: 3000000000 | D5: $ | E5: errors in data
B6: Discount rate | C6: 0.07 | D6: p.a. | E6: formula change or danger cells
B7: Subsidy offered on the purchase price of each electric car | C7: 3000 | D7: $
B10: No. of petrol cars at 1 January 2026 | C10: 5000000
B11: Proportion of petrol cars scrapped at the end of each year | C11: 0.04
B13: % of petrol car sales in the original plan that will now be replaced by electric cars
B14: 2026 | C14: 0.05
B15: =B14+1 -> 2027 | C15: =C14+1% -> 0.06
B16: =B15+1 -> 2028 | C16: =C15+1% -> 0.07
B17: =B16+1 -> 2029 | C17: =C16+1% -> 0.08
B18: =B17+1 -> 2030 | C18: =C17+1% -> 0.09
B19: =B18+1 -> 2031 | C19: =C18+1% -> 0.1
B20: =B19+1 -> 2032 | C20: =C19+1% -> 0.11
B21: =B20+1 -> 2033 | C21: =C20+1% -> 0.12
B22: =B21+1 -> 2034 | C22: =C21+1% -> 0.13
B23: =B22+1 -> 2035 | C23: =C22+1% -> 0.14
B24: =B23+1 -> 2036 | C24: =C23+1% -> 0.15
B25: =B24+1 -> 2037 | C25: =C24+1% -> 0.16
B26: =B25+1 -> 2038 | C26: =C25+1% -> 0.17
... B33: =B32+1 -> 2045 | C33: =C32+1% -> 0.24
B36: Number of full recharges required by one electric car in one year | C36: 90
B37: Energy requirement for full recharge of one electric car | C37: 50 | D37: kWh
B38: Energy supply from one charging station in a year | C38: 438000 | D38: kWh
B40: Cost of building one charging station | C40: 30000 | D40: $ in 2026
B41: Inflation on cost of building station | C41: 0.03 | D41: p.a. from 2027 onwards
B43: Proportion of electric cars expected to be scrapped at the end of each year
B44: Calendar year | C44: % cars scrapped
A45: 2026 | B45: 2026 to 2040 | C45: 0
A46: 2041 | B46: 2041 to 2045 | C46: 0.03
B48: Expenses (in $)
B49: Program admin costs | C49: 150000 | D49: p.a. in 2026
B50: Advertising and other costs | C50: 50000 | D50: p.a. in 2026
B51: Inflation on all expenses | C51: 0.03 | D51: p.a. from 2027 onwards
B55: Additional scenario
B56: Cost of petrol per litre | C56: 1.2 | D56: $ per litre in 2026
B57: Inflation in the cost of one litre of petrol | C57: 0.015 | D57: p.a. from 2027 onwards
...

Sheet Data_correction
B1: count | C1: =COUNT(C$10:C$249) -> 240 | D1: =C1=Parameters!$C$4*12 -> TRUE | P1: count | Q1: =COUNT(Q$10:Q$249) -> 240 | R1: =Q1=Parameters!$C$4*12 -> TRUE
B2: max | C2: =MAX(C10:C249) -> 234567 | P2: max | Q2: =MAX(Q10:Q249) -> 183254
B3: avg | C3: =AVERAGE(C10:C249) -> 85041.767 | P3: avg | Q3: =AVERAGE(Q10:Q249) -> 84963.581
B4: min | C4: =MIN(C10:C249) -> -52248 | D4: =C4>0 -> FALSE | P4: min | Q4: =MIN(Q10:Q249) -> 16755 | R4: =Q4>0 -> TRUE
B5: count of negative values | C5: =COUNTIF($C$10:$C$249,"<=0") -> 1 | D5: =C5=0 -> FALSE | P5: count of negative values | Q5: =COUNTIF($Q$10:$Q$249,"<=0") -> 0 | R5: =Q5=0 -> TRUE
B7: Raw data checks | P7: Corrected data
B8: Petrol car sales | P8: Petrol car sales
B9: Month | C9: =Raw_data!C4 -> Petrol car sales | P9: =B9 -> Month | Q9: =C9 -> Petrol car sales | R9: Reason for correction
B10: =Raw_data!B5 -> 46023 | C10: =Raw_data!C5 -> 16755 | P10: =B10 -> 46023 | Q10: =C10 -> 16755
B11: =Raw_data!B6 -> 46054 | C11: =Raw_data!C6 -> 18135 | P11: =B11 -> 46054 | Q11: =C11 -> 18135
B12: =Raw_data!B7 -> 46082 | C12: =Raw_data!C7 -> 19675 | P12: =B12 -> 46082 | Q12: =C12 -> 19675
B13: =Raw_data!B8 -> 46113 | C13: =Raw_data!C8 -> 21170 | P13: =B13 -> 46113 | Q13: =C13 -> 21170
B14: =Raw_data!B9 -> 46143 | C14: =Raw_data!C9 -> 21300 | P14: =B14 -> 46143 | Q14: =C14 -> 21300
B15: =Raw_data!B10 -> 46174 | C15: =Raw_data!C10 -> 21630 | P15: =B15 -> 46174 | Q15: =C15 -> 21630
B16: =Raw_data!B11 -> 46204 | C16: =Raw_data!C11 -> 23100 | P16: =B16 -> 46204 | Q16: =C16 -> 23100
B17: =Raw_data!B12 -> 46235 | C17: =Raw_data!C12 -> 24800 | P17: =B17 -> 46235 | Q17: =C17 -> 24800
B18: =Raw_data!B13 -> 46266 | C18: =Raw_data!C13 -> 26430 | P18: =B18 -> 46266 | Q18: =C18 -> 26430
B19: =Raw_data!B14 -> 46296 | C19: =Raw_data!C14 -> 28335 | P19: =B19 -> 46296 | Q19: =C19 -> 28335
B20: =Raw_data!B15 -> 46327 | C20: =Raw_data!C15 -> 25925 | P20: =B20 -> 46327 | Q20: =C20 -> 25925
B21: =Raw_data!B16 -> 46357 | C21: =Raw_data!C16 -> 27470 | P21: =B21 -> 46357 | Q21: =C21 -> 27470
... B46: =Raw_data!B41 -> 47119 | C46: =Raw_data!C41 -> 31263 | P46: =B46 -> 47119 | Q46: =C46 -> 31263
B47: =Raw_data!B42 -> 47150 | C47: =Raw_data!C42 -> 11654 | D47: seems low, outlier | P47: =B47 -> 47150 | Q47: =(Q46+Q48)/2 -> 31601 | R47: too low sales, taken average of preceding and succeeding years' sales
B48: =Raw_data!B43 -> 47178 | C48: =Raw_data!C43 -> 31939 | P48: =B48 -> 47178 | Q48: =C48 -> 31939
B49: =Raw_data!B44 -> 47209 | C49: =Raw_data!C44 -> 32215 | P49: =B49 -> 47209 | Q49: =C49 -> 32215
B50: =Raw_data!B45 -> 47239 | C50: =Raw_data!C45 -> 32566 | P50: =B50 -> 47239 | Q50: =C50 -> 32566
B51: =Raw_data!B46 -> 47270 | C51: =Raw_data!C46 -> 32831 | P51: =B51 -> 47270 | Q51: =C51 -> 32831
B52: =Raw_data!B47 -> 47300 | C52: =Raw_data!C47 -> 33227 | P52: =B52 -> 47300 | Q52: =C52 -> 33227
B53: =Raw_data!B48 -> 47331 | C53: =Raw_data!C48 -> 33523 | P53: =B53 -> 47331 | Q53: =C53 -> 33523
B54: =Raw_data!B49 -> 47362 | C54: =Raw_data!C49 -> 33809 | P54: =B54 -> 47362 | Q54: =C54 -> 33809
B55: =Raw_data!B50 -> 47392 | C55: =Raw_data!C50 -> 34119 | P55: =B55 -> 47392 | Q55: =C55 -> 34119
B56: =Raw_data!B51 -> 47423 | C56: =Raw_data!C51 -> 34455 | P56: =B56 -> 47423 | Q56: =C56 -> 34455
B57: =Raw_data!B52 -> 47453 | C57: =Raw_data!C52 -> 34801 | P57: =B57 -> 47453 | Q57: =C57 -> 34801
B58: =Raw_data!B53 -> 47484 | C58: =Raw_data!C53 -> 32840 | P58: =B58 -> 47484 | Q58: =C58 -> 32840
B59: =Raw_data!B54 -> 47515 | C59: =Raw_data!C54 -> 33711 | P59: =B59 -> 47515 | Q59: =C59 -> 33711
... B91: =Raw_data!B86 -> 48488 | C91: =Raw_data!C86 -> 51525 | P91: =B91 -> 48488 | Q91: =C91 -> 51525
B92: =Raw_data!B87 -> 48519 | C92: =Raw_data!C87 -> -52248 | D92: do not expect negative sales | P92: =B92 -> 48519 | Q92: =-C92 -> 52248 | R92: negative sales, converted to positive
B93: =Raw_data!B88 -> 48549 | C93: =Raw_data!C88 -> 52921 | P93: =B93 -> 48549 | Q93: =C93 -> 52921
B94: =Raw_data!B89 -> 48580 | C94: =Raw_data!C89 -> 52314 | P94: =B94 -> 48580 | Q94: =C94 -> 52314
B95: =Raw_data!B90 -> 48611 | C95: =Raw_data!C90 -> 53079 | P95: =B95 -> 48611 | Q95: =C95 -> 53079
B96: =Raw_data!B91 -> 48639 | C96: =Raw_data!C91 -> 53775 | P96: =B96 -> 48639 | Q96: =C96 -> 53775
...

Sheet Conversion to annual sales
B1: Corrected data before CT program launch converted from monthly to annual
K2: Check on total sales
B3: Total | D3: =SUM(D7:D246) -> 20391260 | J3: =SUM(J7:J26) -> 20391260 | K3: =IF(D3=J3,"OK","CHECK") -> OK
B5: Petrol car sales - monthly | G5: Petrol car sales - annual
B6: Month | C6: Year | D6: Petrol car sales | G6: Year | H6: Months included | I6: Check months | J6: Petrol car sales
B7: =Data_correction!P10 -> 46023 | C7: =YEAR(B7) -> 2026 | D7: =Data_correction!Q10 -> 16755 | G7: =C7 -> 2026 | H7: =COUNTIF($C$7:$C$246,G7) -> 12 | I7: =IF(H7=12,"OK","CHECK") -> OK | J7: =SUMIF($C$7:$C$246,G7,$D$7:$D$246) -> 274725
B8: =Data_correction!P11 -> 46054 | C8: =YEAR(B8) -> 2026 | D8: =Data_correction!Q11 -> 18135 | G8: =G7+1 -> 2027 | H8: =COUNTIF($C$7:$C$246,G8) -> 12 | I8: =IF(H8=12,"OK","CHECK") -> OK | J8: =SUMIF($C$7:$C$246,G8,$D$7:$D$246) -> 309931
B9: =Data_correction!P12 -> 46082 | C9: =YEAR(B9) -> 2026 | D9: =Data_correction!Q12 -> 19675 | G9: =G8+1 -> 2028 | H9: =COUNTIF($C$7:$C$246,G9) -> 12 | I9: =IF(H9=12,"OK","CHECK") -> OK | J9: =SUMIF($C$7:$C$246,G9,$D$7:$D$246) -> 350576
B10: =Data_correction!P13 -> 46113 | C10: =YEAR(B10) -> 2026 | D10: =Data_correction!Q13 -> 21170 | G10: =G9+1 -> 2029 | H10: =COUNTIF($C$7:$C$246,G10) -> 12 | I10: =IF(H10=12,"OK","CHECK") -> OK | J10: =SUMIF($C$7:$C$246,G10,$D$7:$D$246) -> 396349
B11: =Data_correction!P14 -> 46143 | C11: =YEAR(B11) -> 2026 | D11: =Data_correction!Q14 -> 21300 | G11: =G10+1 -> 2030 | H11: =COUNTIF($C$7:$C$246,G11) -> 12 | I11: =IF(H11=12,"OK","CHECK") -> OK | J11: =SUMIF($C$7:$C$246,G11,$D$7:$D$246) -> 451802
B12: =Data_correction!P15 -> 46174 | C12: =YEAR(B12) -> 2026 | D12: =Data_correction!Q15 -> 21630 | G12: =G11+1 -> 2031 | H12: =COUNTIF($C$7:$C$246,G12) -> 12 | I12: =IF(H12=12,"OK","CHECK") -> OK | J12: =SUMIF($C$7:$C$246,G12,$D$7:$D$246) -> 514867
B13: =Data_correction!P16 -> 46204 | C13: =YEAR(B13) -> 2026 | D13: =Data_correction!Q16 -> 23100 | G13: =G12+1 -> 2032 | H13: =COUNTIF($C$7:$C$246,G13) -> 12 | I13: =IF(H13=12,"OK","CHECK") -> OK | J13: =SUMIF($C$7:$C$246,G13,$D$7:$D$246) -> 587114
B14: =Data_correction!P17 -> 46235 | C14: =YEAR(B14) -> 2026 | D14: =Data_correction!Q17 -> 24800 | G14: =G13+1 -> 2033 | H14: =COUNTIF($C$7:$C$246,G14) -> 12 | I14: =IF(H14=12,"OK","CHECK") -> OK | J14: =SUMIF($C$7:$C$246,G14,$D$7:$D$246) -> 674998
B15: =Data_correction!P18 -> 46266 | C15: =YEAR(B15) -> 2026 | D15: =Data_correction!Q18 -> 26430 | G15: =G14+1 -> 2034 | H15: =COUNTIF($C$7:$C$246,G15) -> 12 | I15: =IF(H15=12,"OK","CHECK") -> OK | J15: =SUMIF($C$7:$C$246,G15,$D$7:$D$246) -> 776597
B16: =Data_correction!P19 -> 46296 | C16: =YEAR(B16) -> 2026 | D16: =Data_correction!Q19 -> 28335 | G16: =G15+1 -> 2035 | H16: =COUNTIF($C$7:$C$246,G16) -> 12 | I16: =IF(H16=12,"OK","CHECK") -> OK | J16: =SUMIF($C$7:$C$246,G16,$D$7:$D$246) -> 877331
B17: =Data_correction!P20 -> 46327 | C17: =YEAR(B17) -> 2026 | D17: =Data_correction!Q20 -> 25925 | G17: =G16+1 -> 2036 | H17: =COUNTIF($C$7:$C$246,G17) -> 12 | I17: =IF(H17=12,"OK","CHECK") -> OK | J17: =SUMIF($C$7:$C$246,G17,$D$7:$D$246) -> 982627
B18: =Data_correction!P21 -> 46357 | C18: =YEAR(B18) -> 2026 | D18: =Data_correction!Q21 -> 27470 | G18: =G17+1 -> 2037 | H18: =COUNTIF($C$7:$C$246,G18) -> 12 | I18: =IF(H18=12,"OK","CHECK") -> OK | J18: =SUMIF($C$7:$C$246,G18,$D$7:$D$246) -> 1100796.5
B19: =Data_correction!P22 -> 46388 | C19: =YEAR(B19) -> 2027 | D19: =Data_correction!Q22 -> 19233 | G19: =G18+1 -> 2038 | H19: =COUNTIF($C$7:$C$246,G19) -> 12 | I19: =IF(H19=12,"OK","CHECK") -> OK | J19: =SUMIF($C$7:$C$246,G19,$D$7:$D$246) -> 1210771
... B26: =Data_correction!P29 -> 46600 | C26: =YEAR(B26) -> 2027 | D26: =Data_correction!Q29 -> 28488 | G26: =G25+1 -> 2045 | H26: =COUNTIF($C$7:$C$246,G26) -> 12 | I26: =IF(H26=12,"OK","CHECK") -> OK | J26: =SUMIF($C$7:$C$246,G26,$D$7:$D$246) -> 2113327
B27: =Data_correction!P30 -> 46631 | C27: =YEAR(B27) -> 2027 | D27: =Data_correction!Q30 -> 29673
B28: =Data_correction!P31 -> 46661 | C28: =YEAR(B28) -> 2027 | D28: =Data_correction!Q31 -> 30877
B29: =Data_correction!P32 -> 46692 | C29: =YEAR(B29) -> 2027 | D29: =Data_correction!Q32 -> 30181
B30: =Data_correction!P33 -> 46722 | C30: =YEAR(B30) -> 2027 | D30: =Data_correction!Q33 -> 30710
B31: =Data_correction!P34 -> 46753 | C31: =YEAR(B31) -> 2028 | D31: =Data_correction!Q34 -> 23311
B32: =Data_correction!P35 -> 46784 | C32: =YEAR(B32) -> 2028 | D32: =Data_correction!Q35 -> 24355
B33: =Data_correction!P36 -> 46813 | C33: =YEAR(B33) -> 2028 | D33: =Data_correction!Q36 -> 25464
B34: =Data_correction!P37 -> 46844 | C34: =YEAR(B34) -> 2028 | D34: =Data_correction!Q37 -> 26514
B35: =Data_correction!P38 -> 46874 | C35: =YEAR(B35) -> 2028 | D35: =Data_correction!Q38 -> 27593
B36: =Data_correction!P39 -> 46905 | C36: =YEAR(B36) -> 2028 | D36: =Data_correction!Q39 -> 28688
B37: =Data_correction!P40 -> 46935 | C37: =YEAR(B37) -> 2028 | D37: =Data_correction!Q40 -> 29787
B38: =Data_correction!P41 -> 46966 | C38: =YEAR(B38) -> 2028 | D38: =Data_correction!Q41 -> 30797
... B246: =Data_correction!P249 -> 53297 | C246: =YEAR(B246) -> 2045 | D246: =Data_correction!Q249 -> 183254

Sheet Revised sales & total cars
D1: Sales of cars after CT program launch | G1: Petrol cars projection (after CT program launch) | M1: Electric cars projection
B2: Total | C2: =SUM(C7:C26) -> 20391260 | D2: =SUM(D7:D26) -> 3611231.8 | E2: =SUM(E7:E26) -> 16780028 | G2: =SUM(G7:G26) -> 1.5832302e+08 | H2: =SUM(H7:H26) -> 16780028 | I2: =SUM(I7:I26) -> 1.7510305e+08 | J2: =SUM(J7:J26) -> 7004121.8 | K2: =SUM(K7:K26) -> 1.6809892e+08 | M2: =SUM(M7:M26) -> 16863911 | N2: =SUM(N7:N26) -> 3611231.8 | O2: =SUM(O7:O26) -> 20475143 | P2: =SUM(P7:P26) -> 385874.55 | Q2: =SUM(Q7:Q26) -> 20089268
C3: Check on total | E3: Check electric car plus petrol = Total | K3: Check on cars at end of year | Q3: Check on cars at end of year
C4: =C2='Conversion to annual sales'!J3 -> TRUE | E4: =(E2+D2)=C2 -> TRUE | I4: end of year | J4: end of year | K4: =(G2+H2-J2)=K2 -> TRUE | O4: end of year | P4: end of year | Q4: =(M2+N2-P2)=Q2 -> TRUE
B5: Year | C5: Original - Petrol car sales (before CT launch) | D5: Electric car sales | E5: Revised - Petrol cars sales (after CT launch) | G5: Petrol cars at start of year | H5: Petrol sales revised | I5: Petrol cars after sales, before scrap | J5: Petrol cars scrapped | K5: Petrol cars at end of year | M5: Electric cars at start of year | N5: Electric car sales | O5: Electric cars after sales, before scrap | P5: Electric cars scrapped | Q5: Electric cars at end of year
B6: =VAL_DATE -> 46023
B7: =YEAR(B6) -> 2026 | C7: ='Conversion to annual sales'!J7 -> 274725 | D7: =C7*VLOOKUP(B7,Parameters!$B$14:$C$33,2,0) -> 13736.25 | E7: =C7-D7 -> 260988.75 | G7: =Parameters!C10 -> 5000000 | H7: =E7 -> 260988.75 | I7: =G7+H7 -> 5260988.8 | J7: =I7*Parameters!$C$11 -> 210439.55 | K7: =I7-J7 -> 5050549.2 | M7: 0 | N7: =D7 -> 13736.25 | O7: =M7+N7 -> 13736.25 | P7: =O7*VLOOKUP($B7,Parameters!$A$45:$C$46,3,TRUE) -> 0 | Q7: =O7-P7 -> 13736.25
B8: =B7+1 -> 2027 | C8: ='Conversion to annual sales'!J8 -> 309931 | D8: =C8*VLOOKUP(B8,Parameters!$B$14:$C$33,2,0) -> 18595.86 | E8: =C8-D8 -> 291335.14 | G8: =K7 -> 5050549.2 | H8: =E8 -> 291335.14 | I8: =G8+H8 -> 5341884.3 | J8: =I8*Parameters!$C$11 -> 213675.37 | K8: =I8-J8 -> 5128209 | M8: =Q7 -> 13736.25 | N8: =D8 -> 18595.86 | O8: =M8+N8 -> 32332.11 | P8: =O8*VLOOKUP($B8,Parameters!$A$45:$C$46,3,TRUE) -> 0 | Q8: =O8-P8 -> 32332.11
B9: =B8+1 -> 2028 | C9: ='Conversion to annual sales'!J9 -> 350576 | D9: =C9*VLOOKUP(B9,Parameters!$B$14:$C$33,2,0) -> 24540.32 | E9: =C9-D9 -> 326035.68 | G9: =K8 -> 5128209 | H9: =E9 -> 326035.68 | I9: =G9+H9 -> 5454244.6 | J9: =I9*Parameters!$C$11 -> 218169.79 | K9: =I9-J9 -> 5236074.9 | M9: =Q8 -> 32332.11 | N9: =D9 -> 24540.32 | O9: =M9+N9 -> 56872.43 | P9: =O9*VLOOKUP($B9,Parameters!$A$45:$C$46,3,TRUE) -> 0 | Q9: =O9-P9 -> 56872.43
B10: =B9+1 -> 2029 | C10: ='Conversion to annual sales'!J10 -> 396349 | D10: =C10*VLOOKUP(B10,Parameters!$B$14:$C$33,2,0) -> 31707.92 | E10: =C10-D10 -> 364641.08 | G10: =K9 -> 5236074.9 | H10: =E10 -> 364641.08 | I10: =G10+H10 -> 5600715.9 | J10: =I10*Parameters!$C$11 -> 224028.64 | K10: =I10-J10 -> 5376687.3 | M10: =Q9 -> 56872.43 | N10: =D10 -> 31707.92 | O10: =M10+N10 -> 88580.35 | P10: =O10*VLOOKUP($B10,Parameters!$A$45:$C$46,3,TRUE) -> 0 | Q10: =O10-P10 -> 88580.35
B11: =B10+1 -> 2030 | C11: ='Conversion to annual sales'!J11 -> 451802 | D11: =C11*VLOOKUP(B11,Parameters!$B$14:$C$33,2,0) -> 40662.18 | E11: =C11-D11 -> 411139.82 | G11: =K10 -> 5376687.3 | H11: =E11 -> 411139.82 | I11: =G11+H11 -> 5787827.1 | J11: =I11*Parameters!$C$11 -> 231513.08 | K11: =I11-J11 -> 5556314 | M11: =Q10 -> 88580.35 | N11: =D11 -> 40662.18 | O11: =M11+N11 -> 129242.53 | P11: =O11*VLOOKUP($B11,Parameters!$A$45:$C$46,3,TRUE) -> 0 | Q11: =O11-P11 -> 129242.53
B12: =B11+1 -> 2031 | C12: ='Conversion to annual sales'!J12 -> 514867 | D12: =C12*VLOOKUP(B12,Parameters!$B$14:$C$33,2,0) -> 51486.7 | E12: =C12-D12 -> 463380.3 | G12: =K11 -> 5556314 | H12: =E12 -> 463380.3 | I12: =G12+H12 -> 6019694.3 | J12: =I12*Parameters!$C$11 -> 240787.77 | K12: =I12-J12 -> 5778906.6 | M12: =Q11 -> 129242.53 | N12: =D12 -> 51486.7 | O12: =M12+N12 -> 180729.23 | P12: =O12*VLOOKUP($B12,Parameters!$A$45:$C$46,3,TRUE) -> 0 | Q12: =O12-P12 -> 180729.23
B13: =B12+1 -> 2032 | C13: ='Conversion to annual sales'!J13 -> 587114 | D13: =C13*VLOOKUP(B13,Parameters!$B$14:$C$33,2,0) -> 64582.54 | E13: =C13-D13 -> 522531.46 | G13: =K12 -> 5778906.6 | H13: =E13 -> 522531.46 | I13: =G13+H13 -> 6301438 | J13: =I13*Parameters!$C$11 -> 252057.52 | K13: =I13-J13 -> 6049380.5 | M13: =Q12 -> 180729.23 | N13: =D13 -> 64582.54 | O13: =M13+N13 -> 245311.77 | P13: =O13*VLOOKUP($B13,Parameters!$A$45:$C$46,3,TRUE) -> 0 | Q13: =O13-P13 -> 245311.77
B14: =B13+1 -> 2033 | C14: ='Conversion to annual sales'!J14 -> 674998 | D14: =C14*VLOOKUP(B14,Parameters!$B$14:$C$33,2,0) -> 80999.76 | E14: =C14-D14 -> 593998.24 | G14: =K13 -> 6049380.5 | H14: =E14 -> 593998.24 | I14: =G14+H14 -> 6643378.7 | J14: =I14*Parameters!$C$11 -> 265735.15 | K14: =I14-J14 -> 6377643.6 | M14: =Q13 -> 245311.77 | N14: =D14 -> 80999.76 | O14: =M14+N14 -> 326311.53 | P14: =O14*VLOOKUP($B14,Parameters!$A$45:$C$46,3,TRUE) -> 0 | Q14: =O14-P14 -> 326311.53
B15: =B14+1 -> 2034 | C15: ='Conversion to annual sales'!J15 -> 776597 | D15: =C15*VLOOKUP(B15,Parameters!$B$14:$C$33,2,0) -> 100957.61 | E15: =C15-D15 -> 675639.39 | G15: =K14 -> 6377643.6 | H15: =E15 -> 675639.39 | I15: =G15+H15 -> 7053283 | J15: =I15*Parameters!$C$11 -> 282131.32 | K15: =I15-J15 -> 6771151.7 | M15: =Q14 -> 326311.53 | N15: =D15 -> 100957.61 | O15: =M15+N15 -> 427269.14 | P15: =O15*VLOOKUP($B15,Parameters!$A$45:$C$46,3,TRUE) -> 0 | Q15: =O15-P15 -> 427269.14
B16: =B15+1 -> 2035 | C16: ='Conversion to annual sales'!J16 -> 877331 | D16: =C16*VLOOKUP(B16,Parameters!$B$14:$C$33,2,0) -> 122826.34 | E16: =C16-D16 -> 754504.66 | G16: =K15 -> 6771151.7 | H16: =E16 -> 754504.66 | I16: =G16+H16 -> 7525656.3 | J16: =I16*Parameters!$C$11 -> 301026.25 | K16: =I16-J16 -> 7224630.1 | M16: =Q15 -> 427269.14 | N16: =D16 -> 122826.34 | O16: =M16+N16 -> 550095.48 | P16: =O16*VLOOKUP($B16,Parameters!$A$45:$C$46,3,TRUE) -> 0 | Q16: =O16-P16 -> 550095.48
B17: =B16+1 -> 2036 | C17: ='Conversion to annual sales'!J17 -> 982627 | D17: =C17*VLOOKUP(B17,Parameters!$B$14:$C$33,2,0) -> 147394.05 | E17: =C17-D17 -> 835232.95 | G17: =K16 -> 7224630.1 | H17: =E17 -> 835232.95 | I17: =G17+H17 -> 8059863 | J17: =I17*Parameters!$C$11 -> 322394.52 | K17: =I17-J17 -> 7737468.5 | M17: =Q16 -> 550095.48 | N17: =D17 -> 147394.05 | O17: =M17+N17 -> 697489.53 | P17: =O17*VLOOKUP($B17,Parameters!$A$45:$C$46,3,TRUE) -> 0 | Q17: =O17-P17 -> 697489.53
B18: =B17+1 -> 2037 | C18: ='Conversion to annual sales'!J18 -> 1100796.5 | D18: =C18*VLOOKUP(B18,Parameters!$B$14:$C$33,2,0) -> 176127.44 | E18: =C18-D18 -> 924669.06 | G18: =K17 -> 7737468.5 | H18: =E18 -> 924669.06 | I18: =G18+H18 -> 8662137.6 | J18: =I18*Parameters!$C$11 -> 346485.5 | K18: =I18-J18 -> 8315652.1 | M18: =Q17 -> 697489.53 | N18: =D18 -> 176127.44 | O18: =M18+N18 -> 873616.97 | P18: =O18*VLOOKUP($B18,Parameters!$A$45:$C$46,3,TRUE) -> 0 | Q18: =O18-P18 -> 873616.97
B19: =B18+1 -> 2038 | C19: ='Conversion to annual sales'!J19 -> 1210771 | D19: =C19*VLOOKUP(B19,Parameters!$B$14:$C$33,2,0) -> 205831.07 | E19: =C19-D19 -> 1004939.9 | G19: =K18 -> 8315652.1 | H19: =E19 -> 1004939.9 | I19: =G19+H19 -> 9320592 | J19: =I19*Parameters!$C$11 -> 372823.68 | K19: =I19-J19 -> 8947768.3 | M19: =Q18 -> 873616.97 | N19: =D19 -> 205831.07 | O19: =M19+N19 -> 1079448 | P19: =O19*VLOOKUP($B19,Parameters!$A$45:$C$46,3,TRUE) -> 0 | Q19: =O19-P19 -> 1079448
... B26: =B25+1 -> 2045 | C26: ='Conversion to annual sales'!J26 -> 2113327 | D26: =C26*VLOOKUP(B26,Parameters!$B$14:$C$33,2,0) -> 507198.48 | E26: =C26-D26 -> 1606128.5 | G26: =K25 -> 13785440 | H26: =E26 -> 1606128.5 | I26: =G26+H26 -> 15391569 | J26: =I26*Parameters!$C$11 -> 615662.74 | K26: =I26-J26 -> 14775906 | M26: =Q25 -> 2817912.1 | N26: =D26 -> 507198.48 | O26: =M26+N26 -> 3325110.6 | P26: =O26*VLOOKUP($B26,Parameters!$A$45:$C$46,3,TRUE) -> 99753.318 | Q26: =O26-P26 -> 3225357.3

Sheet Cashflow model - base
A1: Base scenario
G2: =SUMPRODUCT(G10:G29,$R10:$R29) -> 5.4592223e+08 | K2: =SUMPRODUCT(K10:K29,$R10:$R29) -> 2758076 | N2: =SUMPRODUCT(N10:N29,$R10:$R29) -> 4.2116008e+09 | P2: NPV of CT program c/fs @ 7% | R2: =SUMPRODUCT(Q10:Q29,$R10:$R29) -> -4.7602811e+09 | S2: =(G2+K2+N2)=-R2 -> TRUE
P3: Budget | R3: =budget -> 3000000000
P4: Comparison (shortfall in budget) | R4: =R2+R3 -> -1.7602811e+09
P5: Comment:
C6: Cost of building stations | I6: Other Expenses | M6: Cost of subsidy on electric cars | P6: The NPV of the program costs is higher than the budget and hence the current budget is not sufficient to implement the CT program.
F7: =SUM(F10:F29)=E29 -> TRUE
B8: Year | C8: average no. of electric cars in a year before scrap | D8: Energy required (in kWh) for full recharge of electric cars | E8: Number of stations needed to meet charging requirement | F8: No. of new stations to be built | G8: Cost of building recharge stations | I8: Program admin costs | J8: Advertising and other | K8: Total expenses | M8: Electric car sales | N8: Cost of subsidy on electric cars | Q8: Net cashflow | R8: Discount factor (7%)
B9: ='Revised sales & total cars'!B6 -> 46023
B10: ='Revised sales & total cars'!B7 -> 2026 | C10: =AVERAGE('Revised sales & total cars'!M7,'Revised sales & total cars'!O7) -> 6868.125 | D10: =C10*no_of_recharges_per_car_pa*energy_req_fullrecharge_per_car -> 30906562 | E10: =ROUNDUP(D10/energy_supply_per_station_pa,0) -> 71 | F10: =E10 -> 71 | G10: =F10*station_build_cost*(1+station_build_cost_inflation)^(B10-$B$10) -> 2130000 | I10: =admin_cost*(1+expense_inflation)^(B10-$B$10) -> 150000 | J10: =advert_cost*(1+expense_inflation)^(B10-$B$10) -> 50000 | K10: =J10+I10 -> 200000 | M10: ='Revised sales & total cars'!D7 -> 13736.25 | N10: =M10*subsidy -> 41208750 | Q10: =-(G10+K10+N10) -> -43538750 | R10: =(1+disc_rate)^-($B10- YEAR($B$9)+0.5) -> 0.96673649
B11: ='Revised sales & total cars'!B8 -> 2027 | C11: =AVERAGE('Revised sales & total cars'!M8,'Revised sales & total cars'!O8) -> 23034.18 | D11: =C11*no_of_recharges_per_car_pa*energy_req_fullrecharge_per_car -> 103653810 | E11: =ROUNDUP(D11/energy_supply_per_station_pa,0) -> 237 | F11: =MAX(0,E11-E10) -> 166 | G11: =F11*station_build_cost*(1+station_build_cost_inflation)^(B11-$B$10) -> 5129400 | I11: =admin_cost*(1+expense_inflation)^(B11-$B$10) -> 154500 | J11: =advert_cost*(1+expense_inflation)^(B11-$B$10) -> 51500 | K11: =J11+I11 -> 206000 | M11: ='Revised sales & total cars'!D8 -> 18595.86 | N11: =M11*subsidy -> 55787580 | Q11: =-(G11+K11+N11) -> -61122980 | R11: =(1+disc_rate)^-($B11-YEAR($B$9)+0.5) -> 0.90349205
B12: ='Revised sales & total cars'!B9 -> 2028 | C12: =AVERAGE('Revised sales & total cars'!M9,'Revised sales & total cars'!O9) -> 44602.27 | D12: =C12*no_of_recharges_per_car_pa*energy_req_fullrecharge_per_car -> 200710215 | E12: =ROUNDUP(D12/energy_supply_per_station_pa,0) -> 459 | F12: =MAX(0,E12-E11) -> 222 | G12: =F12*station_build_cost*(1+station_build_cost_inflation)^(B12-$B$10) -> 7065594 | I12: =admin_cost*(1+expense_inflation)^(B12-$B$10) -> 159135 | J12: =advert_cost*(1+expense_inflation)^(B12-$B$10) -> 53045 | K12: =J12+I12 -> 212180 | M12: ='Revised sales & total cars'!D9 -> 24540.32 | N12: =M12*subsidy -> 73620960 | Q12: =-(G12+K12+N12) -> -80898734 | R12: =(1+disc_rate)^-($B12-YEAR($B$9)+0.5) -> 0.84438509
B13: ='Revised sales & total cars'!B10 -> 2029 | C13: =AVERAGE('Revised sales & total cars'!M10,'Revised sales & total cars'!O10) -> 72726.39 | D13: =C13*no_of_recharges_per_car_pa*energy_req_fullrecharge_per_car -> 3.2726876e+08 | E13: =ROUNDUP(D13/energy_supply_per_station_pa,0) -> 748 | F13: =MAX(0,E13-E12) -> 289 | G13: =F13*station_build_cost*(1+station_build_cost_inflation)^(B13-$B$10) -> 9473943.1 | I13: =admin_cost*(1+expense_inflation)^(B13-$B$10) -> 163909.05 | J13: =advert_cost*(1+expense_inflation)^(B13-$B$10) -> 54636.35 | K13: =J13+I13 -> 218545.4 | M13: ='Revised sales & total cars'!D10 -> 31707.92 | N13: =M13*subsidy -> 95123760 | Q13: =-(G13+K13+N13) -> -1.0481625e+08 | R13: =(1+disc_rate)^-($B13-YEAR($B$9)+0.5) -> 0.78914494
B14: ='Revised sales & total cars'!B11 -> 2030 | C14: =AVERAGE('Revised sales & total cars'!M11,'Revised sales & total cars'!O11) -> 108911.44 | D14: =C14*no_of_recharges_per_car_pa*energy_req_fullrecharge_per_car -> 490101480 | E14: =ROUNDUP(D14/energy_supply_per_station_pa,0) -> 1119 | F14: =MAX(0,E14-E13) -> 371 | G14: =F14*station_build_cost*(1+station_build_cost_inflation)^(B14-$B$10) -> 12526913 | I14: =admin_cost*(1+expense_inflation)^(B14-$B$10) -> 168826.32 | J14: =advert_cost*(1+expense_inflation)^(B14-$B$10) -> 56275.44 | K14: =J14+I14 -> 225101.76 | M14: ='Revised sales & total cars'!D11 -> 40662.18 | N14: =M14*subsidy -> 121986540 | Q14: =-(G14+K14+N14) -> -1.3473855e+08 | R14: =(1+disc_rate)^-($B14-YEAR($B$9)+0.5) -> 0.73751864
B15: ='Revised sales & total cars'!B12 -> 2031 | C15: =AVERAGE('Revised sales & total cars'!M12,'Revised sales & total cars'!O12) -> 154985.88 | D15: =C15*no_of_recharges_per_car_pa*energy_req_fullrecharge_per_car -> 697436460 | E15: =ROUNDUP(D15/energy_supply_per_station_pa,0) -> 1593 | F15: =MAX(0,E15-E14) -> 474 | G15: =F15*station_build_cost*(1+station_build_cost_inflation)^(B15-$B$10) -> 16484877 | I15: =admin_cost*(1+expense_inflation)^(B15-$B$10) -> 173891.11 | J15: =advert_cost*(1+expense_inflation)^(B15-$B$10) -> 57963.704 | K15: =J15+I15 -> 231854.81 | M15: ='Revised sales & total cars'!D12 -> 51486.7 | N15: =M15*subsidy -> 154460100 | Q15: =-(G15+K15+N15) -> -1.7117683e+08 | R15: =(1+disc_rate)^-($B15-YEAR($B$9)+0.5) -> 0.68926976
B16: ='Revised sales & total cars'!B13 -> 2032 | C16: =AVERAGE('Revised sales & total cars'!M13,'Revised sales & total cars'!O13) -> 213020.5 | D16: =C16*no_of_recharges_per_car_pa*energy_req_fullrecharge_per_car -> 9.5859225e+08 | E16: =ROUNDUP(D16/energy_supply_per_station_pa,0) -> 2189 | F16: =MAX(0,E16-E15) -> 596 | G16: =F16*station_build_cost*(1+station_build_cost_inflation)^(B16-$B$10) -> 21349655 | I16: =admin_cost*(1+expense_inflation)^(B16-$B$10) -> 179107.84 | J16: =advert_cost*(1+expense_inflation)^(B16-$B$10) -> 59702.615 | K16: =J16+I16 -> 238810.46 | M16: ='Revised sales & total cars'!D13 -> 64582.54 | N16: =M16*subsidy -> 1.9374762e+08 | Q16: =-(G16+K16+N16) -> -2.1533609e+08 | R16: =(1+disc_rate)^-($B16-YEAR($B$9)+0.5) -> 0.64417734
B17: ='Revised sales & total cars'!B14 -> 2033 | C17: =AVERAGE('Revised sales & total cars'!M14,'Revised sales & total cars'!O14) -> 285811.65 | D17: =C17*no_of_recharges_per_car_pa*energy_req_fullrecharge_per_car -> 1.2861524e+09 | E17: =ROUNDUP(D17/energy_supply_per_station_pa,0) -> 2937 | F17: =MAX(0,E17-E16) -> 748 | G17: =F17*station_build_cost*(1+station_build_cost_inflation)^(B17-$B$10) -> 27598370 | I17: =admin_cost*(1+expense_inflation)^(B17-$B$10) -> 184481.08 | J17: =advert_cost*(1+expense_inflation)^(B17-$B$10) -> 61493.693 | K17: =J17+I17 -> 245974.77 | M17: ='Revised sales & total cars'!D14 -> 80999.76 | N17: =M17*subsidy -> 2.4299928e+08 | Q17: =-(G17+K17+N17) -> -2.7084362e+08 | R17: =(1+disc_rate)^-($B17-YEAR($B$9)+0.5) -> 0.6020349
B18: ='Revised sales & total cars'!B15 -> 2034 | C18: =AVERAGE('Revised sales & total cars'!M15,'Revised sales & total cars'!O15) -> 376790.33 | D18: =C18*no_of_recharges_per_car_pa*energy_req_fullrecharge_per_car -> 1.6955565e+09 | E18: =ROUNDUP(D18/energy_supply_per_station_pa,0) -> 3872 | F18: =MAX(0,E18-E17) -> 935 | G18: =F18*station_build_cost*(1+station_build_cost_inflation)^(B18-$B$10) -> 35532901 | I18: =admin_cost*(1+expense_inflation)^(B18-$B$10) -> 190015.51 | J18: =advert_cost*(1+expense_inflation)^(B18-$B$10) -> 63338.504 | K18: =J18+I18 -> 253354.02 | M18: ='Revised sales & total cars'!D15 -> 100957.61 | N18: =M18*subsidy -> 3.0287283e+08 | Q18: =-(G18+K18+N18) -> -3.3865908e+08 | R18: =(1+disc_rate)^-($B18-YEAR($B$9)+0.5) -> 0.56264944
B19: ='Revised sales & total cars'!B16 -> 2035 | C19: =AVERAGE('Revised sales & total cars'!M16,'Revised sales & total cars'!O16) -> 488682.31 | D19: =C19*no_of_recharges_per_car_pa*energy_req_fullrecharge_per_car -> 2.1990704e+09 | E19: =ROUNDUP(D19/energy_supply_per_station_pa,0) -> 5021 | F19: =MAX(0,E19-E18) -> 1149 | G19: =F19*station_build_cost*(1+station_build_cost_inflation)^(B19-$B$10) -> 44975532 | I19: =admin_cost*(1+expense_inflation)^(B19-$B$10) -> 195715.98 | J19: =advert_cost*(1+expense_inflation)^(B19-$B$10) -> 65238.659 | K19: =J19+I19 -> 260954.64 | M19: ='Revised sales & total cars'!D16 -> 122826.34 | N19: =M19*subsidy -> 3.6847902e+08 | Q19: =-(G19+K19+N19) -> -4.1371551e+08 | R19: =(1+disc_rate)^-($B19-YEAR($B$9)+0.5) -> 0.5258406
B20: ='Revised sales & total cars'!B17 -> 2036 | C20: =AVERAGE('Revised sales & total cars'!M17,'Revised sales & total cars'!O17) -> 623792.51 | D20: =C20*no_of_recharges_per_car_pa*energy_req_fullrecharge_per_car -> 2.8070663e+09 | E20: =ROUNDUP(D20/energy_supply_per_station_pa,0) -> 6409 | F20: =MAX(0,E20-E19) -> 1388 | G20: =F20*station_build_cost*(1+station_build_cost_inflation)^(B20-$B$10) -> 55960678 | I20: =admin_cost*(1+expense_inflation)^(B20-$B$10) -> 201587.46 | J20: =advert_cost*(1+expense_inflation)^(B20-$B$10) -> 67195.819 | K20: =J20+I20 -> 268783.28 | M20: ='Revised sales & total cars'!D17 -> 147394.05 | N20: =M20*subsidy -> 4.4218215e+08 | Q20: =-(G20+K20+N20) -> -4.9841161e+08 | R20: =(1+disc_rate)^-($B20-YEAR($B$9)+0.5) -> 0.49143981
B21: ='Revised sales & total cars'!B18 -> 2037 | C21: =AVERAGE('Revised sales & total cars'!M18,'Revised sales & total cars'!O18) -> 785553.25 | D21: =C21*no_of_recharges_per_car_pa*energy_req_fullrecharge_per_car -> 3534989625 | E21: =ROUNDUP(D21/energy_supply_per_station_pa,0) -> 8071 | F21: =MAX(0,E21-E20) -> 1662 | G21: =F21*station_build_cost*(1+station_build_cost_inflation)^(B21-$B$10) -> 69017901 | I21: =admin_cost*(1+expense_inflation)^(B21-$B$10) -> 207635.08 | J21: =advert_cost*(1+expense_inflation)^(B21-$B$10) -> 69211.694 | K21: =J21+I21 -> 276846.77 | M21: ='Revised sales & total cars'!D18 -> 176127.44 | N21: =M21*subsidy -> 528382320 | Q21: =-(G21+K21+N21) -> -5.9767707e+08 | R21: =(1+disc_rate)^-($B21-YEAR($B$9)+0.5) -> 0.45928954
B22: ='Revised sales & total cars'!B19 -> 2038 | C22: =AVERAGE('Revised sales & total cars'!M19,'Revised sales & total cars'!O19) -> 976532.51 | D22: =C22*no_of_recharges_per_car_pa*energy_req_fullrecharge_per_car -> 4.3943963e+09 | E22: =ROUNDUP(D22/energy_supply_per_station_pa,0) -> 10033 | F22: =MAX(0,E22-E21) -> 1962 | G22: =F22*station_build_cost*(1+station_build_cost_inflation)^(B22-$B$10) -> 83920286 | I22: =admin_cost*(1+expense_inflation)^(B22-$B$10) -> 213864.13 | J22: =advert_cost*(1+expense_inflation)^(B22-$B$10) -> 71288.044 | K22: =J22+I22 -> 285152.18 | M22: ='Revised sales & total cars'!D19 -> 205831.07 | N22: =M22*subsidy -> 617493210 | Q22: =-(G22+K22+N22) -> -7.0169865e+08 | R22: =(1+disc_rate)^-($B22-YEAR($B$9)+0.5) -> 0.42924256
... B29: ='Revised sales & total cars'!B26 -> 2045 | C29: =AVERAGE('Revised sales & total cars'!M26,'Revised sales & total cars'!O26) -> 3071511.4 | D29: =C29*no_of_recharges_per_car_pa*energy_req_fullrecharge_per_car -> 1.3821801e+10 | E29: =ROUNDUP(D29/energy_supply_per_station_pa,0) -> 31557 | F29: =MAX(0,E29-E28) -> 4022 | G29: =F29*station_build_cost*(1+station_build_cost_inflation)^(B29-$B$10) -> 2.1157804e+08 | I29: =admin_cost*(1+expense_inflation)^(B29-$B$10) -> 263025.91 | J29: =advert_cost*(1+expense_inflation)^(B29-$B$10) -> 87675.303 | K29: =J29+I29 -> 350701.21 | M29: ='Revised sales & total cars'!D26 -> 507198.48 | N29: =M29*subsidy -> 1.5215954e+09 | Q29: =-(G29+K29+N29) -> -1.7335242e+09 | R29: =(1+disc_rate)^-($B29-YEAR($B$9)+0.5) -> 0.2673107

Sheet Cashflow model - additional
A1: Additional scenario | V1: Reasonable: The NPV of program cashflows is higher than that under base due to the positive tax income.
G2: =SUMPRODUCT(G10:G29,$U10:$U29) -> 5.4592223e+08 | K2: =SUMPRODUCT(K10:K29,$U10:$U29) -> 2758076 | N2: =SUMPRODUCT(N10:N29,$U10:$U29) -> 4.2116008e+09 | Q2: =SUMPRODUCT(Q10:Q29,$U10:$U29) -> 3.3178924e+09 | S2: NPV of CT program c/fs @ 7% | U2: =SUMPRODUCT(T10:T29,U10:U29) -> -1.4423886e+09 | V2: =U2>'Cashflow model - base'!R2 -> TRUE | W2: =(U2-'Cashflow model - base'!R2)=Q2 -> TRUE
S3: Budget | U3: =budget -> 3000000000
S4: Comparison (excess budget) | U4: =U2+U3 -> 1.5576114e+09
S5: Comment: In this scenario, the entire budget will not be used to meet the program costs as the budget exceeds the NPV of the program cashflows.
C6: Cost of building stations | I6: Other Expenses | M6: Cost of subsidy on electric cars | P6: Tax income on petrol cost
F7: =SUM(F10:F29)=E29 -> TRUE
B8: Year | C8: average no. of electric cars in a year before scrap | D8: Energy required (in kWh) for full recharge of electric cars | E8: Number of stations needed to meet charging requirement | F8: No. of new stations to be built | G8: Cost of building recharge stations | I8: Program admin costs | J8: Advertising and other | K8: Total expenses | M8: Electric car sales | N8: Cost of subsidy on electric cars | P8: Average no. of petrol cars in a year before scrap | Q8: Tax income from petrol cars | T8: Net cashflow | U8: Discount factor (7%)
B9: ='Revised sales & total cars'!B6 -> 46023
B10: ='Revised sales & total cars'!B7 -> 2026 | C10: =AVERAGE('Revised sales & total cars'!M7,'Revised sales & total cars'!O7) -> 6868.125 | D10: =C10*no_of_recharges_per_car_pa*energy_req_fullrecharge_per_car -> 30906562 | E10: =ROUNDUP(D10/energy_supply_per_station_pa,0) -> 71 | F10: =E10 -> 71 | G10: =F10*station_build_cost*(1+station_build_cost_inflation)^(B10-$B$10) -> 2130000 | I10: =admin_cost*(1+expense_inflation)^(B10-$B$10) -> 150000 | J10: =advert_cost*(1+expense_inflation)^(B10-$B$10) -> 50000 | K10: =J10+I10 -> 200000 | M10: ='Revised sales & total cars'!D7 -> 13736.25 | N10: =M10*subsidy -> 41208750 | P10: =AVERAGE('Revised sales & total cars'!G7,'Revised sales & total cars'!I7) -> 5130494.4 | Q10: =P10*avg_petrol_consump_pa*tax_rate_petrol*petrol_cost_per_litre*(1+inflation_petrol)^(B10-$B$10) -> 1.846978e+08 | T10: =-(G10+K10+N10)+Q10 -> 1.4115905e+08 | U10: =(1+disc_rate)^-($B10- YEAR($B$9)+0.5) -> 0.96673649
B11: ='Revised sales & total cars'!B8 -> 2027 | C11: =AVERAGE('Revised sales & total cars'!M8,'Revised sales & total cars'!O8) -> 23034.18 | D11: =C11*no_of_recharges_per_car_pa*energy_req_fullrecharge_per_car -> 103653810 | E11: =ROUNDUP(D11/energy_supply_per_station_pa,0) -> 237 | F11: =MAX(0,E11-E10) -> 166 | G11: =F11*station_build_cost*(1+station_build_cost_inflation)^(B11-$B$10) -> 5129400 | I11: =admin_cost*(1+expense_inflation)^(B11-$B$10) -> 154500 | J11: =advert_cost*(1+expense_inflation)^(B11-$B$10) -> 51500 | K11: =J11+I11 -> 206000 | M11: ='Revised sales & total cars'!D8 -> 18595.86 | N11: =M11*subsidy -> 55787580 | P11: =AVERAGE('Revised sales & total cars'!G8,'Revised sales & total cars'!I8) -> 5196216.8 | Q11: =P11*avg_petrol_consump_pa*tax_rate_petrol*petrol_cost_per_litre*(1+inflation_petrol)^(B11-$B$10) -> 1.8986976e+08 | T11: =-(G11+K11+N11)+Q11 -> 1.2874678e+08 | U11: =(1+disc_rate)^-($B11-YEAR($B$9)+0.5) -> 0.90349205
B12: ='Revised sales & total cars'!B9 -> 2028 | C12: =AVERAGE('Revised sales & total cars'!M9,'Revised sales & total cars'!O9) -> 44602.27 | D12: =C12*no_of_recharges_per_car_pa*energy_req_fullrecharge_per_car -> 200710215 | E12: =ROUNDUP(D12/energy_supply_per_station_pa,0) -> 459 | F12: =MAX(0,E12-E11) -> 222 | G12: =F12*station_build_cost*(1+station_build_cost_inflation)^(B12-$B$10) -> 7065594 | I12: =admin_cost*(1+expense_inflation)^(B12-$B$10) -> 159135 | J12: =advert_cost*(1+expense_inflation)^(B12-$B$10) -> 53045 | K12: =J12+I12 -> 212180 | M12: ='Revised sales & total cars'!D9 -> 24540.32 | N12: =M12*subsidy -> 73620960 | P12: =AVERAGE('Revised sales & total cars'!G9,'Revised sales & total cars'!I9) -> 5291226.8 | Q12: =P12*avg_petrol_consump_pa*tax_rate_petrol*petrol_cost_per_litre*(1+inflation_petrol)^(B12-$B$10) -> 1.9624155e+08 | T12: =-(G12+K12+N12)+Q12 -> 1.1534281e+08 | U12: =(1+disc_rate)^-($B12-YEAR($B$9)+0.5) -> 0.84438509
B13: ='Revised sales & total cars'!B10 -> 2029 | C13: =AVERAGE('Revised sales & total cars'!M10,'Revised sales & total cars'!O10) -> 72726.39 | D13: =C13*no_of_recharges_per_car_pa*energy_req_fullrecharge_per_car -> 3.2726876e+08 | E13: =ROUNDUP(D13/energy_supply_per_station_pa,0) -> 748 | F13: =MAX(0,E13-E12) -> 289 | G13: =F13*station_build_cost*(1+station_build_cost_inflation)^(B13-$B$10) -> 9473943.1 | I13: =admin_cost*(1+expense_inflation)^(B13-$B$10) -> 163909.05 | J13: =advert_cost*(1+expense_inflation)^(B13-$B$10) -> 54636.35 | K13: =J13+I13 -> 218545.4 | M13: ='Revised sales & total cars'!D10 -> 31707.92 | N13: =M13*subsidy -> 95123760 | P13: =AVERAGE('Revised sales & total cars'!G10,'Revised sales & total cars'!I10) -> 5418395.4 | Q13: =P13*avg_petrol_consump_pa*tax_rate_petrol*petrol_cost_per_litre*(1+inflation_petrol)^(B13-$B$10) -> 2.0397236e+08 | T13: =-(G13+K13+N13)+Q13 -> 99156112 | U13: =(1+disc_rate)^-($B13-YEAR($B$9)+0.5) -> 0.78914494
B14: ='Revised sales & total cars'!B11 -> 2030 | C14: =AVERAGE('Revised sales & total cars'!M11,'Revised sales & total cars'!O11) -> 108911.44 | D14: =C14*no_of_recharges_per_car_pa*energy_req_fullrecharge_per_car -> 490101480 | E14: =ROUNDUP(D14/energy_supply_per_station_pa,0) -> 1119 | F14: =MAX(0,E14-E13) -> 371 | G14: =F14*station_build_cost*(1+station_build_cost_inflation)^(B14-$B$10) -> 12526913 | I14: =admin_cost*(1+expense_inflation)^(B14-$B$10) -> 168826.32 | J14: =advert_cost*(1+expense_inflation)^(B14-$B$10) -> 56275.44 | K14: =J14+I14 -> 225101.76 | M14: ='Revised sales & total cars'!D11 -> 40662.18 | N14: =M14*subsidy -> 121986540 | P14: =AVERAGE('Revised sales & total cars'!G11,'Revised sales & total cars'!I11) -> 5582257.2 | Q14: =P14*avg_petrol_consump_pa*tax_rate_petrol*petrol_cost_per_litre*(1+inflation_petrol)^(B14-$B$10) -> 2.1329296e+08 | T14: =-(G14+K14+N14)+Q14 -> 78554401 | U14: =(1+disc_rate)^-($B14-YEAR($B$9)+0.5) -> 0.73751864
B15: ='Revised sales & total cars'!B12 -> 2031 | C15: =AVERAGE('Revised sales & total cars'!M12,'Revised sales & total cars'!O12) -> 154985.88 | D15: =C15*no_of_recharges_per_car_pa*energy_req_fullrecharge_per_car -> 697436460 | E15: =ROUNDUP(D15/energy_supply_per_station_pa,0) -> 1593 | F15: =MAX(0,E15-E14) -> 474 | G15: =F15*station_build_cost*(1+station_build_cost_inflation)^(B15-$B$10) -> 16484877 | I15: =admin_cost*(1+expense_inflation)^(B15-$B$10) -> 173891.11 | J15: =advert_cost*(1+expense_inflation)^(B15-$B$10) -> 57963.704 | K15: =J15+I15 -> 231854.81 | M15: ='Revised sales & total cars'!D12 -> 51486.7 | N15: =M15*subsidy -> 154460100 | P15: =AVERAGE('Revised sales & total cars'!G12,'Revised sales & total cars'!I12) -> 5788004.2 | Q15: =P15*avg_petrol_consump_pa*tax_rate_petrol*petrol_cost_per_litre*(1+inflation_petrol)^(B15-$B$10) -> 2.2447168e+08 | T15: =-(G15+K15+N15)+Q15 -> 53294844 | U15: =(1+disc_rate)^-($B15-YEAR($B$9)+0.5) -> 0.68926976
B16: ='Revised sales & total cars'!B13 -> 2032 | C16: =AVERAGE('Revised sales & total cars'!M13,'Revised sales & total cars'!O13) -> 213020.5 | D16: =C16*no_of_recharges_per_car_pa*energy_req_fullrecharge_per_car -> 9.5859225e+08 | E16: =ROUNDUP(D16/energy_supply_per_station_pa,0) -> 2189 | F16: =MAX(0,E16-E15) -> 596 | G16: =F16*station_build_cost*(1+station_build_cost_inflation)^(B16-$B$10) -> 21349655 | I16: =admin_cost*(1+expense_inflation)^(B16-$B$10) -> 179107.84 | J16: =advert_cost*(1+expense_inflation)^(B16-$B$10) -> 59702.615 | K16: =J16+I16 -> 238810.46 | M16: ='Revised sales & total cars'!D13 -> 64582.54 | N16: =M16*subsidy -> 1.9374762e+08 | P16: =AVERAGE('Revised sales & total cars'!G13,'Revised sales & total cars'!I13) -> 6040172.3 | Q16: =P16*avg_petrol_consump_pa*tax_rate_petrol*petrol_cost_per_litre*(1+inflation_petrol)^(B16-$B$10) -> 2.3776509e+08 | T16: =-(G16+K16+N16)+Q16 -> 22429000 | U16: =(1+disc_rate)^-($B16-YEAR($B$9)+0.5) -> 0.64417734
B17: ='Revised sales & total cars'!B14 -> 2033 | C17: =AVERAGE('Revised sales & total cars'!M14,'Revised sales & total cars'!O14) -> 285811.65 | D17: =C17*no_of_recharges_per_car_pa*energy_req_fullrecharge_per_car -> 1.2861524e+09 | E17: =ROUNDUP(D17/energy_supply_per_station_pa,0) -> 2937 | F17: =MAX(0,E17-E16) -> 748 | G17: =F17*station_build_cost*(1+station_build_cost_inflation)^(B17-$B$10) -> 27598370 | I17: =admin_cost*(1+expense_inflation)^(B17-$B$10) -> 184481.08 | J17: =advert_cost*(1+expense_inflation)^(B17-$B$10) -> 61493.693 | K17: =J17+I17 -> 245974.77 | M17: ='Revised sales & total cars'!D14 -> 80999.76 | N17: =M17*subsidy -> 2.4299928e+08 | P17: =AVERAGE('Revised sales & total cars'!G14,'Revised sales & total cars'!I14) -> 6346379.6 | Q17: =P17*avg_petrol_consump_pa*tax_rate_petrol*petrol_cost_per_litre*(1+inflation_petrol)^(B17-$B$10) -> 2.535659e+08 | T17: =-(G17+K17+N17)+Q17 -> -17277727 | U17: =(1+disc_rate)^-($B17-YEAR($B$9)+0.5) -> 0.6020349
B18: ='Revised sales & total cars'!B15 -> 2034 | C18: =AVERAGE('Revised sales & total cars'!M15,'Revised sales & total cars'!O15) -> 376790.33 | D18: =C18*no_of_recharges_per_car_pa*energy_req_fullrecharge_per_car -> 1.6955565e+09 | E18: =ROUNDUP(D18/energy_supply_per_station_pa,0) -> 3872 | F18: =MAX(0,E18-E17) -> 935 | G18: =F18*station_build_cost*(1+station_build_cost_inflation)^(B18-$B$10) -> 35532901 | I18: =admin_cost*(1+expense_inflation)^(B18-$B$10) -> 190015.51 | J18: =advert_cost*(1+expense_inflation)^(B18-$B$10) -> 63338.504 | K18: =J18+I18 -> 253354.02 | M18: ='Revised sales & total cars'!D15 -> 100957.61 | N18: =M18*subsidy -> 3.0287283e+08 | P18: =AVERAGE('Revised sales & total cars'!G15,'Revised sales & total cars'!I15) -> 6715463.3 | Q18: =P18*avg_petrol_consump_pa*tax_rate_petrol*petrol_cost_per_litre*(1+inflation_petrol)^(B18-$B$10) -> 2.7233711e+08 | T18: =-(G18+K18+N18)+Q18 -> -66321979 | U18: =(1+disc_rate)^-($B18-YEAR($B$9)+0.5) -> 0.56264944
B19: ='Revised sales & total cars'!B16 -> 2035 | C19: =AVERAGE('Revised sales & total cars'!M16,'Revised sales & total cars'!O16) -> 488682.31 | D19: =C19*no_of_recharges_per_car_pa*energy_req_fullrecharge_per_car -> 2.1990704e+09 | E19: =ROUNDUP(D19/energy_supply_per_station_pa,0) -> 5021 | F19: =MAX(0,E19-E18) -> 1149 | G19: =F19*station_build_cost*(1+station_build_cost_inflation)^(B19-$B$10) -> 44975532 | I19: =admin_cost*(1+expense_inflation)^(B19-$B$10) -> 195715.98 | J19: =advert_cost*(1+expense_inflation)^(B19-$B$10) -> 65238.659 | K19: =J19+I19 -> 260954.64 | M19: ='Revised sales & total cars'!D16 -> 122826.34 | N19: =M19*subsidy -> 3.6847902e+08 | P19: =AVERAGE('Revised sales & total cars'!G16,'Revised sales & total cars'!I16) -> 7148404 | Q19: =P19*avg_petrol_consump_pa*tax_rate_petrol*petrol_cost_per_litre*(1+inflation_petrol)^(B19-$B$10) -> 2.9424288e+08 | T19: =-(G19+K19+N19)+Q19 -> -1.1947262e+08 | U19: =(1+disc_rate)^-($B19-YEAR($B$9)+0.5) -> 0.5258406
B20: ='Revised sales & total cars'!B17 -> 2036 | C20: =AVERAGE('Revised sales & total cars'!M17,'Revised sales & total cars'!O17) -> 623792.51 | D20: =C20*no_of_recharges_per_car_pa*energy_req_fullrecharge_per_car -> 2.8070663e+09 | E20: =ROUNDUP(D20/energy_supply_per_station_pa,0) -> 6409 | F20: =MAX(0,E20-E19) -> 1388 | G20: =F20*station_build_cost*(1+station_build_cost_inflation)^(B20-$B$10) -> 55960678 | I20: =admin_cost*(1+expense_inflation)^(B20-$B$10) -> 201587.46 | J20: =advert_cost*(1+expense_inflation)^(B20-$B$10) -> 67195.819 | K20: =J20+I20 -> 268783.28 | M20: ='Revised sales & total cars'!D17 -> 147394.05 | N20: =M20*subsidy -> 4.4218215e+08 | P20: =AVERAGE('Revised sales & total cars'!G17,'Revised sales & total cars'!I17) -> 7642246.5 | Q20: =P20*avg_petrol_consump_pa*tax_rate_petrol*petrol_cost_per_litre*(1+inflation_petrol)^(B20-$B$10) -> 3.1928901e+08 | T20: =-(G20+K20+N20)+Q20 -> -1.791226e+08 | U20: =(1+disc_rate)^-($B20-YEAR($B$9)+0.5) -> 0.49143981
B21: ='Revised sales & total cars'!B18 -> 2037 | C21: =AVERAGE('Revised sales & total cars'!M18,'Revised sales & total cars'!O18) -> 785553.25 | D21: =C21*no_of_recharges_per_car_pa*energy_req_fullrecharge_per_car -> 3534989625 | E21: =ROUNDUP(D21/energy_supply_per_station_pa,0) -> 8071 | F21: =MAX(0,E21-E20) -> 1662 | G21: =F21*station_build_cost*(1+station_build_cost_inflation)^(B21-$B$10) -> 69017901 | I21: =admin_cost*(1+expense_inflation)^(B21-$B$10) -> 207635.08 | J21: =advert_cost*(1+expense_inflation)^(B21-$B$10) -> 69211.694 | K21: =J21+I21 -> 276846.77 | M21: ='Revised sales & total cars'!D18 -> 176127.44 | N21: =M21*subsidy -> 528382320 | P21: =AVERAGE('Revised sales & total cars'!G18,'Revised sales & total cars'!I18) -> 8199803 | Q21: =P21*avg_petrol_consump_pa*tax_rate_petrol*petrol_cost_per_litre*(1+inflation_petrol)^(B21-$B$10) -> 3.4772217e+08 | T21: =-(G21+K21+N21)+Q21 -> -2.4995489e+08 | U21: =(1+disc_rate)^-($B21-YEAR($B$9)+0.5) -> 0.45928954
B22: ='Revised sales & total cars'!B19 -> 2038 | C22: =AVERAGE('Revised sales & total cars'!M19,'Revised sales & total cars'!O19) -> 976532.51 | D22: =C22*no_of_recharges_per_car_pa*energy_req_fullrecharge_per_car -> 4.3943963e+09 | E22: =ROUNDUP(D22/energy_supply_per_station_pa,0) -> 10033 | F22: =MAX(0,E22-E21) -> 1962 | G22: =F22*station_build_cost*(1+station_build_cost_inflation)^(B22-$B$10) -> 83920286 | I22: =admin_cost*(1+expense_inflation)^(B22-$B$10) -> 213864.13 | J22: =advert_cost*(1+expense_inflation)^(B22-$B$10) -> 71288.044 | K22: =J22+I22 -> 285152.18 | M22: ='Revised sales & total cars'!D19 -> 205831.07 | N22: =M22*subsidy -> 617493210 | P22: =AVERAGE('Revised sales & total cars'!G19,'Revised sales & total cars'!I19) -> 8818122 | Q22: =P22*avg_petrol_consump_pa*tax_rate_petrol*petrol_cost_per_litre*(1+inflation_petrol)^(B22-$B$10) -> 3.7955185e+08 | T22: =-(G22+K22+N22)+Q22 -> -3.221468e+08 | U22: =(1+disc_rate)^-($B22-YEAR($B$9)+0.5) -> 0.42924256
... B29: ='Revised sales & total cars'!B26 -> 2045 | C29: =AVERAGE('Revised sales & total cars'!M26,'Revised sales & total cars'!O26) -> 3071511.4 | D29: =C29*no_of_recharges_per_car_pa*energy_req_fullrecharge_per_car -> 1.3821801e+10 | E29: =ROUNDUP(D29/energy_supply_per_station_pa,0) -> 31557 | F29: =MAX(0,E29-E28) -> 4022 | G29: =F29*station_build_cost*(1+station_build_cost_inflation)^(B29-$B$10) -> 2.1157804e+08 | I29: =admin_cost*(1+expense_inflation)^(B29-$B$10) -> 263025.91 | J29: =advert_cost*(1+expense_inflation)^(B29-$B$10) -> 87675.303 | K29: =J29+I29 -> 350701.21 | M29: ='Revised sales & total cars'!D26 -> 507198.48 | N29: =M29*subsidy -> 1.5215954e+09 | P29: =AVERAGE('Revised sales & total cars'!G26,'Revised sales & total cars'!I26) -> 14588504 | Q29: =P29*avg_petrol_consump_pa*tax_rate_petrol*petrol_cost_per_litre*(1+inflation_petrol)^(B29-$B$10) -> 6.9689616e+08 | T29: =-(G29+K29+N29)+Q29 -> -1.036628e+09 | U29: =(1+disc_rate)^-($B29-YEAR($B$9)+0.5) -> 0.2673107

Sheet Results summary
B2: Summary of results (at 7% p.a. discount rate) (in $)
B4: =VAL_DATE -> 46023 | C4: Base scenario | E4: Additional scenario
B5: Budget | C5: NPV of program c/fs | D5: Shortfall in budget | E5: NPV of program c/fs | F5: Excess budget
B6: =Parameters!C5 -> 3000000000 | C6: ='Cashflow model - base'!$R$2 -> -4.7602811e+09 | D6: ='Cashflow model - base'!R4 -> -1.7602811e+09 | E6: ='Cashflow model - additional'!$U$2 -> -1.4423886e+09 | F6: ='Cashflow model - additional'!U4 -> 1.5576114e+09

Sheet Pie_chart
C3: (in $)
B4: NPV of total expense cashflows | C4: ='Cashflow model - additional'!K2 -> 2758076
B5: NPV of "subsidy cost on electric cars net of tax income on petrol cars" | C5: ='Cashflow model - additional'!N2-'Cashflow model - additional'!Q2 -> 8.9370834e+08
B6: NPV of cost of building recharging stations | C6: ='Cashflow model - additional'!G2 -> 5.4592223e+08
B7: Excess budget in additional scenario | C7: ='Cashflow model - additional'!U4 -> 1.5576114e+09
B8: Total-> | C8: =SUM(C4:C7) -> 3e+09 | D8: -> sum should be equal to budget
C9: =budget=C8 -> TRUE
