Workbook

Sheet Data
B1: Raw data provided by the client
B4: Movie schedule and seating capacity by screen
B5: Screen | C5: Capacity | D5: Jan | E5: Feb | F5: Mar | G5: Apr | H5: May | I5: Jun | J5: Jul | K5: Aug | L5: Sep | M5: Oct | N5: Nov | O5: Dec
B6: 1 | C6: 850 | D6: Major 1 | E6: Major 1 | F6: Regular 3 | G6: Major 2 | H6: Major 2 | I6: Regular 6 | J6: Epic 1 | K6: Epic 1 | L6: Regular 7 | M6: Major | N6: Major 3 | O6: Regular 10
B7: 2 | C7: 450 | D7: Major 1 | E7: Regular 1 | F7: Major 1 | G7: Major 2 | H7: Regular 5 | I7: Major 2 | J7: Epic 1 | K7: Epic 1 | L7: Epic 1 | M7: Major 3 | N7: Regular 10 | O7: Major 3
B8: 3 | C8: 200 | D8: Regular 1 | E8: Regular 2 | F8: Regular 3 | G8: Regular 4 | H8: Regular 4 | I8: Regular 5 | J8: Epic 1 | K8: Regular 7 | L8: Epic 1 | M8: Epic 1 | N8: Regular 9 | O8: Regular 10
B9: 4 | C9: 150 | D9: Regular 2 | E9: Regular 2 | F9: Regular 1 | G9: Regular 3 | H9: Regular 4 | I9: Regular 4 | J9: Regular 6 | K9: Regular 8 | L9: Regular 8 | M9: Regular 9 | N9: Regular 9 | O9: Regular 9
B12: Projected utilisation rate | C12: Regular | D12: Major | E12: Epic | H12: Commission arrangement with movie distributors (% of ticket price) | I12: Regular | J12: Major | K12: Epic
B13: Month | C13: R | D13: M | E13: E | H13: Month | I13: R | J13: M | K13: E
B14: 1 | C14: 0.85 | D14: 0.93 | E14: 0.98 | H14: 1 | I14: 0.45 | J14: 0.55 | K14: 0.65
B15: 2 | C15: 0.65 | D15: 0.8 | E15: 0.85 | H15: 2 | I15: 0.35 | J15: 0.45 | K15: 0.55
B16: 3 | C16: 0.45 | D16: 0.65 | E16: 0.7 | H16: 3 | I16: 0.15 | J16: 0.3 | K16: 0.45
B17: 4 | C17: 0 | D17: 0 | E17: 0.6 | H17: 4 | I17: 0 | J17: 0 | K17: 0.2
B20: A. Number of movies seen over a year | C20: B. Unique Cinemagoers (annual) | D20: C. Proportion buying snacks
B21: 1 | C21: 185220 | D21: 0.22257935
B22: 2 | C22: 270000 | D22: =D21*1.3 -> 0.28935316
B23: 3 | C23: 180000 | D23: =D21*1.35 -> 0.30048212
B24: 4 | C24: 135000 | D24: 0.39
B25: 5 | C25: 81000 | D25: 0.35
B26: 6 | C26: 54000 | D26: 0.42
B27: 7 | C27: 27000 | D27: 0.4
B28: 8 | C28: 5400 | D28: 0.5
B29: 9 | C29: 3600 | D29: 0.65
B30: 10 | C30: 1080 | D30: 0.57
B31: 11 | C31: 1080 | D31: 0.68
B32: 12 | C32: 900 | D32: 0.59
B33: 13 | C33: 540 | D33: 0.7
B34: 14 | C34: 360 | D34: 0.71

Sheet Data_checks
B1: Data checks
B4: =Data!B4 -> Movie schedule and seating capacity by screen
B5: =Data!B5 -> Screen | C5: =Data!C5 -> Capacity | D5: =Data!D5 -> Jan | E5: =Data!E5 -> Feb | F5: =Data!F5 -> Mar | G5: =Data!G5 -> Apr | H5: =Data!H5 -> May | I5: =Data!I5 -> Jun | ... O5: =Data!O5 -> Dec
B6: =Data!B6 -> 1 | C6: =Data!C6 -> 850 | D6: =Data!D6 -> Major 1 | E6: =Data!E6 -> Major 1 | F6: =Data!F6 -> Regular 3 | G6: =Data!G6 -> Major 2 | H6: =Data!H6 -> Major 2 | I6: =Data!I6 -> Regular 6 | ... O6: =Data!O6 -> Regular 10
B7: =Data!B7 -> 2 | C7: =Data!C7 -> 450 | D7: =Data!D7 -> Major 1 | E7: =Data!E7 -> Regular 1 | F7: =Data!F7 -> Major 1 | G7: =Data!G7 -> Major 2 | H7: =Data!H7 -> Regular 5 | I7: =Data!I7 -> Major 2 | ... O7: =Data!O7 -> Major 3
B8: =Data!B8 -> 3 | C8: =Data!C8 -> 200 | D8: =Data!D8 -> Regular 1 | E8: =Data!E8 -> Regular 2 | F8: =Data!F8 -> Regular 3 | G8: =Data!G8 -> Regular 4 | H8: =Data!H8 -> Regular 4 | I8: =Data!I8 -> Regular 5 | ... O8: =Data!O8 -> Regular 10
B9: =Data!B9 -> 4 | C9: =Data!C9 -> 150 | D9: =Data!D9 -> Regular 2 | E9: =Data!E9 -> Regular 2 | F9: =Data!F9 -> Regular 1 | G9: =Data!G9 -> Regular 3 | H9: =Data!H9 -> Regular 4 | I9: =Data!I9 -> Regular 4 | ... O9: =Data!O9 -> Regular 9
B11: Checks:
C12: Equivalent number of monthly screenings
B13: Epic 1 | C13: =COUNTIF($D$6:$O$9,B13) -> 8 | E13: Commentary
B14: Major 1 | C14: =COUNTIF($D$6:$O$9,B14) -> 4 | E14: It makes sense the Epic release is shown the most times, followed by Major releases.
B15: Major 2 | C15: =COUNTIF($D$6:$O$9,B15) -> 4 | E15: Each movie is shown for two to four months over the year. No reasons to doubt the validity of the movie schedule
B16: Major 3 | C16: =COUNTIF($D$6:$O$9,B16) -> 3
B17: Regular 1 | C17: =COUNTIF($D$6:$O$9,B17) -> 3
B18: Regular 2 | C18: =COUNTIF($D$6:$O$9,B18) -> 3
B19: Regular 3 | C19: =COUNTIF($D$6:$O$9,B19) -> 3
B20: Regular 4 | C20: =COUNTIF($D$6:$O$9,B20) -> 4
B21: Regular 5 | C21: =COUNTIF($D$6:$O$9,B21) -> 2
B22: Regular 6 | C22: =COUNTIF($D$6:$O$9,B22) -> 2
B23: Regular 7 | C23: =COUNTIF($D$6:$O$9,B23) -> 2
B24: Regular 8 | C24: =COUNTIF($D$6:$O$9,B24) -> 2
B25: Regular 9 | C25: =COUNTIF($D$6:$O$9,B25) -> 4
B26: Regular 10 | C26: =COUNTIF($D$6:$O$9,B26) -> 3
B27: Total | C27: =SUM(C13:C26) -> 47 | D27: =COUNTA(D6:O9)=C27 -> FALSE
B29: =Data!B12 -> Projected utilisation rate | H29: =Data!H12 -> Commission arrangement with movie distributors (% of ticket price)
B30: Month | C30: =Data!C13 -> R | D30: =Data!D13 -> M | E30: =Data!E13 -> E | H30: Month | I30: =Data!I13 -> R | J30: =Data!J13 -> M | K30: =Data!K13 -> E
B31: 1 | C31: =Data!C14 -> 0.85 | D31: =Data!D14 -> 0.93 | E31: =Data!E14 -> 0.98 | H31: 1 | I31: =Data!I14 -> 0.45 | J31: =Data!J14 -> 0.55 | K31: =Data!K14 -> 0.65
B32: 2 | C32: =Data!C15 -> 0.65 | D32: =Data!D15 -> 0.8 | E32: =Data!E15 -> 0.85 | H32: 2 | I32: =Data!I15 -> 0.35 | J32: =Data!J15 -> 0.45 | K32: =Data!K15 -> 0.55
B33: 3 | C33: =Data!C16 -> 0.45 | D33: =Data!D16 -> 0.65 | E33: =Data!E16 -> 0.7 | H33: 3 | I33: =Data!I16 -> 0.15 | J33: =Data!J16 -> 0.3 | K33: =Data!K16 -> 0.45
B34: 4 | C34: =Data!C17 -> 0 | D34: =Data!D17 -> 0 | E34: =Data!E17 -> 0.6 | H34: 4 | I34: =Data!I17 -> 0 | J34: =Data!J17 -> 0 | K34: =Data!K17 -> 0.2
B36: Checks:
B37: By eyes only, Epic has the highest utilisation rate, followed by Major then Regular, which makes sense
B38: The utilisation rate is lower the longer a movie has been in the cinema, which seems reasonable.
B39: Commision rates follows a very similar pattern as the utilisation rate, which again makes sense.
B40: No doubt in the validity of the data provided.
B43: =Data!B20 -> A. Number of movies seen over a year | C43: =Data!C20 -> B. Unique Cinemagoers (annual) | D43: =Data!D20 -> C. Proportion buying snacks | E43: Numbers of movies seen | F43: As a proportion of number of movies seen
B44: =Data!B21 -> 1 | C44: =Data!C21 -> 185220 | D44: =Data!D21 -> 0.22257935 | E44: =C44*B44 -> 185220 | F44: =E44/$E$58 -> 0.065118339
B45: =Data!B22 -> 2 | C45: =Data!C22 -> 270000 | D45: =Data!D22 -> 0.28935316 | E45: =C45*B45 -> 540000 | F45: =E45/$E$58 -> 0.18984939
B46: =Data!B23 -> 3 | C46: =Data!C23 -> 180000 | D46: =Data!D23 -> 0.30048212 | E46: =C46*B46 -> 540000 | F46: =E46/$E$58 -> 0.18984939
B47: =Data!B24 -> 4 | C47: =Data!C24 -> 135000 | D47: =Data!D24 -> 0.39 | E47: =C47*B47 -> 540000 | F47: =E47/$E$58 -> 0.18984939
...

Sheet Parameters
B1: Parameters
C3: Original | D3: Annual pass
B4: Screenings per day | C4: 6
B5: Number of day in a month | C5: 30
B6: Ticket price ($) | C6: 13
B7: Average snack spend ($) | C7: 22
B9: Staff | C9: 32
B10: Hourly rate ($) | C10: 25
B11: Number of hours worked a day | C11: 8
B12: Monthly overheads ($) | C12: 300000
B13: Costs per average snack spend ($) | C13: 2
B15: Annual pass fee | C15: 0 | D15: 74
B16: Number of films for annual pass* (Annual pass threshold) | C16: 15 | D16: 5 | E16: *In the original scenario this is entered as 15 as annual pass is not an option and no cinemagoers will watch 15 or more films.
B17: Change in snack spending habit | C17: 0 | D17: 0.2
B18: Discount on snacks for passholders | C18: 0 | D18: 0.1

Sheet Calc_original
B1: Cinema going and profit calculations for original scenario (i.e. no annual pass)
B5: Schedule
B6: Screen | C6: Jan | D6: Feb | E6: Mar | F6: Apr | G6: May | H6: Jun | I6: Jul | J6: Aug | K6: Sep | L6: Oct | M6: Nov | N6: Dec
B7: =Data_checks!$B6 -> 1 | C7: =Data_checks!D6 -> Major 1 | D7: =Data_checks!E6 -> Major 1 | E7: =Data_checks!F6 -> Regular 3 | F7: =Data_checks!G6 -> Major 2 | G7: =Data_checks!H6 -> Major 2 | H7: =Data_checks!I6 -> Regular 6 | I7: =Data_checks!J6 -> Epic 1 | J7: =Data_checks!K6 -> Epic 1 | ... N7: =Data_checks!O6 -> Regular 10
B8: =Data_checks!$B7 -> 2 | C8: =Data_checks!D7 -> Major 1 | D8: =Data_checks!E7 -> Regular 1 | E8: =Data_checks!F7 -> Major 1 | F8: =Data_checks!G7 -> Major 2 | G8: =Data_checks!H7 -> Regular 5 | H8: =Data_checks!I7 -> Major 2 | I8: =Data_checks!J7 -> Epic 1 | J8: =Data_checks!K7 -> Epic 1 | ... N8: =Data_checks!O7 -> Major 3
B9: =Data_checks!$B8 -> 3 | C9: =Data_checks!D8 -> Regular 1 | D9: =Data_checks!E8 -> Regular 2 | E9: =Data_checks!F8 -> Regular 3 | F9: =Data_checks!G8 -> Regular 4 | G9: =Data_checks!H8 -> Regular 4 | H9: =Data_checks!I8 -> Regular 5 | I9: =Data_checks!J8 -> Epic 1 | J9: =Data_checks!K8 -> Regular 7 | ... N9: =Data_checks!O8 -> Regular 10
B10: =Data_checks!$B9 -> 4 | C10: =Data_checks!D9 -> Regular 2 | D10: =Data_checks!E9 -> Regular 2 | E10: =Data_checks!F9 -> Regular 1 | F10: =Data_checks!G9 -> Regular 3 | G10: =Data_checks!H9 -> Regular 4 | H10: =Data_checks!I9 -> Regular 4 | I10: =Data_checks!J9 -> Regular 6 | J10: =Data_checks!K9 -> Regular 8 | ... N10: =Data_checks!O9 -> Regular 9
B12: Number of months movie has been showing
B13: Screen | C13: =C6 -> Jan | D13: =D6 -> Feb | E13: =E6 -> Mar | F13: =F6 -> Apr | G13: =G6 -> May | H13: =H6 -> Jun | I13: =I6 -> Jul | J13: =J6 -> Aug | ... N13: =N6 -> Dec
B14: =B7 -> 1 | C14: 1 | D14: =IF(COUNTIF(C$7:C$10,D7)>0,1,0)+IF(COUNTIF(B$7:B$10,D7)>0,1,0)+IF(COUNTIF(A$7:A$10,D7)>0,1,0)+1 -> 2 | E14: =IF(COUNTIF(D$7:D$10,E7)>0,1,0)+IF(COUNTIF(C$7:C$10,E7)>0,1,0)+IF(COUNTIF(B$7:B$10,E7)>0,1,0)+1 -> 1 | F14: =IF(COUNTIF(E$7:E$10,F7)>0,1,0)+IF(COUNTIF(D$7:D$10,F7)>0,1,0)+IF(COUNTIF(C$7:C$10,F7)>0,1,0)+1 -> 1 | G14: =IF(COUNTIF(F$7:F$10,G7)>0,1,0)+IF(COUNTIF(E$7:E$10,G7)>0,1,0)+IF(COUNTIF(D$7:D$10,G7)>0,1,0)+1 -> 2 | H14: =IF(COUNTIF(G$7:G$10,H7)>0,1,0)+IF(COUNTIF(F$7:F$10,H7)>0,1,0)+IF(COUNTIF(E$7:E$10,H7)>0,1,0)+1 -> 1 | I14: =IF(COUNTIF(H$7:H$10,I7)>0,1,0)+IF(COUNTIF(G$7:G$10,I7)>0,1,0)+IF(COUNTIF(F$7:F$10,I7)>0,1,0)+1 -> 1 | J14: =IF(COUNTIF(I$7:I$10,J7)>0,1,0)+IF(COUNTIF(H$7:H$10,J7)>0,1,0)+IF(COUNTIF(G$7:G$10,J7)>0,1,0)+1 -> 2 | K14: =IF(COUNTIF(J$7:J$10,K7)>0,1,0)+IF(COUNTIF(I$7:I$10,K7)>0,1,0)+IF(COUNTIF(H$7:H$10,K7)>0,1,0)+1 -> 2 | ... N14: =IF(COUNTIF(M$7:M$10,N7)>0,1,0)+IF(COUNTIF(L$7:L$10,N7)>0,1,0)+IF(COUNTIF(K$7:K$10,N7)>0,1,0)+1 -> 2
B15: =B8 -> 2 | C15: 1 | D15: =IF(COUNTIF(C$7:C$10,D8)>0,1,0)+IF(COUNTIF(B$7:B$10,D8)>0,1,0)+IF(COUNTIF(A$7:A$10,D8)>0,1,0)+1 -> 2 | E15: =IF(COUNTIF(D$7:D$10,E8)>0,1,0)+IF(COUNTIF(C$7:C$10,E8)>0,1,0)+IF(COUNTIF(B$7:B$10,E8)>0,1,0)+1 -> 3 | F15: =IF(COUNTIF(E$7:E$10,F8)>0,1,0)+IF(COUNTIF(D$7:D$10,F8)>0,1,0)+IF(COUNTIF(C$7:C$10,F8)>0,1,0)+1 -> 1 | G15: =IF(COUNTIF(F$7:F$10,G8)>0,1,0)+IF(COUNTIF(E$7:E$10,G8)>0,1,0)+IF(COUNTIF(D$7:D$10,G8)>0,1,0)+1 -> 1 | H15: =IF(COUNTIF(G$7:G$10,H8)>0,1,0)+IF(COUNTIF(F$7:F$10,H8)>0,1,0)+IF(COUNTIF(E$7:E$10,H8)>0,1,0)+1 -> 3 | I15: =IF(COUNTIF(H$7:H$10,I8)>0,1,0)+IF(COUNTIF(G$7:G$10,I8)>0,1,0)+IF(COUNTIF(F$7:F$10,I8)>0,1,0)+1 -> 1 | J15: =IF(COUNTIF(I$7:I$10,J8)>0,1,0)+IF(COUNTIF(H$7:H$10,J8)>0,1,0)+IF(COUNTIF(G$7:G$10,J8)>0,1,0)+1 -> 2 | K15: =IF(COUNTIF(J$7:J$10,K8)>0,1,0)+IF(COUNTIF(I$7:I$10,K8)>0,1,0)+IF(COUNTIF(H$7:H$10,K8)>0,1,0)+1 -> 3 | ... N15: =IF(COUNTIF(M$7:M$10,N8)>0,1,0)+IF(COUNTIF(L$7:L$10,N8)>0,1,0)+IF(COUNTIF(K$7:K$10,N8)>0,1,0)+1 -> 3
B16: =B9 -> 3 | C16: 1 | D16: =IF(COUNTIF(C$7:C$10,D9)>0,1,0)+IF(COUNTIF(B$7:B$10,D9)>0,1,0)+IF(COUNTIF(A$7:A$10,D9)>0,1,0)+1 -> 2 | E16: =IF(COUNTIF(D$7:D$10,E9)>0,1,0)+IF(COUNTIF(C$7:C$10,E9)>0,1,0)+IF(COUNTIF(B$7:B$10,E9)>0,1,0)+1 -> 1 | F16: =IF(COUNTIF(E$7:E$10,F9)>0,1,0)+IF(COUNTIF(D$7:D$10,F9)>0,1,0)+IF(COUNTIF(C$7:C$10,F9)>0,1,0)+1 -> 1 | G16: =IF(COUNTIF(F$7:F$10,G9)>0,1,0)+IF(COUNTIF(E$7:E$10,G9)>0,1,0)+IF(COUNTIF(D$7:D$10,G9)>0,1,0)+1 -> 2 | H16: =IF(COUNTIF(G$7:G$10,H9)>0,1,0)+IF(COUNTIF(F$7:F$10,H9)>0,1,0)+IF(COUNTIF(E$7:E$10,H9)>0,1,0)+1 -> 2 | I16: =IF(COUNTIF(H$7:H$10,I9)>0,1,0)+IF(COUNTIF(G$7:G$10,I9)>0,1,0)+IF(COUNTIF(F$7:F$10,I9)>0,1,0)+1 -> 1 | J16: =IF(COUNTIF(I$7:I$10,J9)>0,1,0)+IF(COUNTIF(H$7:H$10,J9)>0,1,0)+IF(COUNTIF(G$7:G$10,J9)>0,1,0)+1 -> 1 | K16: =IF(COUNTIF(J$7:J$10,K9)>0,1,0)+IF(COUNTIF(I$7:I$10,K9)>0,1,0)+IF(COUNTIF(H$7:H$10,K9)>0,1,0)+1 -> 3 | ... N16: =IF(COUNTIF(M$7:M$10,N9)>0,1,0)+IF(COUNTIF(L$7:L$10,N9)>0,1,0)+IF(COUNTIF(K$7:K$10,N9)>0,1,0)+1 -> 2
B17: =B10 -> 4 | C17: 1 | D17: =IF(COUNTIF(C$7:C$10,D10)>0,1,0)+IF(COUNTIF(B$7:B$10,D10)>0,1,0)+IF(COUNTIF(A$7:A$10,D10)>0,1,0)+1 -> 2 | E17: =IF(COUNTIF(D$7:D$10,E10)>0,1,0)+IF(COUNTIF(C$7:C$10,E10)>0,1,0)+IF(COUNTIF(B$7:B$10,E10)>0,1,0)+1 -> 3 | F17: =IF(COUNTIF(E$7:E$10,F10)>0,1,0)+IF(COUNTIF(D$7:D$10,F10)>0,1,0)+IF(COUNTIF(C$7:C$10,F10)>0,1,0)+1 -> 2 | G17: =IF(COUNTIF(F$7:F$10,G10)>0,1,0)+IF(COUNTIF(E$7:E$10,G10)>0,1,0)+IF(COUNTIF(D$7:D$10,G10)>0,1,0)+1 -> 2 | H17: =IF(COUNTIF(G$7:G$10,H10)>0,1,0)+IF(COUNTIF(F$7:F$10,H10)>0,1,0)+IF(COUNTIF(E$7:E$10,H10)>0,1,0)+1 -> 3 | I17: =IF(COUNTIF(H$7:H$10,I10)>0,1,0)+IF(COUNTIF(G$7:G$10,I10)>0,1,0)+IF(COUNTIF(F$7:F$10,I10)>0,1,0)+1 -> 2 | J17: =IF(COUNTIF(I$7:I$10,J10)>0,1,0)+IF(COUNTIF(H$7:H$10,J10)>0,1,0)+IF(COUNTIF(G$7:G$10,J10)>0,1,0)+1 -> 1 | K17: =IF(COUNTIF(J$7:J$10,K10)>0,1,0)+IF(COUNTIF(I$7:I$10,K10)>0,1,0)+IF(COUNTIF(H$7:H$10,K10)>0,1,0)+1 -> 2 | ... N17: =IF(COUNTIF(M$7:M$10,N10)>0,1,0)+IF(COUNTIF(L$7:L$10,N10)>0,1,0)+IF(COUNTIF(K$7:K$10,N10)>0,1,0)+1 -> 3
B19: Projected screen usage
B20: Screen | C20: =C13 -> Jan | D20: =D13 -> Feb | E20: =E13 -> Mar | F20: =F13 -> Apr | G20: =G13 -> May | H20: =H13 -> Jun | I20: =I13 -> Jul | J20: =J13 -> Aug | ... N20: =N13 -> Dec
B21: =B14 -> 1 | C21: =INDEX(Data_checks!$C$31:$E$34,MATCH(C14,Data_checks!$B$31:$B$34,0),MATCH(LEFT(C7,1),Data_checks!$C$30:$E$30,0)) -> 0.93 | D21: =INDEX(Data_checks!$C$31:$E$34,MATCH(D14,Data_checks!$B$31:$B$34,0),MATCH(LEFT(D7,1),Data_checks!$C$30:$E$30,0)) -> 0.8 | E21: =INDEX(Data_checks!$C$31:$E$34,MATCH(E14,Data_checks!$B$31:$B$34,0),MATCH(LEFT(E7,1),Data_checks!$C$30:$E$30,0)) -> 0.85 | F21: =INDEX(Data_checks!$C$31:$E$34,MATCH(F14,Data_checks!$B$31:$B$34,0),MATCH(LEFT(F7,1),Data_checks!$C$30:$E$30,0)) -> 0.93 | G21: =INDEX(Data_checks!$C$31:$E$34,MATCH(G14,Data_checks!$B$31:$B$34,0),MATCH(LEFT(G7,1),Data_checks!$C$30:$E$30,0)) -> 0.8 | H21: =INDEX(Data_checks!$C$31:$E$34,MATCH(H14,Data_checks!$B$31:$B$34,0),MATCH(LEFT(H7,1),Data_checks!$C$30:$E$30,0)) -> 0.85 | I21: =INDEX(Data_checks!$C$31:$E$34,MATCH(I14,Data_checks!$B$31:$B$34,0),MATCH(LEFT(I7,1),Data_checks!$C$30:$E$30,0)) -> 0.98 | J21: =INDEX(Data_checks!$C$31:$E$34,MATCH(J14,Data_checks!$B$31:$B$34,0),MATCH(LEFT(J7,1),Data_checks!$C$30:$E$30,0)) -> 0.85 | ... N21: =INDEX(Data_checks!$C$31:$E$34,MATCH(N14,Data_checks!$B$31:$B$34,0),MATCH(LEFT(N7,1),Data_checks!$C$30:$E$30,0)) -> 0.65
B22: =B15 -> 2 | C22: =INDEX(Data_checks!$C$31:$E$34,MATCH(C15,Data_checks!$B$31:$B$34,0),MATCH(LEFT(C8,1),Data_checks!$C$30:$E$30,0)) -> 0.93 | D22: =INDEX(Data_checks!$C$31:$E$34,MATCH(D15,Data_checks!$B$31:$B$34,0),MATCH(LEFT(D8,1),Data_checks!$C$30:$E$30,0)) -> 0.65 | E22: =INDEX(Data_checks!$C$31:$E$34,MATCH(E15,Data_checks!$B$31:$B$34,0),MATCH(LEFT(E8,1),Data_checks!$C$30:$E$30,0)) -> 0.65 | F22: =INDEX(Data_checks!$C$31:$E$34,MATCH(F15,Data_checks!$B$31:$B$34,0),MATCH(LEFT(F8,1),Data_checks!$C$30:$E$30,0)) -> 0.93 | G22: =INDEX(Data_checks!$C$31:$E$34,MATCH(G15,Data_checks!$B$31:$B$34,0),MATCH(LEFT(G8,1),Data_checks!$C$30:$E$30,0)) -> 0.85 | H22: =INDEX(Data_checks!$C$31:$E$34,MATCH(H15,Data_checks!$B$31:$B$34,0),MATCH(LEFT(H8,1),Data_checks!$C$30:$E$30,0)) -> 0.65 | I22: =INDEX(Data_checks!$C$31:$E$34,MATCH(I15,Data_checks!$B$31:$B$34,0),MATCH(LEFT(I8,1),Data_checks!$C$30:$E$30,0)) -> 0.98 | J22: =INDEX(Data_checks!$C$31:$E$34,MATCH(J15,Data_checks!$B$31:$B$34,0),MATCH(LEFT(J8,1),Data_checks!$C$30:$E$30,0)) -> 0.85 | ... N22: =INDEX(Data_checks!$C$31:$E$34,MATCH(N15,Data_checks!$B$31:$B$34,0),MATCH(LEFT(N8,1),Data_checks!$C$30:$E$30,0)) -> 0.65
B23: =B16 -> 3 | C23: =INDEX(Data_checks!$C$31:$E$34,MATCH(C16,Data_checks!$B$31:$B$34,0),MATCH(LEFT(C9,1),Data_checks!$C$30:$E$30,0)) -> 0.85 | D23: =INDEX(Data_checks!$C$31:$E$34,MATCH(D16,Data_checks!$B$31:$B$34,0),MATCH(LEFT(D9,1),Data_checks!$C$30:$E$30,0)) -> 0.65 | E23: =INDEX(Data_checks!$C$31:$E$34,MATCH(E16,Data_checks!$B$31:$B$34,0),MATCH(LEFT(E9,1),Data_checks!$C$30:$E$30,0)) -> 0.85 | F23: =INDEX(Data_checks!$C$31:$E$34,MATCH(F16,Data_checks!$B$31:$B$34,0),MATCH(LEFT(F9,1),Data_checks!$C$30:$E$30,0)) -> 0.85 | G23: =INDEX(Data_checks!$C$31:$E$34,MATCH(G16,Data_checks!$B$31:$B$34,0),MATCH(LEFT(G9,1),Data_checks!$C$30:$E$30,0)) -> 0.65 | H23: =INDEX(Data_checks!$C$31:$E$34,MATCH(H16,Data_checks!$B$31:$B$34,0),MATCH(LEFT(H9,1),Data_checks!$C$30:$E$30,0)) -> 0.65 | I23: =INDEX(Data_checks!$C$31:$E$34,MATCH(I16,Data_checks!$B$31:$B$34,0),MATCH(LEFT(I9,1),Data_checks!$C$30:$E$30,0)) -> 0.98 | J23: =INDEX(Data_checks!$C$31:$E$34,MATCH(J16,Data_checks!$B$31:$B$34,0),MATCH(LEFT(J9,1),Data_checks!$C$30:$E$30,0)) -> 0.85 | ... N23: =INDEX(Data_checks!$C$31:$E$34,MATCH(N16,Data_checks!$B$31:$B$34,0),MATCH(LEFT(N9,1),Data_checks!$C$30:$E$30,0)) -> 0.65
B24: =B17 -> 4 | C24: =INDEX(Data_checks!$C$31:$E$34,MATCH(C17,Data_checks!$B$31:$B$34,0),MATCH(LEFT(C10,1),Data_checks!$C$30:$E$30,0)) -> 0.85 | D24: =INDEX(Data_checks!$C$31:$E$34,MATCH(D17,Data_checks!$B$31:$B$34,0),MATCH(LEFT(D10,1),Data_checks!$C$30:$E$30,0)) -> 0.65 | E24: =INDEX(Data_checks!$C$31:$E$34,MATCH(E17,Data_checks!$B$31:$B$34,0),MATCH(LEFT(E10,1),Data_checks!$C$30:$E$30,0)) -> 0.45 | F24: =INDEX(Data_checks!$C$31:$E$34,MATCH(F17,Data_checks!$B$31:$B$34,0),MATCH(LEFT(F10,1),Data_checks!$C$30:$E$30,0)) -> 0.65 | G24: =INDEX(Data_checks!$C$31:$E$34,MATCH(G17,Data_checks!$B$31:$B$34,0),MATCH(LEFT(G10,1),Data_checks!$C$30:$E$30,0)) -> 0.65 | H24: =INDEX(Data_checks!$C$31:$E$34,MATCH(H17,Data_checks!$B$31:$B$34,0),MATCH(LEFT(H10,1),Data_checks!$C$30:$E$30,0)) -> 0.45 | I24: =INDEX(Data_checks!$C$31:$E$34,MATCH(I17,Data_checks!$B$31:$B$34,0),MATCH(LEFT(I10,1),Data_checks!$C$30:$E$30,0)) -> 0.65 | J24: =INDEX(Data_checks!$C$31:$E$34,MATCH(J17,Data_checks!$B$31:$B$34,0),MATCH(LEFT(J10,1),Data_checks!$C$30:$E$30,0)) -> 0.85 | ... N24: =INDEX(Data_checks!$C$31:$E$34,MATCH(N17,Data_checks!$B$31:$B$34,0),MATCH(LEFT(N10,1),Data_checks!$C$30:$E$30,0)) -> 0.45
B26: Projected cinemagoers (split by screen for commission calculation)
B27: Screen | C27: {=C20:N20} -> Jan | D27: Feb | E27: Mar | F27: Apr | G27: May | H27: Jun | I27: Jul | J27: Aug | K27: Sep | L27: Oct | M27: Nov | N27: Dec
B28: =B21 -> 1 | C28: =VLOOKUP($B28,Data_checks!$B$6:$C$9,2,TRUE)*C21*Parameters!$C$5*Parameters!$C$4 -> 142290 | D28: =VLOOKUP($B28,Data_checks!$B$6:$C$9,2,TRUE)*D21*Parameters!$C$5*Parameters!$C$4 -> 122400 | E28: =VLOOKUP($B28,Data_checks!$B$6:$C$9,2,TRUE)*E21*Parameters!$C$5*Parameters!$C$4 -> 130050 | F28: =VLOOKUP($B28,Data_checks!$B$6:$C$9,2,TRUE)*F21*Parameters!$C$5*Parameters!$C$4 -> 142290 | G28: =VLOOKUP($B28,Data_checks!$B$6:$C$9,2,TRUE)*G21*Parameters!$C$5*Parameters!$C$4 -> 122400 | H28: =VLOOKUP($B28,Data_checks!$B$6:$C$9,2,TRUE)*H21*Parameters!$C$5*Parameters!$C$4 -> 130050 | I28: =VLOOKUP($B28,Data_checks!$B$6:$C$9,2,TRUE)*I21*Parameters!$C$5*Parameters!$C$4 -> 149940 | J28: =VLOOKUP($B28,Data_checks!$B$6:$C$9,2,TRUE)*J21*Parameters!$C$5*Parameters!$C$4 -> 130050 | ... N28: =VLOOKUP($B28,Data_checks!$B$6:$C$9,2,TRUE)*N21*Parameters!$C$5*Parameters!$C$4 -> 99450
B29: =B22 -> 2 | C29: =VLOOKUP($B29,Data_checks!$B$6:$C$9,2,TRUE)*C22*Parameters!$C$5*Parameters!$C$4 -> 75330 | D29: =VLOOKUP($B29,Data_checks!$B$6:$C$9,2,TRUE)*D22*Parameters!$C$5*Parameters!$C$4 -> 52650 | E29: =VLOOKUP($B29,Data_checks!$B$6:$C$9,2,TRUE)*E22*Parameters!$C$5*Parameters!$C$4 -> 52650 | F29: =VLOOKUP($B29,Data_checks!$B$6:$C$9,2,TRUE)*F22*Parameters!$C$5*Parameters!$C$4 -> 75330 | G29: =VLOOKUP($B29,Data_checks!$B$6:$C$9,2,TRUE)*G22*Parameters!$C$5*Parameters!$C$4 -> 68850 | H29: =VLOOKUP($B29,Data_checks!$B$6:$C$9,2,TRUE)*H22*Parameters!$C$5*Parameters!$C$4 -> 52650 | I29: =VLOOKUP($B29,Data_checks!$B$6:$C$9,2,TRUE)*I22*Parameters!$C$5*Parameters!$C$4 -> 79380 | J29: =VLOOKUP($B29,Data_checks!$B$6:$C$9,2,TRUE)*J22*Parameters!$C$5*Parameters!$C$4 -> 68850 | ... N29: =VLOOKUP($B29,Data_checks!$B$6:$C$9,2,TRUE)*N22*Parameters!$C$5*Parameters!$C$4 -> 52650
B30: =B23 -> 3 | C30: =VLOOKUP($B30,Data_checks!$B$6:$C$9,2,TRUE)*C23*Parameters!$C$5*Parameters!$C$4 -> 30600 | D30: =VLOOKUP($B30,Data_checks!$B$6:$C$9,2,TRUE)*D23*Parameters!$C$5*Parameters!$C$4 -> 23400 | E30: =VLOOKUP($B30,Data_checks!$B$6:$C$9,2,TRUE)*E23*Parameters!$C$5*Parameters!$C$4 -> 30600 | F30: =VLOOKUP($B30,Data_checks!$B$6:$C$9,2,TRUE)*F23*Parameters!$C$5*Parameters!$C$4 -> 30600 | G30: =VLOOKUP($B30,Data_checks!$B$6:$C$9,2,TRUE)*G23*Parameters!$C$5*Parameters!$C$4 -> 23400 | H30: =VLOOKUP($B30,Data_checks!$B$6:$C$9,2,TRUE)*H23*Parameters!$C$5*Parameters!$C$4 -> 23400 | I30: =VLOOKUP($B30,Data_checks!$B$6:$C$9,2,TRUE)*I23*Parameters!$C$5*Parameters!$C$4 -> 35280 | J30: =VLOOKUP($B30,Data_checks!$B$6:$C$9,2,TRUE)*J23*Parameters!$C$5*Parameters!$C$4 -> 30600 | ... N30: =VLOOKUP($B30,Data_checks!$B$6:$C$9,2,TRUE)*N23*Parameters!$C$5*Parameters!$C$4 -> 23400
B31: =B24 -> 4 | C31: =VLOOKUP($B31,Data_checks!$B$6:$C$9,2,TRUE)*C24*Parameters!$C$5*Parameters!$C$4 -> 22950 | D31: =VLOOKUP($B31,Data_checks!$B$6:$C$9,2,TRUE)*D24*Parameters!$C$5*Parameters!$C$4 -> 17550 | E31: =VLOOKUP($B31,Data_checks!$B$6:$C$9,2,TRUE)*E24*Parameters!$C$5*Parameters!$C$4 -> 12150 | F31: =VLOOKUP($B31,Data_checks!$B$6:$C$9,2,TRUE)*F24*Parameters!$C$5*Parameters!$C$4 -> 17550 | G31: =VLOOKUP($B31,Data_checks!$B$6:$C$9,2,TRUE)*G24*Parameters!$C$5*Parameters!$C$4 -> 17550 | H31: =VLOOKUP($B31,Data_checks!$B$6:$C$9,2,TRUE)*H24*Parameters!$C$5*Parameters!$C$4 -> 12150 | I31: =VLOOKUP($B31,Data_checks!$B$6:$C$9,2,TRUE)*I24*Parameters!$C$5*Parameters!$C$4 -> 17550 | J31: =VLOOKUP($B31,Data_checks!$B$6:$C$9,2,TRUE)*J24*Parameters!$C$5*Parameters!$C$4 -> 22950 | ... N31: =VLOOKUP($B31,Data_checks!$B$6:$C$9,2,TRUE)*N24*Parameters!$C$5*Parameters!$C$4 -> 12150 | P31: Check on attendance data
B32: Total cinema | C32: =SUM(C28:C31) -> 271170 | D32: =SUM(D28:D31) -> 216000 | E32: =SUM(E28:E31) -> 225450 | F32: =SUM(F28:F31) -> 265770 | G32: =SUM(G28:G31) -> 232200 | H32: =SUM(H28:H31) -> 218250 | I32: =SUM(I28:I31) -> 282150 | J32: =SUM(J28:J31) -> 252450 | ... N32: =SUM(N28:N31) -> 187650 | O32: =SUM(C32:N32) -> 2844360 | P32: =IF(O32=Data_checks!E58,"Data is internally consistent","Data is not consistent. Please check") -> Data is internally consistent
B34: Number of films seen split by unique cinemagoers (This is the number of films seen split by month and by unique cinemagoers. E.g. if you sum up row 49, i.e. the number of cinemagoers who have seen 14 movies a year, the sum would equal to that in the data check (5040))
B35: Total number of movies seen in yr | C35: =C27 -> Jan | D35: =D27 -> Feb | E35: =E27 -> Mar | F35: =F27 -> Apr | G35: =G27 -> May | H35: =H27 -> Jun | I35: =I27 -> Jul | J35: =J27 -> Aug | ... N35: =N27 -> Dec
B36: =Data!B21 -> 1 | C36: =C$32*Data_checks!$F44 -> 17658.14 | D36: =D$32*Data_checks!$F44 -> 14065.561 | E36: =E$32*Data_checks!$F44 -> 14680.93 | F36: =F$32*Data_checks!$F44 -> 17306.501 | G36: =G$32*Data_checks!$F44 -> 15120.478 | H36: =H$32*Data_checks!$F44 -> 14212.078 | I36: =I$32*Data_checks!$F44 -> 18373.139 | J36: =J$32*Data_checks!$F44 -> 16439.125 | ... N36: =N$32*Data_checks!$F44 -> 12219.456
B37: =Data!B22 -> 2 | C37: =C$32*Data_checks!$F45 -> 51481.458 | D37: =D$32*Data_checks!$F45 -> 41007.467 | E37: =E$32*Data_checks!$F45 -> 42801.544 | F37: =F$32*Data_checks!$F45 -> 50456.271 | G37: =G$32*Data_checks!$F45 -> 44083.027 | H37: =H$32*Data_checks!$F45 -> 41434.629 | I37: =I$32*Data_checks!$F45 -> 53566.004 | J37: =J$32*Data_checks!$F45 -> 47927.478 | ... N37: =N$32*Data_checks!$F45 -> 35625.237
B38: =Data!B23 -> 3 | C38: =C$32*Data_checks!$F46 -> 51481.458 | D38: =D$32*Data_checks!$F46 -> 41007.467 | E38: =E$32*Data_checks!$F46 -> 42801.544 | F38: =F$32*Data_checks!$F46 -> 50456.271 | G38: =G$32*Data_checks!$F46 -> 44083.027 | H38: =H$32*Data_checks!$F46 -> 41434.629 | I38: =I$32*Data_checks!$F46 -> 53566.004 | J38: =J$32*Data_checks!$F46 -> 47927.478 | ... N38: =N$32*Data_checks!$F46 -> 35625.237
B39: =Data!B24 -> 4 | C39: =C$32*Data_checks!$F47 -> 51481.458 | D39: =D$32*Data_checks!$F47 -> 41007.467 | E39: =E$32*Data_checks!$F47 -> 42801.544 | F39: =F$32*Data_checks!$F47 -> 50456.271 | G39: =G$32*Data_checks!$F47 -> 44083.027 | H39: =H$32*Data_checks!$F47 -> 41434.629 | I39: =I$32*Data_checks!$F47 -> 53566.004 | J39: =J$32*Data_checks!$F47 -> 47927.478 | ... N39: =N$32*Data_checks!$F47 -> 35625.237
B40: =Data!B25 -> 5 | C40: =C$32*Data_checks!$F48 -> 38611.094 | D40: =D$32*Data_checks!$F48 -> 30755.601 | E40: =E$32*Data_checks!$F48 -> 32101.158 | F40: =F$32*Data_checks!$F48 -> 37842.204 | G40: =G$32*Data_checks!$F48 -> 33062.271 | H40: =H$32*Data_checks!$F48 -> 31075.971 | I40: =I$32*Data_checks!$F48 -> 40174.503 | J40: =J$32*Data_checks!$F48 -> 35945.608 | ... N40: =N$32*Data_checks!$F48 -> 26718.928
B41: =Data!B26 -> 6 | C41: =C$32*Data_checks!$F49 -> 30888.875 | D41: =D$32*Data_checks!$F49 -> 24604.48 | E41: =E$32*Data_checks!$F49 -> 25680.926 | F41: =F$32*Data_checks!$F49 -> 30273.763 | G41: =G$32*Data_checks!$F49 -> 26449.816 | H41: =H$32*Data_checks!$F49 -> 24860.777 | I41: =I$32*Data_checks!$F49 -> 32139.603 | J41: =J$32*Data_checks!$F49 -> 28756.487 | ... N41: =N$32*Data_checks!$F49 -> 21375.142
B42: =Data!B27 -> 7 | C42: =C$32*Data_checks!$F50 -> 18018.51 | D42: =D$32*Data_checks!$F50 -> 14352.614 | E42: =E$32*Data_checks!$F50 -> 14980.54 | F42: =F$32*Data_checks!$F50 -> 17659.695 | G42: =G$32*Data_checks!$F50 -> 15429.06 | H42: =H$32*Data_checks!$F50 -> 14502.12 | I42: =I$32*Data_checks!$F50 -> 18748.102 | J42: =J$32*Data_checks!$F50 -> 16774.617 | ... N42: =N$32*Data_checks!$F50 -> 12468.833
B43: =Data!B28 -> 8 | C43: =C$32*Data_checks!$F51 -> 4118.5166 | D43: =D$32*Data_checks!$F51 -> 3280.5974 | E43: =E$32*Data_checks!$F51 -> 3424.1235 | F43: =F$32*Data_checks!$F51 -> 4036.5017 | G43: =G$32*Data_checks!$F51 -> 3526.6422 | H43: =H$32*Data_checks!$F51 -> 3314.7703 | I43: =I$32*Data_checks!$F51 -> 4285.2803 | J43: =J$32*Data_checks!$F51 -> 3834.1982 | ... N43: =N$32*Data_checks!$F51 -> 2850.019
B44: =Data!B29 -> 9 | C44: =C$32*Data_checks!$F52 -> 3088.8875 | D44: =D$32*Data_checks!$F52 -> 2460.448 | E44: =E$32*Data_checks!$F52 -> 2568.0926 | F44: =F$32*Data_checks!$F52 -> 3027.3763 | G44: =G$32*Data_checks!$F52 -> 2644.9816 | H44: =H$32*Data_checks!$F52 -> 2486.0777 | I44: =I$32*Data_checks!$F52 -> 3213.9603 | J44: =J$32*Data_checks!$F52 -> 2875.6487 | ... N44: =N$32*Data_checks!$F52 -> 2137.5142
B45: =Data!B30 -> 10 | C45: =C$32*Data_checks!$F53 -> 1029.6292 | D45: =D$32*Data_checks!$F53 -> 820.14935 | E45: =E$32*Data_checks!$F53 -> 856.03088 | F45: =F$32*Data_checks!$F53 -> 1009.1254 | G45: =G$32*Data_checks!$F53 -> 881.66055 | H45: =H$32*Data_checks!$F53 -> 828.69257 | I45: =I$32*Data_checks!$F53 -> 1071.3201 | J45: =J$32*Data_checks!$F53 -> 958.54955 | ... N45: =N$32*Data_checks!$F53 -> 712.50475
B46: =Data!B31 -> 11 | C46: =C$32*Data_checks!$F54 -> 1132.5921 | D46: =D$32*Data_checks!$F54 -> 902.16428 | E46: =E$32*Data_checks!$F54 -> 941.63397 | F46: =F$32*Data_checks!$F54 -> 1110.038 | G46: =G$32*Data_checks!$F54 -> 969.8266 | H46: =H$32*Data_checks!$F54 -> 911.56183 | I46: =I$32*Data_checks!$F54 -> 1178.4521 | J46: =J$32*Data_checks!$F54 -> 1054.4045 | ... N46: =N$32*Data_checks!$F54 -> 783.75522
B47: =Data!B32 -> 12 | C47: =C$32*Data_checks!$F55 -> 1029.6292 | D47: =D$32*Data_checks!$F55 -> 820.14935 | E47: =E$32*Data_checks!$F55 -> 856.03088 | F47: =F$32*Data_checks!$F55 -> 1009.1254 | G47: =G$32*Data_checks!$F55 -> 881.66055 | H47: =H$32*Data_checks!$F55 -> 828.69257 | I47: =I$32*Data_checks!$F55 -> 1071.3201 | J47: =J$32*Data_checks!$F55 -> 958.54955 | ... N47: =N$32*Data_checks!$F55 -> 712.50475
...

Sheet Calc_annual_pass
B1: Cinema going and profit calculations for annual pass
B5: Schedule
B6: Screen | C6: Jan | D6: Feb | E6: Mar | F6: Apr | G6: May | H6: Jun | I6: Jul | J6: Aug | K6: Sep | L6: Oct | M6: Nov | N6: Dec
B7: =Data_checks!$B6 -> 1 | C7: =Data_checks!D6 -> Major 1 | D7: =Data_checks!E6 -> Major 1 | E7: =Data_checks!F6 -> Regular 3 | F7: =Data_checks!G6 -> Major 2 | G7: =Data_checks!H6 -> Major 2 | H7: =Data_checks!I6 -> Regular 6 | I7: =Data_checks!J6 -> Epic 1 | J7: =Data_checks!K6 -> Epic 1 | ... N7: =Data_checks!O6 -> Regular 10
B8: =Data_checks!$B7 -> 2 | C8: =Data_checks!D7 -> Major 1 | D8: =Data_checks!E7 -> Regular 1 | E8: =Data_checks!F7 -> Major 1 | F8: =Data_checks!G7 -> Major 2 | G8: =Data_checks!H7 -> Regular 5 | H8: =Data_checks!I7 -> Major 2 | I8: =Data_checks!J7 -> Epic 1 | J8: =Data_checks!K7 -> Epic 1 | ... N8: =Data_checks!O7 -> Major 3
B9: =Data_checks!$B8 -> 3 | C9: =Data_checks!D8 -> Regular 1 | D9: =Data_checks!E8 -> Regular 2 | E9: =Data_checks!F8 -> Regular 3 | F9: =Data_checks!G8 -> Regular 4 | G9: =Data_checks!H8 -> Regular 4 | H9: =Data_checks!I8 -> Regular 5 | I9: =Data_checks!J8 -> Epic 1 | J9: =Data_checks!K8 -> Regular 7 | ... N9: =Data_checks!O8 -> Regular 10
B10: =Data_checks!$B9 -> 4 | C10: =Data_checks!D9 -> Regular 2 | D10: =Data_checks!E9 -> Regular 2 | E10: =Data_checks!F9 -> Regular 1 | F10: =Data_checks!G9 -> Regular 3 | G10: =Data_checks!H9 -> Regular 4 | H10: =Data_checks!I9 -> Regular 4 | I10: =Data_checks!J9 -> Regular 6 | J10: =Data_checks!K9 -> Regular 8 | ... N10: =Data_checks!O9 -> Regular 9
B12: Number of months movie has been showing
B13: Screen | C13: =C6 -> Jan | D13: =D6 -> Feb | E13: =E6 -> Mar | F13: =F6 -> Apr | G13: =G6 -> May | H13: =H6 -> Jun | I13: =I6 -> Jul | J13: =J6 -> Aug | ... N13: =N6 -> Dec
B14: =B7 -> 1 | C14: 1 | D14: =IF(COUNTIF(C$7:C$10,D7)>0,1,0)+IF(COUNTIF(B$7:B$10,D7)>0,1,0)+IF(COUNTIF(A$7:A$10,D7)>0,1,0)+1 -> 2 | E14: =IF(COUNTIF(D$7:D$10,E7)>0,1,0)+IF(COUNTIF(C$7:C$10,E7)>0,1,0)+IF(COUNTIF(B$7:B$10,E7)>0,1,0)+1 -> 1 | F14: =IF(COUNTIF(E$7:E$10,F7)>0,1,0)+IF(COUNTIF(D$7:D$10,F7)>0,1,0)+IF(COUNTIF(C$7:C$10,F7)>0,1,0)+1 -> 1 | G14: =IF(COUNTIF(F$7:F$10,G7)>0,1,0)+IF(COUNTIF(E$7:E$10,G7)>0,1,0)+IF(COUNTIF(D$7:D$10,G7)>0,1,0)+1 -> 2 | H14: =IF(COUNTIF(G$7:G$10,H7)>0,1,0)+IF(COUNTIF(F$7:F$10,H7)>0,1,0)+IF(COUNTIF(E$7:E$10,H7)>0,1,0)+1 -> 1 | I14: =IF(COUNTIF(H$7:H$10,I7)>0,1,0)+IF(COUNTIF(G$7:G$10,I7)>0,1,0)+IF(COUNTIF(F$7:F$10,I7)>0,1,0)+1 -> 1 | J14: =IF(COUNTIF(I$7:I$10,J7)>0,1,0)+IF(COUNTIF(H$7:H$10,J7)>0,1,0)+IF(COUNTIF(G$7:G$10,J7)>0,1,0)+1 -> 2 | K14: =IF(COUNTIF(J$7:J$10,K7)>0,1,0)+IF(COUNTIF(I$7:I$10,K7)>0,1,0)+IF(COUNTIF(H$7:H$10,K7)>0,1,0)+1 -> 2 | ... N14: =IF(COUNTIF(M$7:M$10,N7)>0,1,0)+IF(COUNTIF(L$7:L$10,N7)>0,1,0)+IF(COUNTIF(K$7:K$10,N7)>0,1,0)+1 -> 2
B15: =B8 -> 2 | C15: 1 | D15: =IF(COUNTIF(C$7:C$10,D8)>0,1,0)+IF(COUNTIF(B$7:B$10,D8)>0,1,0)+IF(COUNTIF(A$7:A$10,D8)>0,1,0)+1 -> 2 | E15: =IF(COUNTIF(D$7:D$10,E8)>0,1,0)+IF(COUNTIF(C$7:C$10,E8)>0,1,0)+IF(COUNTIF(B$7:B$10,E8)>0,1,0)+1 -> 3 | F15: =IF(COUNTIF(E$7:E$10,F8)>0,1,0)+IF(COUNTIF(D$7:D$10,F8)>0,1,0)+IF(COUNTIF(C$7:C$10,F8)>0,1,0)+1 -> 1 | G15: =IF(COUNTIF(F$7:F$10,G8)>0,1,0)+IF(COUNTIF(E$7:E$10,G8)>0,1,0)+IF(COUNTIF(D$7:D$10,G8)>0,1,0)+1 -> 1 | H15: =IF(COUNTIF(G$7:G$10,H8)>0,1,0)+IF(COUNTIF(F$7:F$10,H8)>0,1,0)+IF(COUNTIF(E$7:E$10,H8)>0,1,0)+1 -> 3 | I15: =IF(COUNTIF(H$7:H$10,I8)>0,1,0)+IF(COUNTIF(G$7:G$10,I8)>0,1,0)+IF(COUNTIF(F$7:F$10,I8)>0,1,0)+1 -> 1 | J15: =IF(COUNTIF(I$7:I$10,J8)>0,1,0)+IF(COUNTIF(H$7:H$10,J8)>0,1,0)+IF(COUNTIF(G$7:G$10,J8)>0,1,0)+1 -> 2 | K15: =IF(COUNTIF(J$7:J$10,K8)>0,1,0)+IF(COUNTIF(I$7:I$10,K8)>0,1,0)+IF(COUNTIF(H$7:H$10,K8)>0,1,0)+1 -> 3 | ... N15: =IF(COUNTIF(M$7:M$10,N8)>0,1,0)+IF(COUNTIF(L$7:L$10,N8)>0,1,0)+IF(COUNTIF(K$7:K$10,N8)>0,1,0)+1 -> 3
B16: =B9 -> 3 | C16: 1 | D16: =IF(COUNTIF(C$7:C$10,D9)>0,1,0)+IF(COUNTIF(B$7:B$10,D9)>0,1,0)+IF(COUNTIF(A$7:A$10,D9)>0,1,0)+1 -> 2 | E16: =IF(COUNTIF(D$7:D$10,E9)>0,1,0)+IF(COUNTIF(C$7:C$10,E9)>0,1,0)+IF(COUNTIF(B$7:B$10,E9)>0,1,0)+1 -> 1 | F16: =IF(COUNTIF(E$7:E$10,F9)>0,1,0)+IF(COUNTIF(D$7:D$10,F9)>0,1,0)+IF(COUNTIF(C$7:C$10,F9)>0,1,0)+1 -> 1 | G16: =IF(COUNTIF(F$7:F$10,G9)>0,1,0)+IF(COUNTIF(E$7:E$10,G9)>0,1,0)+IF(COUNTIF(D$7:D$10,G9)>0,1,0)+1 -> 2 | H16: =IF(COUNTIF(G$7:G$10,H9)>0,1,0)+IF(COUNTIF(F$7:F$10,H9)>0,1,0)+IF(COUNTIF(E$7:E$10,H9)>0,1,0)+1 -> 2 | I16: =IF(COUNTIF(H$7:H$10,I9)>0,1,0)+IF(COUNTIF(G$7:G$10,I9)>0,1,0)+IF(COUNTIF(F$7:F$10,I9)>0,1,0)+1 -> 1 | J16: =IF(COUNTIF(I$7:I$10,J9)>0,1,0)+IF(COUNTIF(H$7:H$10,J9)>0,1,0)+IF(COUNTIF(G$7:G$10,J9)>0,1,0)+1 -> 1 | K16: =IF(COUNTIF(J$7:J$10,K9)>0,1,0)+IF(COUNTIF(I$7:I$10,K9)>0,1,0)+IF(COUNTIF(H$7:H$10,K9)>0,1,0)+1 -> 3 | ... N16: =IF(COUNTIF(M$7:M$10,N9)>0,1,0)+IF(COUNTIF(L$7:L$10,N9)>0,1,0)+IF(COUNTIF(K$7:K$10,N9)>0,1,0)+1 -> 2
B17: =B10 -> 4 | C17: 1 | D17: =IF(COUNTIF(C$7:C$10,D10)>0,1,0)+IF(COUNTIF(B$7:B$10,D10)>0,1,0)+IF(COUNTIF(A$7:A$10,D10)>0,1,0)+1 -> 2 | E17: =IF(COUNTIF(D$7:D$10,E10)>0,1,0)+IF(COUNTIF(C$7:C$10,E10)>0,1,0)+IF(COUNTIF(B$7:B$10,E10)>0,1,0)+1 -> 3 | F17: =IF(COUNTIF(E$7:E$10,F10)>0,1,0)+IF(COUNTIF(D$7:D$10,F10)>0,1,0)+IF(COUNTIF(C$7:C$10,F10)>0,1,0)+1 -> 2 | G17: =IF(COUNTIF(F$7:F$10,G10)>0,1,0)+IF(COUNTIF(E$7:E$10,G10)>0,1,0)+IF(COUNTIF(D$7:D$10,G10)>0,1,0)+1 -> 2 | H17: =IF(COUNTIF(G$7:G$10,H10)>0,1,0)+IF(COUNTIF(F$7:F$10,H10)>0,1,0)+IF(COUNTIF(E$7:E$10,H10)>0,1,0)+1 -> 3 | I17: =IF(COUNTIF(H$7:H$10,I10)>0,1,0)+IF(COUNTIF(G$7:G$10,I10)>0,1,0)+IF(COUNTIF(F$7:F$10,I10)>0,1,0)+1 -> 2 | J17: =IF(COUNTIF(I$7:I$10,J10)>0,1,0)+IF(COUNTIF(H$7:H$10,J10)>0,1,0)+IF(COUNTIF(G$7:G$10,J10)>0,1,0)+1 -> 1 | K17: =IF(COUNTIF(J$7:J$10,K10)>0,1,0)+IF(COUNTIF(I$7:I$10,K10)>0,1,0)+IF(COUNTIF(H$7:H$10,K10)>0,1,0)+1 -> 2 | ... N17: =IF(COUNTIF(M$7:M$10,N10)>0,1,0)+IF(COUNTIF(L$7:L$10,N10)>0,1,0)+IF(COUNTIF(K$7:K$10,N10)>0,1,0)+1 -> 3
B19: Projected screen usage
B20: Screen | C20: =C13 -> Jan | D20: =D13 -> Feb | E20: =E13 -> Mar | F20: =F13 -> Apr | G20: =G13 -> May | H20: =H13 -> Jun | I20: =I13 -> Jul | J20: =J13 -> Aug | ... N20: =N13 -> Dec
B21: =B14 -> 1 | C21: =INDEX(Data_checks!$C$31:$E$34,MATCH(C14,Data_checks!$B$31:$B$34,0),MATCH(LEFT(C7,1),Data_checks!$C$30:$E$30,0)) -> 0.93 | D21: =INDEX(Data_checks!$C$31:$E$34,MATCH(D14,Data_checks!$B$31:$B$34,0),MATCH(LEFT(D7,1),Data_checks!$C$30:$E$30,0)) -> 0.8 | E21: =INDEX(Data_checks!$C$31:$E$34,MATCH(E14,Data_checks!$B$31:$B$34,0),MATCH(LEFT(E7,1),Data_checks!$C$30:$E$30,0)) -> 0.85 | F21: =INDEX(Data_checks!$C$31:$E$34,MATCH(F14,Data_checks!$B$31:$B$34,0),MATCH(LEFT(F7,1),Data_checks!$C$30:$E$30,0)) -> 0.93 | G21: =INDEX(Data_checks!$C$31:$E$34,MATCH(G14,Data_checks!$B$31:$B$34,0),MATCH(LEFT(G7,1),Data_checks!$C$30:$E$30,0)) -> 0.8 | H21: =INDEX(Data_checks!$C$31:$E$34,MATCH(H14,Data_checks!$B$31:$B$34,0),MATCH(LEFT(H7,1),Data_checks!$C$30:$E$30,0)) -> 0.85 | I21: =INDEX(Data_checks!$C$31:$E$34,MATCH(I14,Data_checks!$B$31:$B$34,0),MATCH(LEFT(I7,1),Data_checks!$C$30:$E$30,0)) -> 0.98 | J21: =INDEX(Data_checks!$C$31:$E$34,MATCH(J14,Data_checks!$B$31:$B$34,0),MATCH(LEFT(J7,1),Data_checks!$C$30:$E$30,0)) -> 0.85 | ... N21: =INDEX(Data_checks!$C$31:$E$34,MATCH(N14,Data_checks!$B$31:$B$34,0),MATCH(LEFT(N7,1),Data_checks!$C$30:$E$30,0)) -> 0.65
B22: =B15 -> 2 | C22: =INDEX(Data_checks!$C$31:$E$34,MATCH(C15,Data_checks!$B$31:$B$34,0),MATCH(LEFT(C8,1),Data_checks!$C$30:$E$30,0)) -> 0.93 | D22: =INDEX(Data_checks!$C$31:$E$34,MATCH(D15,Data_checks!$B$31:$B$34,0),MATCH(LEFT(D8,1),Data_checks!$C$30:$E$30,0)) -> 0.65 | E22: =INDEX(Data_checks!$C$31:$E$34,MATCH(E15,Data_checks!$B$31:$B$34,0),MATCH(LEFT(E8,1),Data_checks!$C$30:$E$30,0)) -> 0.65 | F22: =INDEX(Data_checks!$C$31:$E$34,MATCH(F15,Data_checks!$B$31:$B$34,0),MATCH(LEFT(F8,1),Data_checks!$C$30:$E$30,0)) -> 0.93 | G22: =INDEX(Data_checks!$C$31:$E$34,MATCH(G15,Data_checks!$B$31:$B$34,0),MATCH(LEFT(G8,1),Data_checks!$C$30:$E$30,0)) -> 0.85 | H22: =INDEX(Data_checks!$C$31:$E$34,MATCH(H15,Data_checks!$B$31:$B$34,0),MATCH(LEFT(H8,1),Data_checks!$C$30:$E$30,0)) -> 0.65 | I22: =INDEX(Data_checks!$C$31:$E$34,MATCH(I15,Data_checks!$B$31:$B$34,0),MATCH(LEFT(I8,1),Data_checks!$C$30:$E$30,0)) -> 0.98 | J22: =INDEX(Data_checks!$C$31:$E$34,MATCH(J15,Data_checks!$B$31:$B$34,0),MATCH(LEFT(J8,1),Data_checks!$C$30:$E$30,0)) -> 0.85 | ... N22: =INDEX(Data_checks!$C$31:$E$34,MATCH(N15,Data_checks!$B$31:$B$34,0),MATCH(LEFT(N8,1),Data_checks!$C$30:$E$30,0)) -> 0.65
B23: =B16 -> 3 | C23: =INDEX(Data_checks!$C$31:$E$34,MATCH(C16,Data_checks!$B$31:$B$34,0),MATCH(LEFT(C9,1),Data_checks!$C$30:$E$30,0)) -> 0.85 | D23: =INDEX(Data_checks!$C$31:$E$34,MATCH(D16,Data_checks!$B$31:$B$34,0),MATCH(LEFT(D9,1),Data_checks!$C$30:$E$30,0)) -> 0.65 | E23: =INDEX(Data_checks!$C$31:$E$34,MATCH(E16,Data_checks!$B$31:$B$34,0),MATCH(LEFT(E9,1),Data_checks!$C$30:$E$30,0)) -> 0.85 | F23: =INDEX(Data_checks!$C$31:$E$34,MATCH(F16,Data_checks!$B$31:$B$34,0),MATCH(LEFT(F9,1),Data_checks!$C$30:$E$30,0)) -> 0.85 | G23: =INDEX(Data_checks!$C$31:$E$34,MATCH(G16,Data_checks!$B$31:$B$34,0),MATCH(LEFT(G9,1),Data_checks!$C$30:$E$30,0)) -> 0.65 | H23: =INDEX(Data_checks!$C$31:$E$34,MATCH(H16,Data_checks!$B$31:$B$34,0),MATCH(LEFT(H9,1),Data_checks!$C$30:$E$30,0)) -> 0.65 | I23: =INDEX(Data_checks!$C$31:$E$34,MATCH(I16,Data_checks!$B$31:$B$34,0),MATCH(LEFT(I9,1),Data_checks!$C$30:$E$30,0)) -> 0.98 | J23: =INDEX(Data_checks!$C$31:$E$34,MATCH(J16,Data_checks!$B$31:$B$34,0),MATCH(LEFT(J9,1),Data_checks!$C$30:$E$30,0)) -> 0.85 | ... N23: =INDEX(Data_checks!$C$31:$E$34,MATCH(N16,Data_checks!$B$31:$B$34,0),MATCH(LEFT(N9,1),Data_checks!$C$30:$E$30,0)) -> 0.65
B24: =B17 -> 4 | C24: =INDEX(Data_checks!$C$31:$E$34,MATCH(C17,Data_checks!$B$31:$B$34,0),MATCH(LEFT(C10,1),Data_checks!$C$30:$E$30,0)) -> 0.85 | D24: =INDEX(Data_checks!$C$31:$E$34,MATCH(D17,Data_checks!$B$31:$B$34,0),MATCH(LEFT(D10,1),Data_checks!$C$30:$E$30,0)) -> 0.65 | E24: =INDEX(Data_checks!$C$31:$E$34,MATCH(E17,Data_checks!$B$31:$B$34,0),MATCH(LEFT(E10,1),Data_checks!$C$30:$E$30,0)) -> 0.45 | F24: =INDEX(Data_checks!$C$31:$E$34,MATCH(F17,Data_checks!$B$31:$B$34,0),MATCH(LEFT(F10,1),Data_checks!$C$30:$E$30,0)) -> 0.65 | G24: =INDEX(Data_checks!$C$31:$E$34,MATCH(G17,Data_checks!$B$31:$B$34,0),MATCH(LEFT(G10,1),Data_checks!$C$30:$E$30,0)) -> 0.65 | H24: =INDEX(Data_checks!$C$31:$E$34,MATCH(H17,Data_checks!$B$31:$B$34,0),MATCH(LEFT(H10,1),Data_checks!$C$30:$E$30,0)) -> 0.45 | I24: =INDEX(Data_checks!$C$31:$E$34,MATCH(I17,Data_checks!$B$31:$B$34,0),MATCH(LEFT(I10,1),Data_checks!$C$30:$E$30,0)) -> 0.65 | J24: =INDEX(Data_checks!$C$31:$E$34,MATCH(J17,Data_checks!$B$31:$B$34,0),MATCH(LEFT(J10,1),Data_checks!$C$30:$E$30,0)) -> 0.85 | ... N24: =INDEX(Data_checks!$C$31:$E$34,MATCH(N17,Data_checks!$B$31:$B$34,0),MATCH(LEFT(N10,1),Data_checks!$C$30:$E$30,0)) -> 0.45
B26: Projected cinemagoers (split by screen for commission calculation)
B27: Screen | C27: {=C20:N20} -> Jan | D27: Feb | E27: Mar | F27: Apr | G27: May | H27: Jun | I27: Jul | J27: Aug | K27: Sep | L27: Oct | M27: Nov | N27: Dec
B28: =B21 -> 1 | C28: =VLOOKUP($B28,Data_checks!$B$6:$C$9,2,TRUE)*C21*Parameters!$C$5*Parameters!$C$4 -> 142290 | D28: =VLOOKUP($B28,Data_checks!$B$6:$C$9,2,TRUE)*D21*Parameters!$C$5*Parameters!$C$4 -> 122400 | E28: =VLOOKUP($B28,Data_checks!$B$6:$C$9,2,TRUE)*E21*Parameters!$C$5*Parameters!$C$4 -> 130050 | F28: =VLOOKUP($B28,Data_checks!$B$6:$C$9,2,TRUE)*F21*Parameters!$C$5*Parameters!$C$4 -> 142290 | G28: =VLOOKUP($B28,Data_checks!$B$6:$C$9,2,TRUE)*G21*Parameters!$C$5*Parameters!$C$4 -> 122400 | H28: =VLOOKUP($B28,Data_checks!$B$6:$C$9,2,TRUE)*H21*Parameters!$C$5*Parameters!$C$4 -> 130050 | I28: =VLOOKUP($B28,Data_checks!$B$6:$C$9,2,TRUE)*I21*Parameters!$C$5*Parameters!$C$4 -> 149940 | J28: =VLOOKUP($B28,Data_checks!$B$6:$C$9,2,TRUE)*J21*Parameters!$C$5*Parameters!$C$4 -> 130050 | ... N28: =VLOOKUP($B28,Data_checks!$B$6:$C$9,2,TRUE)*N21*Parameters!$C$5*Parameters!$C$4 -> 99450
B29: =B22 -> 2 | C29: =VLOOKUP($B29,Data_checks!$B$6:$C$9,2,TRUE)*C22*Parameters!$C$5*Parameters!$C$4 -> 75330 | D29: =VLOOKUP($B29,Data_checks!$B$6:$C$9,2,TRUE)*D22*Parameters!$C$5*Parameters!$C$4 -> 52650 | E29: =VLOOKUP($B29,Data_checks!$B$6:$C$9,2,TRUE)*E22*Parameters!$C$5*Parameters!$C$4 -> 52650 | F29: =VLOOKUP($B29,Data_checks!$B$6:$C$9,2,TRUE)*F22*Parameters!$C$5*Parameters!$C$4 -> 75330 | G29: =VLOOKUP($B29,Data_checks!$B$6:$C$9,2,TRUE)*G22*Parameters!$C$5*Parameters!$C$4 -> 68850 | H29: =VLOOKUP($B29,Data_checks!$B$6:$C$9,2,TRUE)*H22*Parameters!$C$5*Parameters!$C$4 -> 52650 | I29: =VLOOKUP($B29,Data_checks!$B$6:$C$9,2,TRUE)*I22*Parameters!$C$5*Parameters!$C$4 -> 79380 | J29: =VLOOKUP($B29,Data_checks!$B$6:$C$9,2,TRUE)*J22*Parameters!$C$5*Parameters!$C$4 -> 68850 | ... N29: =VLOOKUP($B29,Data_checks!$B$6:$C$9,2,TRUE)*N22*Parameters!$C$5*Parameters!$C$4 -> 52650
B30: =B23 -> 3 | C30: =VLOOKUP($B30,Data_checks!$B$6:$C$9,2,TRUE)*C23*Parameters!$C$5*Parameters!$C$4 -> 30600 | D30: =VLOOKUP($B30,Data_checks!$B$6:$C$9,2,TRUE)*D23*Parameters!$C$5*Parameters!$C$4 -> 23400 | E30: =VLOOKUP($B30,Data_checks!$B$6:$C$9,2,TRUE)*E23*Parameters!$C$5*Parameters!$C$4 -> 30600 | F30: =VLOOKUP($B30,Data_checks!$B$6:$C$9,2,TRUE)*F23*Parameters!$C$5*Parameters!$C$4 -> 30600 | G30: =VLOOKUP($B30,Data_checks!$B$6:$C$9,2,TRUE)*G23*Parameters!$C$5*Parameters!$C$4 -> 23400 | H30: =VLOOKUP($B30,Data_checks!$B$6:$C$9,2,TRUE)*H23*Parameters!$C$5*Parameters!$C$4 -> 23400 | I30: =VLOOKUP($B30,Data_checks!$B$6:$C$9,2,TRUE)*I23*Parameters!$C$5*Parameters!$C$4 -> 35280 | J30: =VLOOKUP($B30,Data_checks!$B$6:$C$9,2,TRUE)*J23*Parameters!$C$5*Parameters!$C$4 -> 30600 | ... N30: =VLOOKUP($B30,Data_checks!$B$6:$C$9,2,TRUE)*N23*Parameters!$C$5*Parameters!$C$4 -> 23400
B31: =B24 -> 4 | C31: =VLOOKUP($B31,Data_checks!$B$6:$C$9,2,TRUE)*C24*Parameters!$C$5*Parameters!$C$4 -> 22950 | D31: =VLOOKUP($B31,Data_checks!$B$6:$C$9,2,TRUE)*D24*Parameters!$C$5*Parameters!$C$4 -> 17550 | E31: =VLOOKUP($B31,Data_checks!$B$6:$C$9,2,TRUE)*E24*Parameters!$C$5*Parameters!$C$4 -> 12150 | F31: =VLOOKUP($B31,Data_checks!$B$6:$C$9,2,TRUE)*F24*Parameters!$C$5*Parameters!$C$4 -> 17550 | G31: =VLOOKUP($B31,Data_checks!$B$6:$C$9,2,TRUE)*G24*Parameters!$C$5*Parameters!$C$4 -> 17550 | H31: =VLOOKUP($B31,Data_checks!$B$6:$C$9,2,TRUE)*H24*Parameters!$C$5*Parameters!$C$4 -> 12150 | I31: =VLOOKUP($B31,Data_checks!$B$6:$C$9,2,TRUE)*I24*Parameters!$C$5*Parameters!$C$4 -> 17550 | J31: =VLOOKUP($B31,Data_checks!$B$6:$C$9,2,TRUE)*J24*Parameters!$C$5*Parameters!$C$4 -> 22950 | ... N31: =VLOOKUP($B31,Data_checks!$B$6:$C$9,2,TRUE)*N24*Parameters!$C$5*Parameters!$C$4 -> 12150 | P31: Check on attendance data
B32: Total cinema | C32: =SUM(C28:C31) -> 271170 | D32: =SUM(D28:D31) -> 216000 | E32: =SUM(E28:E31) -> 225450 | F32: =SUM(F28:F31) -> 265770 | G32: =SUM(G28:G31) -> 232200 | H32: =SUM(H28:H31) -> 218250 | I32: =SUM(I28:I31) -> 282150 | J32: =SUM(J28:J31) -> 252450 | ... N32: =SUM(N28:N31) -> 187650 | O32: =SUM(C32:N32) -> 2844360 | P32: =IF(O32=Data_checks!E58,"Data is internally consistent","Data is not consistent. Please check") -> Data is internally consistent
B34: Number of films seen split by unique cinemagoers (This is the number of films seen split by month and by unique cinemagoers. E.g. if you sum up row 49, i.e. the number of cinemagoers who have seen 14 movies a year, the sum would equal to that in the data check (5040))
B35: Total number of movies seen in yr | C35: =C27 -> Jan | D35: =D27 -> Feb | E35: =E27 -> Mar | F35: =F27 -> Apr | G35: =G27 -> May | H35: =H27 -> Jun | I35: =I27 -> Jul | J35: =J27 -> Aug | ... N35: =N27 -> Dec
B36: =Data!B21 -> 1 | C36: =C$32*Data_checks!$F44 -> 17658.14 | D36: =D$32*Data_checks!$F44 -> 14065.561 | E36: =E$32*Data_checks!$F44 -> 14680.93 | F36: =F$32*Data_checks!$F44 -> 17306.501 | G36: =G$32*Data_checks!$F44 -> 15120.478 | H36: =H$32*Data_checks!$F44 -> 14212.078 | I36: =I$32*Data_checks!$F44 -> 18373.139 | J36: =J$32*Data_checks!$F44 -> 16439.125 | ... N36: =N$32*Data_checks!$F44 -> 12219.456
B37: =Data!B22 -> 2 | C37: =C$32*Data_checks!$F45 -> 51481.458 | D37: =D$32*Data_checks!$F45 -> 41007.467 | E37: =E$32*Data_checks!$F45 -> 42801.544 | F37: =F$32*Data_checks!$F45 -> 50456.271 | G37: =G$32*Data_checks!$F45 -> 44083.027 | H37: =H$32*Data_checks!$F45 -> 41434.629 | I37: =I$32*Data_checks!$F45 -> 53566.004 | J37: =J$32*Data_checks!$F45 -> 47927.478 | ... N37: =N$32*Data_checks!$F45 -> 35625.237
B38: =Data!B23 -> 3 | C38: =C$32*Data_checks!$F46 -> 51481.458 | D38: =D$32*Data_checks!$F46 -> 41007.467 | E38: =E$32*Data_checks!$F46 -> 42801.544 | F38: =F$32*Data_checks!$F46 -> 50456.271 | G38: =G$32*Data_checks!$F46 -> 44083.027 | H38: =H$32*Data_checks!$F46 -> 41434.629 | I38: =I$32*Data_checks!$F46 -> 53566.004 | J38: =J$32*Data_checks!$F46 -> 47927.478 | ... N38: =N$32*Data_checks!$F46 -> 35625.237
B39: =Data!B24 -> 4 | C39: =C$32*Data_checks!$F47 -> 51481.458 | D39: =D$32*Data_checks!$F47 -> 41007.467 | E39: =E$32*Data_checks!$F47 -> 42801.544 | F39: =F$32*Data_checks!$F47 -> 50456.271 | G39: =G$32*Data_checks!$F47 -> 44083.027 | H39: =H$32*Data_checks!$F47 -> 41434.629 | I39: =I$32*Data_checks!$F47 -> 53566.004 | J39: =J$32*Data_checks!$F47 -> 47927.478 | ... N39: =N$32*Data_checks!$F47 -> 35625.237
B40: =Data!B25 -> 5 | C40: =C$32*Data_checks!$F48 -> 38611.094 | D40: =D$32*Data_checks!$F48 -> 30755.601 | E40: =E$32*Data_checks!$F48 -> 32101.158 | F40: =F$32*Data_checks!$F48 -> 37842.204 | G40: =G$32*Data_checks!$F48 -> 33062.271 | H40: =H$32*Data_checks!$F48 -> 31075.971 | I40: =I$32*Data_checks!$F48 -> 40174.503 | J40: =J$32*Data_checks!$F48 -> 35945.608 | ... N40: =N$32*Data_checks!$F48 -> 26718.928
B41: =Data!B26 -> 6 | C41: =C$32*Data_checks!$F49 -> 30888.875 | D41: =D$32*Data_checks!$F49 -> 24604.48 | E41: =E$32*Data_checks!$F49 -> 25680.926 | F41: =F$32*Data_checks!$F49 -> 30273.763 | G41: =G$32*Data_checks!$F49 -> 26449.816 | H41: =H$32*Data_checks!$F49 -> 24860.777 | I41: =I$32*Data_checks!$F49 -> 32139.603 | J41: =J$32*Data_checks!$F49 -> 28756.487 | ... N41: =N$32*Data_checks!$F49 -> 21375.142
B42: =Data!B27 -> 7 | C42: =C$32*Data_checks!$F50 -> 18018.51 | D42: =D$32*Data_checks!$F50 -> 14352.614 | E42: =E$32*Data_checks!$F50 -> 14980.54 | F42: =F$32*Data_checks!$F50 -> 17659.695 | G42: =G$32*Data_checks!$F50 -> 15429.06 | H42: =H$32*Data_checks!$F50 -> 14502.12 | I42: =I$32*Data_checks!$F50 -> 18748.102 | J42: =J$32*Data_checks!$F50 -> 16774.617 | ... N42: =N$32*Data_checks!$F50 -> 12468.833
B43: =Data!B28 -> 8 | C43: =C$32*Data_checks!$F51 -> 4118.5166 | D43: =D$32*Data_checks!$F51 -> 3280.5974 | E43: =E$32*Data_checks!$F51 -> 3424.1235 | F43: =F$32*Data_checks!$F51 -> 4036.5017 | G43: =G$32*Data_checks!$F51 -> 3526.6422 | H43: =H$32*Data_checks!$F51 -> 3314.7703 | I43: =I$32*Data_checks!$F51 -> 4285.2803 | J43: =J$32*Data_checks!$F51 -> 3834.1982 | ... N43: =N$32*Data_checks!$F51 -> 2850.019
B44: =Data!B29 -> 9 | C44: =C$32*Data_checks!$F52 -> 3088.8875 | D44: =D$32*Data_checks!$F52 -> 2460.448 | E44: =E$32*Data_checks!$F52 -> 2568.0926 | F44: =F$32*Data_checks!$F52 -> 3027.3763 | G44: =G$32*Data_checks!$F52 -> 2644.9816 | H44: =H$32*Data_checks!$F52 -> 2486.0777 | I44: =I$32*Data_checks!$F52 -> 3213.9603 | J44: =J$32*Data_checks!$F52 -> 2875.6487 | ... N44: =N$32*Data_checks!$F52 -> 2137.5142
B45: =Data!B30 -> 10 | C45: =C$32*Data_checks!$F53 -> 1029.6292 | D45: =D$32*Data_checks!$F53 -> 820.14935 | E45: =E$32*Data_checks!$F53 -> 856.03088 | F45: =F$32*Data_checks!$F53 -> 1009.1254 | G45: =G$32*Data_checks!$F53 -> 881.66055 | H45: =H$32*Data_checks!$F53 -> 828.69257 | I45: =I$32*Data_checks!$F53 -> 1071.3201 | J45: =J$32*Data_checks!$F53 -> 958.54955 | ... N45: =N$32*Data_checks!$F53 -> 712.50475
B46: =Data!B31 -> 11 | C46: =C$32*Data_checks!$F54 -> 1132.5921 | D46: =D$32*Data_checks!$F54 -> 902.16428 | E46: =E$32*Data_checks!$F54 -> 941.63397 | F46: =F$32*Data_checks!$F54 -> 1110.038 | G46: =G$32*Data_checks!$F54 -> 969.8266 | H46: =H$32*Data_checks!$F54 -> 911.56183 | I46: =I$32*Data_checks!$F54 -> 1178.4521 | J46: =J$32*Data_checks!$F54 -> 1054.4045 | ... N46: =N$32*Data_checks!$F54 -> 783.75522
B47: =Data!B32 -> 12 | C47: =C$32*Data_checks!$F55 -> 1029.6292 | D47: =D$32*Data_checks!$F55 -> 820.14935 | E47: =E$32*Data_checks!$F55 -> 856.03088 | F47: =F$32*Data_checks!$F55 -> 1009.1254 | G47: =G$32*Data_checks!$F55 -> 881.66055 | H47: =H$32*Data_checks!$F55 -> 828.69257 | I47: =I$32*Data_checks!$F55 -> 1071.3201 | J47: =J$32*Data_checks!$F55 -> 958.54955 | ... N47: =N$32*Data_checks!$F55 -> 712.50475
...
